ERROR 2023-05-15 23:28:59,803 log 10876 15300 Internal Server Error: /auth/register/
Traceback (most recent call last):
  File "C:\Users\Acer\AppData\Local\Programs\Python\Python311\Lib\site-packages\django\core\handlers\exception.py", line 56, in inner
    response = get_response(request)
               ^^^^^^^^^^^^^^^^^^^^^
  File "C:\Users\Acer\AppData\Local\Programs\Python\Python311\Lib\site-packages\django\core\handlers\base.py", line 197, in _get_response
    response = wrapped_callback(request, *callback_args, **callback_kwargs)
               ^^^^^^^^^^^^^^^^^^^^^^^^^^^^^^^^^^^^^^^^^^^^^^^^^^^^^^^^^^^^
  File "C:\Users\Acer\AppData\Local\Programs\Python\Python311\Lib\site-packages\django\views\decorators\csrf.py", line 55, in wrapped_view
    return view_func(*args, **kwargs)
           ^^^^^^^^^^^^^^^^^^^^^^^^^^
  File "C:\Users\Acer\AppData\Local\Programs\Python\Python311\Lib\site-packages\django\views\generic\base.py", line 103, in view
    return self.dispatch(request, *args, **kwargs)
           ^^^^^^^^^^^^^^^^^^^^^^^^^^^^^^^^^^^^^^^
  File "C:\Users\Acer\AppData\Local\Programs\Python\Python311\Lib\site-packages\rest_framework\views.py", line 509, in dispatch
    response = self.handle_exception(exc)
               ^^^^^^^^^^^^^^^^^^^^^^^^^^
  File "C:\Users\Acer\AppData\Local\Programs\Python\Python311\Lib\site-packages\rest_framework\views.py", line 469, in handle_exception
    self.raise_uncaught_exception(exc)
  File "C:\Users\Acer\AppData\Local\Programs\Python\Python311\Lib\site-packages\rest_framework\views.py", line 480, in raise_uncaught_exception
    raise exc
  File "C:\Users\Acer\AppData\Local\Programs\Python\Python311\Lib\site-packages\rest_framework\views.py", line 506, in dispatch
    response = handler(request, *args, **kwargs)
               ^^^^^^^^^^^^^^^^^^^^^^^^^^^^^^^^^
  File "E:\uni\8\OOD\Enigma_BackEnd\Enigma\MyUser\views.py", line 34, in post
    token, created = Token.objects.get_or_create(user=user)
                     ^^^^^
NameError: name 'Token' is not defined
ERROR 2023-05-15 23:28:59,803 basehttp 10876 15300 "POST /auth/register/ HTTP/1.1" 500 98869
ERROR 2023-05-15 23:30:02,107 log 14516 5672 Internal Server Error: /auth/register/
Traceback (most recent call last):
  File "C:\Users\Acer\AppData\Local\Programs\Python\Python311\Lib\site-packages\django\core\handlers\exception.py", line 56, in inner
    response = get_response(request)
               ^^^^^^^^^^^^^^^^^^^^^
  File "C:\Users\Acer\AppData\Local\Programs\Python\Python311\Lib\site-packages\django\core\handlers\base.py", line 197, in _get_response
    response = wrapped_callback(request, *callback_args, **callback_kwargs)
               ^^^^^^^^^^^^^^^^^^^^^^^^^^^^^^^^^^^^^^^^^^^^^^^^^^^^^^^^^^^^
  File "C:\Users\Acer\AppData\Local\Programs\Python\Python311\Lib\site-packages\django\views\decorators\csrf.py", line 55, in wrapped_view
    return view_func(*args, **kwargs)
           ^^^^^^^^^^^^^^^^^^^^^^^^^^
  File "C:\Users\Acer\AppData\Local\Programs\Python\Python311\Lib\site-packages\django\views\generic\base.py", line 103, in view
    return self.dispatch(request, *args, **kwargs)
           ^^^^^^^^^^^^^^^^^^^^^^^^^^^^^^^^^^^^^^^
  File "C:\Users\Acer\AppData\Local\Programs\Python\Python311\Lib\site-packages\rest_framework\views.py", line 509, in dispatch
    response = self.handle_exception(exc)
               ^^^^^^^^^^^^^^^^^^^^^^^^^^
  File "C:\Users\Acer\AppData\Local\Programs\Python\Python311\Lib\site-packages\rest_framework\views.py", line 469, in handle_exception
    self.raise_uncaught_exception(exc)
  File "C:\Users\Acer\AppData\Local\Programs\Python\Python311\Lib\site-packages\rest_framework\views.py", line 480, in raise_uncaught_exception
    raise exc
  File "C:\Users\Acer\AppData\Local\Programs\Python\Python311\Lib\site-packages\rest_framework\views.py", line 506, in dispatch
    response = handler(request, *args, **kwargs)
               ^^^^^^^^^^^^^^^^^^^^^^^^^^^^^^^^^
  File "E:\uni\8\OOD\Enigma_BackEnd\Enigma\MyUser\views.py", line 45, in post
    email_body ='Hi '+user.username+' Use link below to verify your email \n'+absurl
                      ^^^^^^^^^^^^^
AttributeError: 'MyUser' object has no attribute 'username'
ERROR 2023-05-15 23:30:02,107 basehttp 14516 5672 "POST /auth/register/ HTTP/1.1" 500 100406
ERROR 2023-05-15 23:30:26,577 log 14516 5672 Internal Server Error: /auth/register/
Traceback (most recent call last):
  File "C:\Users\Acer\AppData\Local\Programs\Python\Python311\Lib\site-packages\django\core\handlers\exception.py", line 56, in inner
    response = get_response(request)
               ^^^^^^^^^^^^^^^^^^^^^
  File "C:\Users\Acer\AppData\Local\Programs\Python\Python311\Lib\site-packages\django\core\handlers\base.py", line 197, in _get_response
    response = wrapped_callback(request, *callback_args, **callback_kwargs)
               ^^^^^^^^^^^^^^^^^^^^^^^^^^^^^^^^^^^^^^^^^^^^^^^^^^^^^^^^^^^^
  File "C:\Users\Acer\AppData\Local\Programs\Python\Python311\Lib\site-packages\django\views\decorators\csrf.py", line 55, in wrapped_view
    return view_func(*args, **kwargs)
           ^^^^^^^^^^^^^^^^^^^^^^^^^^
  File "C:\Users\Acer\AppData\Local\Programs\Python\Python311\Lib\site-packages\django\views\generic\base.py", line 103, in view
    return self.dispatch(request, *args, **kwargs)
           ^^^^^^^^^^^^^^^^^^^^^^^^^^^^^^^^^^^^^^^
  File "C:\Users\Acer\AppData\Local\Programs\Python\Python311\Lib\site-packages\rest_framework\views.py", line 509, in dispatch
    response = self.handle_exception(exc)
               ^^^^^^^^^^^^^^^^^^^^^^^^^^
  File "C:\Users\Acer\AppData\Local\Programs\Python\Python311\Lib\site-packages\rest_framework\views.py", line 469, in handle_exception
    self.raise_uncaught_exception(exc)
  File "C:\Users\Acer\AppData\Local\Programs\Python\Python311\Lib\site-packages\rest_framework\views.py", line 480, in raise_uncaught_exception
    raise exc
  File "C:\Users\Acer\AppData\Local\Programs\Python\Python311\Lib\site-packages\rest_framework\views.py", line 506, in dispatch
    response = handler(request, *args, **kwargs)
               ^^^^^^^^^^^^^^^^^^^^^^^^^^^^^^^^^
  File "E:\uni\8\OOD\Enigma_BackEnd\Enigma\MyUser\views.py", line 45, in post
    email_body ='Hi '+user.username+' Use link below to verify your email \n'+absurl
                      ^^^^^^^^^^^^^
AttributeError: 'MyUser' object has no attribute 'username'
ERROR 2023-05-15 23:30:26,577 basehttp 14516 5672 "POST /auth/register/ HTTP/1.1" 500 100406
ERROR 2023-05-15 23:31:38,367 log 6408 17072 Internal Server Error: /auth/register/
Traceback (most recent call last):
  File "C:\Users\Acer\AppData\Local\Programs\Python\Python311\Lib\site-packages\django\core\handlers\exception.py", line 56, in inner
    response = get_response(request)
               ^^^^^^^^^^^^^^^^^^^^^
  File "C:\Users\Acer\AppData\Local\Programs\Python\Python311\Lib\site-packages\django\core\handlers\base.py", line 197, in _get_response
    response = wrapped_callback(request, *callback_args, **callback_kwargs)
               ^^^^^^^^^^^^^^^^^^^^^^^^^^^^^^^^^^^^^^^^^^^^^^^^^^^^^^^^^^^^
  File "C:\Users\Acer\AppData\Local\Programs\Python\Python311\Lib\site-packages\django\views\decorators\csrf.py", line 55, in wrapped_view
    return view_func(*args, **kwargs)
           ^^^^^^^^^^^^^^^^^^^^^^^^^^
  File "C:\Users\Acer\AppData\Local\Programs\Python\Python311\Lib\site-packages\django\views\generic\base.py", line 103, in view
    return self.dispatch(request, *args, **kwargs)
           ^^^^^^^^^^^^^^^^^^^^^^^^^^^^^^^^^^^^^^^
  File "C:\Users\Acer\AppData\Local\Programs\Python\Python311\Lib\site-packages\rest_framework\views.py", line 509, in dispatch
    response = self.handle_exception(exc)
               ^^^^^^^^^^^^^^^^^^^^^^^^^^
  File "C:\Users\Acer\AppData\Local\Programs\Python\Python311\Lib\site-packages\rest_framework\views.py", line 469, in handle_exception
    self.raise_uncaught_exception(exc)
  File "C:\Users\Acer\AppData\Local\Programs\Python\Python311\Lib\site-packages\rest_framework\views.py", line 480, in raise_uncaught_exception
    raise exc
  File "C:\Users\Acer\AppData\Local\Programs\Python\Python311\Lib\site-packages\rest_framework\views.py", line 506, in dispatch
    response = handler(request, *args, **kwargs)
               ^^^^^^^^^^^^^^^^^^^^^^^^^^^^^^^^^
  File "E:\uni\8\OOD\Enigma_BackEnd\Enigma\MyUser\views.py", line 49, in post
    Util.send_email(data)
  File "E:\uni\8\OOD\Enigma_BackEnd\Enigma\MyUser\utils.py", line 8, in send_email
    email.send()
  File "C:\Users\Acer\AppData\Local\Programs\Python\Python311\Lib\site-packages\django\core\mail\message.py", line 298, in send
    return self.get_connection(fail_silently).send_messages([self])
           ^^^^^^^^^^^^^^^^^^^^^^^^^^^^^^^^^^^^^^^^^^^^^^^^^^^^^^^^
  File "C:\Users\Acer\AppData\Local\Programs\Python\Python311\Lib\site-packages\django\core\mail\backends\smtp.py", line 124, in send_messages
    new_conn_created = self.open()
                       ^^^^^^^^^^^
  File "C:\Users\Acer\AppData\Local\Programs\Python\Python311\Lib\site-packages\django\core\mail\backends\smtp.py", line 80, in open
    self.connection = self.connection_class(
                      ^^^^^^^^^^^^^^^^^^^^^^
  File "C:\Users\Acer\AppData\Local\Programs\Python\Python311\Lib\smtplib.py", line 255, in __init__
    (code, msg) = self.connect(host, port)
                  ^^^^^^^^^^^^^^^^^^^^^^^^
  File "C:\Users\Acer\AppData\Local\Programs\Python\Python311\Lib\smtplib.py", line 341, in connect
    self.sock = self._get_socket(host, port, self.timeout)
                ^^^^^^^^^^^^^^^^^^^^^^^^^^^^^^^^^^^^^^^^^^
  File "C:\Users\Acer\AppData\Local\Programs\Python\Python311\Lib\smtplib.py", line 312, in _get_socket
    return socket.create_connection((host, port), timeout,
           ^^^^^^^^^^^^^^^^^^^^^^^^^^^^^^^^^^^^^^^^^^^^^^^
  File "C:\Users\Acer\AppData\Local\Programs\Python\Python311\Lib\socket.py", line 851, in create_connection
    raise exceptions[0]
  File "C:\Users\Acer\AppData\Local\Programs\Python\Python311\Lib\socket.py", line 836, in create_connection
    sock.connect(sa)
ConnectionRefusedError: [WinError 10061] No connection could be made because the target machine actively refused it
ERROR 2023-05-15 23:31:38,367 basehttp 6408 17072 "POST /auth/register/ HTTP/1.1" 500 140705
ERROR 2023-05-15 23:40:54,603 log 16776 14204 Internal Server Error: /group/DeleteGroup/
ERROR 2023-05-15 23:40:54,603 log 16776 14204 Internal Server Error: /group/GroupInfo/
ERROR 2023-05-15 23:40:54,603 log 16776 14204 Internal Server Error: /group/GroupInfo/
ERROR 2023-05-15 23:40:54,634 log 16776 14204 Internal Server Error: /group/ShowGroups/
ERROR 2023-05-15 23:40:54,650 log 16776 14204 Internal Server Error: /group/ShowMembers/
ERROR 2023-05-15 23:40:57,548 log 16776 14204 Internal Server Error: /auth/UserInfo/
ERROR 2023-05-15 23:40:57,771 log 16776 14204 Internal Server Error: /buy/UserGroupBuys/
ERROR 2023-05-15 23:41:42,415 log 8692 4968 Internal Server Error: /group/DeleteGroup/
ERROR 2023-05-15 23:41:42,415 log 8692 4968 Internal Server Error: /group/GroupInfo/
ERROR 2023-05-15 23:41:42,415 log 8692 4968 Internal Server Error: /group/GroupInfo/
ERROR 2023-05-15 23:41:42,430 log 8692 4968 Internal Server Error: /group/ShowGroups/
ERROR 2023-05-15 23:41:42,462 log 8692 4968 Internal Server Error: /group/ShowMembers/
ERROR 2023-05-15 23:41:45,339 log 8692 4968 Internal Server Error: /buy/UserGroupBuys/
ERROR 2023-05-15 23:50:00,785 log 11596 7124 Internal Server Error: /group/DeleteGroup/
ERROR 2023-05-15 23:50:00,798 log 11596 7124 Internal Server Error: /group/GroupInfo/
ERROR 2023-05-15 23:50:00,800 log 11596 7124 Internal Server Error: /group/GroupInfo/
ERROR 2023-05-15 23:50:00,825 log 11596 7124 Internal Server Error: /group/ShowGroups/
ERROR 2023-05-15 23:50:00,851 log 11596 7124 Internal Server Error: /group/ShowMembers/
ERROR 2023-05-15 23:50:04,193 log 11596 7124 Internal Server Error: /buy/UserGroupBuys/
ERROR 2023-05-15 23:50:51,749 log 12840 13424 Internal Server Error: /group/DeleteGroup/
ERROR 2023-05-15 23:50:51,759 log 12840 13424 Internal Server Error: /group/GroupInfo/
ERROR 2023-05-15 23:50:51,762 log 12840 13424 Internal Server Error: /group/GroupInfo/
ERROR 2023-05-15 23:50:51,781 log 12840 13424 Internal Server Error: /group/ShowGroups/
ERROR 2023-05-15 23:50:51,804 log 12840 13424 Internal Server Error: /group/ShowMembers/
ERROR 2023-05-15 23:50:54,786 log 12840 13424 Internal Server Error: /buy/UserGroupBuys/
ERROR 2023-05-16 00:02:08,252 log 14164 11836 Internal Server Error: /group/DeleteGroup/
ERROR 2023-05-16 00:02:08,261 log 14164 11836 Internal Server Error: /group/GroupInfo/
ERROR 2023-05-16 00:02:08,263 log 14164 11836 Internal Server Error: /group/GroupInfo/
ERROR 2023-05-16 00:02:08,283 log 14164 11836 Internal Server Error: /group/ShowGroups/
ERROR 2023-05-16 00:02:08,304 log 14164 11836 Internal Server Error: /group/ShowMembers/
ERROR 2023-05-16 00:02:11,250 log 14164 11836 Internal Server Error: /auth/UserInfo/
ERROR 2023-05-16 00:02:11,468 log 14164 11836 Internal Server Error: /buy/UserGroupBuys/
ERROR 2023-05-16 13:12:46,883 log 13204 17536 Internal Server Error: /auth/UserInfo/
ERROR 2023-05-16 13:12:59,471 log 7072 4888 Internal Server Error: /group/DeleteGroup/
ERROR 2023-05-16 13:12:59,482 log 7072 4888 Internal Server Error: /group/GroupInfo/
ERROR 2023-05-16 13:12:59,485 log 7072 4888 Internal Server Error: /group/GroupInfo/
ERROR 2023-05-16 13:12:59,511 log 7072 4888 Internal Server Error: /group/ShowGroups/
ERROR 2023-05-16 13:12:59,573 log 7072 4888 Internal Server Error: /group/ShowMembers/
ERROR 2023-05-16 13:13:29,799 log 16180 17368 Internal Server Error: /buy/UserGroupBuys/
ERROR 2023-05-16 13:36:48,919 log 9016 2536 Internal Server Error: /group/DeleteGroup/
ERROR 2023-05-16 13:36:48,929 log 9016 2536 Internal Server Error: /group/GroupInfo/
ERROR 2023-05-16 13:36:48,932 log 9016 2536 Internal Server Error: /group/GroupInfo/
ERROR 2023-05-16 13:36:48,956 log 9016 2536 Internal Server Error: /group/ShowGroups/
ERROR 2023-05-16 13:36:48,982 log 9016 2536 Internal Server Error: /group/ShowMembers/
ERROR 2023-05-16 13:37:55,148 log 9884 12780 Internal Server Error: /buy/UserGroupBuys/
ERROR 2023-05-16 13:38:02,899 log 17528 5904 Internal Server Error: /group/DeleteGroup/
ERROR 2023-05-16 13:38:02,931 log 17528 5904 Internal Server Error: /group/GroupInfo/
ERROR 2023-05-16 13:38:02,940 log 17528 5904 Internal Server Error: /group/GroupInfo/
ERROR 2023-05-16 13:38:03,023 log 17528 5904 Internal Server Error: /group/ShowGroups/
ERROR 2023-05-16 13:38:03,123 log 17528 5904 Internal Server Error: /group/ShowMembers/
ERROR 2023-05-16 13:55:22,653 log 8468 6232 Internal Server Error: /group/DeleteGroup/
ERROR 2023-05-16 13:55:22,661 log 8468 6232 Internal Server Error: /group/GroupInfo/
ERROR 2023-05-16 13:55:22,663 log 8468 6232 Internal Server Error: /group/GroupInfo/
ERROR 2023-05-16 13:55:22,681 log 8468 6232 Internal Server Error: /group/ShowGroups/
ERROR 2023-05-16 13:55:22,700 log 8468 6232 Internal Server Error: /group/ShowMembers/
ERROR 2023-05-16 13:58:24,584 log 6300 13788 Internal Server Error: /group/DeleteGroup/
ERROR 2023-05-16 13:58:24,591 log 6300 13788 Internal Server Error: /group/GroupInfo/
ERROR 2023-05-16 13:58:24,594 log 6300 13788 Internal Server Error: /group/GroupInfo/
ERROR 2023-05-16 13:58:24,610 log 6300 13788 Internal Server Error: /group/ShowGroups/
ERROR 2023-05-16 13:58:24,629 log 6300 13788 Internal Server Error: /group/ShowMembers/
ERROR 2023-05-16 13:58:50,065 log 17608 18292 Internal Server Error: /group/DeleteGroup/
ERROR 2023-05-16 13:58:50,073 log 17608 18292 Internal Server Error: /group/GroupInfo/
ERROR 2023-05-16 13:58:50,075 log 17608 18292 Internal Server Error: /group/GroupInfo/
ERROR 2023-05-16 13:58:50,092 log 17608 18292 Internal Server Error: /group/ShowGroups/
ERROR 2023-05-16 13:58:50,112 log 17608 18292 Internal Server Error: /group/ShowMembers/
ERROR 2023-05-16 14:02:40,717 log 6232 10424 Internal Server Error: /group/DeleteGroup/
ERROR 2023-05-16 14:02:40,726 log 6232 10424 Internal Server Error: /group/GroupInfo/
ERROR 2023-05-16 14:02:40,728 log 6232 10424 Internal Server Error: /group/GroupInfo/
ERROR 2023-05-16 14:02:40,746 log 6232 10424 Internal Server Error: /group/ShowGroups/
ERROR 2023-05-16 14:02:40,765 log 6232 10424 Internal Server Error: /group/ShowMembers/
ERROR 2023-05-16 14:02:45,937 log 14928 2744 Internal Server Error: /group/DeleteGroup/
ERROR 2023-05-16 14:02:45,945 log 14928 2744 Internal Server Error: /group/GroupInfo/
ERROR 2023-05-16 14:02:45,948 log 14928 2744 Internal Server Error: /group/GroupInfo/
ERROR 2023-05-16 14:02:45,967 log 14928 2744 Internal Server Error: /group/ShowGroups/
ERROR 2023-05-16 14:02:45,987 log 14928 2744 Internal Server Error: /group/ShowMembers/
ERROR 2023-05-16 14:05:51,033 log 8396 12988 Internal Server Error: /group/DeleteGroup/
ERROR 2023-05-16 14:05:51,040 log 8396 12988 Internal Server Error: /group/GroupInfo/
ERROR 2023-05-16 14:05:51,042 log 8396 12988 Internal Server Error: /group/GroupInfo/
ERROR 2023-05-16 14:05:51,059 log 8396 12988 Internal Server Error: /group/ShowGroups/
ERROR 2023-05-16 14:05:51,078 log 8396 12988 Internal Server Error: /group/ShowMembers/
ERROR 2023-05-16 14:06:04,747 log 14552 6916 Internal Server Error: /buy/UserGroupBuys/
ERROR 2023-05-16 14:06:11,940 log 15432 16688 Internal Server Error: /auth/UserInfo/
ERROR 2023-05-16 14:07:58,019 log 16172 16836 Internal Server Error: /auth/UserInfo/
ERROR 2023-05-16 14:08:26,996 log 8668 13348 Internal Server Error: /auth/LeaveGroup/
ERROR 2023-05-16 14:08:28,602 log 8668 13348 Internal Server Error: /auth/UserInfo/
ERROR 2023-05-18 11:58:13,987 views 12992 3780 Error: Group not found.
ERROR 2023-05-18 11:58:25,271 views 12992 3780 Error: Group not found.
ERROR 2023-05-18 11:59:10,702 views 12992 3780 Error: 'groupID'
ERROR 2023-05-18 11:59:10,702 log 12992 3780 Internal Server Error: /auth/LeaveGroup/
ERROR 2023-05-18 11:59:10,703 basehttp 12992 3780 "POST /auth/LeaveGroup/ HTTP/1.1" 500 23
ERROR 2023-05-18 11:59:20,660 views 12992 3780 Error: Group not found.
ERROR 2023-05-18 12:01:16,171 views 11236 12216 Error: Group not found.
ERROR 2023-05-18 12:02:19,596 views 11716 10796 Error: Group not found.
ERROR 2023-05-18 12:03:29,239 views 7640 17216 Error: Group not found.
ERROR 2023-05-18 12:03:30,550 views 7640 17216 Error: Group not found.
ERROR 2023-05-18 12:03:44,725 views 16088 15432 Error: Group not found.
ERROR 2023-05-18 12:03:45,668 views 16088 15432 Error: Group not found.
ERROR 2023-05-18 12:03:45,854 views 16088 15432 Error: Group not found.
ERROR 2023-05-18 12:03:46,023 views 16088 15432 Error: Group not found.
ERROR 2023-05-18 12:03:46,162 views 16088 15432 Error: Group not found.
ERROR 2023-05-18 12:03:46,307 views 16088 15432 Error: Group not found.
ERROR 2023-05-18 13:15:42,140 log 16864 8248 Internal Server Error: /auth/register/
Traceback (most recent call last):
  File "C:\Users\Acer\AppData\Local\Programs\Python\Python311\Lib\site-packages\django\core\handlers\exception.py", line 56, in inner
    response = get_response(request)
               ^^^^^^^^^^^^^^^^^^^^^
  File "C:\Users\Acer\AppData\Local\Programs\Python\Python311\Lib\site-packages\django\core\handlers\base.py", line 197, in _get_response
    response = wrapped_callback(request, *callback_args, **callback_kwargs)
               ^^^^^^^^^^^^^^^^^^^^^^^^^^^^^^^^^^^^^^^^^^^^^^^^^^^^^^^^^^^^
  File "C:\Users\Acer\AppData\Local\Programs\Python\Python311\Lib\site-packages\django\views\decorators\csrf.py", line 55, in wrapped_view
    return view_func(*args, **kwargs)
           ^^^^^^^^^^^^^^^^^^^^^^^^^^
  File "C:\Users\Acer\AppData\Local\Programs\Python\Python311\Lib\site-packages\django\views\generic\base.py", line 103, in view
    return self.dispatch(request, *args, **kwargs)
           ^^^^^^^^^^^^^^^^^^^^^^^^^^^^^^^^^^^^^^^
  File "C:\Users\Acer\AppData\Local\Programs\Python\Python311\Lib\site-packages\rest_framework\views.py", line 509, in dispatch
    response = self.handle_exception(exc)
               ^^^^^^^^^^^^^^^^^^^^^^^^^^
  File "C:\Users\Acer\AppData\Local\Programs\Python\Python311\Lib\site-packages\rest_framework\views.py", line 469, in handle_exception
    self.raise_uncaught_exception(exc)
  File "C:\Users\Acer\AppData\Local\Programs\Python\Python311\Lib\site-packages\rest_framework\views.py", line 480, in raise_uncaught_exception
    raise exc
  File "C:\Users\Acer\AppData\Local\Programs\Python\Python311\Lib\site-packages\rest_framework\views.py", line 506, in dispatch
    response = handler(request, *args, **kwargs)
               ^^^^^^^^^^^^^^^^^^^^^^^^^^^^^^^^^
  File "E:\uni\8\OOD\Enigma_BackEnd\Enigma\MyUser\views.py", line 34, in post
    serializer.is_valid(raise_exception=True)
  File "C:\Users\Acer\AppData\Local\Programs\Python\Python311\Lib\site-packages\rest_framework\serializers.py", line 227, in is_valid
    self._validated_data = self.run_validation(self.initial_data)
                           ^^^^^^^^^^^^^^^^^^^^^^^^^^^^^^^^^^^^^^
  File "C:\Users\Acer\AppData\Local\Programs\Python\Python311\Lib\site-packages\rest_framework\serializers.py", line 430, in run_validation
    assert value is not None, '.validate() should return the validated data'
           ^^^^^^^^^^^^^^^^^
AssertionError: .validate() should return the validated data
ERROR 2023-05-18 13:15:42,140 basehttp 16864 8248 "POST /auth/register/ HTTP/1.1" 500 107247
