INFO 2023-05-13 18:49:04,915 autoreload 5080 492 Watching for file changes with StatReloader
INFO 2023-05-13 18:52:57,793 autoreload 14068 3132 Watching for file changes with StatReloader
WARNING 2023-05-13 18:53:20,871 log 14068 8360 Not Found: /
WARNING 2023-05-13 18:53:20,871 basehttp 14068 8360 "GET / HTTP/1.1" 404 2374
WARNING 2023-05-13 18:53:20,938 log 14068 8360 Not Found: /favicon.ico
INFO 2023-05-13 18:53:20,939 basehttp 14068 8360 - Broken pipe from ('127.0.0.1', 59487)
INFO 2023-05-13 18:54:04,296 basehttp 14068 8716 "GET /auth/register HTTP/1.1" 301 0
WARNING 2023-05-13 18:54:04,470 log 14068 8716 Method Not Allowed: /auth/register/
WARNING 2023-05-13 18:54:04,471 basehttp 14068 8716 "GET /auth/register/ HTTP/1.1" 405 8050
INFO 2023-05-13 18:54:04,704 basehttp 14068 2028 - Broken pipe from ('127.0.0.1', 60362)
INFO 2023-05-13 18:54:04,740 basehttp 14068 7120 - Broken pipe from ('127.0.0.1', 60364)
INFO 2023-05-13 18:54:04,745 basehttp 14068 8716 - Broken pipe from ('127.0.0.1', 60358)
INFO 2023-05-13 18:54:04,756 basehttp 14068 2276 - Broken pipe from ('127.0.0.1', 60366)
INFO 2023-05-13 18:54:04,786 basehttp 14068 9592 - Broken pipe from ('127.0.0.1', 60363)
WARNING 2023-05-13 18:54:26,709 log 14068 3504 Bad Request: /auth/register/
WARNING 2023-05-13 18:54:26,710 basehttp 14068 3504 "POST /auth/register/ HTTP/1.1" 400 8163
INFO 2023-05-13 18:55:16,605 basehttp 14068 3504 "POST /auth/register/ HTTP/1.1" 201 8231
INFO 2023-05-13 18:56:17,049 basehttp 14068 8500 "POST /auth/token/ HTTP/1.1" 200 52
ERROR 2023-05-13 18:58:37,213 log 14068 4572 Internal Server Error: /group/CreateGroup/
Traceback (most recent call last):
  File "C:\Users\Acer\AppData\Local\Programs\Python\Python311\Lib\site-packages\django\utils\datastructures.py", line 84, in __getitem__
    list_ = super().__getitem__(key)
            ^^^^^^^^^^^^^^^^^^^^^^^^
KeyError: 'emails'

During handling of the above exception, another exception occurred:

Traceback (most recent call last):
  File "C:\Users\Acer\AppData\Local\Programs\Python\Python311\Lib\site-packages\django\core\handlers\exception.py", line 56, in inner
    response = get_response(request)
               ^^^^^^^^^^^^^^^^^^^^^
  File "C:\Users\Acer\AppData\Local\Programs\Python\Python311\Lib\site-packages\django\core\handlers\base.py", line 197, in _get_response
    response = wrapped_callback(request, *callback_args, **callback_kwargs)
               ^^^^^^^^^^^^^^^^^^^^^^^^^^^^^^^^^^^^^^^^^^^^^^^^^^^^^^^^^^^^
  File "C:\Users\Acer\AppData\Local\Programs\Python\Python311\Lib\site-packages\django\views\decorators\csrf.py", line 55, in wrapped_view
    return view_func(*args, **kwargs)
           ^^^^^^^^^^^^^^^^^^^^^^^^^^
  File "C:\Users\Acer\AppData\Local\Programs\Python\Python311\Lib\site-packages\django\views\generic\base.py", line 103, in view
    return self.dispatch(request, *args, **kwargs)
           ^^^^^^^^^^^^^^^^^^^^^^^^^^^^^^^^^^^^^^^
  File "C:\Users\Acer\AppData\Local\Programs\Python\Python311\Lib\site-packages\rest_framework\views.py", line 509, in dispatch
    response = self.handle_exception(exc)
               ^^^^^^^^^^^^^^^^^^^^^^^^^^
  File "C:\Users\Acer\AppData\Local\Programs\Python\Python311\Lib\site-packages\rest_framework\views.py", line 469, in handle_exception
    self.raise_uncaught_exception(exc)
  File "C:\Users\Acer\AppData\Local\Programs\Python\Python311\Lib\site-packages\rest_framework\views.py", line 480, in raise_uncaught_exception
    raise exc
  File "C:\Users\Acer\AppData\Local\Programs\Python\Python311\Lib\site-packages\rest_framework\views.py", line 506, in dispatch
    response = handler(request, *args, **kwargs)
               ^^^^^^^^^^^^^^^^^^^^^^^^^^^^^^^^^
  File "E:\uni\8\OOD\Enigma_BackEnd\Enigma\Group\views.py", line 24, in post
    data["emails"] = request.data['emails']
                     ~~~~~~~~~~~~^^^^^^^^^^
  File "C:\Users\Acer\AppData\Local\Programs\Python\Python311\Lib\site-packages\django\utils\datastructures.py", line 86, in __getitem__
    raise MultiValueDictKeyError(key)
django.utils.datastructures.MultiValueDictKeyError: 'emails'
ERROR 2023-05-13 18:58:37,216 basehttp 14068 4572 "POST /group/CreateGroup/ HTTP/1.1" 500 106419
ERROR 2023-05-13 18:59:26,194 log 14068 4572 Internal Server Error: /group/CreateGroup/
Traceback (most recent call last):
  File "C:\Users\Acer\AppData\Local\Programs\Python\Python311\Lib\site-packages\django\core\handlers\exception.py", line 56, in inner
    response = get_response(request)
               ^^^^^^^^^^^^^^^^^^^^^
  File "C:\Users\Acer\AppData\Local\Programs\Python\Python311\Lib\site-packages\django\core\handlers\base.py", line 197, in _get_response
    response = wrapped_callback(request, *callback_args, **callback_kwargs)
               ^^^^^^^^^^^^^^^^^^^^^^^^^^^^^^^^^^^^^^^^^^^^^^^^^^^^^^^^^^^^
  File "C:\Users\Acer\AppData\Local\Programs\Python\Python311\Lib\site-packages\django\views\decorators\csrf.py", line 55, in wrapped_view
    return view_func(*args, **kwargs)
           ^^^^^^^^^^^^^^^^^^^^^^^^^^
  File "C:\Users\Acer\AppData\Local\Programs\Python\Python311\Lib\site-packages\django\views\generic\base.py", line 103, in view
    return self.dispatch(request, *args, **kwargs)
           ^^^^^^^^^^^^^^^^^^^^^^^^^^^^^^^^^^^^^^^
  File "C:\Users\Acer\AppData\Local\Programs\Python\Python311\Lib\site-packages\rest_framework\views.py", line 509, in dispatch
    response = self.handle_exception(exc)
               ^^^^^^^^^^^^^^^^^^^^^^^^^^
  File "C:\Users\Acer\AppData\Local\Programs\Python\Python311\Lib\site-packages\rest_framework\views.py", line 469, in handle_exception
    self.raise_uncaught_exception(exc)
  File "C:\Users\Acer\AppData\Local\Programs\Python\Python311\Lib\site-packages\rest_framework\views.py", line 480, in raise_uncaught_exception
    raise exc
  File "C:\Users\Acer\AppData\Local\Programs\Python\Python311\Lib\site-packages\rest_framework\views.py", line 506, in dispatch
    response = handler(request, *args, **kwargs)
               ^^^^^^^^^^^^^^^^^^^^^^^^^^^^^^^^^
  File "E:\uni\8\OOD\Enigma_BackEnd\Enigma\Group\views.py", line 25, in post
    data["emails"].append(str(self.request.user.email))
    ^^^^^^^^^^^^^^^^^^^^^
AttributeError: 'str' object has no attribute 'append'
ERROR 2023-05-13 18:59:26,195 basehttp 14068 4572 "POST /group/CreateGroup/ HTTP/1.1" 500 98367
ERROR 2023-05-13 18:59:32,256 log 14068 4572 Internal Server Error: /group/CreateGroup/
Traceback (most recent call last):
  File "C:\Users\Acer\AppData\Local\Programs\Python\Python311\Lib\site-packages\django\core\handlers\exception.py", line 56, in inner
    response = get_response(request)
               ^^^^^^^^^^^^^^^^^^^^^
  File "C:\Users\Acer\AppData\Local\Programs\Python\Python311\Lib\site-packages\django\core\handlers\base.py", line 197, in _get_response
    response = wrapped_callback(request, *callback_args, **callback_kwargs)
               ^^^^^^^^^^^^^^^^^^^^^^^^^^^^^^^^^^^^^^^^^^^^^^^^^^^^^^^^^^^^
  File "C:\Users\Acer\AppData\Local\Programs\Python\Python311\Lib\site-packages\django\views\decorators\csrf.py", line 55, in wrapped_view
    return view_func(*args, **kwargs)
           ^^^^^^^^^^^^^^^^^^^^^^^^^^
  File "C:\Users\Acer\AppData\Local\Programs\Python\Python311\Lib\site-packages\django\views\generic\base.py", line 103, in view
    return self.dispatch(request, *args, **kwargs)
           ^^^^^^^^^^^^^^^^^^^^^^^^^^^^^^^^^^^^^^^
  File "C:\Users\Acer\AppData\Local\Programs\Python\Python311\Lib\site-packages\rest_framework\views.py", line 509, in dispatch
    response = self.handle_exception(exc)
               ^^^^^^^^^^^^^^^^^^^^^^^^^^
  File "C:\Users\Acer\AppData\Local\Programs\Python\Python311\Lib\site-packages\rest_framework\views.py", line 469, in handle_exception
    self.raise_uncaught_exception(exc)
  File "C:\Users\Acer\AppData\Local\Programs\Python\Python311\Lib\site-packages\rest_framework\views.py", line 480, in raise_uncaught_exception
    raise exc
  File "C:\Users\Acer\AppData\Local\Programs\Python\Python311\Lib\site-packages\rest_framework\views.py", line 506, in dispatch
    response = handler(request, *args, **kwargs)
               ^^^^^^^^^^^^^^^^^^^^^^^^^^^^^^^^^
  File "E:\uni\8\OOD\Enigma_BackEnd\Enigma\Group\views.py", line 25, in post
    data["emails"].append(str(self.request.user.email))
    ^^^^^^^^^^^^^^^^^^^^^
AttributeError: 'str' object has no attribute 'append'
ERROR 2023-05-13 18:59:32,258 basehttp 14068 4572 "POST /group/CreateGroup/ HTTP/1.1" 500 98402
ERROR 2023-05-13 18:59:36,911 log 14068 4572 Internal Server Error: /group/CreateGroup/
Traceback (most recent call last):
  File "C:\Users\Acer\AppData\Local\Programs\Python\Python311\Lib\site-packages\django\core\handlers\exception.py", line 56, in inner
    response = get_response(request)
               ^^^^^^^^^^^^^^^^^^^^^
  File "C:\Users\Acer\AppData\Local\Programs\Python\Python311\Lib\site-packages\django\core\handlers\base.py", line 197, in _get_response
    response = wrapped_callback(request, *callback_args, **callback_kwargs)
               ^^^^^^^^^^^^^^^^^^^^^^^^^^^^^^^^^^^^^^^^^^^^^^^^^^^^^^^^^^^^
  File "C:\Users\Acer\AppData\Local\Programs\Python\Python311\Lib\site-packages\django\views\decorators\csrf.py", line 55, in wrapped_view
    return view_func(*args, **kwargs)
           ^^^^^^^^^^^^^^^^^^^^^^^^^^
  File "C:\Users\Acer\AppData\Local\Programs\Python\Python311\Lib\site-packages\django\views\generic\base.py", line 103, in view
    return self.dispatch(request, *args, **kwargs)
           ^^^^^^^^^^^^^^^^^^^^^^^^^^^^^^^^^^^^^^^
  File "C:\Users\Acer\AppData\Local\Programs\Python\Python311\Lib\site-packages\rest_framework\views.py", line 509, in dispatch
    response = self.handle_exception(exc)
               ^^^^^^^^^^^^^^^^^^^^^^^^^^
  File "C:\Users\Acer\AppData\Local\Programs\Python\Python311\Lib\site-packages\rest_framework\views.py", line 469, in handle_exception
    self.raise_uncaught_exception(exc)
  File "C:\Users\Acer\AppData\Local\Programs\Python\Python311\Lib\site-packages\rest_framework\views.py", line 480, in raise_uncaught_exception
    raise exc
  File "C:\Users\Acer\AppData\Local\Programs\Python\Python311\Lib\site-packages\rest_framework\views.py", line 506, in dispatch
    response = handler(request, *args, **kwargs)
               ^^^^^^^^^^^^^^^^^^^^^^^^^^^^^^^^^
  File "E:\uni\8\OOD\Enigma_BackEnd\Enigma\Group\views.py", line 25, in post
    data["emails"].append(str(self.request.user.email))
    ^^^^^^^^^^^^^^^^^^^^^
AttributeError: 'str' object has no attribute 'append'
ERROR 2023-05-13 18:59:36,912 basehttp 14068 4572 "POST /group/CreateGroup/ HTTP/1.1" 500 98375
INFO 2023-05-13 19:00:23,051 autoreload 14068 3132 E:\uni\8\OOD\Enigma_BackEnd\Enigma\Enigma\settings.py changed, reloading.
INFO 2023-05-14 00:12:17,583 autoreload 13032 2848 Watching for file changes with StatReloader
INFO 2023-05-14 00:12:25,013 autoreload 13032 2848 E:\uni\8\OOD\Enigma_BackEnd\Enigma\Enigma\settings.py changed, reloading.
INFO 2023-05-14 00:12:25,949 autoreload 16628 8300 Watching for file changes with StatReloader
WARNING 2023-05-14 00:31:51,563 log 2652 14600 Not Found: /group/DeleteGroup/
WARNING 2023-05-14 00:31:51,573 log 2652 14600 Forbidden: /group/DeleteGroup/
ERROR 2023-05-14 00:31:51,576 log 2652 14600 Internal Server Error: /group/GroupInfo/
ERROR 2023-05-14 00:31:51,578 log 2652 14600 Internal Server Error: /group/GroupInfo/
WARNING 2023-05-14 00:31:51,581 log 2652 14600 Not Found: /group/GroupInfo/
WARNING 2023-05-14 00:31:51,587 log 2652 14600 Unauthorized: /group/GroupInfo/
WARNING 2023-05-14 00:31:51,590 log 2652 14600 Not Found: /group/GroupInfo/
ERROR 2023-05-14 00:31:51,592 log 2652 14600 Internal Server Error: /group/ShowGroups/
WARNING 2023-05-14 00:31:51,594 log 2652 14600 Method Not Allowed: /group/ShowGroups/
WARNING 2023-05-14 00:31:51,596 log 2652 14600 Not Found: /group/ShowGroups/
WARNING 2023-05-14 00:31:51,603 log 2652 14600 Unauthorized: /group/ShowGroups/
ERROR 2023-05-14 00:31:51,608 log 2652 14600 Internal Server Error: /group/ShowMembers/
WARNING 2023-05-14 00:31:51,612 log 2652 14600 Forbidden: /group/ShowMembers/
WARNING 2023-05-14 00:31:51,617 log 2652 14600 Forbidden: /group/ShowMembers/
WARNING 2023-05-14 00:31:51,627 log 2652 14600 Forbidden: /group/ShowMembers/
WARNING 2023-05-14 00:31:52,657 log 2652 14600 Bad Request: /auth/token/
WARNING 2023-05-14 00:31:53,181 log 2652 14600 Bad Request: /auth/token/
WARNING 2023-05-14 00:31:53,184 log 2652 14600 Bad Request: /auth/register/
WARNING 2023-05-14 00:31:53,188 log 2652 14600 Bad Request: /auth/register/
WARNING 2023-05-14 00:32:52,307 log 13468 2160 Not Found: /group/DeleteGroup/
WARNING 2023-05-14 00:32:52,315 log 13468 2160 Forbidden: /group/DeleteGroup/
ERROR 2023-05-14 00:32:52,318 log 13468 2160 Internal Server Error: /group/GroupInfo/
ERROR 2023-05-14 00:32:52,321 log 13468 2160 Internal Server Error: /group/GroupInfo/
WARNING 2023-05-14 00:32:52,323 log 13468 2160 Not Found: /group/GroupInfo/
WARNING 2023-05-14 00:32:52,329 log 13468 2160 Unauthorized: /group/GroupInfo/
WARNING 2023-05-14 00:32:52,332 log 13468 2160 Not Found: /group/GroupInfo/
ERROR 2023-05-14 00:32:52,334 log 13468 2160 Internal Server Error: /group/ShowGroups/
WARNING 2023-05-14 00:32:52,336 log 13468 2160 Method Not Allowed: /group/ShowGroups/
WARNING 2023-05-14 00:32:52,339 log 13468 2160 Not Found: /group/ShowGroups/
WARNING 2023-05-14 00:32:52,345 log 13468 2160 Unauthorized: /group/ShowGroups/
ERROR 2023-05-14 00:32:52,353 log 13468 2160 Internal Server Error: /group/ShowMembers/
WARNING 2023-05-14 00:32:52,359 log 13468 2160 Forbidden: /group/ShowMembers/
WARNING 2023-05-14 00:32:52,362 log 13468 2160 Forbidden: /group/ShowMembers/
WARNING 2023-05-14 00:32:52,372 log 13468 2160 Forbidden: /group/ShowMembers/
WARNING 2023-05-14 00:32:53,435 log 13468 2160 Bad Request: /auth/token/
WARNING 2023-05-14 00:32:53,925 log 13468 2160 Bad Request: /auth/token/
WARNING 2023-05-14 00:32:53,927 log 13468 2160 Bad Request: /auth/register/
WARNING 2023-05-14 00:32:53,929 log 13468 2160 Bad Request: /auth/register/
WARNING 2023-05-14 05:22:18,351 log 9684 11896 Forbidden: /group/AddUserGroup/
ERROR 2023-05-14 05:32:59,909 log 14164 17200 Internal Server Error: /group/AddUserGroup/
Traceback (most recent call last):
  File "C:\Python311\Lib\site-packages\django\core\handlers\exception.py", line 56, in inner
    response = get_response(request)
               ^^^^^^^^^^^^^^^^^^^^^
  File "C:\Python311\Lib\site-packages\django\core\handlers\base.py", line 197, in _get_response
    response = wrapped_callback(request, *callback_args, **callback_kwargs)
               ^^^^^^^^^^^^^^^^^^^^^^^^^^^^^^^^^^^^^^^^^^^^^^^^^^^^^^^^^^^^
  File "C:\Python311\Lib\site-packages\django\views\decorators\csrf.py", line 55, in wrapped_view
    return view_func(*args, **kwargs)
           ^^^^^^^^^^^^^^^^^^^^^^^^^^
  File "C:\Python311\Lib\site-packages\django\views\generic\base.py", line 103, in view
    return self.dispatch(request, *args, **kwargs)
           ^^^^^^^^^^^^^^^^^^^^^^^^^^^^^^^^^^^^^^^
  File "C:\Python311\Lib\site-packages\rest_framework\views.py", line 509, in dispatch
    response = self.handle_exception(exc)
               ^^^^^^^^^^^^^^^^^^^^^^^^^^
  File "C:\Python311\Lib\site-packages\rest_framework\views.py", line 469, in handle_exception
    self.raise_uncaught_exception(exc)
  File "C:\Python311\Lib\site-packages\rest_framework\views.py", line 480, in raise_uncaught_exception
    raise exc
  File "C:\Python311\Lib\site-packages\rest_framework\views.py", line 497, in dispatch
    self.initial(request, *args, **kwargs)
  File "C:\Python311\Lib\site-packages\rest_framework\views.py", line 415, in initial
    self.check_permissions(request)
  File "C:\Python311\Lib\site-packages\rest_framework\views.py", line 332, in check_permissions
    if not permission.has_permission(request, self):
           ^^^^^^^^^^^^^^^^^^^^^^^^^^^^^^^^^^^^^^^^
  File "C:\Users\Maryam\Documents\GitHub\Enigma_BackEnd\Enigma\Group\permissions.py", line 10, in has_permission
    members = Members.objects.filter(userID=request.user, groupID=request.data['groupID'])
                                                                  ~~~~~~~~~~~~^^^^^^^^^^^
KeyError: 'groupID'
ERROR 2023-05-14 05:34:50,915 log 15080 2228 Internal Server Error: /group/AddUserGroup/
Traceback (most recent call last):
  File "C:\Python311\Lib\site-packages\django\core\handlers\exception.py", line 56, in inner
    response = get_response(request)
               ^^^^^^^^^^^^^^^^^^^^^
  File "C:\Python311\Lib\site-packages\django\core\handlers\base.py", line 197, in _get_response
    response = wrapped_callback(request, *callback_args, **callback_kwargs)
               ^^^^^^^^^^^^^^^^^^^^^^^^^^^^^^^^^^^^^^^^^^^^^^^^^^^^^^^^^^^^
  File "C:\Python311\Lib\site-packages\django\views\decorators\csrf.py", line 55, in wrapped_view
    return view_func(*args, **kwargs)
           ^^^^^^^^^^^^^^^^^^^^^^^^^^
  File "C:\Python311\Lib\site-packages\django\views\generic\base.py", line 103, in view
    return self.dispatch(request, *args, **kwargs)
           ^^^^^^^^^^^^^^^^^^^^^^^^^^^^^^^^^^^^^^^
  File "C:\Python311\Lib\site-packages\rest_framework\views.py", line 509, in dispatch
    response = self.handle_exception(exc)
               ^^^^^^^^^^^^^^^^^^^^^^^^^^
  File "C:\Python311\Lib\site-packages\rest_framework\views.py", line 469, in handle_exception
    self.raise_uncaught_exception(exc)
  File "C:\Python311\Lib\site-packages\rest_framework\views.py", line 480, in raise_uncaught_exception
    raise exc
  File "C:\Python311\Lib\site-packages\rest_framework\views.py", line 497, in dispatch
    self.initial(request, *args, **kwargs)
  File "C:\Python311\Lib\site-packages\rest_framework\views.py", line 415, in initial
    self.check_permissions(request)
  File "C:\Python311\Lib\site-packages\rest_framework\views.py", line 332, in check_permissions
    if not permission.has_permission(request, self):
           ^^^^^^^^^^^^^^^^^^^^^^^^^^^^^^^^^^^^^^^^
  File "C:\Users\Maryam\Documents\GitHub\Enigma_BackEnd\Enigma\Group\permissions.py", line 10, in has_permission
    members = Members.objects.filter(userID=request.user, groupID=request.data['groupID'])
                                                                  ~~~~~~~~~~~~^^^^^^^^^^^
KeyError: 'groupID'
ERROR 2023-05-14 05:35:55,986 log 13784 14472 Internal Server Error: /group/AddUserGroup/
Traceback (most recent call last):
  File "C:\Python311\Lib\site-packages\django\core\handlers\exception.py", line 56, in inner
    response = get_response(request)
               ^^^^^^^^^^^^^^^^^^^^^
  File "C:\Python311\Lib\site-packages\django\core\handlers\base.py", line 197, in _get_response
    response = wrapped_callback(request, *callback_args, **callback_kwargs)
               ^^^^^^^^^^^^^^^^^^^^^^^^^^^^^^^^^^^^^^^^^^^^^^^^^^^^^^^^^^^^
  File "C:\Python311\Lib\site-packages\django\views\decorators\csrf.py", line 55, in wrapped_view
    return view_func(*args, **kwargs)
           ^^^^^^^^^^^^^^^^^^^^^^^^^^
  File "C:\Python311\Lib\site-packages\django\views\generic\base.py", line 103, in view
    return self.dispatch(request, *args, **kwargs)
           ^^^^^^^^^^^^^^^^^^^^^^^^^^^^^^^^^^^^^^^
  File "C:\Python311\Lib\site-packages\rest_framework\views.py", line 509, in dispatch
    response = self.handle_exception(exc)
               ^^^^^^^^^^^^^^^^^^^^^^^^^^
  File "C:\Python311\Lib\site-packages\rest_framework\views.py", line 469, in handle_exception
    self.raise_uncaught_exception(exc)
  File "C:\Python311\Lib\site-packages\rest_framework\views.py", line 480, in raise_uncaught_exception
    raise exc
  File "C:\Python311\Lib\site-packages\rest_framework\views.py", line 497, in dispatch
    self.initial(request, *args, **kwargs)
  File "C:\Python311\Lib\site-packages\rest_framework\views.py", line 415, in initial
    self.check_permissions(request)
  File "C:\Python311\Lib\site-packages\rest_framework\views.py", line 332, in check_permissions
    if not permission.has_permission(request, self):
           ^^^^^^^^^^^^^^^^^^^^^^^^^^^^^^^^^^^^^^^^
  File "C:\Users\Maryam\Documents\GitHub\Enigma_BackEnd\Enigma\Group\permissions.py", line 10, in has_permission
    members = Members.objects.filter(userID=request.user, groupID=request.data['groupID'])
                                                                  ~~~~~~~~~~~~^^^^^^^^^^^
KeyError: 'groupID'
ERROR 2023-05-14 05:36:16,694 log 9172 14428 Internal Server Error: /group/AddUserGroup/
Traceback (most recent call last):
  File "C:\Python311\Lib\site-packages\django\core\handlers\exception.py", line 56, in inner
    response = get_response(request)
               ^^^^^^^^^^^^^^^^^^^^^
  File "C:\Python311\Lib\site-packages\django\core\handlers\base.py", line 197, in _get_response
    response = wrapped_callback(request, *callback_args, **callback_kwargs)
               ^^^^^^^^^^^^^^^^^^^^^^^^^^^^^^^^^^^^^^^^^^^^^^^^^^^^^^^^^^^^
  File "C:\Python311\Lib\site-packages\django\views\decorators\csrf.py", line 55, in wrapped_view
    return view_func(*args, **kwargs)
           ^^^^^^^^^^^^^^^^^^^^^^^^^^
  File "C:\Python311\Lib\site-packages\django\views\generic\base.py", line 103, in view
    return self.dispatch(request, *args, **kwargs)
           ^^^^^^^^^^^^^^^^^^^^^^^^^^^^^^^^^^^^^^^
  File "C:\Python311\Lib\site-packages\rest_framework\views.py", line 509, in dispatch
    response = self.handle_exception(exc)
               ^^^^^^^^^^^^^^^^^^^^^^^^^^
  File "C:\Python311\Lib\site-packages\rest_framework\views.py", line 469, in handle_exception
    self.raise_uncaught_exception(exc)
  File "C:\Python311\Lib\site-packages\rest_framework\views.py", line 480, in raise_uncaught_exception
    raise exc
  File "C:\Python311\Lib\site-packages\rest_framework\views.py", line 497, in dispatch
    self.initial(request, *args, **kwargs)
  File "C:\Python311\Lib\site-packages\rest_framework\views.py", line 415, in initial
    self.check_permissions(request)
  File "C:\Python311\Lib\site-packages\rest_framework\views.py", line 332, in check_permissions
    if not permission.has_permission(request, self):
           ^^^^^^^^^^^^^^^^^^^^^^^^^^^^^^^^^^^^^^^^
  File "C:\Users\Maryam\Documents\GitHub\Enigma_BackEnd\Enigma\Group\permissions.py", line 10, in has_permission
    members = Members.objects.filter(userID=request.user, groupID=request.data['groupID'])
                                                                  ~~~~~~~~~~~~^^^^^^^^^^^
KeyError: 'groupID'
ERROR 2023-05-14 05:36:57,901 log 9760 11652 Internal Server Error: /group/AddUserGroup/
Traceback (most recent call last):
  File "C:\Python311\Lib\site-packages\django\core\handlers\exception.py", line 56, in inner
    response = get_response(request)
               ^^^^^^^^^^^^^^^^^^^^^
  File "C:\Python311\Lib\site-packages\django\core\handlers\base.py", line 197, in _get_response
    response = wrapped_callback(request, *callback_args, **callback_kwargs)
               ^^^^^^^^^^^^^^^^^^^^^^^^^^^^^^^^^^^^^^^^^^^^^^^^^^^^^^^^^^^^
  File "C:\Python311\Lib\site-packages\django\views\decorators\csrf.py", line 55, in wrapped_view
    return view_func(*args, **kwargs)
           ^^^^^^^^^^^^^^^^^^^^^^^^^^
  File "C:\Python311\Lib\site-packages\django\views\generic\base.py", line 103, in view
    return self.dispatch(request, *args, **kwargs)
           ^^^^^^^^^^^^^^^^^^^^^^^^^^^^^^^^^^^^^^^
  File "C:\Python311\Lib\site-packages\rest_framework\views.py", line 509, in dispatch
    response = self.handle_exception(exc)
               ^^^^^^^^^^^^^^^^^^^^^^^^^^
  File "C:\Python311\Lib\site-packages\rest_framework\views.py", line 469, in handle_exception
    self.raise_uncaught_exception(exc)
  File "C:\Python311\Lib\site-packages\rest_framework\views.py", line 480, in raise_uncaught_exception
    raise exc
  File "C:\Python311\Lib\site-packages\rest_framework\views.py", line 497, in dispatch
    self.initial(request, *args, **kwargs)
  File "C:\Python311\Lib\site-packages\rest_framework\views.py", line 415, in initial
    self.check_permissions(request)
  File "C:\Python311\Lib\site-packages\rest_framework\views.py", line 332, in check_permissions
    if not permission.has_permission(request, self):
           ^^^^^^^^^^^^^^^^^^^^^^^^^^^^^^^^^^^^^^^^
  File "C:\Users\Maryam\Documents\GitHub\Enigma_BackEnd\Enigma\Group\permissions.py", line 10, in has_permission
    members = Members.objects.filter(userID=request.user, groupID=request.data['groupID'])
                                                                  ~~~~~~~~~~~~^^^^^^^^^^^
KeyError: 'groupID'
ERROR 2023-05-14 05:38:42,031 log 12500 10796 Internal Server Error: /group/AddUserGroup/
Traceback (most recent call last):
  File "C:\Python311\Lib\site-packages\django\core\handlers\exception.py", line 56, in inner
    response = get_response(request)
               ^^^^^^^^^^^^^^^^^^^^^
  File "C:\Python311\Lib\site-packages\django\core\handlers\base.py", line 197, in _get_response
    response = wrapped_callback(request, *callback_args, **callback_kwargs)
               ^^^^^^^^^^^^^^^^^^^^^^^^^^^^^^^^^^^^^^^^^^^^^^^^^^^^^^^^^^^^
  File "C:\Python311\Lib\site-packages\django\views\decorators\csrf.py", line 55, in wrapped_view
    return view_func(*args, **kwargs)
           ^^^^^^^^^^^^^^^^^^^^^^^^^^
  File "C:\Python311\Lib\site-packages\django\views\generic\base.py", line 103, in view
    return self.dispatch(request, *args, **kwargs)
           ^^^^^^^^^^^^^^^^^^^^^^^^^^^^^^^^^^^^^^^
  File "C:\Python311\Lib\site-packages\rest_framework\views.py", line 509, in dispatch
    response = self.handle_exception(exc)
               ^^^^^^^^^^^^^^^^^^^^^^^^^^
  File "C:\Python311\Lib\site-packages\rest_framework\views.py", line 469, in handle_exception
    self.raise_uncaught_exception(exc)
  File "C:\Python311\Lib\site-packages\rest_framework\views.py", line 480, in raise_uncaught_exception
    raise exc
  File "C:\Python311\Lib\site-packages\rest_framework\views.py", line 497, in dispatch
    self.initial(request, *args, **kwargs)
  File "C:\Python311\Lib\site-packages\rest_framework\views.py", line 415, in initial
    self.check_permissions(request)
  File "C:\Python311\Lib\site-packages\rest_framework\views.py", line 332, in check_permissions
    if not permission.has_permission(request, self):
           ^^^^^^^^^^^^^^^^^^^^^^^^^^^^^^^^^^^^^^^^
  File "C:\Users\Maryam\Documents\GitHub\Enigma_BackEnd\Enigma\Group\permissions.py", line 10, in has_permission
    members = Members.objects.filter(userID=request.user, groupID=request.data['groupID'])
                                                                  ~~~~~~~~~~~~^^^^^^^^^^^
KeyError: 'groupID'
WARNING 2023-05-14 05:40:39,303 log 7152 4832 Forbidden: /group/AddUserGroup/
WARNING 2023-05-14 05:44:13,446 log 9288 13716 Forbidden: /group/AddUserGroup/
WARNING 2023-05-14 05:45:10,814 log 12084 11616 Forbidden: /group/AddUserGroup/
WARNING 2023-05-14 05:50:07,448 log 12588 10220 Not Found: /group/AddUserGroup/
WARNING 2023-05-14 05:53:24,905 log 3332 15896 Not Found: /group/AddUserGroup/
WARNING 2023-05-14 05:54:53,591 log 4544 6108 Not Found: /group/AddUserGroup/
WARNING 2023-05-14 06:03:22,454 log 8700 4504 Not Found: /group/AddUserGroup/
WARNING 2023-05-14 06:05:16,565 log 2232 3636 Forbidden: /group/AddUserGroup/
WARNING 2023-05-14 06:09:36,497 log 8440 9768 Not Found: /group/AddUserGroup/
WARNING 2023-05-14 06:10:10,814 log 15676 14068 Not Found: /group/AddUserGroup/
WARNING 2023-05-14 06:10:49,818 log 17516 10844 Not Found: /group/AddUserGroup/
WARNING 2023-05-14 06:15:54,968 log 1776 17584 Not Found: /group/AddUserGroup/
ERROR 2023-05-14 06:15:54,989 log 1776 17584 Internal Server Error: /group/AddUserGroup/
Traceback (most recent call last):
  File "C:\Python311\Lib\site-packages\django\core\handlers\exception.py", line 56, in inner
    response = get_response(request)
               ^^^^^^^^^^^^^^^^^^^^^
  File "C:\Python311\Lib\site-packages\django\core\handlers\base.py", line 197, in _get_response
    response = wrapped_callback(request, *callback_args, **callback_kwargs)
               ^^^^^^^^^^^^^^^^^^^^^^^^^^^^^^^^^^^^^^^^^^^^^^^^^^^^^^^^^^^^
  File "C:\Python311\Lib\site-packages\django\views\decorators\csrf.py", line 55, in wrapped_view
    return view_func(*args, **kwargs)
           ^^^^^^^^^^^^^^^^^^^^^^^^^^
  File "C:\Python311\Lib\site-packages\django\views\generic\base.py", line 103, in view
    return self.dispatch(request, *args, **kwargs)
           ^^^^^^^^^^^^^^^^^^^^^^^^^^^^^^^^^^^^^^^
  File "C:\Python311\Lib\site-packages\rest_framework\views.py", line 509, in dispatch
    response = self.handle_exception(exc)
               ^^^^^^^^^^^^^^^^^^^^^^^^^^
  File "C:\Python311\Lib\site-packages\rest_framework\views.py", line 469, in handle_exception
    self.raise_uncaught_exception(exc)
  File "C:\Python311\Lib\site-packages\rest_framework\views.py", line 480, in raise_uncaught_exception
    raise exc
  File "C:\Python311\Lib\site-packages\rest_framework\views.py", line 506, in dispatch
    response = handler(request, *args, **kwargs)
               ^^^^^^^^^^^^^^^^^^^^^^^^^^^^^^^^^
  File "C:\Users\Maryam\Documents\GitHub\Enigma_BackEnd\Enigma\Group\views.py", line 39, in post
    for emailUser in data['emails']:
                     ~~~~^^^^^^^^^^
KeyError: 'emails'
WARNING 2023-05-14 06:19:04,384 log 1972 9420 Not Found: /group/AddUserGroup/
ERROR 2023-05-14 06:19:04,404 log 1972 9420 Internal Server Error: /group/AddUserGroup/
Traceback (most recent call last):
  File "C:\Python311\Lib\site-packages\django\core\handlers\exception.py", line 56, in inner
    response = get_response(request)
               ^^^^^^^^^^^^^^^^^^^^^
  File "C:\Python311\Lib\site-packages\django\core\handlers\base.py", line 197, in _get_response
    response = wrapped_callback(request, *callback_args, **callback_kwargs)
               ^^^^^^^^^^^^^^^^^^^^^^^^^^^^^^^^^^^^^^^^^^^^^^^^^^^^^^^^^^^^
  File "C:\Python311\Lib\site-packages\django\views\decorators\csrf.py", line 55, in wrapped_view
    return view_func(*args, **kwargs)
           ^^^^^^^^^^^^^^^^^^^^^^^^^^
  File "C:\Python311\Lib\site-packages\django\views\generic\base.py", line 103, in view
    return self.dispatch(request, *args, **kwargs)
           ^^^^^^^^^^^^^^^^^^^^^^^^^^^^^^^^^^^^^^^
  File "C:\Python311\Lib\site-packages\rest_framework\views.py", line 509, in dispatch
    response = self.handle_exception(exc)
               ^^^^^^^^^^^^^^^^^^^^^^^^^^
  File "C:\Python311\Lib\site-packages\rest_framework\views.py", line 469, in handle_exception
    self.raise_uncaught_exception(exc)
  File "C:\Python311\Lib\site-packages\rest_framework\views.py", line 480, in raise_uncaught_exception
    raise exc
  File "C:\Python311\Lib\site-packages\rest_framework\views.py", line 506, in dispatch
    response = handler(request, *args, **kwargs)
               ^^^^^^^^^^^^^^^^^^^^^^^^^^^^^^^^^
  File "C:\Users\Maryam\Documents\GitHub\Enigma_BackEnd\Enigma\Group\views.py", line 39, in post
    for emailUser in data['emails']:
                     ~~~~^^^^^^^^^^
KeyError: 'emails'
WARNING 2023-05-14 06:19:31,750 log 8760 13012 Not Found: /group/AddUserGroup/
ERROR 2023-05-14 06:19:31,769 log 8760 13012 Internal Server Error: /group/AddUserGroup/
Traceback (most recent call last):
  File "C:\Python311\Lib\site-packages\django\core\handlers\exception.py", line 56, in inner
    response = get_response(request)
               ^^^^^^^^^^^^^^^^^^^^^
  File "C:\Python311\Lib\site-packages\django\core\handlers\base.py", line 197, in _get_response
    response = wrapped_callback(request, *callback_args, **callback_kwargs)
               ^^^^^^^^^^^^^^^^^^^^^^^^^^^^^^^^^^^^^^^^^^^^^^^^^^^^^^^^^^^^
  File "C:\Python311\Lib\site-packages\django\views\decorators\csrf.py", line 55, in wrapped_view
    return view_func(*args, **kwargs)
           ^^^^^^^^^^^^^^^^^^^^^^^^^^
  File "C:\Python311\Lib\site-packages\django\views\generic\base.py", line 103, in view
    return self.dispatch(request, *args, **kwargs)
           ^^^^^^^^^^^^^^^^^^^^^^^^^^^^^^^^^^^^^^^
  File "C:\Python311\Lib\site-packages\rest_framework\views.py", line 509, in dispatch
    response = self.handle_exception(exc)
               ^^^^^^^^^^^^^^^^^^^^^^^^^^
  File "C:\Python311\Lib\site-packages\rest_framework\views.py", line 469, in handle_exception
    self.raise_uncaught_exception(exc)
  File "C:\Python311\Lib\site-packages\rest_framework\views.py", line 480, in raise_uncaught_exception
    raise exc
  File "C:\Python311\Lib\site-packages\rest_framework\views.py", line 506, in dispatch
    response = handler(request, *args, **kwargs)
               ^^^^^^^^^^^^^^^^^^^^^^^^^^^^^^^^^
  File "C:\Users\Maryam\Documents\GitHub\Enigma_BackEnd\Enigma\Group\views.py", line 39, in post
    for emailUser in data['emails']:
                     ~~~~^^^^^^^^^^
KeyError: 'emails'
WARNING 2023-05-14 06:19:57,043 log 10816 9628 Not Found: /group/AddUserGroup/
ERROR 2023-05-14 06:19:57,063 log 10816 9628 Internal Server Error: /group/AddUserGroup/
Traceback (most recent call last):
  File "C:\Python311\Lib\site-packages\django\core\handlers\exception.py", line 56, in inner
    response = get_response(request)
               ^^^^^^^^^^^^^^^^^^^^^
  File "C:\Python311\Lib\site-packages\django\core\handlers\base.py", line 197, in _get_response
    response = wrapped_callback(request, *callback_args, **callback_kwargs)
               ^^^^^^^^^^^^^^^^^^^^^^^^^^^^^^^^^^^^^^^^^^^^^^^^^^^^^^^^^^^^
  File "C:\Python311\Lib\site-packages\django\views\decorators\csrf.py", line 55, in wrapped_view
    return view_func(*args, **kwargs)
           ^^^^^^^^^^^^^^^^^^^^^^^^^^
  File "C:\Python311\Lib\site-packages\django\views\generic\base.py", line 103, in view
    return self.dispatch(request, *args, **kwargs)
           ^^^^^^^^^^^^^^^^^^^^^^^^^^^^^^^^^^^^^^^
  File "C:\Python311\Lib\site-packages\rest_framework\views.py", line 509, in dispatch
    response = self.handle_exception(exc)
               ^^^^^^^^^^^^^^^^^^^^^^^^^^
  File "C:\Python311\Lib\site-packages\rest_framework\views.py", line 469, in handle_exception
    self.raise_uncaught_exception(exc)
  File "C:\Python311\Lib\site-packages\rest_framework\views.py", line 480, in raise_uncaught_exception
    raise exc
  File "C:\Python311\Lib\site-packages\rest_framework\views.py", line 506, in dispatch
    response = handler(request, *args, **kwargs)
               ^^^^^^^^^^^^^^^^^^^^^^^^^^^^^^^^^
  File "C:\Users\Maryam\Documents\GitHub\Enigma_BackEnd\Enigma\Group\views.py", line 39, in post
    for emailUser in data['emails']:
                     ~~~~^^^^^^^^^^
KeyError: 'emails'
WARNING 2023-05-14 06:20:23,088 log 4308 10936 Not Found: /group/AddUserGroup/
ERROR 2023-05-14 06:20:23,110 log 4308 10936 Internal Server Error: /group/AddUserGroup/
Traceback (most recent call last):
  File "C:\Python311\Lib\site-packages\django\core\handlers\exception.py", line 56, in inner
    response = get_response(request)
               ^^^^^^^^^^^^^^^^^^^^^
  File "C:\Python311\Lib\site-packages\django\core\handlers\base.py", line 197, in _get_response
    response = wrapped_callback(request, *callback_args, **callback_kwargs)
               ^^^^^^^^^^^^^^^^^^^^^^^^^^^^^^^^^^^^^^^^^^^^^^^^^^^^^^^^^^^^
  File "C:\Python311\Lib\site-packages\django\views\decorators\csrf.py", line 55, in wrapped_view
    return view_func(*args, **kwargs)
           ^^^^^^^^^^^^^^^^^^^^^^^^^^
  File "C:\Python311\Lib\site-packages\django\views\generic\base.py", line 103, in view
    return self.dispatch(request, *args, **kwargs)
           ^^^^^^^^^^^^^^^^^^^^^^^^^^^^^^^^^^^^^^^
  File "C:\Python311\Lib\site-packages\rest_framework\views.py", line 509, in dispatch
    response = self.handle_exception(exc)
               ^^^^^^^^^^^^^^^^^^^^^^^^^^
  File "C:\Python311\Lib\site-packages\rest_framework\views.py", line 469, in handle_exception
    self.raise_uncaught_exception(exc)
  File "C:\Python311\Lib\site-packages\rest_framework\views.py", line 480, in raise_uncaught_exception
    raise exc
  File "C:\Python311\Lib\site-packages\rest_framework\views.py", line 506, in dispatch
    response = handler(request, *args, **kwargs)
               ^^^^^^^^^^^^^^^^^^^^^^^^^^^^^^^^^
  File "C:\Users\Maryam\Documents\GitHub\Enigma_BackEnd\Enigma\Group\views.py", line 39, in post
    for emailUser in data['emails']:
                     ~~~~^^^^^^^^^^
KeyError: 'emails'
WARNING 2023-05-14 06:22:28,572 log 844 12556 Not Found: /group/AddUserGroup/
WARNING 2023-05-14 06:26:09,999 log 13816 10112 Not Found: /group/AddUserGroup/
WARNING 2023-05-14 06:26:10,017 log 13816 10112 Not Found: /group/AddUserGroup/
WARNING 2023-05-14 06:27:48,209 log 1796 1104 Not Found: /group/AddUserGroup/
WARNING 2023-05-14 07:23:03,694 log 1396 15248 Not Found: /group/AddUserGroup/
WARNING 2023-05-14 07:23:03,716 log 1396 15248 Not Found: /group/AddUserGroup/
WARNING 2023-05-14 07:23:26,510 log 10436 14744 Not Found: /group/AddUserGroup/
WARNING 2023-05-14 07:23:26,515 log 10436 14744 Forbidden: /group/AddUserGroup/
WARNING 2023-05-14 07:23:26,536 log 10436 14744 Not Found: /group/AddUserGroup/
WARNING 2023-05-14 07:45:12,174 log 6768 16656 Not Found: /group/AddUserGroup/
WARNING 2023-05-14 07:45:12,181 log 6768 16656 Forbidden: /group/AddUserGroup/
WARNING 2023-05-14 07:45:12,204 log 6768 16656 Not Found: /group/AddUserGroup/
WARNING 2023-05-14 07:47:05,774 log 11640 15652 Not Found: /group/AddUserGroup/
WARNING 2023-05-14 07:47:05,785 log 11640 15652 Forbidden: /group/AddUserGroup/
WARNING 2023-05-14 07:47:05,814 log 11640 15652 Not Found: /group/AddUserGroup/
ERROR 2023-05-14 07:48:53,089 log 18008 6256 Internal Server Error: /group/AddUserGroup/
Traceback (most recent call last):
  File "C:\Python311\Lib\site-packages\django\core\handlers\exception.py", line 56, in inner
    response = get_response(request)
               ^^^^^^^^^^^^^^^^^^^^^
  File "C:\Python311\Lib\site-packages\django\core\handlers\base.py", line 197, in _get_response
    response = wrapped_callback(request, *callback_args, **callback_kwargs)
               ^^^^^^^^^^^^^^^^^^^^^^^^^^^^^^^^^^^^^^^^^^^^^^^^^^^^^^^^^^^^
  File "C:\Python311\Lib\site-packages\django\views\decorators\csrf.py", line 55, in wrapped_view
    return view_func(*args, **kwargs)
           ^^^^^^^^^^^^^^^^^^^^^^^^^^
  File "C:\Python311\Lib\site-packages\django\views\generic\base.py", line 103, in view
    return self.dispatch(request, *args, **kwargs)
           ^^^^^^^^^^^^^^^^^^^^^^^^^^^^^^^^^^^^^^^
  File "C:\Python311\Lib\site-packages\rest_framework\views.py", line 509, in dispatch
    response = self.handle_exception(exc)
               ^^^^^^^^^^^^^^^^^^^^^^^^^^
  File "C:\Python311\Lib\site-packages\rest_framework\views.py", line 469, in handle_exception
    self.raise_uncaught_exception(exc)
  File "C:\Python311\Lib\site-packages\rest_framework\views.py", line 480, in raise_uncaught_exception
    raise exc
  File "C:\Python311\Lib\site-packages\rest_framework\views.py", line 506, in dispatch
    response = handler(request, *args, **kwargs)
               ^^^^^^^^^^^^^^^^^^^^^^^^^^^^^^^^^
  File "C:\Users\Maryam\Documents\GitHub\Enigma_BackEnd\Enigma\Group\views.py", line 45, in post
    if not Members.objects.get(groupID=group, userID=user):
           ^^^^^^^^^^^^^^^^^^^^^^^^^^^^^^^^^^^^^^^^^^^^^^^
  File "C:\Python311\Lib\site-packages\django\db\models\manager.py", line 85, in manager_method
    return getattr(self.get_queryset(), name)(*args, **kwargs)
           ^^^^^^^^^^^^^^^^^^^^^^^^^^^^^^^^^^^^^^^^^^^^^^^^^^^
  File "C:\Python311\Lib\site-packages\django\db\models\query.py", line 650, in get
    raise self.model.DoesNotExist(
Group.models.Members.DoesNotExist: Members matching query does not exist.
WARNING 2023-05-14 07:48:53,104 log 18008 6256 Forbidden: /group/AddUserGroup/
ERROR 2023-05-14 07:48:53,112 log 18008 6256 Internal Server Error: /group/AddUserGroup/
Traceback (most recent call last):
  File "C:\Python311\Lib\site-packages\django\core\handlers\exception.py", line 56, in inner
    response = get_response(request)
               ^^^^^^^^^^^^^^^^^^^^^
  File "C:\Python311\Lib\site-packages\django\core\handlers\base.py", line 197, in _get_response
    response = wrapped_callback(request, *callback_args, **callback_kwargs)
               ^^^^^^^^^^^^^^^^^^^^^^^^^^^^^^^^^^^^^^^^^^^^^^^^^^^^^^^^^^^^
  File "C:\Python311\Lib\site-packages\django\views\decorators\csrf.py", line 55, in wrapped_view
    return view_func(*args, **kwargs)
           ^^^^^^^^^^^^^^^^^^^^^^^^^^
  File "C:\Python311\Lib\site-packages\django\views\generic\base.py", line 103, in view
    return self.dispatch(request, *args, **kwargs)
           ^^^^^^^^^^^^^^^^^^^^^^^^^^^^^^^^^^^^^^^
  File "C:\Python311\Lib\site-packages\rest_framework\views.py", line 509, in dispatch
    response = self.handle_exception(exc)
               ^^^^^^^^^^^^^^^^^^^^^^^^^^
  File "C:\Python311\Lib\site-packages\rest_framework\views.py", line 469, in handle_exception
    self.raise_uncaught_exception(exc)
  File "C:\Python311\Lib\site-packages\rest_framework\views.py", line 480, in raise_uncaught_exception
    raise exc
  File "C:\Python311\Lib\site-packages\rest_framework\views.py", line 506, in dispatch
    response = handler(request, *args, **kwargs)
               ^^^^^^^^^^^^^^^^^^^^^^^^^^^^^^^^^
  File "C:\Users\Maryam\Documents\GitHub\Enigma_BackEnd\Enigma\Group\views.py", line 45, in post
    if not Members.objects.get(groupID=group, userID=user):
           ^^^^^^^^^^^^^^^^^^^^^^^^^^^^^^^^^^^^^^^^^^^^^^^
  File "C:\Python311\Lib\site-packages\django\db\models\manager.py", line 85, in manager_method
    return getattr(self.get_queryset(), name)(*args, **kwargs)
           ^^^^^^^^^^^^^^^^^^^^^^^^^^^^^^^^^^^^^^^^^^^^^^^^^^^
  File "C:\Python311\Lib\site-packages\django\db\models\query.py", line 650, in get
    raise self.model.DoesNotExist(
Group.models.Members.DoesNotExist: Members matching query does not exist.
ERROR 2023-05-14 07:48:53,124 log 18008 6256 Internal Server Error: /group/AddUserGroup/
Traceback (most recent call last):
  File "C:\Python311\Lib\site-packages\django\core\handlers\exception.py", line 56, in inner
    response = get_response(request)
               ^^^^^^^^^^^^^^^^^^^^^
  File "C:\Python311\Lib\site-packages\django\core\handlers\base.py", line 197, in _get_response
    response = wrapped_callback(request, *callback_args, **callback_kwargs)
               ^^^^^^^^^^^^^^^^^^^^^^^^^^^^^^^^^^^^^^^^^^^^^^^^^^^^^^^^^^^^
  File "C:\Python311\Lib\site-packages\django\views\decorators\csrf.py", line 55, in wrapped_view
    return view_func(*args, **kwargs)
           ^^^^^^^^^^^^^^^^^^^^^^^^^^
  File "C:\Python311\Lib\site-packages\django\views\generic\base.py", line 103, in view
    return self.dispatch(request, *args, **kwargs)
           ^^^^^^^^^^^^^^^^^^^^^^^^^^^^^^^^^^^^^^^
  File "C:\Python311\Lib\site-packages\rest_framework\views.py", line 509, in dispatch
    response = self.handle_exception(exc)
               ^^^^^^^^^^^^^^^^^^^^^^^^^^
  File "C:\Python311\Lib\site-packages\rest_framework\views.py", line 469, in handle_exception
    self.raise_uncaught_exception(exc)
  File "C:\Python311\Lib\site-packages\rest_framework\views.py", line 480, in raise_uncaught_exception
    raise exc
  File "C:\Python311\Lib\site-packages\rest_framework\views.py", line 506, in dispatch
    response = handler(request, *args, **kwargs)
               ^^^^^^^^^^^^^^^^^^^^^^^^^^^^^^^^^
  File "C:\Users\Maryam\Documents\GitHub\Enigma_BackEnd\Enigma\Group\views.py", line 45, in post
    if not Members.objects.get(groupID=group, userID=user):
           ^^^^^^^^^^^^^^^^^^^^^^^^^^^^^^^^^^^^^^^^^^^^^^^
  File "C:\Python311\Lib\site-packages\django\db\models\manager.py", line 85, in manager_method
    return getattr(self.get_queryset(), name)(*args, **kwargs)
           ^^^^^^^^^^^^^^^^^^^^^^^^^^^^^^^^^^^^^^^^^^^^^^^^^^^
  File "C:\Python311\Lib\site-packages\django\db\models\query.py", line 650, in get
    raise self.model.DoesNotExist(
Group.models.Members.DoesNotExist: Members matching query does not exist.
ERROR 2023-05-14 07:49:30,828 log 18400 8004 Internal Server Error: /group/AddUserGroup/
Traceback (most recent call last):
  File "C:\Python311\Lib\site-packages\django\core\handlers\exception.py", line 56, in inner
    response = get_response(request)
               ^^^^^^^^^^^^^^^^^^^^^
  File "C:\Python311\Lib\site-packages\django\core\handlers\base.py", line 197, in _get_response
    response = wrapped_callback(request, *callback_args, **callback_kwargs)
               ^^^^^^^^^^^^^^^^^^^^^^^^^^^^^^^^^^^^^^^^^^^^^^^^^^^^^^^^^^^^
  File "C:\Python311\Lib\site-packages\django\views\decorators\csrf.py", line 55, in wrapped_view
    return view_func(*args, **kwargs)
           ^^^^^^^^^^^^^^^^^^^^^^^^^^
  File "C:\Python311\Lib\site-packages\django\views\generic\base.py", line 103, in view
    return self.dispatch(request, *args, **kwargs)
           ^^^^^^^^^^^^^^^^^^^^^^^^^^^^^^^^^^^^^^^
  File "C:\Python311\Lib\site-packages\rest_framework\views.py", line 509, in dispatch
    response = self.handle_exception(exc)
               ^^^^^^^^^^^^^^^^^^^^^^^^^^
  File "C:\Python311\Lib\site-packages\rest_framework\views.py", line 469, in handle_exception
    self.raise_uncaught_exception(exc)
  File "C:\Python311\Lib\site-packages\rest_framework\views.py", line 480, in raise_uncaught_exception
    raise exc
  File "C:\Python311\Lib\site-packages\rest_framework\views.py", line 506, in dispatch
    response = handler(request, *args, **kwargs)
               ^^^^^^^^^^^^^^^^^^^^^^^^^^^^^^^^^
  File "C:\Users\Maryam\Documents\GitHub\Enigma_BackEnd\Enigma\Group\views.py", line 45, in post
    if not Members.objects.get(groupID=group, userID=user):
           ^^^^^^^^^^^^^^^^^^^^^^^^^^^^^^^^^^^^^^^^^^^^^^^
  File "C:\Python311\Lib\site-packages\django\db\models\manager.py", line 85, in manager_method
    return getattr(self.get_queryset(), name)(*args, **kwargs)
           ^^^^^^^^^^^^^^^^^^^^^^^^^^^^^^^^^^^^^^^^^^^^^^^^^^^
  File "C:\Python311\Lib\site-packages\django\db\models\query.py", line 650, in get
    raise self.model.DoesNotExist(
Group.models.Members.DoesNotExist: Members matching query does not exist.
WARNING 2023-05-14 07:49:30,842 log 18400 8004 Forbidden: /group/AddUserGroup/
ERROR 2023-05-14 07:49:30,852 log 18400 8004 Internal Server Error: /group/AddUserGroup/
Traceback (most recent call last):
  File "C:\Python311\Lib\site-packages\django\core\handlers\exception.py", line 56, in inner
    response = get_response(request)
               ^^^^^^^^^^^^^^^^^^^^^
  File "C:\Python311\Lib\site-packages\django\core\handlers\base.py", line 197, in _get_response
    response = wrapped_callback(request, *callback_args, **callback_kwargs)
               ^^^^^^^^^^^^^^^^^^^^^^^^^^^^^^^^^^^^^^^^^^^^^^^^^^^^^^^^^^^^
  File "C:\Python311\Lib\site-packages\django\views\decorators\csrf.py", line 55, in wrapped_view
    return view_func(*args, **kwargs)
           ^^^^^^^^^^^^^^^^^^^^^^^^^^
  File "C:\Python311\Lib\site-packages\django\views\generic\base.py", line 103, in view
    return self.dispatch(request, *args, **kwargs)
           ^^^^^^^^^^^^^^^^^^^^^^^^^^^^^^^^^^^^^^^
  File "C:\Python311\Lib\site-packages\rest_framework\views.py", line 509, in dispatch
    response = self.handle_exception(exc)
               ^^^^^^^^^^^^^^^^^^^^^^^^^^
  File "C:\Python311\Lib\site-packages\rest_framework\views.py", line 469, in handle_exception
    self.raise_uncaught_exception(exc)
  File "C:\Python311\Lib\site-packages\rest_framework\views.py", line 480, in raise_uncaught_exception
    raise exc
  File "C:\Python311\Lib\site-packages\rest_framework\views.py", line 506, in dispatch
    response = handler(request, *args, **kwargs)
               ^^^^^^^^^^^^^^^^^^^^^^^^^^^^^^^^^
  File "C:\Users\Maryam\Documents\GitHub\Enigma_BackEnd\Enigma\Group\views.py", line 45, in post
    if not Members.objects.get(groupID=group, userID=user):
           ^^^^^^^^^^^^^^^^^^^^^^^^^^^^^^^^^^^^^^^^^^^^^^^
  File "C:\Python311\Lib\site-packages\django\db\models\manager.py", line 85, in manager_method
    return getattr(self.get_queryset(), name)(*args, **kwargs)
           ^^^^^^^^^^^^^^^^^^^^^^^^^^^^^^^^^^^^^^^^^^^^^^^^^^^
  File "C:\Python311\Lib\site-packages\django\db\models\query.py", line 650, in get
    raise self.model.DoesNotExist(
Group.models.Members.DoesNotExist: Members matching query does not exist.
ERROR 2023-05-14 07:49:30,868 log 18400 8004 Internal Server Error: /group/AddUserGroup/
Traceback (most recent call last):
  File "C:\Python311\Lib\site-packages\django\core\handlers\exception.py", line 56, in inner
    response = get_response(request)
               ^^^^^^^^^^^^^^^^^^^^^
  File "C:\Python311\Lib\site-packages\django\core\handlers\base.py", line 197, in _get_response
    response = wrapped_callback(request, *callback_args, **callback_kwargs)
               ^^^^^^^^^^^^^^^^^^^^^^^^^^^^^^^^^^^^^^^^^^^^^^^^^^^^^^^^^^^^
  File "C:\Python311\Lib\site-packages\django\views\decorators\csrf.py", line 55, in wrapped_view
    return view_func(*args, **kwargs)
           ^^^^^^^^^^^^^^^^^^^^^^^^^^
  File "C:\Python311\Lib\site-packages\django\views\generic\base.py", line 103, in view
    return self.dispatch(request, *args, **kwargs)
           ^^^^^^^^^^^^^^^^^^^^^^^^^^^^^^^^^^^^^^^
  File "C:\Python311\Lib\site-packages\rest_framework\views.py", line 509, in dispatch
    response = self.handle_exception(exc)
               ^^^^^^^^^^^^^^^^^^^^^^^^^^
  File "C:\Python311\Lib\site-packages\rest_framework\views.py", line 469, in handle_exception
    self.raise_uncaught_exception(exc)
  File "C:\Python311\Lib\site-packages\rest_framework\views.py", line 480, in raise_uncaught_exception
    raise exc
  File "C:\Python311\Lib\site-packages\rest_framework\views.py", line 506, in dispatch
    response = handler(request, *args, **kwargs)
               ^^^^^^^^^^^^^^^^^^^^^^^^^^^^^^^^^
  File "C:\Users\Maryam\Documents\GitHub\Enigma_BackEnd\Enigma\Group\views.py", line 45, in post
    if not Members.objects.get(groupID=group, userID=user):
           ^^^^^^^^^^^^^^^^^^^^^^^^^^^^^^^^^^^^^^^^^^^^^^^
  File "C:\Python311\Lib\site-packages\django\db\models\manager.py", line 85, in manager_method
    return getattr(self.get_queryset(), name)(*args, **kwargs)
           ^^^^^^^^^^^^^^^^^^^^^^^^^^^^^^^^^^^^^^^^^^^^^^^^^^^
  File "C:\Python311\Lib\site-packages\django\db\models\query.py", line 650, in get
    raise self.model.DoesNotExist(
Group.models.Members.DoesNotExist: Members matching query does not exist.
ERROR 2023-05-14 07:49:52,539 log 11608 1608 Internal Server Error: /group/AddUserGroup/
Traceback (most recent call last):
  File "C:\Python311\Lib\site-packages\django\core\handlers\exception.py", line 56, in inner
    response = get_response(request)
               ^^^^^^^^^^^^^^^^^^^^^
  File "C:\Python311\Lib\site-packages\django\core\handlers\base.py", line 197, in _get_response
    response = wrapped_callback(request, *callback_args, **callback_kwargs)
               ^^^^^^^^^^^^^^^^^^^^^^^^^^^^^^^^^^^^^^^^^^^^^^^^^^^^^^^^^^^^
  File "C:\Python311\Lib\site-packages\django\views\decorators\csrf.py", line 55, in wrapped_view
    return view_func(*args, **kwargs)
           ^^^^^^^^^^^^^^^^^^^^^^^^^^
  File "C:\Python311\Lib\site-packages\django\views\generic\base.py", line 103, in view
    return self.dispatch(request, *args, **kwargs)
           ^^^^^^^^^^^^^^^^^^^^^^^^^^^^^^^^^^^^^^^
  File "C:\Python311\Lib\site-packages\rest_framework\views.py", line 509, in dispatch
    response = self.handle_exception(exc)
               ^^^^^^^^^^^^^^^^^^^^^^^^^^
  File "C:\Python311\Lib\site-packages\rest_framework\views.py", line 469, in handle_exception
    self.raise_uncaught_exception(exc)
  File "C:\Python311\Lib\site-packages\rest_framework\views.py", line 480, in raise_uncaught_exception
    raise exc
  File "C:\Python311\Lib\site-packages\rest_framework\views.py", line 506, in dispatch
    response = handler(request, *args, **kwargs)
               ^^^^^^^^^^^^^^^^^^^^^^^^^^^^^^^^^
  File "C:\Users\Maryam\Documents\GitHub\Enigma_BackEnd\Enigma\Group\views.py", line 45, in post
    if not Members.objects.get(groupID=group, userID=user):
           ^^^^^^^^^^^^^^^^^^^^^^^^^^^^^^^^^^^^^^^^^^^^^^^
  File "C:\Python311\Lib\site-packages\django\db\models\manager.py", line 85, in manager_method
    return getattr(self.get_queryset(), name)(*args, **kwargs)
           ^^^^^^^^^^^^^^^^^^^^^^^^^^^^^^^^^^^^^^^^^^^^^^^^^^^
  File "C:\Python311\Lib\site-packages\django\db\models\query.py", line 650, in get
    raise self.model.DoesNotExist(
Group.models.Members.DoesNotExist: Members matching query does not exist.
WARNING 2023-05-14 07:49:52,553 log 11608 1608 Forbidden: /group/AddUserGroup/
ERROR 2023-05-14 07:49:52,563 log 11608 1608 Internal Server Error: /group/AddUserGroup/
Traceback (most recent call last):
  File "C:\Python311\Lib\site-packages\django\core\handlers\exception.py", line 56, in inner
    response = get_response(request)
               ^^^^^^^^^^^^^^^^^^^^^
  File "C:\Python311\Lib\site-packages\django\core\handlers\base.py", line 197, in _get_response
    response = wrapped_callback(request, *callback_args, **callback_kwargs)
               ^^^^^^^^^^^^^^^^^^^^^^^^^^^^^^^^^^^^^^^^^^^^^^^^^^^^^^^^^^^^
  File "C:\Python311\Lib\site-packages\django\views\decorators\csrf.py", line 55, in wrapped_view
    return view_func(*args, **kwargs)
           ^^^^^^^^^^^^^^^^^^^^^^^^^^
  File "C:\Python311\Lib\site-packages\django\views\generic\base.py", line 103, in view
    return self.dispatch(request, *args, **kwargs)
           ^^^^^^^^^^^^^^^^^^^^^^^^^^^^^^^^^^^^^^^
  File "C:\Python311\Lib\site-packages\rest_framework\views.py", line 509, in dispatch
    response = self.handle_exception(exc)
               ^^^^^^^^^^^^^^^^^^^^^^^^^^
  File "C:\Python311\Lib\site-packages\rest_framework\views.py", line 469, in handle_exception
    self.raise_uncaught_exception(exc)
  File "C:\Python311\Lib\site-packages\rest_framework\views.py", line 480, in raise_uncaught_exception
    raise exc
  File "C:\Python311\Lib\site-packages\rest_framework\views.py", line 506, in dispatch
    response = handler(request, *args, **kwargs)
               ^^^^^^^^^^^^^^^^^^^^^^^^^^^^^^^^^
  File "C:\Users\Maryam\Documents\GitHub\Enigma_BackEnd\Enigma\Group\views.py", line 45, in post
    if not Members.objects.get(groupID=group, userID=user):
           ^^^^^^^^^^^^^^^^^^^^^^^^^^^^^^^^^^^^^^^^^^^^^^^
  File "C:\Python311\Lib\site-packages\django\db\models\manager.py", line 85, in manager_method
    return getattr(self.get_queryset(), name)(*args, **kwargs)
           ^^^^^^^^^^^^^^^^^^^^^^^^^^^^^^^^^^^^^^^^^^^^^^^^^^^
  File "C:\Python311\Lib\site-packages\django\db\models\query.py", line 650, in get
    raise self.model.DoesNotExist(
Group.models.Members.DoesNotExist: Members matching query does not exist.
ERROR 2023-05-14 07:49:52,578 log 11608 1608 Internal Server Error: /group/AddUserGroup/
Traceback (most recent call last):
  File "C:\Python311\Lib\site-packages\django\core\handlers\exception.py", line 56, in inner
    response = get_response(request)
               ^^^^^^^^^^^^^^^^^^^^^
  File "C:\Python311\Lib\site-packages\django\core\handlers\base.py", line 197, in _get_response
    response = wrapped_callback(request, *callback_args, **callback_kwargs)
               ^^^^^^^^^^^^^^^^^^^^^^^^^^^^^^^^^^^^^^^^^^^^^^^^^^^^^^^^^^^^
  File "C:\Python311\Lib\site-packages\django\views\decorators\csrf.py", line 55, in wrapped_view
    return view_func(*args, **kwargs)
           ^^^^^^^^^^^^^^^^^^^^^^^^^^
  File "C:\Python311\Lib\site-packages\django\views\generic\base.py", line 103, in view
    return self.dispatch(request, *args, **kwargs)
           ^^^^^^^^^^^^^^^^^^^^^^^^^^^^^^^^^^^^^^^
  File "C:\Python311\Lib\site-packages\rest_framework\views.py", line 509, in dispatch
    response = self.handle_exception(exc)
               ^^^^^^^^^^^^^^^^^^^^^^^^^^
  File "C:\Python311\Lib\site-packages\rest_framework\views.py", line 469, in handle_exception
    self.raise_uncaught_exception(exc)
  File "C:\Python311\Lib\site-packages\rest_framework\views.py", line 480, in raise_uncaught_exception
    raise exc
  File "C:\Python311\Lib\site-packages\rest_framework\views.py", line 506, in dispatch
    response = handler(request, *args, **kwargs)
               ^^^^^^^^^^^^^^^^^^^^^^^^^^^^^^^^^
  File "C:\Users\Maryam\Documents\GitHub\Enigma_BackEnd\Enigma\Group\views.py", line 45, in post
    if not Members.objects.get(groupID=group, userID=user):
           ^^^^^^^^^^^^^^^^^^^^^^^^^^^^^^^^^^^^^^^^^^^^^^^
  File "C:\Python311\Lib\site-packages\django\db\models\manager.py", line 85, in manager_method
    return getattr(self.get_queryset(), name)(*args, **kwargs)
           ^^^^^^^^^^^^^^^^^^^^^^^^^^^^^^^^^^^^^^^^^^^^^^^^^^^
  File "C:\Python311\Lib\site-packages\django\db\models\query.py", line 650, in get
    raise self.model.DoesNotExist(
Group.models.Members.DoesNotExist: Members matching query does not exist.
INFO 2023-05-14 07:51:57,897 autoreload 1088 9064 Watching for file changes with StatReloader
ERROR 2023-05-14 07:53:59,800 log 13104 8364 Internal Server Error: /group/AddUserGroup/
Traceback (most recent call last):
  File "C:\Python311\Lib\site-packages\django\core\handlers\exception.py", line 56, in inner
    response = get_response(request)
               ^^^^^^^^^^^^^^^^^^^^^
  File "C:\Python311\Lib\site-packages\django\core\handlers\base.py", line 197, in _get_response
    response = wrapped_callback(request, *callback_args, **callback_kwargs)
               ^^^^^^^^^^^^^^^^^^^^^^^^^^^^^^^^^^^^^^^^^^^^^^^^^^^^^^^^^^^^
  File "C:\Python311\Lib\site-packages\django\views\decorators\csrf.py", line 55, in wrapped_view
    return view_func(*args, **kwargs)
           ^^^^^^^^^^^^^^^^^^^^^^^^^^
  File "C:\Python311\Lib\site-packages\django\views\generic\base.py", line 103, in view
    return self.dispatch(request, *args, **kwargs)
           ^^^^^^^^^^^^^^^^^^^^^^^^^^^^^^^^^^^^^^^
  File "C:\Python311\Lib\site-packages\rest_framework\views.py", line 509, in dispatch
    response = self.handle_exception(exc)
               ^^^^^^^^^^^^^^^^^^^^^^^^^^
  File "C:\Python311\Lib\site-packages\rest_framework\views.py", line 469, in handle_exception
    self.raise_uncaught_exception(exc)
  File "C:\Python311\Lib\site-packages\rest_framework\views.py", line 480, in raise_uncaught_exception
    raise exc
  File "C:\Python311\Lib\site-packages\rest_framework\views.py", line 506, in dispatch
    response = handler(request, *args, **kwargs)
               ^^^^^^^^^^^^^^^^^^^^^^^^^^^^^^^^^
  File "C:\Users\Maryam\Documents\GitHub\Enigma_BackEnd\Enigma\Group\views.py", line 45, in post
    if not Members.objects.get(groupID=group, userID=user):
           ^^^^^^^^^^^^^^^^^^^^^^^^^^^^^^^^^^^^^^^^^^^^^^^
  File "C:\Python311\Lib\site-packages\django\db\models\manager.py", line 85, in manager_method
    return getattr(self.get_queryset(), name)(*args, **kwargs)
           ^^^^^^^^^^^^^^^^^^^^^^^^^^^^^^^^^^^^^^^^^^^^^^^^^^^
  File "C:\Python311\Lib\site-packages\django\db\models\query.py", line 650, in get
    raise self.model.DoesNotExist(
Group.models.Members.DoesNotExist: Members matching query does not exist.
WARNING 2023-05-14 07:53:59,814 log 13104 8364 Forbidden: /group/AddUserGroup/
ERROR 2023-05-14 07:53:59,823 log 13104 8364 Internal Server Error: /group/AddUserGroup/
Traceback (most recent call last):
  File "C:\Python311\Lib\site-packages\django\core\handlers\exception.py", line 56, in inner
    response = get_response(request)
               ^^^^^^^^^^^^^^^^^^^^^
  File "C:\Python311\Lib\site-packages\django\core\handlers\base.py", line 197, in _get_response
    response = wrapped_callback(request, *callback_args, **callback_kwargs)
               ^^^^^^^^^^^^^^^^^^^^^^^^^^^^^^^^^^^^^^^^^^^^^^^^^^^^^^^^^^^^
  File "C:\Python311\Lib\site-packages\django\views\decorators\csrf.py", line 55, in wrapped_view
    return view_func(*args, **kwargs)
           ^^^^^^^^^^^^^^^^^^^^^^^^^^
  File "C:\Python311\Lib\site-packages\django\views\generic\base.py", line 103, in view
    return self.dispatch(request, *args, **kwargs)
           ^^^^^^^^^^^^^^^^^^^^^^^^^^^^^^^^^^^^^^^
  File "C:\Python311\Lib\site-packages\rest_framework\views.py", line 509, in dispatch
    response = self.handle_exception(exc)
               ^^^^^^^^^^^^^^^^^^^^^^^^^^
  File "C:\Python311\Lib\site-packages\rest_framework\views.py", line 469, in handle_exception
    self.raise_uncaught_exception(exc)
  File "C:\Python311\Lib\site-packages\rest_framework\views.py", line 480, in raise_uncaught_exception
    raise exc
  File "C:\Python311\Lib\site-packages\rest_framework\views.py", line 506, in dispatch
    response = handler(request, *args, **kwargs)
               ^^^^^^^^^^^^^^^^^^^^^^^^^^^^^^^^^
  File "C:\Users\Maryam\Documents\GitHub\Enigma_BackEnd\Enigma\Group\views.py", line 45, in post
    if not Members.objects.get(groupID=group, userID=user):
           ^^^^^^^^^^^^^^^^^^^^^^^^^^^^^^^^^^^^^^^^^^^^^^^
  File "C:\Python311\Lib\site-packages\django\db\models\manager.py", line 85, in manager_method
    return getattr(self.get_queryset(), name)(*args, **kwargs)
           ^^^^^^^^^^^^^^^^^^^^^^^^^^^^^^^^^^^^^^^^^^^^^^^^^^^
  File "C:\Python311\Lib\site-packages\django\db\models\query.py", line 650, in get
    raise self.model.DoesNotExist(
Group.models.Members.DoesNotExist: Members matching query does not exist.
ERROR 2023-05-14 07:53:59,836 log 13104 8364 Internal Server Error: /group/AddUserGroup/
Traceback (most recent call last):
  File "C:\Python311\Lib\site-packages\django\core\handlers\exception.py", line 56, in inner
    response = get_response(request)
               ^^^^^^^^^^^^^^^^^^^^^
  File "C:\Python311\Lib\site-packages\django\core\handlers\base.py", line 197, in _get_response
    response = wrapped_callback(request, *callback_args, **callback_kwargs)
               ^^^^^^^^^^^^^^^^^^^^^^^^^^^^^^^^^^^^^^^^^^^^^^^^^^^^^^^^^^^^
  File "C:\Python311\Lib\site-packages\django\views\decorators\csrf.py", line 55, in wrapped_view
    return view_func(*args, **kwargs)
           ^^^^^^^^^^^^^^^^^^^^^^^^^^
  File "C:\Python311\Lib\site-packages\django\views\generic\base.py", line 103, in view
    return self.dispatch(request, *args, **kwargs)
           ^^^^^^^^^^^^^^^^^^^^^^^^^^^^^^^^^^^^^^^
  File "C:\Python311\Lib\site-packages\rest_framework\views.py", line 509, in dispatch
    response = self.handle_exception(exc)
               ^^^^^^^^^^^^^^^^^^^^^^^^^^
  File "C:\Python311\Lib\site-packages\rest_framework\views.py", line 469, in handle_exception
    self.raise_uncaught_exception(exc)
  File "C:\Python311\Lib\site-packages\rest_framework\views.py", line 480, in raise_uncaught_exception
    raise exc
  File "C:\Python311\Lib\site-packages\rest_framework\views.py", line 506, in dispatch
    response = handler(request, *args, **kwargs)
               ^^^^^^^^^^^^^^^^^^^^^^^^^^^^^^^^^
  File "C:\Users\Maryam\Documents\GitHub\Enigma_BackEnd\Enigma\Group\views.py", line 45, in post
    if not Members.objects.get(groupID=group, userID=user):
           ^^^^^^^^^^^^^^^^^^^^^^^^^^^^^^^^^^^^^^^^^^^^^^^
  File "C:\Python311\Lib\site-packages\django\db\models\manager.py", line 85, in manager_method
    return getattr(self.get_queryset(), name)(*args, **kwargs)
           ^^^^^^^^^^^^^^^^^^^^^^^^^^^^^^^^^^^^^^^^^^^^^^^^^^^
  File "C:\Python311\Lib\site-packages\django\db\models\query.py", line 650, in get
    raise self.model.DoesNotExist(
Group.models.Members.DoesNotExist: Members matching query does not exist.
ERROR 2023-05-14 07:55:41,467 log 16772 12204 Internal Server Error: /group/AddUserGroup/
Traceback (most recent call last):
  File "C:\Python311\Lib\site-packages\django\core\handlers\exception.py", line 56, in inner
    response = get_response(request)
               ^^^^^^^^^^^^^^^^^^^^^
  File "C:\Python311\Lib\site-packages\django\core\handlers\base.py", line 197, in _get_response
    response = wrapped_callback(request, *callback_args, **callback_kwargs)
               ^^^^^^^^^^^^^^^^^^^^^^^^^^^^^^^^^^^^^^^^^^^^^^^^^^^^^^^^^^^^
  File "C:\Python311\Lib\site-packages\django\views\decorators\csrf.py", line 55, in wrapped_view
    return view_func(*args, **kwargs)
           ^^^^^^^^^^^^^^^^^^^^^^^^^^
  File "C:\Python311\Lib\site-packages\django\views\generic\base.py", line 103, in view
    return self.dispatch(request, *args, **kwargs)
           ^^^^^^^^^^^^^^^^^^^^^^^^^^^^^^^^^^^^^^^
  File "C:\Python311\Lib\site-packages\rest_framework\views.py", line 509, in dispatch
    response = self.handle_exception(exc)
               ^^^^^^^^^^^^^^^^^^^^^^^^^^
  File "C:\Python311\Lib\site-packages\rest_framework\views.py", line 469, in handle_exception
    self.raise_uncaught_exception(exc)
  File "C:\Python311\Lib\site-packages\rest_framework\views.py", line 480, in raise_uncaught_exception
    raise exc
  File "C:\Python311\Lib\site-packages\rest_framework\views.py", line 506, in dispatch
    response = handler(request, *args, **kwargs)
               ^^^^^^^^^^^^^^^^^^^^^^^^^^^^^^^^^
  File "C:\Users\Maryam\Documents\GitHub\Enigma_BackEnd\Enigma\Group\views.py", line 46, in post
    if not Members.objects.get(groupID=group, userID=user):
           ^^^^^^^^^^^^^^^^^^^^^^^^^^^^^^^^^^^^^^^^^^^^^^^
  File "C:\Python311\Lib\site-packages\django\db\models\manager.py", line 85, in manager_method
    return getattr(self.get_queryset(), name)(*args, **kwargs)
           ^^^^^^^^^^^^^^^^^^^^^^^^^^^^^^^^^^^^^^^^^^^^^^^^^^^
  File "C:\Python311\Lib\site-packages\django\db\models\query.py", line 650, in get
    raise self.model.DoesNotExist(
Group.models.Members.DoesNotExist: Members matching query does not exist.
WARNING 2023-05-14 07:55:41,482 log 16772 12204 Forbidden: /group/AddUserGroup/
ERROR 2023-05-14 07:55:41,490 log 16772 12204 Internal Server Error: /group/AddUserGroup/
Traceback (most recent call last):
  File "C:\Python311\Lib\site-packages\django\core\handlers\exception.py", line 56, in inner
    response = get_response(request)
               ^^^^^^^^^^^^^^^^^^^^^
  File "C:\Python311\Lib\site-packages\django\core\handlers\base.py", line 197, in _get_response
    response = wrapped_callback(request, *callback_args, **callback_kwargs)
               ^^^^^^^^^^^^^^^^^^^^^^^^^^^^^^^^^^^^^^^^^^^^^^^^^^^^^^^^^^^^
  File "C:\Python311\Lib\site-packages\django\views\decorators\csrf.py", line 55, in wrapped_view
    return view_func(*args, **kwargs)
           ^^^^^^^^^^^^^^^^^^^^^^^^^^
  File "C:\Python311\Lib\site-packages\django\views\generic\base.py", line 103, in view
    return self.dispatch(request, *args, **kwargs)
           ^^^^^^^^^^^^^^^^^^^^^^^^^^^^^^^^^^^^^^^
  File "C:\Python311\Lib\site-packages\rest_framework\views.py", line 509, in dispatch
    response = self.handle_exception(exc)
               ^^^^^^^^^^^^^^^^^^^^^^^^^^
  File "C:\Python311\Lib\site-packages\rest_framework\views.py", line 469, in handle_exception
    self.raise_uncaught_exception(exc)
  File "C:\Python311\Lib\site-packages\rest_framework\views.py", line 480, in raise_uncaught_exception
    raise exc
  File "C:\Python311\Lib\site-packages\rest_framework\views.py", line 506, in dispatch
    response = handler(request, *args, **kwargs)
               ^^^^^^^^^^^^^^^^^^^^^^^^^^^^^^^^^
  File "C:\Users\Maryam\Documents\GitHub\Enigma_BackEnd\Enigma\Group\views.py", line 46, in post
    if not Members.objects.get(groupID=group, userID=user):
           ^^^^^^^^^^^^^^^^^^^^^^^^^^^^^^^^^^^^^^^^^^^^^^^
  File "C:\Python311\Lib\site-packages\django\db\models\manager.py", line 85, in manager_method
    return getattr(self.get_queryset(), name)(*args, **kwargs)
           ^^^^^^^^^^^^^^^^^^^^^^^^^^^^^^^^^^^^^^^^^^^^^^^^^^^
  File "C:\Python311\Lib\site-packages\django\db\models\query.py", line 650, in get
    raise self.model.DoesNotExist(
Group.models.Members.DoesNotExist: Members matching query does not exist.
ERROR 2023-05-14 07:55:41,504 log 16772 12204 Internal Server Error: /group/AddUserGroup/
Traceback (most recent call last):
  File "C:\Python311\Lib\site-packages\django\core\handlers\exception.py", line 56, in inner
    response = get_response(request)
               ^^^^^^^^^^^^^^^^^^^^^
  File "C:\Python311\Lib\site-packages\django\core\handlers\base.py", line 197, in _get_response
    response = wrapped_callback(request, *callback_args, **callback_kwargs)
               ^^^^^^^^^^^^^^^^^^^^^^^^^^^^^^^^^^^^^^^^^^^^^^^^^^^^^^^^^^^^
  File "C:\Python311\Lib\site-packages\django\views\decorators\csrf.py", line 55, in wrapped_view
    return view_func(*args, **kwargs)
           ^^^^^^^^^^^^^^^^^^^^^^^^^^
  File "C:\Python311\Lib\site-packages\django\views\generic\base.py", line 103, in view
    return self.dispatch(request, *args, **kwargs)
           ^^^^^^^^^^^^^^^^^^^^^^^^^^^^^^^^^^^^^^^
  File "C:\Python311\Lib\site-packages\rest_framework\views.py", line 509, in dispatch
    response = self.handle_exception(exc)
               ^^^^^^^^^^^^^^^^^^^^^^^^^^
  File "C:\Python311\Lib\site-packages\rest_framework\views.py", line 469, in handle_exception
    self.raise_uncaught_exception(exc)
  File "C:\Python311\Lib\site-packages\rest_framework\views.py", line 480, in raise_uncaught_exception
    raise exc
  File "C:\Python311\Lib\site-packages\rest_framework\views.py", line 506, in dispatch
    response = handler(request, *args, **kwargs)
               ^^^^^^^^^^^^^^^^^^^^^^^^^^^^^^^^^
  File "C:\Users\Maryam\Documents\GitHub\Enigma_BackEnd\Enigma\Group\views.py", line 46, in post
    if not Members.objects.get(groupID=group, userID=user):
           ^^^^^^^^^^^^^^^^^^^^^^^^^^^^^^^^^^^^^^^^^^^^^^^
  File "C:\Python311\Lib\site-packages\django\db\models\manager.py", line 85, in manager_method
    return getattr(self.get_queryset(), name)(*args, **kwargs)
           ^^^^^^^^^^^^^^^^^^^^^^^^^^^^^^^^^^^^^^^^^^^^^^^^^^^
  File "C:\Python311\Lib\site-packages\django\db\models\query.py", line 650, in get
    raise self.model.DoesNotExist(
Group.models.Members.DoesNotExist: Members matching query does not exist.
WARNING 2023-05-14 07:59:18,350 log 6704 1308 Not Found: /group/AddUserGroup/
WARNING 2023-05-14 07:59:18,356 log 6704 1308 Forbidden: /group/AddUserGroup/
WARNING 2023-05-14 07:59:18,382 log 6704 1308 Not Found: /group/AddUserGroup/
WARNING 2023-05-14 08:02:29,472 log 5600 14084 Not Found: /group/AddUserGroup/
WARNING 2023-05-14 08:02:29,480 log 5600 14084 Forbidden: /group/AddUserGroup/
WARNING 2023-05-14 08:02:29,502 log 5600 14084 Not Found: /group/AddUserGroup/
WARNING 2023-05-14 12:00:37,040 log 960 1744 Not Found: /group/AddUserGroup/
WARNING 2023-05-14 12:00:37,046 log 960 1744 Forbidden: /group/AddUserGroup/
ERROR 2023-05-14 12:00:37,055 log 960 1744 Internal Server Error: /group/AddUserGroup/
Traceback (most recent call last):
  File "C:\Python311\Lib\site-packages\django\core\handlers\exception.py", line 56, in inner
    response = get_response(request)
               ^^^^^^^^^^^^^^^^^^^^^
  File "C:\Python311\Lib\site-packages\django\core\handlers\base.py", line 197, in _get_response
    response = wrapped_callback(request, *callback_args, **callback_kwargs)
               ^^^^^^^^^^^^^^^^^^^^^^^^^^^^^^^^^^^^^^^^^^^^^^^^^^^^^^^^^^^^
  File "C:\Python311\Lib\site-packages\django\views\decorators\csrf.py", line 55, in wrapped_view
    return view_func(*args, **kwargs)
           ^^^^^^^^^^^^^^^^^^^^^^^^^^
  File "C:\Python311\Lib\site-packages\django\views\generic\base.py", line 103, in view
    return self.dispatch(request, *args, **kwargs)
           ^^^^^^^^^^^^^^^^^^^^^^^^^^^^^^^^^^^^^^^
  File "C:\Python311\Lib\site-packages\rest_framework\views.py", line 509, in dispatch
    response = self.handle_exception(exc)
               ^^^^^^^^^^^^^^^^^^^^^^^^^^
  File "C:\Python311\Lib\site-packages\rest_framework\views.py", line 469, in handle_exception
    self.raise_uncaught_exception(exc)
  File "C:\Python311\Lib\site-packages\rest_framework\views.py", line 480, in raise_uncaught_exception
    raise exc
  File "C:\Python311\Lib\site-packages\rest_framework\views.py", line 497, in dispatch
    self.initial(request, *args, **kwargs)
  File "C:\Python311\Lib\site-packages\rest_framework\views.py", line 415, in initial
    self.check_permissions(request)
  File "C:\Python311\Lib\site-packages\rest_framework\views.py", line 332, in check_permissions
    if not permission.has_permission(request, self):
           ^^^^^^^^^^^^^^^^^^^^^^^^^^^^^^^^^^^^^^^^
  File "C:\Users\Maryam\Documents\GitHub\Enigma_BackEnd\Enigma\Group\permissions.py", line 10, in has_permission
    members = Members.objects.filter(userID=request.user, groupID=request.data['groupID'])
                                                                  ~~~~~~~~~~~~^^^^^^^^^^^
TypeError: list indices must be integers or slices, not str
WARNING 2023-05-14 12:00:37,089 log 960 1744 Not Found: /group/AddUserGroup/
WARNING 2023-05-14 12:05:43,887 log 6728 13200 Not Found: /group/AddUserGroup/
WARNING 2023-05-14 12:05:43,895 log 6728 13200 Forbidden: /group/AddUserGroup/
ERROR 2023-05-14 12:05:43,905 log 6728 13200 Internal Server Error: /group/AddUserGroup/
Traceback (most recent call last):
  File "C:\Python311\Lib\site-packages\django\core\handlers\exception.py", line 56, in inner
    response = get_response(request)
               ^^^^^^^^^^^^^^^^^^^^^
  File "C:\Python311\Lib\site-packages\django\core\handlers\base.py", line 197, in _get_response
    response = wrapped_callback(request, *callback_args, **callback_kwargs)
               ^^^^^^^^^^^^^^^^^^^^^^^^^^^^^^^^^^^^^^^^^^^^^^^^^^^^^^^^^^^^
  File "C:\Python311\Lib\site-packages\django\views\decorators\csrf.py", line 55, in wrapped_view
    return view_func(*args, **kwargs)
           ^^^^^^^^^^^^^^^^^^^^^^^^^^
  File "C:\Python311\Lib\site-packages\django\views\generic\base.py", line 103, in view
    return self.dispatch(request, *args, **kwargs)
           ^^^^^^^^^^^^^^^^^^^^^^^^^^^^^^^^^^^^^^^
  File "C:\Python311\Lib\site-packages\rest_framework\views.py", line 509, in dispatch
    response = self.handle_exception(exc)
               ^^^^^^^^^^^^^^^^^^^^^^^^^^
  File "C:\Python311\Lib\site-packages\rest_framework\views.py", line 469, in handle_exception
    self.raise_uncaught_exception(exc)
  File "C:\Python311\Lib\site-packages\rest_framework\views.py", line 480, in raise_uncaught_exception
    raise exc
  File "C:\Python311\Lib\site-packages\rest_framework\views.py", line 497, in dispatch
    self.initial(request, *args, **kwargs)
  File "C:\Python311\Lib\site-packages\rest_framework\views.py", line 415, in initial
    self.check_permissions(request)
  File "C:\Python311\Lib\site-packages\rest_framework\views.py", line 332, in check_permissions
    if not permission.has_permission(request, self):
           ^^^^^^^^^^^^^^^^^^^^^^^^^^^^^^^^^^^^^^^^
  File "C:\Users\Maryam\Documents\GitHub\Enigma_BackEnd\Enigma\Group\permissions.py", line 10, in has_permission
    members = Members.objects.filter(userID=request.user, groupID=request.data['groupID'])
                                                                  ~~~~~~~~~~~~^^^^^^^^^^^
TypeError: list indices must be integers or slices, not str
WARNING 2023-05-14 12:05:43,939 log 6728 13200 Not Found: /group/AddUserGroup/
WARNING 2023-05-14 12:07:15,317 log 7608 6128 Not Found: /group/AddUserGroup/
WARNING 2023-05-14 12:07:15,324 log 7608 6128 Forbidden: /group/AddUserGroup/
ERROR 2023-05-14 12:07:15,332 log 7608 6128 Internal Server Error: /group/AddUserGroup/
Traceback (most recent call last):
  File "C:\Python311\Lib\site-packages\django\core\handlers\exception.py", line 56, in inner
    response = get_response(request)
               ^^^^^^^^^^^^^^^^^^^^^
  File "C:\Python311\Lib\site-packages\django\core\handlers\base.py", line 197, in _get_response
    response = wrapped_callback(request, *callback_args, **callback_kwargs)
               ^^^^^^^^^^^^^^^^^^^^^^^^^^^^^^^^^^^^^^^^^^^^^^^^^^^^^^^^^^^^
  File "C:\Python311\Lib\site-packages\django\views\decorators\csrf.py", line 55, in wrapped_view
    return view_func(*args, **kwargs)
           ^^^^^^^^^^^^^^^^^^^^^^^^^^
  File "C:\Python311\Lib\site-packages\django\views\generic\base.py", line 103, in view
    return self.dispatch(request, *args, **kwargs)
           ^^^^^^^^^^^^^^^^^^^^^^^^^^^^^^^^^^^^^^^
  File "C:\Python311\Lib\site-packages\rest_framework\views.py", line 509, in dispatch
    response = self.handle_exception(exc)
               ^^^^^^^^^^^^^^^^^^^^^^^^^^
  File "C:\Python311\Lib\site-packages\rest_framework\views.py", line 469, in handle_exception
    self.raise_uncaught_exception(exc)
  File "C:\Python311\Lib\site-packages\rest_framework\views.py", line 480, in raise_uncaught_exception
    raise exc
  File "C:\Python311\Lib\site-packages\rest_framework\views.py", line 497, in dispatch
    self.initial(request, *args, **kwargs)
  File "C:\Python311\Lib\site-packages\rest_framework\views.py", line 415, in initial
    self.check_permissions(request)
  File "C:\Python311\Lib\site-packages\rest_framework\views.py", line 332, in check_permissions
    if not permission.has_permission(request, self):
           ^^^^^^^^^^^^^^^^^^^^^^^^^^^^^^^^^^^^^^^^
  File "C:\Users\Maryam\Documents\GitHub\Enigma_BackEnd\Enigma\Group\permissions.py", line 10, in has_permission
    members = Members.objects.filter(userID=request.user, groupID=request.data['groupID'])
                                                                  ~~~~~~~~~~~~^^^^^^^^^^^
TypeError: list indices must be integers or slices, not str
WARNING 2023-05-14 12:07:15,365 log 7608 6128 Not Found: /group/AddUserGroup/
WARNING 2023-05-14 12:07:39,762 log 4068 2212 Not Found: /group/AddUserGroup/
WARNING 2023-05-14 12:07:39,770 log 4068 2212 Forbidden: /group/AddUserGroup/
ERROR 2023-05-14 12:07:39,779 log 4068 2212 Internal Server Error: /group/AddUserGroup/
Traceback (most recent call last):
  File "C:\Python311\Lib\site-packages\django\core\handlers\exception.py", line 56, in inner
    response = get_response(request)
               ^^^^^^^^^^^^^^^^^^^^^
  File "C:\Python311\Lib\site-packages\django\core\handlers\base.py", line 197, in _get_response
    response = wrapped_callback(request, *callback_args, **callback_kwargs)
               ^^^^^^^^^^^^^^^^^^^^^^^^^^^^^^^^^^^^^^^^^^^^^^^^^^^^^^^^^^^^
  File "C:\Python311\Lib\site-packages\django\views\decorators\csrf.py", line 55, in wrapped_view
    return view_func(*args, **kwargs)
           ^^^^^^^^^^^^^^^^^^^^^^^^^^
  File "C:\Python311\Lib\site-packages\django\views\generic\base.py", line 103, in view
    return self.dispatch(request, *args, **kwargs)
           ^^^^^^^^^^^^^^^^^^^^^^^^^^^^^^^^^^^^^^^
  File "C:\Python311\Lib\site-packages\rest_framework\views.py", line 509, in dispatch
    response = self.handle_exception(exc)
               ^^^^^^^^^^^^^^^^^^^^^^^^^^
  File "C:\Python311\Lib\site-packages\rest_framework\views.py", line 469, in handle_exception
    self.raise_uncaught_exception(exc)
  File "C:\Python311\Lib\site-packages\rest_framework\views.py", line 480, in raise_uncaught_exception
    raise exc
  File "C:\Python311\Lib\site-packages\rest_framework\views.py", line 497, in dispatch
    self.initial(request, *args, **kwargs)
  File "C:\Python311\Lib\site-packages\rest_framework\views.py", line 415, in initial
    self.check_permissions(request)
  File "C:\Python311\Lib\site-packages\rest_framework\views.py", line 332, in check_permissions
    if not permission.has_permission(request, self):
           ^^^^^^^^^^^^^^^^^^^^^^^^^^^^^^^^^^^^^^^^
  File "C:\Users\Maryam\Documents\GitHub\Enigma_BackEnd\Enigma\Group\permissions.py", line 10, in has_permission
    members = Members.objects.filter(userID=request.user, groupID=request.data['groupID'])
                                                                  ~~~~~~~~~~~~^^^^^^^^^^^
TypeError: list indices must be integers or slices, not str
WARNING 2023-05-14 12:07:39,812 log 4068 2212 Not Found: /group/AddUserGroup/
WARNING 2023-05-14 12:08:00,961 log 15812 15544 Not Found: /group/AddUserGroup/
WARNING 2023-05-14 12:08:00,968 log 15812 15544 Forbidden: /group/AddUserGroup/
ERROR 2023-05-14 12:08:00,978 log 15812 15544 Internal Server Error: /group/AddUserGroup/
Traceback (most recent call last):
  File "C:\Python311\Lib\site-packages\django\core\handlers\exception.py", line 56, in inner
    response = get_response(request)
               ^^^^^^^^^^^^^^^^^^^^^
  File "C:\Python311\Lib\site-packages\django\core\handlers\base.py", line 197, in _get_response
    response = wrapped_callback(request, *callback_args, **callback_kwargs)
               ^^^^^^^^^^^^^^^^^^^^^^^^^^^^^^^^^^^^^^^^^^^^^^^^^^^^^^^^^^^^
  File "C:\Python311\Lib\site-packages\django\views\decorators\csrf.py", line 55, in wrapped_view
    return view_func(*args, **kwargs)
           ^^^^^^^^^^^^^^^^^^^^^^^^^^
  File "C:\Python311\Lib\site-packages\django\views\generic\base.py", line 103, in view
    return self.dispatch(request, *args, **kwargs)
           ^^^^^^^^^^^^^^^^^^^^^^^^^^^^^^^^^^^^^^^
  File "C:\Python311\Lib\site-packages\rest_framework\views.py", line 509, in dispatch
    response = self.handle_exception(exc)
               ^^^^^^^^^^^^^^^^^^^^^^^^^^
  File "C:\Python311\Lib\site-packages\rest_framework\views.py", line 469, in handle_exception
    self.raise_uncaught_exception(exc)
  File "C:\Python311\Lib\site-packages\rest_framework\views.py", line 480, in raise_uncaught_exception
    raise exc
  File "C:\Python311\Lib\site-packages\rest_framework\views.py", line 497, in dispatch
    self.initial(request, *args, **kwargs)
  File "C:\Python311\Lib\site-packages\rest_framework\views.py", line 415, in initial
    self.check_permissions(request)
  File "C:\Python311\Lib\site-packages\rest_framework\views.py", line 332, in check_permissions
    if not permission.has_permission(request, self):
           ^^^^^^^^^^^^^^^^^^^^^^^^^^^^^^^^^^^^^^^^
  File "C:\Users\Maryam\Documents\GitHub\Enigma_BackEnd\Enigma\Group\permissions.py", line 10, in has_permission
    members = Members.objects.filter(userID=request.user, groupID=request.data['groupID'])
                                                                  ~~~~~~~~~~~~^^^^^^^^^^^
TypeError: list indices must be integers or slices, not str
WARNING 2023-05-14 12:08:01,011 log 15812 15544 Not Found: /group/AddUserGroup/
WARNING 2023-05-14 12:08:57,151 log 13424 15240 Not Found: /group/AddUserGroup/
WARNING 2023-05-14 12:08:57,158 log 13424 15240 Forbidden: /group/AddUserGroup/
ERROR 2023-05-14 12:08:57,167 log 13424 15240 Internal Server Error: /group/AddUserGroup/
Traceback (most recent call last):
  File "C:\Python311\Lib\site-packages\django\core\handlers\exception.py", line 56, in inner
    response = get_response(request)
               ^^^^^^^^^^^^^^^^^^^^^
  File "C:\Python311\Lib\site-packages\django\core\handlers\base.py", line 197, in _get_response
    response = wrapped_callback(request, *callback_args, **callback_kwargs)
               ^^^^^^^^^^^^^^^^^^^^^^^^^^^^^^^^^^^^^^^^^^^^^^^^^^^^^^^^^^^^
  File "C:\Python311\Lib\site-packages\django\views\decorators\csrf.py", line 55, in wrapped_view
    return view_func(*args, **kwargs)
           ^^^^^^^^^^^^^^^^^^^^^^^^^^
  File "C:\Python311\Lib\site-packages\django\views\generic\base.py", line 103, in view
    return self.dispatch(request, *args, **kwargs)
           ^^^^^^^^^^^^^^^^^^^^^^^^^^^^^^^^^^^^^^^
  File "C:\Python311\Lib\site-packages\rest_framework\views.py", line 509, in dispatch
    response = self.handle_exception(exc)
               ^^^^^^^^^^^^^^^^^^^^^^^^^^
  File "C:\Python311\Lib\site-packages\rest_framework\views.py", line 469, in handle_exception
    self.raise_uncaught_exception(exc)
  File "C:\Python311\Lib\site-packages\rest_framework\views.py", line 480, in raise_uncaught_exception
    raise exc
  File "C:\Python311\Lib\site-packages\rest_framework\views.py", line 497, in dispatch
    self.initial(request, *args, **kwargs)
  File "C:\Python311\Lib\site-packages\rest_framework\views.py", line 415, in initial
    self.check_permissions(request)
  File "C:\Python311\Lib\site-packages\rest_framework\views.py", line 332, in check_permissions
    if not permission.has_permission(request, self):
           ^^^^^^^^^^^^^^^^^^^^^^^^^^^^^^^^^^^^^^^^
  File "C:\Users\Maryam\Documents\GitHub\Enigma_BackEnd\Enigma\Group\permissions.py", line 10, in has_permission
    members = Members.objects.filter(userID=request.user, groupID=request.data['groupID'])
                                                                  ~~~~~~~~~~~~^^^^^^^^^^^
KeyError: 'groupID'
WARNING 2023-05-14 12:08:57,198 log 13424 15240 Not Found: /group/AddUserGroup/
WARNING 2023-05-14 12:54:30,159 log 11092 10264 Not Found: /group/AddUserGroup/
WARNING 2023-05-14 12:54:30,165 log 11092 10264 Forbidden: /group/AddUserGroup/
ERROR 2023-05-14 12:54:30,171 log 11092 10264 Internal Server Error: /group/AddUserGroup/
Traceback (most recent call last):
  File "C:\Python311\Lib\site-packages\django\core\handlers\exception.py", line 56, in inner
    response = get_response(request)
               ^^^^^^^^^^^^^^^^^^^^^
  File "C:\Python311\Lib\site-packages\django\core\handlers\base.py", line 197, in _get_response
    response = wrapped_callback(request, *callback_args, **callback_kwargs)
               ^^^^^^^^^^^^^^^^^^^^^^^^^^^^^^^^^^^^^^^^^^^^^^^^^^^^^^^^^^^^
  File "C:\Python311\Lib\site-packages\django\views\decorators\csrf.py", line 55, in wrapped_view
    return view_func(*args, **kwargs)
           ^^^^^^^^^^^^^^^^^^^^^^^^^^
  File "C:\Python311\Lib\site-packages\django\views\generic\base.py", line 103, in view
    return self.dispatch(request, *args, **kwargs)
           ^^^^^^^^^^^^^^^^^^^^^^^^^^^^^^^^^^^^^^^
  File "C:\Python311\Lib\site-packages\rest_framework\views.py", line 509, in dispatch
    response = self.handle_exception(exc)
               ^^^^^^^^^^^^^^^^^^^^^^^^^^
  File "C:\Python311\Lib\site-packages\rest_framework\views.py", line 469, in handle_exception
    self.raise_uncaught_exception(exc)
  File "C:\Python311\Lib\site-packages\rest_framework\views.py", line 480, in raise_uncaught_exception
    raise exc
  File "C:\Python311\Lib\site-packages\rest_framework\views.py", line 497, in dispatch
    self.initial(request, *args, **kwargs)
  File "C:\Python311\Lib\site-packages\rest_framework\views.py", line 415, in initial
    self.check_permissions(request)
  File "C:\Python311\Lib\site-packages\rest_framework\views.py", line 332, in check_permissions
    if not permission.has_permission(request, self):
           ^^^^^^^^^^^^^^^^^^^^^^^^^^^^^^^^^^^^^^^^
  File "C:\Users\Maryam\Documents\GitHub\Enigma_BackEnd\Enigma\Group\permissions.py", line 10, in has_permission
    members = Members.objects.filter(userID=request.user, groupID=request.data['groupID'])
                                                                  ~~~~~~~~~~~~^^^^^^^^^^^
KeyError: 'groupID'
WARNING 2023-05-14 12:54:30,243 log 11092 10264 Not Found: /group/AddUserGroup/
WARNING 2023-05-14 13:10:51,193 log 4044 9896 Not Found: /group/AddUserGroup/
WARNING 2023-05-14 13:10:51,200 log 4044 9896 Forbidden: /group/AddUserGroup/
ERROR 2023-05-14 13:10:51,207 log 4044 9896 Internal Server Error: /group/AddUserGroup/
Traceback (most recent call last):
  File "C:\Python311\Lib\site-packages\django\core\handlers\exception.py", line 56, in inner
    response = get_response(request)
               ^^^^^^^^^^^^^^^^^^^^^
  File "C:\Python311\Lib\site-packages\django\core\handlers\base.py", line 197, in _get_response
    response = wrapped_callback(request, *callback_args, **callback_kwargs)
               ^^^^^^^^^^^^^^^^^^^^^^^^^^^^^^^^^^^^^^^^^^^^^^^^^^^^^^^^^^^^
  File "C:\Python311\Lib\site-packages\django\views\decorators\csrf.py", line 55, in wrapped_view
    return view_func(*args, **kwargs)
           ^^^^^^^^^^^^^^^^^^^^^^^^^^
  File "C:\Python311\Lib\site-packages\django\views\generic\base.py", line 103, in view
    return self.dispatch(request, *args, **kwargs)
           ^^^^^^^^^^^^^^^^^^^^^^^^^^^^^^^^^^^^^^^
  File "C:\Python311\Lib\site-packages\rest_framework\views.py", line 509, in dispatch
    response = self.handle_exception(exc)
               ^^^^^^^^^^^^^^^^^^^^^^^^^^
  File "C:\Python311\Lib\site-packages\rest_framework\views.py", line 469, in handle_exception
    self.raise_uncaught_exception(exc)
  File "C:\Python311\Lib\site-packages\rest_framework\views.py", line 480, in raise_uncaught_exception
    raise exc
  File "C:\Python311\Lib\site-packages\rest_framework\views.py", line 497, in dispatch
    self.initial(request, *args, **kwargs)
  File "C:\Python311\Lib\site-packages\rest_framework\views.py", line 415, in initial
    self.check_permissions(request)
  File "C:\Python311\Lib\site-packages\rest_framework\views.py", line 332, in check_permissions
    if not permission.has_permission(request, self):
           ^^^^^^^^^^^^^^^^^^^^^^^^^^^^^^^^^^^^^^^^
  File "C:\Users\Maryam\Documents\GitHub\Enigma_BackEnd\Enigma\Group\permissions.py", line 10, in has_permission
    members = Members.objects.filter(userID=request.user, groupID=request.data['groupID'])
                                                                  ~~~~~~~~~~~~^^^^^^^^^^^
KeyError: 'groupID'
WARNING 2023-05-14 13:10:51,239 log 4044 9896 Not Found: /group/AddUserGroup/
WARNING 2023-05-14 13:13:49,506 log 9784 292 Not Found: /group/AddUserGroup/
WARNING 2023-05-14 13:13:49,516 log 9784 292 Forbidden: /group/AddUserGroup/
ERROR 2023-05-14 13:13:49,526 log 9784 292 Internal Server Error: /group/AddUserGroup/
Traceback (most recent call last):
  File "C:\Python311\Lib\site-packages\django\db\models\fields\__init__.py", line 2018, in get_prep_value
    return int(value)
           ^^^^^^^^^^
  File "C:\Python311\Lib\site-packages\django\contrib\auth\models.py", line 437, in __int__
    raise TypeError(
TypeError: Cannot cast AnonymousUser to int. Are you trying to use it in place of User?

The above exception was the direct cause of the following exception:

Traceback (most recent call last):
  File "C:\Python311\Lib\site-packages\django\core\handlers\exception.py", line 56, in inner
    response = get_response(request)
               ^^^^^^^^^^^^^^^^^^^^^
  File "C:\Python311\Lib\site-packages\django\core\handlers\base.py", line 197, in _get_response
    response = wrapped_callback(request, *callback_args, **callback_kwargs)
               ^^^^^^^^^^^^^^^^^^^^^^^^^^^^^^^^^^^^^^^^^^^^^^^^^^^^^^^^^^^^
  File "C:\Python311\Lib\site-packages\django\views\decorators\csrf.py", line 55, in wrapped_view
    return view_func(*args, **kwargs)
           ^^^^^^^^^^^^^^^^^^^^^^^^^^
  File "C:\Python311\Lib\site-packages\django\views\generic\base.py", line 103, in view
    return self.dispatch(request, *args, **kwargs)
           ^^^^^^^^^^^^^^^^^^^^^^^^^^^^^^^^^^^^^^^
  File "C:\Python311\Lib\site-packages\rest_framework\views.py", line 509, in dispatch
    response = self.handle_exception(exc)
               ^^^^^^^^^^^^^^^^^^^^^^^^^^
  File "C:\Python311\Lib\site-packages\rest_framework\views.py", line 469, in handle_exception
    self.raise_uncaught_exception(exc)
  File "C:\Python311\Lib\site-packages\rest_framework\views.py", line 480, in raise_uncaught_exception
    raise exc
  File "C:\Python311\Lib\site-packages\rest_framework\views.py", line 497, in dispatch
    self.initial(request, *args, **kwargs)
  File "C:\Python311\Lib\site-packages\rest_framework\views.py", line 415, in initial
    self.check_permissions(request)
  File "C:\Python311\Lib\site-packages\rest_framework\views.py", line 332, in check_permissions
    if not permission.has_permission(request, self):
           ^^^^^^^^^^^^^^^^^^^^^^^^^^^^^^^^^^^^^^^^
  File "C:\Users\Maryam\Documents\GitHub\Enigma_BackEnd\Enigma\Group\permissions.py", line 10, in has_permission
    members = Members.objects.filter(userID=request.user, groupID=request.data.get('groupID'))
              ^^^^^^^^^^^^^^^^^^^^^^^^^^^^^^^^^^^^^^^^^^^^^^^^^^^^^^^^^^^^^^^^^^^^^^^^^^^^^^^^
  File "C:\Python311\Lib\site-packages\django\db\models\manager.py", line 85, in manager_method
    return getattr(self.get_queryset(), name)(*args, **kwargs)
           ^^^^^^^^^^^^^^^^^^^^^^^^^^^^^^^^^^^^^^^^^^^^^^^^^^^
  File "C:\Python311\Lib\site-packages\django\db\models\query.py", line 1421, in filter
    return self._filter_or_exclude(False, args, kwargs)
           ^^^^^^^^^^^^^^^^^^^^^^^^^^^^^^^^^^^^^^^^^^^^
  File "C:\Python311\Lib\site-packages\django\db\models\query.py", line 1439, in _filter_or_exclude
    clone._filter_or_exclude_inplace(negate, args, kwargs)
  File "C:\Python311\Lib\site-packages\django\db\models\query.py", line 1446, in _filter_or_exclude_inplace
    self._query.add_q(Q(*args, **kwargs))
  File "C:\Python311\Lib\site-packages\django\db\models\sql\query.py", line 1532, in add_q
    clause, _ = self._add_q(q_object, self.used_aliases)
                ^^^^^^^^^^^^^^^^^^^^^^^^^^^^^^^^^^^^^^^^
  File "C:\Python311\Lib\site-packages\django\db\models\sql\query.py", line 1562, in _add_q
    child_clause, needed_inner = self.build_filter(
                                 ^^^^^^^^^^^^^^^^^^
  File "C:\Python311\Lib\site-packages\django\db\models\sql\query.py", line 1478, in build_filter
    condition = self.build_lookup(lookups, col, value)
                ^^^^^^^^^^^^^^^^^^^^^^^^^^^^^^^^^^^^^^
  File "C:\Python311\Lib\site-packages\django\db\models\sql\query.py", line 1303, in build_lookup
    lookup = lookup_class(lhs, rhs)
             ^^^^^^^^^^^^^^^^^^^^^^
  File "C:\Python311\Lib\site-packages\django\db\models\lookups.py", line 27, in __init__
    self.rhs = self.get_prep_lookup()
               ^^^^^^^^^^^^^^^^^^^^^^
  File "C:\Python311\Lib\site-packages\django\db\models\fields\related_lookups.py", line 166, in get_prep_lookup
    self.rhs = target_field.get_prep_value(self.rhs)
               ^^^^^^^^^^^^^^^^^^^^^^^^^^^^^^^^^^^^^
  File "C:\Python311\Lib\site-packages\django\db\models\fields\__init__.py", line 2020, in get_prep_value
    raise e.__class__(
TypeError: Field 'user_id' expected a number but got <django.contrib.auth.models.AnonymousUser object at 0x000001E121F3E890>.
WARNING 2023-05-14 13:13:49,632 log 9784 292 Not Found: /group/AddUserGroup/
WARNING 2023-05-14 13:18:42,884 log 4892 7084 Not Found: /group/AddUserGroup/
WARNING 2023-05-14 13:18:42,890 log 4892 7084 Forbidden: /group/AddUserGroup/
ERROR 2023-05-14 13:18:42,896 log 4892 7084 Internal Server Error: /group/AddUserGroup/
Traceback (most recent call last):
  File "C:\Python311\Lib\site-packages\django\core\handlers\exception.py", line 56, in inner
    response = get_response(request)
               ^^^^^^^^^^^^^^^^^^^^^
  File "C:\Python311\Lib\site-packages\django\core\handlers\base.py", line 197, in _get_response
    response = wrapped_callback(request, *callback_args, **callback_kwargs)
               ^^^^^^^^^^^^^^^^^^^^^^^^^^^^^^^^^^^^^^^^^^^^^^^^^^^^^^^^^^^^
  File "C:\Python311\Lib\site-packages\django\views\decorators\csrf.py", line 55, in wrapped_view
    return view_func(*args, **kwargs)
           ^^^^^^^^^^^^^^^^^^^^^^^^^^
  File "C:\Python311\Lib\site-packages\django\views\generic\base.py", line 103, in view
    return self.dispatch(request, *args, **kwargs)
           ^^^^^^^^^^^^^^^^^^^^^^^^^^^^^^^^^^^^^^^
  File "C:\Python311\Lib\site-packages\rest_framework\views.py", line 509, in dispatch
    response = self.handle_exception(exc)
               ^^^^^^^^^^^^^^^^^^^^^^^^^^
  File "C:\Python311\Lib\site-packages\rest_framework\views.py", line 469, in handle_exception
    self.raise_uncaught_exception(exc)
  File "C:\Python311\Lib\site-packages\rest_framework\views.py", line 480, in raise_uncaught_exception
    raise exc
  File "C:\Python311\Lib\site-packages\rest_framework\views.py", line 497, in dispatch
    self.initial(request, *args, **kwargs)
  File "C:\Python311\Lib\site-packages\rest_framework\views.py", line 415, in initial
    self.check_permissions(request)
  File "C:\Python311\Lib\site-packages\rest_framework\views.py", line 332, in check_permissions
    if not permission.has_permission(request, self):
           ^^^^^^^^^^^^^^^^^^^^^^^^^^^^^^^^^^^^^^^^
  File "C:\Users\Maryam\Documents\GitHub\Enigma_BackEnd\Enigma\Group\permissions.py", line 12, in has_permission
    members = Members.objects.filter(userID=request.user, groupID=request.data['groupID'])
                                                                  ~~~~~~~~~~~~^^^^^^^^^^^
KeyError: 'groupID'
WARNING 2023-05-14 13:18:42,930 log 4892 7084 Not Found: /group/AddUserGroup/
WARNING 2023-05-14 13:19:17,508 log 17552 13356 Not Found: /group/AddUserGroup/
WARNING 2023-05-14 13:19:17,517 log 17552 13356 Forbidden: /group/AddUserGroup/
WARNING 2023-05-14 13:19:17,522 log 17552 13356 Not Found: /group/AddUserGroup/
WARNING 2023-05-14 13:19:17,548 log 17552 13356 Not Found: /group/AddUserGroup/
WARNING 2023-05-14 13:21:41,147 log 15616 1668 Not Found: /group/AddUserGroup/
WARNING 2023-05-14 13:21:41,156 log 15616 1668 Forbidden: /group/AddUserGroup/
WARNING 2023-05-14 13:21:41,162 log 15616 1668 Not Found: /group/AddUserGroup/
WARNING 2023-05-14 13:21:41,189 log 15616 1668 Not Found: /group/AddUserGroup/
WARNING 2023-05-14 13:34:23,711 log 17000 17300 Not Found: /group/AddUserGroup/
WARNING 2023-05-14 13:34:23,718 log 17000 17300 Forbidden: /group/AddUserGroup/
WARNING 2023-05-14 13:34:23,720 log 17000 17300 Forbidden: /group/AddUserGroup/
WARNING 2023-05-14 13:34:23,746 log 17000 17300 Not Found: /group/AddUserGroup/
WARNING 2023-05-14 13:35:34,375 log 16712 11868 Not Found: /group/AddUserGroup/
WARNING 2023-05-14 13:35:34,383 log 16712 11868 Forbidden: /group/AddUserGroup/
WARNING 2023-05-14 13:35:34,387 log 16712 11868 Forbidden: /group/AddUserGroup/
WARNING 2023-05-14 13:35:34,413 log 16712 11868 Not Found: /group/AddUserGroup/
WARNING 2023-05-14 13:35:56,896 log 10108 8040 Not Found: /group/AddUserGroup/
WARNING 2023-05-14 13:35:56,902 log 10108 8040 Forbidden: /group/AddUserGroup/
WARNING 2023-05-14 13:35:56,904 log 10108 8040 Forbidden: /group/AddUserGroup/
WARNING 2023-05-14 13:35:56,928 log 10108 8040 Not Found: /group/AddUserGroup/
WARNING 2023-05-14 13:36:17,635 log 6704 5252 Not Found: /group/AddUserGroup/
WARNING 2023-05-14 13:36:17,641 log 6704 5252 Forbidden: /group/AddUserGroup/
WARNING 2023-05-14 13:36:17,644 log 6704 5252 Forbidden: /group/AddUserGroup/
WARNING 2023-05-14 13:36:17,668 log 6704 5252 Not Found: /group/AddUserGroup/
WARNING 2023-05-14 13:41:16,413 log 17056 17036 Not Found: /group/AddUserGroup/
WARNING 2023-05-14 13:41:16,436 log 17056 17036 Forbidden: /group/AddUserGroup/
WARNING 2023-05-14 13:41:16,438 log 17056 17036 Forbidden: /group/AddUserGroup/
WARNING 2023-05-14 13:41:16,462 log 17056 17036 Not Found: /group/AddUserGroup/
WARNING 2023-05-14 13:42:00,682 log 14932 16072 Not Found: /group/AddUserGroup/
WARNING 2023-05-14 13:42:00,689 log 14932 16072 Forbidden: /group/AddUserGroup/
WARNING 2023-05-14 13:42:00,691 log 14932 16072 Forbidden: /group/AddUserGroup/
WARNING 2023-05-14 13:42:00,718 log 14932 16072 Not Found: /group/AddUserGroup/
WARNING 2023-05-14 14:13:14,652 log 13556 12028 Not Found: /group/AddUserGroup/
WARNING 2023-05-14 14:13:14,657 log 13556 12028 Forbidden: /group/AddUserGroup/
WARNING 2023-05-14 14:13:14,660 log 13556 12028 Forbidden: /group/AddUserGroup/
WARNING 2023-05-14 14:13:14,662 log 13556 12028 Forbidden: /group/AddUserGroup/
WARNING 2023-05-14 14:13:14,681 log 13556 12028 Not Found: /group/AddUserGroup/
WARNING 2023-05-14 14:19:46,660 log 16496 5992 Not Found: /group/AddUserGroup/
WARNING 2023-05-14 14:19:46,664 log 16496 5992 Forbidden: /group/AddUserGroup/
WARNING 2023-05-14 14:19:46,668 log 16496 5992 Forbidden: /group/AddUserGroup/
WARNING 2023-05-14 14:19:46,670 log 16496 5992 Forbidden: /group/AddUserGroup/
WARNING 2023-05-14 14:19:46,693 log 16496 5992 Not Found: /group/AddUserGroup/
WARNING 2023-05-14 14:20:23,869 log 13356 14172 Not Found: /group/AddUserGroup/
WARNING 2023-05-14 14:20:23,875 log 13356 14172 Forbidden: /group/AddUserGroup/
WARNING 2023-05-14 14:20:23,879 log 13356 14172 Forbidden: /group/AddUserGroup/
WARNING 2023-05-14 14:20:23,883 log 13356 14172 Forbidden: /group/AddUserGroup/
WARNING 2023-05-14 14:20:23,913 log 13356 14172 Not Found: /group/AddUserGroup/
WARNING 2023-05-14 18:25:00,253 log 7000 10116 Not Found: /group/AddUserGroup/
WARNING 2023-05-14 18:25:00,259 log 7000 10116 Forbidden: /group/AddUserGroup/
WARNING 2023-05-14 18:25:00,261 log 7000 10116 Forbidden: /group/AddUserGroup/
WARNING 2023-05-14 18:25:00,280 log 7000 10116 Not Found: /group/AddUserGroup/
ERROR 2023-05-14 18:25:15,763 log 7796 7752 Internal Server Error: /group/CreateGroup/
Traceback (most recent call last):
  File "C:\Python311\Lib\site-packages\django\core\handlers\exception.py", line 56, in inner
    response = get_response(request)
               ^^^^^^^^^^^^^^^^^^^^^
  File "C:\Python311\Lib\site-packages\django\core\handlers\base.py", line 197, in _get_response
    response = wrapped_callback(request, *callback_args, **callback_kwargs)
               ^^^^^^^^^^^^^^^^^^^^^^^^^^^^^^^^^^^^^^^^^^^^^^^^^^^^^^^^^^^^
  File "C:\Python311\Lib\site-packages\django\views\decorators\csrf.py", line 55, in wrapped_view
    return view_func(*args, **kwargs)
           ^^^^^^^^^^^^^^^^^^^^^^^^^^
  File "C:\Python311\Lib\site-packages\django\views\generic\base.py", line 103, in view
    return self.dispatch(request, *args, **kwargs)
           ^^^^^^^^^^^^^^^^^^^^^^^^^^^^^^^^^^^^^^^
  File "C:\Python311\Lib\site-packages\rest_framework\views.py", line 509, in dispatch
    response = self.handle_exception(exc)
               ^^^^^^^^^^^^^^^^^^^^^^^^^^
  File "C:\Python311\Lib\site-packages\rest_framework\views.py", line 469, in handle_exception
    self.raise_uncaught_exception(exc)
  File "C:\Python311\Lib\site-packages\rest_framework\views.py", line 480, in raise_uncaught_exception
    raise exc
  File "C:\Python311\Lib\site-packages\rest_framework\views.py", line 506, in dispatch
    response = handler(request, *args, **kwargs)
               ^^^^^^^^^^^^^^^^^^^^^^^^^^^^^^^^^
  File "C:\Users\Maryam\Documents\GitHub\Enigma_BackEnd\Enigma\Group\views.py", line 25, in post
    data["emails"] = request.data['emails']
                     ~~~~~~~~~~~~^^^^^^^^^^
KeyError: 'emails'
WARNING 2023-05-14 18:40:15,327 log 13096 13616 Bad Request: /group/CreateGroup/
WARNING 2023-05-14 18:40:15,344 log 13096 13616 Bad Request: /group/CreateGroup/
WARNING 2023-05-14 18:40:15,347 log 13096 13616 Bad Request: /group/CreateGroup/
WARNING 2023-05-14 18:40:15,358 log 13096 13616 Bad Request: /group/CreateGroup/
WARNING 2023-05-14 18:40:15,361 log 13096 13616 Bad Request: /group/CreateGroup/
WARNING 2023-05-14 18:41:19,828 log 5732 9872 Forbidden: /group/DeleteGroup/
ERROR 2023-05-14 18:41:19,832 log 5732 9872 Internal Server Error: /group/DeleteGroup/
WARNING 2023-05-14 18:41:19,836 log 5732 9872 Forbidden: /group/DeleteGroup/
ERROR 2023-05-14 18:41:19,840 log 5732 9872 Internal Server Error: /group/GroupInfo/
ERROR 2023-05-14 18:41:19,843 log 5732 9872 Internal Server Error: /group/GroupInfo/
WARNING 2023-05-14 18:41:19,846 log 5732 9872 Not Found: /group/GroupInfo/
WARNING 2023-05-14 18:41:19,853 log 5732 9872 Unauthorized: /group/GroupInfo/
WARNING 2023-05-14 18:41:19,857 log 5732 9872 Not Found: /group/GroupInfo/
WARNING 2023-05-14 18:41:19,861 log 5732 9872 Forbidden: /group/GroupInfo/
ERROR 2023-05-14 18:41:19,864 log 5732 9872 Internal Server Error: /group/ShowGroups/
WARNING 2023-05-14 18:41:19,866 log 5732 9872 Method Not Allowed: /group/ShowGroups/
WARNING 2023-05-14 18:41:19,870 log 5732 9872 Not Found: /group/ShowGroups/
WARNING 2023-05-14 18:41:19,877 log 5732 9872 Unauthorized: /group/ShowGroups/
WARNING 2023-05-14 18:41:19,880 log 5732 9872 Not Found: /group/ShowGroups/
ERROR 2023-05-14 18:41:19,892 log 5732 9872 Internal Server Error: /group/ShowMembers/
WARNING 2023-05-14 18:41:19,898 log 5732 9872 Forbidden: /group/ShowMembers/
WARNING 2023-05-14 18:41:19,901 log 5732 9872 Forbidden: /group/ShowMembers/
WARNING 2023-05-14 18:41:19,922 log 5732 9872 Forbidden: /group/ShowMembers/
WARNING 2023-05-14 18:41:19,937 log 5732 9872 Bad Request: /group/CreateGroup/
WARNING 2023-05-14 18:41:19,957 log 5732 9872 Bad Request: /group/CreateGroup/
WARNING 2023-05-14 18:41:19,961 log 5732 9872 Bad Request: /group/CreateGroup/
WARNING 2023-05-14 18:41:19,971 log 5732 9872 Bad Request: /group/CreateGroup/
WARNING 2023-05-14 18:41:19,976 log 5732 9872 Bad Request: /group/CreateGroup/
WARNING 2023-05-14 18:47:31,968 log 10032 17220 Bad Request: /group/CreateGroup/
WARNING 2023-05-14 18:47:31,985 log 10032 17220 Bad Request: /group/CreateGroup/
WARNING 2023-05-14 18:47:31,990 log 10032 17220 Bad Request: /group/CreateGroup/
WARNING 2023-05-14 18:47:32,000 log 10032 17220 Bad Request: /group/CreateGroup/
WARNING 2023-05-14 18:47:32,004 log 10032 17220 Bad Request: /group/CreateGroup/
WARNING 2023-05-14 18:47:39,133 log 15024 13536 Bad Request: /group/CreateGroup/
WARNING 2023-05-14 18:47:39,154 log 15024 13536 Bad Request: /group/CreateGroup/
WARNING 2023-05-14 18:47:39,159 log 15024 13536 Bad Request: /group/CreateGroup/
WARNING 2023-05-14 18:47:39,172 log 15024 13536 Bad Request: /group/CreateGroup/
WARNING 2023-05-14 18:47:39,177 log 15024 13536 Bad Request: /group/CreateGroup/
WARNING 2023-05-14 18:57:19,343 log 17476 11396 Bad Request: /group/CreateGroup/
WARNING 2023-05-14 18:57:19,369 log 17476 11396 Not Found: /group/CreateGroup/
WARNING 2023-05-14 18:57:19,374 log 17476 11396 Bad Request: /group/CreateGroup/
WARNING 2023-05-14 18:57:19,378 log 17476 11396 Bad Request: /group/CreateGroup/
WARNING 2023-05-14 18:57:19,392 log 17476 11396 Bad Request: /group/CreateGroup/
WARNING 2023-05-14 18:57:19,397 log 17476 11396 Bad Request: /group/CreateGroup/
WARNING 2023-05-14 18:57:19,423 log 17476 11396 Not Found: /group/CreateGroup/
WARNING 2023-05-14 18:57:27,851 log 11596 836 Forbidden: /group/DeleteGroup/
ERROR 2023-05-14 18:57:27,855 log 11596 836 Internal Server Error: /group/DeleteGroup/
WARNING 2023-05-14 18:57:27,859 log 11596 836 Forbidden: /group/DeleteGroup/
ERROR 2023-05-14 18:57:27,864 log 11596 836 Internal Server Error: /group/GroupInfo/
ERROR 2023-05-14 18:57:27,869 log 11596 836 Internal Server Error: /group/GroupInfo/
WARNING 2023-05-14 18:57:27,871 log 11596 836 Not Found: /group/GroupInfo/
WARNING 2023-05-14 18:57:27,882 log 11596 836 Unauthorized: /group/GroupInfo/
WARNING 2023-05-14 18:57:27,886 log 11596 836 Not Found: /group/GroupInfo/
WARNING 2023-05-14 18:57:27,889 log 11596 836 Forbidden: /group/GroupInfo/
ERROR 2023-05-14 18:57:27,893 log 11596 836 Internal Server Error: /group/ShowGroups/
WARNING 2023-05-14 18:57:27,896 log 11596 836 Method Not Allowed: /group/ShowGroups/
WARNING 2023-05-14 18:57:27,900 log 11596 836 Not Found: /group/ShowGroups/
WARNING 2023-05-14 18:57:27,906 log 11596 836 Unauthorized: /group/ShowGroups/
WARNING 2023-05-14 18:57:27,910 log 11596 836 Not Found: /group/ShowGroups/
ERROR 2023-05-14 18:57:27,924 log 11596 836 Internal Server Error: /group/ShowMembers/
WARNING 2023-05-14 18:57:27,935 log 11596 836 Forbidden: /group/ShowMembers/
WARNING 2023-05-14 18:57:27,939 log 11596 836 Forbidden: /group/ShowMembers/
WARNING 2023-05-14 18:57:27,966 log 11596 836 Forbidden: /group/ShowMembers/
WARNING 2023-05-14 18:57:27,993 log 11596 836 Bad Request: /group/CreateGroup/
WARNING 2023-05-14 18:57:28,022 log 11596 836 Not Found: /group/CreateGroup/
WARNING 2023-05-14 18:57:28,027 log 11596 836 Bad Request: /group/CreateGroup/
WARNING 2023-05-14 18:57:28,034 log 11596 836 Bad Request: /group/CreateGroup/
WARNING 2023-05-14 18:57:28,048 log 11596 836 Bad Request: /group/CreateGroup/
WARNING 2023-05-14 18:57:28,053 log 11596 836 Bad Request: /group/CreateGroup/
WARNING 2023-05-14 18:57:28,080 log 11596 836 Not Found: /group/CreateGroup/
WARNING 2023-05-14 19:00:21,548 log 16992 10876 Not Found: /group/AddUserGroup/
WARNING 2023-05-14 19:00:21,554 log 16992 10876 Forbidden: /group/AddUserGroup/
WARNING 2023-05-14 19:00:21,557 log 16992 10876 Forbidden: /group/AddUserGroup/
WARNING 2023-05-14 19:00:21,582 log 16992 10876 Not Found: /group/AddUserGroup/
WARNING 2023-05-14 19:00:21,593 log 16992 10876 Forbidden: /group/DeleteGroup/
ERROR 2023-05-14 19:00:21,598 log 16992 10876 Internal Server Error: /group/DeleteGroup/
WARNING 2023-05-14 19:00:21,601 log 16992 10876 Forbidden: /group/DeleteGroup/
ERROR 2023-05-14 19:00:21,605 log 16992 10876 Internal Server Error: /group/GroupInfo/
ERROR 2023-05-14 19:00:21,609 log 16992 10876 Internal Server Error: /group/GroupInfo/
WARNING 2023-05-14 19:00:21,612 log 16992 10876 Not Found: /group/GroupInfo/
WARNING 2023-05-14 19:00:21,620 log 16992 10876 Unauthorized: /group/GroupInfo/
WARNING 2023-05-14 19:00:21,624 log 16992 10876 Not Found: /group/GroupInfo/
WARNING 2023-05-14 19:00:21,628 log 16992 10876 Forbidden: /group/GroupInfo/
ERROR 2023-05-14 19:00:21,631 log 16992 10876 Internal Server Error: /group/ShowGroups/
WARNING 2023-05-14 19:00:21,633 log 16992 10876 Method Not Allowed: /group/ShowGroups/
WARNING 2023-05-14 19:00:21,635 log 16992 10876 Not Found: /group/ShowGroups/
WARNING 2023-05-14 19:00:21,643 log 16992 10876 Unauthorized: /group/ShowGroups/
WARNING 2023-05-14 19:00:21,646 log 16992 10876 Not Found: /group/ShowGroups/
ERROR 2023-05-14 19:00:21,655 log 16992 10876 Internal Server Error: /group/ShowMembers/
WARNING 2023-05-14 19:00:21,662 log 16992 10876 Forbidden: /group/ShowMembers/
WARNING 2023-05-14 19:00:21,666 log 16992 10876 Forbidden: /group/ShowMembers/
WARNING 2023-05-14 19:00:21,686 log 16992 10876 Forbidden: /group/ShowMembers/
WARNING 2023-05-14 19:00:21,705 log 16992 10876 Bad Request: /group/CreateGroup/
WARNING 2023-05-14 19:00:21,729 log 16992 10876 Not Found: /group/CreateGroup/
WARNING 2023-05-14 19:00:21,732 log 16992 10876 Bad Request: /group/CreateGroup/
WARNING 2023-05-14 19:00:21,735 log 16992 10876 Bad Request: /group/CreateGroup/
WARNING 2023-05-14 19:00:21,749 log 16992 10876 Bad Request: /group/CreateGroup/
WARNING 2023-05-14 19:00:21,752 log 16992 10876 Bad Request: /group/CreateGroup/
WARNING 2023-05-14 19:00:21,776 log 16992 10876 Not Found: /group/CreateGroup/
WARNING 2023-05-14 19:11:06,202 log 13728 16752 Unauthorized: /auth/register/
WARNING 2023-05-14 19:11:06,450 log 13728 16752 Bad Request: /auth/token/
WARNING 2023-05-14 19:11:06,452 log 13728 16752 Unauthorized: /auth/register/
WARNING 2023-05-14 19:11:06,699 log 13728 16752 Bad Request: /auth/token/
WARNING 2023-05-14 19:11:06,701 log 13728 16752 Unauthorized: /auth/register/
WARNING 2023-05-14 19:11:06,947 log 13728 16752 Bad Request: /auth/token/
WARNING 2023-05-14 19:11:06,949 log 13728 16752 Unauthorized: /auth/register/
WARNING 2023-05-14 19:11:06,950 log 13728 16752 Unauthorized: /auth/register/
WARNING 2023-05-14 19:11:06,952 log 13728 16752 Unauthorized: /auth/register/
WARNING 2023-05-14 19:55:46,501 log 4640 9132 Not Found: /group/AddUserGroup/
WARNING 2023-05-14 19:55:46,505 log 4640 9132 Forbidden: /group/AddUserGroup/
WARNING 2023-05-14 19:55:46,507 log 4640 9132 Forbidden: /group/AddUserGroup/
WARNING 2023-05-14 19:55:46,526 log 4640 9132 Not Found: /group/AddUserGroup/
WARNING 2023-05-14 19:55:46,533 log 4640 9132 Forbidden: /group/DeleteGroup/
ERROR 2023-05-14 19:55:46,537 log 4640 9132 Internal Server Error: /group/DeleteGroup/
WARNING 2023-05-14 19:55:46,540 log 4640 9132 Forbidden: /group/DeleteGroup/
ERROR 2023-05-14 19:55:46,542 log 4640 9132 Internal Server Error: /group/GroupInfo/
ERROR 2023-05-14 19:55:46,545 log 4640 9132 Internal Server Error: /group/GroupInfo/
WARNING 2023-05-14 19:55:46,547 log 4640 9132 Not Found: /group/GroupInfo/
WARNING 2023-05-14 19:55:46,552 log 4640 9132 Unauthorized: /group/GroupInfo/
WARNING 2023-05-14 19:55:46,555 log 4640 9132 Not Found: /group/GroupInfo/
WARNING 2023-05-14 19:55:46,558 log 4640 9132 Forbidden: /group/GroupInfo/
ERROR 2023-05-14 19:55:46,560 log 4640 9132 Internal Server Error: /group/ShowGroups/
WARNING 2023-05-14 19:55:46,562 log 4640 9132 Method Not Allowed: /group/ShowGroups/
WARNING 2023-05-14 19:55:46,564 log 4640 9132 Not Found: /group/ShowGroups/
WARNING 2023-05-14 19:55:46,569 log 4640 9132 Unauthorized: /group/ShowGroups/
WARNING 2023-05-14 19:55:46,571 log 4640 9132 Not Found: /group/ShowGroups/
ERROR 2023-05-14 19:55:46,580 log 4640 9132 Internal Server Error: /group/ShowMembers/
WARNING 2023-05-14 19:55:46,583 log 4640 9132 Forbidden: /group/ShowMembers/
WARNING 2023-05-14 19:55:46,587 log 4640 9132 Forbidden: /group/ShowMembers/
WARNING 2023-05-14 19:55:46,600 log 4640 9132 Forbidden: /group/ShowMembers/
WARNING 2023-05-14 19:55:46,613 log 4640 9132 Bad Request: /group/CreateGroup/
WARNING 2023-05-14 19:55:46,629 log 4640 9132 Not Found: /group/CreateGroup/
WARNING 2023-05-14 19:55:46,632 log 4640 9132 Bad Request: /group/CreateGroup/
WARNING 2023-05-14 19:55:46,634 log 4640 9132 Bad Request: /group/CreateGroup/
WARNING 2023-05-14 19:55:46,643 log 4640 9132 Bad Request: /group/CreateGroup/
WARNING 2023-05-14 19:55:46,645 log 4640 9132 Bad Request: /group/CreateGroup/
WARNING 2023-05-14 19:55:46,661 log 4640 9132 Not Found: /group/CreateGroup/
WARNING 2023-05-14 21:08:51,383 log 7148 9792 Bad Request: /auth/EditProfile/
WARNING 2023-05-14 21:08:51,385 log 7148 9792 Bad Request: /group/CreateGroup/
WARNING 2023-05-14 21:08:51,389 log 7148 9792 Method Not Allowed: /auth/EditProfile/
WARNING 2023-05-14 21:09:29,579 log 7472 9024 Bad Request: /auth/EditProfile/
WARNING 2023-05-14 21:09:29,581 log 7472 9024 Method Not Allowed: /group/CreateGroup/
WARNING 2023-05-14 21:09:29,583 log 7472 9024 Bad Request: /auth/EditProfile/
WARNING 2023-05-14 21:12:53,387 log 1040 17676 Bad Request: /auth/EditProfile/
WARNING 2023-05-14 21:12:53,389 log 1040 17676 Method Not Allowed: /group/CreateGroup/
WARNING 2023-05-14 21:12:53,391 log 1040 17676 Bad Request: /auth/EditProfile/
WARNING 2023-05-14 21:14:02,033 log 1936 6696 Bad Request: /auth/EditProfile/
WARNING 2023-05-14 21:14:02,035 log 1936 6696 Method Not Allowed: /group/CreateGroup/
WARNING 2023-05-14 21:14:02,037 log 1936 6696 Bad Request: /auth/EditProfile/
WARNING 2023-05-14 21:14:23,841 log 5936 17968 Bad Request: /auth/EditProfile/
WARNING 2023-05-14 21:14:23,843 log 5936 17968 Method Not Allowed: /group/CreateGroup/
WARNING 2023-05-14 21:14:23,845 log 5936 17968 Bad Request: /auth/EditProfile/
WARNING 2023-05-14 21:20:26,402 log 17112 16256 Bad Request: /auth/EditProfile/
WARNING 2023-05-14 21:20:26,404 log 17112 16256 Method Not Allowed: /group/CreateGroup/
WARNING 2023-05-14 21:20:26,408 log 17112 16256 Bad Request: /auth/EditProfile/
WARNING 2023-05-14 21:24:35,838 log 8996 11616 Bad Request: /auth/EditProfile/
WARNING 2023-05-14 21:24:35,840 log 8996 11616 Method Not Allowed: /group/CreateGroup/
WARNING 2023-05-14 21:24:35,843 log 8996 11616 Bad Request: /auth/EditProfile/
WARNING 2023-05-14 21:25:13,119 log 15600 12144 Bad Request: /auth/EditProfile/
WARNING 2023-05-14 21:25:13,121 log 15600 12144 Method Not Allowed: /group/CreateGroup/
WARNING 2023-05-14 21:25:13,123 log 15600 12144 Bad Request: /auth/EditProfile/
WARNING 2023-05-14 21:30:33,695 log 5676 15812 Bad Request: /auth/EditProfile/
WARNING 2023-05-14 21:30:33,697 log 5676 15812 Method Not Allowed: /group/CreateGroup/
WARNING 2023-05-14 21:30:33,699 log 5676 15812 Bad Request: /auth/EditProfile/
WARNING 2023-05-14 21:30:56,214 log 15644 13508 Bad Request: /auth/EditProfile/
WARNING 2023-05-14 21:30:56,216 log 15644 13508 Method Not Allowed: /group/CreateGroup/
WARNING 2023-05-14 21:30:56,219 log 15644 13508 Bad Request: /auth/EditProfile/
WARNING 2023-05-14 21:31:34,348 log 14728 11404 Bad Request: /auth/EditProfile/
WARNING 2023-05-14 21:31:34,352 log 14728 11404 Bad Request: /auth/EditProfile/
WARNING 2023-05-14 21:31:34,354 log 14728 11404 Bad Request: /auth/EditProfile/
WARNING 2023-05-14 21:32:22,990 log 11588 4060 Bad Request: /auth/EditProfile/
WARNING 2023-05-14 21:32:22,993 log 11588 4060 Bad Request: /auth/EditProfile/
WARNING 2023-05-14 21:32:22,995 log 11588 4060 Bad Request: /auth/EditProfile/
WARNING 2023-05-14 21:34:51,987 log 13396 10800 Bad Request: /auth/EditProfile/
WARNING 2023-05-14 21:34:51,990 log 13396 10800 Bad Request: /auth/EditProfile/
WARNING 2023-05-14 21:34:51,992 log 13396 10800 Bad Request: /auth/EditProfile/
WARNING 2023-05-14 21:38:32,356 log 7216 16928 Bad Request: /auth/EditProfile/
WARNING 2023-05-14 21:38:32,359 log 7216 16928 Bad Request: /auth/EditProfile/
WARNING 2023-05-14 21:38:32,361 log 7216 16928 Bad Request: /auth/EditProfile/
WARNING 2023-05-14 21:39:41,021 log 12672 16376 Bad Request: /auth/EditProfile/
WARNING 2023-05-14 21:39:41,025 log 12672 16376 Bad Request: /auth/EditProfile/
WARNING 2023-05-14 21:39:41,029 log 12672 16376 Bad Request: /auth/EditProfile/
WARNING 2023-05-14 21:41:51,033 log 8844 1240 Bad Request: /auth/EditProfile/
WARNING 2023-05-14 21:41:51,036 log 8844 1240 Bad Request: /auth/EditProfile/
WARNING 2023-05-14 21:41:51,038 log 8844 1240 Bad Request: /auth/EditProfile/
WARNING 2023-05-14 21:43:24,083 log 7088 15252 Bad Request: /auth/EditProfile/
WARNING 2023-05-14 21:43:24,086 log 7088 15252 Bad Request: /auth/EditProfile/
WARNING 2023-05-14 21:43:24,089 log 7088 15252 Bad Request: /auth/EditProfile/
WARNING 2023-05-14 21:44:05,146 log 1544 7180 Bad Request: /auth/EditProfile/
WARNING 2023-05-14 21:44:05,149 log 1544 7180 Bad Request: /auth/EditProfile/
WARNING 2023-05-14 21:44:05,151 log 1544 7180 Bad Request: /auth/EditProfile/
WARNING 2023-05-14 21:44:28,322 log 924 15812 Bad Request: /auth/EditProfile/
WARNING 2023-05-14 21:44:28,325 log 924 15812 Bad Request: /auth/EditProfile/
WARNING 2023-05-14 21:44:28,327 log 924 15812 Bad Request: /auth/EditProfile/
WARNING 2023-05-14 21:46:43,976 log 5272 16432 Bad Request: /auth/EditProfile/
WARNING 2023-05-14 21:46:43,980 log 5272 16432 Bad Request: /auth/EditProfile/
WARNING 2023-05-14 21:46:43,984 log 5272 16432 Bad Request: /auth/EditProfile/
WARNING 2023-05-14 21:49:59,960 log 15560 1676 Bad Request: /auth/EditProfile/
WARNING 2023-05-14 21:49:59,962 log 15560 1676 Bad Request: /auth/EditProfile/
WARNING 2023-05-14 21:49:59,964 log 15560 1676 Bad Request: /auth/EditProfile/
WARNING 2023-05-14 21:57:56,381 log 16716 200 Bad Request: /auth/EditProfile/
WARNING 2023-05-14 21:57:56,384 log 16716 200 Bad Request: /auth/EditProfile/
WARNING 2023-05-14 21:57:56,386 log 16716 200 Bad Request: /auth/EditProfile/
WARNING 2023-05-14 21:58:37,959 log 9436 12208 Bad Request: /auth/EditProfile/
WARNING 2023-05-14 21:58:37,962 log 9436 12208 Bad Request: /auth/EditProfile/
WARNING 2023-05-14 21:58:37,964 log 9436 12208 Bad Request: /auth/EditProfile/
WARNING 2023-05-14 22:00:07,655 log 18028 11684 Bad Request: /auth/EditProfile/
WARNING 2023-05-14 22:00:07,658 log 18028 11684 Bad Request: /auth/EditProfile/
WARNING 2023-05-14 22:00:07,661 log 18028 11684 Bad Request: /auth/EditProfile/
WARNING 2023-05-14 22:00:49,103 log 15676 4348 Bad Request: /auth/EditProfile/
WARNING 2023-05-14 22:00:49,105 log 15676 4348 Bad Request: /auth/EditProfile/
WARNING 2023-05-14 22:00:49,107 log 15676 4348 Bad Request: /auth/EditProfile/
WARNING 2023-05-14 22:01:02,316 log 4336 16516 Bad Request: /auth/EditProfile/
WARNING 2023-05-14 22:01:02,318 log 4336 16516 Bad Request: /auth/EditProfile/
WARNING 2023-05-14 22:01:02,321 log 4336 16516 Bad Request: /auth/EditProfile/
WARNING 2023-05-14 22:01:24,919 log 648 7844 Bad Request: /auth/EditProfile/
WARNING 2023-05-14 22:01:24,922 log 648 7844 Bad Request: /auth/EditProfile/
WARNING 2023-05-14 22:01:24,925 log 648 7844 Bad Request: /auth/EditProfile/
WARNING 2023-05-14 22:03:12,539 log 13976 15252 Bad Request: /auth/EditProfile/
WARNING 2023-05-14 22:03:12,543 log 13976 15252 Bad Request: /auth/EditProfile/
WARNING 2023-05-14 22:03:12,546 log 13976 15252 Bad Request: /auth/EditProfile/
WARNING 2023-05-14 22:03:30,184 log 15520 13632 Bad Request: /auth/EditProfile/
WARNING 2023-05-14 22:03:30,187 log 15520 13632 Bad Request: /auth/EditProfile/
WARNING 2023-05-14 22:03:30,189 log 15520 13632 Bad Request: /auth/EditProfile/
WARNING 2023-05-14 22:05:05,671 log 11436 16536 Bad Request: /auth/EditProfile/
WARNING 2023-05-14 22:05:05,674 log 11436 16536 Bad Request: /auth/EditProfile/
WARNING 2023-05-14 22:05:05,676 log 11436 16536 Bad Request: /auth/EditProfile/
WARNING 2023-05-14 22:05:53,427 log 7912 10608 Bad Request: /auth/EditProfile/
WARNING 2023-05-14 22:05:53,430 log 7912 10608 Bad Request: /auth/EditProfile/
WARNING 2023-05-14 22:05:53,432 log 7912 10608 Bad Request: /auth/EditProfile/
WARNING 2023-05-14 22:11:57,789 log 15220 1900 Bad Request: /auth/EditProfile/
WARNING 2023-05-14 22:11:57,792 log 15220 1900 Bad Request: /auth/EditProfile/
WARNING 2023-05-14 22:11:57,794 log 15220 1900 Bad Request: /auth/EditProfile/
WARNING 2023-05-14 22:18:44,999 log 13276 6928 Bad Request: /auth/EditProfile/
WARNING 2023-05-14 22:18:45,002 log 13276 6928 Bad Request: /auth/EditProfile/
WARNING 2023-05-14 22:19:45,508 log 12320 12684 Bad Request: /auth/EditProfile/
WARNING 2023-05-14 22:19:45,510 log 12320 12684 Bad Request: /auth/EditProfile/
WARNING 2023-05-14 22:20:06,145 log 8000 7544 Bad Request: /auth/EditProfile/
WARNING 2023-05-14 22:20:06,148 log 8000 7544 Bad Request: /auth/EditProfile/
WARNING 2023-05-14 22:22:18,605 log 856 17424 Bad Request: /auth/EditProfile/
WARNING 2023-05-14 22:22:18,608 log 856 17424 Bad Request: /auth/EditProfile/
WARNING 2023-05-14 22:22:18,610 log 856 17424 Bad Request: /auth/EditProfile/
WARNING 2023-05-14 22:24:13,602 log 8756 12152 Bad Request: /auth/EditProfile/
WARNING 2023-05-14 22:24:13,605 log 8756 12152 Bad Request: /auth/EditProfile/
WARNING 2023-05-14 22:24:13,607 log 8756 12152 Bad Request: /auth/EditProfile/
WARNING 2023-05-14 22:27:00,569 log 12660 2556 Bad Request: /auth/EditProfile/
WARNING 2023-05-14 22:27:00,572 log 12660 2556 Bad Request: /auth/EditProfile/
WARNING 2023-05-14 22:27:00,574 log 12660 2556 Bad Request: /auth/EditProfile/
WARNING 2023-05-14 22:27:40,866 log 10996 14288 Bad Request: /auth/EditProfile/
WARNING 2023-05-14 22:27:40,868 log 10996 14288 Bad Request: /auth/EditProfile/
WARNING 2023-05-14 22:27:40,870 log 10996 14288 Bad Request: /auth/EditProfile/
WARNING 2023-05-14 22:28:13,932 log 14568 16436 Bad Request: /auth/EditProfile/
WARNING 2023-05-14 22:28:13,935 log 14568 16436 Bad Request: /auth/EditProfile/
WARNING 2023-05-14 22:28:13,939 log 14568 16436 Bad Request: /auth/EditProfile/
ERROR 2023-05-14 22:32:07,565 log 16460 10512 Internal Server Error: /auth/EditProfile/
Traceback (most recent call last):
  File "C:\Python311\Lib\site-packages\django\core\handlers\exception.py", line 56, in inner
    response = get_response(request)
               ^^^^^^^^^^^^^^^^^^^^^
  File "C:\Python311\Lib\site-packages\django\core\handlers\base.py", line 197, in _get_response
    response = wrapped_callback(request, *callback_args, **callback_kwargs)
               ^^^^^^^^^^^^^^^^^^^^^^^^^^^^^^^^^^^^^^^^^^^^^^^^^^^^^^^^^^^^
  File "C:\Python311\Lib\site-packages\django\views\decorators\csrf.py", line 55, in wrapped_view
    return view_func(*args, **kwargs)
           ^^^^^^^^^^^^^^^^^^^^^^^^^^
  File "C:\Python311\Lib\site-packages\django\views\generic\base.py", line 103, in view
    return self.dispatch(request, *args, **kwargs)
           ^^^^^^^^^^^^^^^^^^^^^^^^^^^^^^^^^^^^^^^
  File "C:\Python311\Lib\site-packages\rest_framework\views.py", line 509, in dispatch
    response = self.handle_exception(exc)
               ^^^^^^^^^^^^^^^^^^^^^^^^^^
  File "C:\Python311\Lib\site-packages\rest_framework\views.py", line 469, in handle_exception
    self.raise_uncaught_exception(exc)
  File "C:\Python311\Lib\site-packages\rest_framework\views.py", line 480, in raise_uncaught_exception
    raise exc
  File "C:\Python311\Lib\site-packages\rest_framework\views.py", line 506, in dispatch
    response = handler(request, *args, **kwargs)
               ^^^^^^^^^^^^^^^^^^^^^^^^^^^^^^^^^
  File "C:\Python311\Lib\site-packages\rest_framework\generics.py", line 226, in put
    return self.update(request, *args, **kwargs)
           ^^^^^^^^^^^^^^^^^^^^^^^^^^^^^^^^^^^^^
  File "C:\Python311\Lib\site-packages\rest_framework\mixins.py", line 68, in update
    self.perform_update(serializer)
  File "C:\Users\Maryam\Documents\GitHub\Enigma_BackEnd\Enigma\MyUser\views.py", line 82, in perform_update
    serializer.save(user=self.request.user)
  File "C:\Python311\Lib\site-packages\rest_framework\serializers.py", line 207, in save
    self.instance = self.update(self.instance, validated_data)
                    ^^^^^^^^^^^^^^^^^^^^^^^^^^^^^^^^^^^^^^^^^^
  File "C:\Python311\Lib\site-packages\rest_framework\serializers.py", line 1006, in update
    instance.save()
  File "C:\Python311\Lib\site-packages\django\contrib\auth\base_user.py", line 68, in save
    super().save(*args, **kwargs)
  File "C:\Python311\Lib\site-packages\django\db\models\base.py", line 812, in save
    self.save_base(
  File "C:\Python311\Lib\site-packages\django\db\models\base.py", line 863, in save_base
    updated = self._save_table(
              ^^^^^^^^^^^^^^^^^
  File "C:\Python311\Lib\site-packages\django\db\models\base.py", line 976, in _save_table
    updated = self._do_update(
              ^^^^^^^^^^^^^^^^
  File "C:\Python311\Lib\site-packages\django\db\models\base.py", line 1040, in _do_update
    return filtered._update(values) > 0
           ^^^^^^^^^^^^^^^^^^^^^^^^
  File "C:\Python311\Lib\site-packages\django\db\models\query.py", line 1216, in _update
    return query.get_compiler(self.db).execute_sql(CURSOR)
           ^^^^^^^^^^^^^^^^^^^^^^^^^^^^^^^^^^^^^^^^^^^^^^^
  File "C:\Python311\Lib\site-packages\django\db\models\sql\compiler.py", line 1822, in execute_sql
    cursor = super().execute_sql(result_type)
             ^^^^^^^^^^^^^^^^^^^^^^^^^^^^^^^^
  File "C:\Python311\Lib\site-packages\django\db\models\sql\compiler.py", line 1385, in execute_sql
    sql, params = self.as_sql()
                  ^^^^^^^^^^^^^
  File "C:\Python311\Lib\site-packages\django\db\models\sql\compiler.py", line 1785, in as_sql
    % (field, val, field.__class__.__name__)
              ^^^
  File "C:\Python311\Lib\site-packages\django\db\models\base.py", line 586, in __repr__
    return "<%s: %s>" % (self.__class__.__name__, self)
                                                  ^^^^
TypeError: __str__ returned non-string (type MyUser)
WARNING 2023-05-14 22:32:07,596 log 16460 10512 Bad Request: /auth/EditProfile/
WARNING 2023-05-14 22:32:07,600 log 16460 10512 Bad Request: /auth/EditProfile/
WARNING 2023-05-14 22:54:50,565 log 16352 17324 Bad Request: /auth/EditProfile/
WARNING 2023-05-14 22:54:50,567 log 16352 17324 Bad Request: /auth/EditProfile/
WARNING 2023-05-14 22:55:40,439 log 4084 10296 Bad Request: /auth/EditProfile/
WARNING 2023-05-14 22:55:40,443 log 4084 10296 Bad Request: /auth/EditProfile/
WARNING 2023-05-14 22:56:44,498 log 1952 5652 Bad Request: /auth/EditProfile/
WARNING 2023-05-14 22:56:44,500 log 1952 5652 Bad Request: /auth/EditProfile/
WARNING 2023-05-14 22:58:18,548 log 16172 6696 Bad Request: /auth/EditProfile/
WARNING 2023-05-14 22:58:18,550 log 16172 6696 Bad Request: /auth/EditProfile/
WARNING 2023-05-14 22:59:15,381 log 12592 4376 Bad Request: /auth/EditProfile/
WARNING 2023-05-14 22:59:15,384 log 12592 4376 Bad Request: /auth/EditProfile/
WARNING 2023-05-14 23:00:29,690 log 9712 13780 Bad Request: /auth/EditProfile/
WARNING 2023-05-14 23:00:29,692 log 9712 13780 Bad Request: /auth/EditProfile/
ERROR 2023-05-15 00:00:53,502 log 13448 14172 Internal Server Error: /auth/EditProfile/
Traceback (most recent call last):
  File "C:\Python311\Lib\site-packages\django\db\models\fields\__init__.py", line 2018, in get_prep_value
    return int(value)
           ^^^^^^^^^^
ValueError: invalid literal for int() with base 10: 'test'

The above exception was the direct cause of the following exception:

Traceback (most recent call last):
  File "C:\Python311\Lib\site-packages\django\core\handlers\exception.py", line 56, in inner
    response = get_response(request)
               ^^^^^^^^^^^^^^^^^^^^^
  File "C:\Python311\Lib\site-packages\django\core\handlers\base.py", line 197, in _get_response
    response = wrapped_callback(request, *callback_args, **callback_kwargs)
               ^^^^^^^^^^^^^^^^^^^^^^^^^^^^^^^^^^^^^^^^^^^^^^^^^^^^^^^^^^^^
  File "C:\Python311\Lib\site-packages\django\views\decorators\csrf.py", line 55, in wrapped_view
    return view_func(*args, **kwargs)
           ^^^^^^^^^^^^^^^^^^^^^^^^^^
  File "C:\Python311\Lib\site-packages\django\views\generic\base.py", line 103, in view
    return self.dispatch(request, *args, **kwargs)
           ^^^^^^^^^^^^^^^^^^^^^^^^^^^^^^^^^^^^^^^
  File "C:\Python311\Lib\site-packages\rest_framework\views.py", line 509, in dispatch
    response = self.handle_exception(exc)
               ^^^^^^^^^^^^^^^^^^^^^^^^^^
  File "C:\Python311\Lib\site-packages\rest_framework\views.py", line 469, in handle_exception
    self.raise_uncaught_exception(exc)
  File "C:\Python311\Lib\site-packages\rest_framework\views.py", line 480, in raise_uncaught_exception
    raise exc
  File "C:\Python311\Lib\site-packages\rest_framework\views.py", line 506, in dispatch
    response = handler(request, *args, **kwargs)
               ^^^^^^^^^^^^^^^^^^^^^^^^^^^^^^^^^
  File "C:\Python311\Lib\site-packages\rest_framework\generics.py", line 226, in put
    return self.update(request, *args, **kwargs)
           ^^^^^^^^^^^^^^^^^^^^^^^^^^^^^^^^^^^^^
  File "C:\Python311\Lib\site-packages\rest_framework\mixins.py", line 68, in update
    self.perform_update(serializer)
  File "C:\Users\Maryam\Documents\GitHub\Enigma_BackEnd\Enigma\MyUser\views.py", line 82, in perform_update
    serializer.save(user=self.request.user)
  File "C:\Python311\Lib\site-packages\rest_framework\serializers.py", line 207, in save
    self.instance = self.update(self.instance, validated_data)
                    ^^^^^^^^^^^^^^^^^^^^^^^^^^^^^^^^^^^^^^^^^^
  File "C:\Python311\Lib\site-packages\rest_framework\serializers.py", line 1006, in update
    instance.save()
  File "C:\Python311\Lib\site-packages\django\contrib\auth\base_user.py", line 68, in save
    super().save(*args, **kwargs)
  File "C:\Python311\Lib\site-packages\django\db\models\base.py", line 812, in save
    self.save_base(
  File "C:\Python311\Lib\site-packages\django\db\models\base.py", line 863, in save_base
    updated = self._save_table(
              ^^^^^^^^^^^^^^^^^
  File "C:\Python311\Lib\site-packages\django\db\models\base.py", line 976, in _save_table
    updated = self._do_update(
              ^^^^^^^^^^^^^^^^
  File "C:\Python311\Lib\site-packages\django\db\models\base.py", line 1040, in _do_update
    return filtered._update(values) > 0
           ^^^^^^^^^^^^^^^^^^^^^^^^
  File "C:\Python311\Lib\site-packages\django\db\models\query.py", line 1216, in _update
    return query.get_compiler(self.db).execute_sql(CURSOR)
           ^^^^^^^^^^^^^^^^^^^^^^^^^^^^^^^^^^^^^^^^^^^^^^^
  File "C:\Python311\Lib\site-packages\django\db\models\sql\compiler.py", line 1822, in execute_sql
    cursor = super().execute_sql(result_type)
             ^^^^^^^^^^^^^^^^^^^^^^^^^^^^^^^^
  File "C:\Python311\Lib\site-packages\django\db\models\sql\compiler.py", line 1385, in execute_sql
    sql, params = self.as_sql()
                  ^^^^^^^^^^^^^
  File "C:\Python311\Lib\site-packages\django\db\models\sql\compiler.py", line 1788, in as_sql
    val = field.get_db_prep_save(val, connection=self.connection)
          ^^^^^^^^^^^^^^^^^^^^^^^^^^^^^^^^^^^^^^^^^^^^^^^^^^^^^^^
  File "C:\Python311\Lib\site-packages\django\db\models\fields\__init__.py", line 925, in get_db_prep_save
    return self.get_db_prep_value(value, connection=connection, prepared=False)
           ^^^^^^^^^^^^^^^^^^^^^^^^^^^^^^^^^^^^^^^^^^^^^^^^^^^^^^^^^^^^^^^^^^^^
  File "C:\Python311\Lib\site-packages\django\db\models\fields\__init__.py", line 920, in get_db_prep_value
    value = self.get_prep_value(value)
            ^^^^^^^^^^^^^^^^^^^^^^^^^^
  File "C:\Python311\Lib\site-packages\django\db\models\fields\__init__.py", line 2020, in get_prep_value
    raise e.__class__(
ValueError: Field 'picture_id' expected a number but got 'test'.
WARNING 2023-05-15 00:00:53,515 log 13448 14172 Bad Request: /auth/EditProfile/
WARNING 2023-05-15 00:00:53,517 log 13448 14172 Bad Request: /auth/EditProfile/
WARNING 2023-05-15 00:01:31,139 log 8832 17300 Bad Request: /auth/EditProfile/
WARNING 2023-05-15 00:01:31,141 log 8832 17300 Bad Request: /auth/EditProfile/
WARNING 2023-05-15 00:02:43,959 log 11920 9420 Bad Request: /auth/EditProfile/
WARNING 2023-05-15 00:02:43,961 log 11920 9420 Bad Request: /auth/EditProfile/
WARNING 2023-05-15 00:12:00,876 log 7604 11244 Bad Request: /auth/EditProfile/
WARNING 2023-05-15 00:12:00,879 log 7604 11244 Bad Request: /auth/EditProfile/
ERROR 2023-05-15 00:13:36,771 log 11736 4068 Internal Server Error: /auth/EditProfile/
Traceback (most recent call last):
  File "C:\Python311\Lib\site-packages\django\core\handlers\exception.py", line 56, in inner
    response = get_response(request)
               ^^^^^^^^^^^^^^^^^^^^^
  File "C:\Python311\Lib\site-packages\django\core\handlers\base.py", line 197, in _get_response
    response = wrapped_callback(request, *callback_args, **callback_kwargs)
               ^^^^^^^^^^^^^^^^^^^^^^^^^^^^^^^^^^^^^^^^^^^^^^^^^^^^^^^^^^^^
  File "C:\Python311\Lib\site-packages\django\views\decorators\csrf.py", line 55, in wrapped_view
    return view_func(*args, **kwargs)
           ^^^^^^^^^^^^^^^^^^^^^^^^^^
  File "C:\Python311\Lib\site-packages\django\views\generic\base.py", line 103, in view
    return self.dispatch(request, *args, **kwargs)
           ^^^^^^^^^^^^^^^^^^^^^^^^^^^^^^^^^^^^^^^
  File "C:\Python311\Lib\site-packages\rest_framework\views.py", line 509, in dispatch
    response = self.handle_exception(exc)
               ^^^^^^^^^^^^^^^^^^^^^^^^^^
  File "C:\Python311\Lib\site-packages\rest_framework\views.py", line 469, in handle_exception
    self.raise_uncaught_exception(exc)
  File "C:\Python311\Lib\site-packages\rest_framework\views.py", line 480, in raise_uncaught_exception
    raise exc
  File "C:\Python311\Lib\site-packages\rest_framework\views.py", line 506, in dispatch
    response = handler(request, *args, **kwargs)
               ^^^^^^^^^^^^^^^^^^^^^^^^^^^^^^^^^
  File "C:\Python311\Lib\site-packages\rest_framework\generics.py", line 226, in put
    return self.update(request, *args, **kwargs)
           ^^^^^^^^^^^^^^^^^^^^^^^^^^^^^^^^^^^^^
  File "C:\Python311\Lib\site-packages\rest_framework\mixins.py", line 67, in update
    serializer.is_valid(raise_exception=True)
  File "C:\Python311\Lib\site-packages\rest_framework\serializers.py", line 227, in is_valid
    self._validated_data = self.run_validation(self.initial_data)
                           ^^^^^^^^^^^^^^^^^^^^^^^^^^^^^^^^^^^^^^
  File "C:\Python311\Lib\site-packages\rest_framework\serializers.py", line 430, in run_validation
    assert value is not None, '.validate() should return the validated data'
           ^^^^^^^^^^^^^^^^^
AssertionError: .validate() should return the validated data
ERROR 2023-05-15 00:13:36,779 log 11736 4068 Internal Server Error: /auth/EditProfile/
Traceback (most recent call last):
  File "C:\Python311\Lib\site-packages\django\core\handlers\exception.py", line 56, in inner
    response = get_response(request)
               ^^^^^^^^^^^^^^^^^^^^^
  File "C:\Python311\Lib\site-packages\django\core\handlers\base.py", line 197, in _get_response
    response = wrapped_callback(request, *callback_args, **callback_kwargs)
               ^^^^^^^^^^^^^^^^^^^^^^^^^^^^^^^^^^^^^^^^^^^^^^^^^^^^^^^^^^^^
  File "C:\Python311\Lib\site-packages\django\views\decorators\csrf.py", line 55, in wrapped_view
    return view_func(*args, **kwargs)
           ^^^^^^^^^^^^^^^^^^^^^^^^^^
  File "C:\Python311\Lib\site-packages\django\views\generic\base.py", line 103, in view
    return self.dispatch(request, *args, **kwargs)
           ^^^^^^^^^^^^^^^^^^^^^^^^^^^^^^^^^^^^^^^
  File "C:\Python311\Lib\site-packages\rest_framework\views.py", line 509, in dispatch
    response = self.handle_exception(exc)
               ^^^^^^^^^^^^^^^^^^^^^^^^^^
  File "C:\Python311\Lib\site-packages\rest_framework\views.py", line 469, in handle_exception
    self.raise_uncaught_exception(exc)
  File "C:\Python311\Lib\site-packages\rest_framework\views.py", line 480, in raise_uncaught_exception
    raise exc
  File "C:\Python311\Lib\site-packages\rest_framework\views.py", line 506, in dispatch
    response = handler(request, *args, **kwargs)
               ^^^^^^^^^^^^^^^^^^^^^^^^^^^^^^^^^
  File "C:\Python311\Lib\site-packages\rest_framework\generics.py", line 226, in put
    return self.update(request, *args, **kwargs)
           ^^^^^^^^^^^^^^^^^^^^^^^^^^^^^^^^^^^^^
  File "C:\Python311\Lib\site-packages\rest_framework\mixins.py", line 67, in update
    serializer.is_valid(raise_exception=True)
  File "C:\Python311\Lib\site-packages\rest_framework\serializers.py", line 227, in is_valid
    self._validated_data = self.run_validation(self.initial_data)
                           ^^^^^^^^^^^^^^^^^^^^^^^^^^^^^^^^^^^^^^
  File "C:\Python311\Lib\site-packages\rest_framework\serializers.py", line 430, in run_validation
    assert value is not None, '.validate() should return the validated data'
           ^^^^^^^^^^^^^^^^^
AssertionError: .validate() should return the validated data
ERROR 2023-05-15 00:13:36,782 log 11736 4068 Internal Server Error: /auth/EditProfile/
Traceback (most recent call last):
  File "C:\Python311\Lib\site-packages\django\core\handlers\exception.py", line 56, in inner
    response = get_response(request)
               ^^^^^^^^^^^^^^^^^^^^^
  File "C:\Python311\Lib\site-packages\django\core\handlers\base.py", line 197, in _get_response
    response = wrapped_callback(request, *callback_args, **callback_kwargs)
               ^^^^^^^^^^^^^^^^^^^^^^^^^^^^^^^^^^^^^^^^^^^^^^^^^^^^^^^^^^^^
  File "C:\Python311\Lib\site-packages\django\views\decorators\csrf.py", line 55, in wrapped_view
    return view_func(*args, **kwargs)
           ^^^^^^^^^^^^^^^^^^^^^^^^^^
  File "C:\Python311\Lib\site-packages\django\views\generic\base.py", line 103, in view
    return self.dispatch(request, *args, **kwargs)
           ^^^^^^^^^^^^^^^^^^^^^^^^^^^^^^^^^^^^^^^
  File "C:\Python311\Lib\site-packages\rest_framework\views.py", line 509, in dispatch
    response = self.handle_exception(exc)
               ^^^^^^^^^^^^^^^^^^^^^^^^^^
  File "C:\Python311\Lib\site-packages\rest_framework\views.py", line 469, in handle_exception
    self.raise_uncaught_exception(exc)
  File "C:\Python311\Lib\site-packages\rest_framework\views.py", line 480, in raise_uncaught_exception
    raise exc
  File "C:\Python311\Lib\site-packages\rest_framework\views.py", line 506, in dispatch
    response = handler(request, *args, **kwargs)
               ^^^^^^^^^^^^^^^^^^^^^^^^^^^^^^^^^
  File "C:\Python311\Lib\site-packages\rest_framework\generics.py", line 226, in put
    return self.update(request, *args, **kwargs)
           ^^^^^^^^^^^^^^^^^^^^^^^^^^^^^^^^^^^^^
  File "C:\Python311\Lib\site-packages\rest_framework\mixins.py", line 67, in update
    serializer.is_valid(raise_exception=True)
  File "C:\Python311\Lib\site-packages\rest_framework\serializers.py", line 227, in is_valid
    self._validated_data = self.run_validation(self.initial_data)
                           ^^^^^^^^^^^^^^^^^^^^^^^^^^^^^^^^^^^^^^
  File "C:\Python311\Lib\site-packages\rest_framework\serializers.py", line 430, in run_validation
    assert value is not None, '.validate() should return the validated data'
           ^^^^^^^^^^^^^^^^^
AssertionError: .validate() should return the validated data
WARNING 2023-05-15 00:13:36,786 log 11736 4068 Bad Request: /auth/EditProfile/
WARNING 2023-05-15 00:13:36,788 log 11736 4068 Bad Request: /auth/EditProfile/
ERROR 2023-05-15 00:13:36,790 log 11736 4068 Internal Server Error: /auth/EditProfile/
Traceback (most recent call last):
  File "C:\Python311\Lib\site-packages\django\core\handlers\exception.py", line 56, in inner
    response = get_response(request)
               ^^^^^^^^^^^^^^^^^^^^^
  File "C:\Python311\Lib\site-packages\django\core\handlers\base.py", line 197, in _get_response
    response = wrapped_callback(request, *callback_args, **callback_kwargs)
               ^^^^^^^^^^^^^^^^^^^^^^^^^^^^^^^^^^^^^^^^^^^^^^^^^^^^^^^^^^^^
  File "C:\Python311\Lib\site-packages\django\views\decorators\csrf.py", line 55, in wrapped_view
    return view_func(*args, **kwargs)
           ^^^^^^^^^^^^^^^^^^^^^^^^^^
  File "C:\Python311\Lib\site-packages\django\views\generic\base.py", line 103, in view
    return self.dispatch(request, *args, **kwargs)
           ^^^^^^^^^^^^^^^^^^^^^^^^^^^^^^^^^^^^^^^
  File "C:\Python311\Lib\site-packages\rest_framework\views.py", line 509, in dispatch
    response = self.handle_exception(exc)
               ^^^^^^^^^^^^^^^^^^^^^^^^^^
  File "C:\Python311\Lib\site-packages\rest_framework\views.py", line 469, in handle_exception
    self.raise_uncaught_exception(exc)
  File "C:\Python311\Lib\site-packages\rest_framework\views.py", line 480, in raise_uncaught_exception
    raise exc
  File "C:\Python311\Lib\site-packages\rest_framework\views.py", line 506, in dispatch
    response = handler(request, *args, **kwargs)
               ^^^^^^^^^^^^^^^^^^^^^^^^^^^^^^^^^
  File "C:\Python311\Lib\site-packages\rest_framework\generics.py", line 226, in put
    return self.update(request, *args, **kwargs)
           ^^^^^^^^^^^^^^^^^^^^^^^^^^^^^^^^^^^^^
  File "C:\Python311\Lib\site-packages\rest_framework\mixins.py", line 67, in update
    serializer.is_valid(raise_exception=True)
  File "C:\Python311\Lib\site-packages\rest_framework\serializers.py", line 227, in is_valid
    self._validated_data = self.run_validation(self.initial_data)
                           ^^^^^^^^^^^^^^^^^^^^^^^^^^^^^^^^^^^^^^
  File "C:\Python311\Lib\site-packages\rest_framework\serializers.py", line 430, in run_validation
    assert value is not None, '.validate() should return the validated data'
           ^^^^^^^^^^^^^^^^^
AssertionError: .validate() should return the validated data
WARNING 2023-05-15 00:14:37,333 log 3876 10172 Bad Request: /auth/EditProfile/
WARNING 2023-05-15 00:14:37,335 log 3876 10172 Bad Request: /auth/EditProfile/
WARNING 2023-05-15 00:16:31,344 log 15368 17372 Bad Request: /auth/EditProfile/
WARNING 2023-05-15 00:16:31,347 log 15368 17372 Bad Request: /auth/EditProfile/
WARNING 2023-05-15 00:20:16,740 log 11964 16612 Bad Request: /auth/EditProfile/
WARNING 2023-05-15 00:20:16,742 log 11964 16612 Bad Request: /auth/EditProfile/
WARNING 2023-05-15 00:21:38,323 log 16140 4660 Bad Request: /auth/EditProfile/
WARNING 2023-05-15 00:21:38,325 log 16140 4660 Bad Request: /auth/EditProfile/
WARNING 2023-05-15 00:23:43,227 log 13024 9648 Bad Request: /auth/EditProfile/
WARNING 2023-05-15 00:23:43,230 log 13024 9648 Bad Request: /auth/EditProfile/
WARNING 2023-05-15 00:24:42,650 log 5988 4840 Bad Request: /auth/EditProfile/
WARNING 2023-05-15 00:24:42,652 log 5988 4840 Bad Request: /auth/EditProfile/
WARNING 2023-05-15 00:26:35,042 log 3208 11140 Bad Request: /auth/EditProfile/
WARNING 2023-05-15 00:26:35,044 log 3208 11140 Bad Request: /auth/EditProfile/
WARNING 2023-05-15 00:27:58,165 log 12036 11896 Bad Request: /auth/EditProfile/
WARNING 2023-05-15 00:27:58,167 log 12036 11896 Bad Request: /auth/EditProfile/
WARNING 2023-05-15 00:35:04,788 log 10464 8532 Bad Request: /auth/EditProfile/
WARNING 2023-05-15 00:35:04,790 log 10464 8532 Bad Request: /auth/EditProfile/
WARNING 2023-05-15 00:35:38,968 log 10420 3184 Bad Request: /auth/EditProfile/
WARNING 2023-05-15 00:35:38,971 log 10420 3184 Bad Request: /auth/EditProfile/
WARNING 2023-05-15 00:37:24,905 log 9028 18428 Bad Request: /auth/EditProfile/
WARNING 2023-05-15 00:37:24,907 log 9028 18428 Bad Request: /auth/EditProfile/
WARNING 2023-05-15 00:38:47,877 log 8272 12128 Bad Request: /auth/EditProfile/
WARNING 2023-05-15 00:38:47,879 log 8272 12128 Bad Request: /auth/EditProfile/
WARNING 2023-05-15 00:45:39,959 log 4668 17760 Bad Request: /auth/EditProfile/
WARNING 2023-05-15 00:45:39,960 log 4668 17760 Bad Request: /auth/EditProfile/
WARNING 2023-05-15 00:47:27,398 log 15864 9968 Bad Request: /auth/EditProfile/
WARNING 2023-05-15 00:47:27,401 log 15864 9968 Bad Request: /auth/EditProfile/
WARNING 2023-05-15 00:49:12,964 log 11892 15668 Bad Request: /auth/EditProfile/
WARNING 2023-05-15 00:49:12,967 log 11892 15668 Bad Request: /auth/EditProfile/
WARNING 2023-05-15 00:53:30,867 log 11040 6680 Bad Request: /auth/EditProfile/
WARNING 2023-05-15 00:53:30,870 log 11040 6680 Bad Request: /auth/EditProfile/
WARNING 2023-05-15 00:56:30,300 log 13440 17032 Bad Request: /auth/EditProfile/
WARNING 2023-05-15 00:56:30,302 log 13440 17032 Bad Request: /auth/EditProfile/
WARNING 2023-05-15 00:57:33,346 log 10756 9084 Bad Request: /auth/EditProfile/
WARNING 2023-05-15 00:57:33,349 log 10756 9084 Bad Request: /auth/EditProfile/
WARNING 2023-05-15 00:58:16,314 log 4896 8704 Bad Request: /auth/EditProfile/
WARNING 2023-05-15 00:58:16,316 log 4896 8704 Bad Request: /auth/EditProfile/
WARNING 2023-05-15 00:59:42,140 log 9784 9968 Bad Request: /auth/EditProfile/
WARNING 2023-05-15 00:59:42,144 log 9784 9968 Bad Request: /auth/EditProfile/
WARNING 2023-05-15 01:13:26,897 log 6256 9932 Bad Request: /auth/EditProfile/
WARNING 2023-05-15 01:13:26,899 log 6256 9932 Bad Request: /auth/EditProfile/
WARNING 2023-05-15 01:15:13,950 log 12592 13024 Bad Request: /auth/EditProfile/
WARNING 2023-05-15 01:15:13,954 log 12592 13024 Bad Request: /auth/EditProfile/
WARNING 2023-05-15 01:15:48,053 log 17392 6372 Bad Request: /auth/EditProfile/
WARNING 2023-05-15 01:15:48,056 log 17392 6372 Bad Request: /auth/EditProfile/
WARNING 2023-05-15 01:16:00,953 log 5660 14876 Bad Request: /auth/EditProfile/
WARNING 2023-05-15 01:16:00,957 log 5660 14876 Bad Request: /auth/EditProfile/
WARNING 2023-05-15 01:16:27,679 log 11704 6004 Bad Request: /auth/EditProfile/
WARNING 2023-05-15 01:16:27,681 log 11704 6004 Bad Request: /auth/EditProfile/
WARNING 2023-05-15 01:16:59,948 log 10248 13268 Bad Request: /auth/EditProfile/
WARNING 2023-05-15 01:16:59,950 log 10248 13268 Bad Request: /auth/EditProfile/
WARNING 2023-05-15 01:18:56,183 log 6300 2104 Bad Request: /auth/EditProfile/
WARNING 2023-05-15 01:18:56,185 log 6300 2104 Bad Request: /auth/EditProfile/
WARNING 2023-05-15 01:22:46,947 log 8284 3372 Bad Request: /auth/EditProfile/
WARNING 2023-05-15 01:22:46,950 log 8284 3372 Bad Request: /auth/EditProfile/
WARNING 2023-05-15 01:23:48,966 log 16276 5912 Bad Request: /auth/EditProfile/
WARNING 2023-05-15 01:23:48,969 log 16276 5912 Bad Request: /auth/EditProfile/
WARNING 2023-05-15 01:23:48,971 log 16276 5912 Bad Request: /auth/EditProfile/
WARNING 2023-05-15 01:23:48,974 log 16276 5912 Bad Request: /auth/EditProfile/
WARNING 2023-05-15 01:23:48,977 log 16276 5912 Bad Request: /auth/EditProfile/
WARNING 2023-05-15 01:23:48,980 log 16276 5912 Bad Request: /auth/EditProfile/
WARNING 2023-05-15 01:23:48,983 log 16276 5912 Bad Request: /auth/EditProfile/
WARNING 2023-05-15 01:24:46,232 log 17476 5072 Bad Request: /auth/EditProfile/
WARNING 2023-05-15 01:24:46,235 log 17476 5072 Bad Request: /auth/EditProfile/
WARNING 2023-05-15 01:24:46,238 log 17476 5072 Bad Request: /auth/EditProfile/
WARNING 2023-05-15 01:24:46,242 log 17476 5072 Bad Request: /auth/EditProfile/
WARNING 2023-05-15 01:24:46,245 log 17476 5072 Bad Request: /auth/EditProfile/
WARNING 2023-05-15 01:24:46,249 log 17476 5072 Bad Request: /auth/EditProfile/
WARNING 2023-05-15 01:25:18,758 log 15480 15240 Bad Request: /auth/EditProfile/
WARNING 2023-05-15 01:25:18,760 log 15480 15240 Bad Request: /auth/EditProfile/
ERROR 2023-05-15 01:26:27,640 log 9056 14012 Internal Server Error: /auth/EditProfile/
Traceback (most recent call last):
  File "C:\Python311\Lib\site-packages\django\core\handlers\exception.py", line 56, in inner
    response = get_response(request)
               ^^^^^^^^^^^^^^^^^^^^^
  File "C:\Python311\Lib\site-packages\django\core\handlers\base.py", line 197, in _get_response
    response = wrapped_callback(request, *callback_args, **callback_kwargs)
               ^^^^^^^^^^^^^^^^^^^^^^^^^^^^^^^^^^^^^^^^^^^^^^^^^^^^^^^^^^^^
  File "C:\Python311\Lib\site-packages\django\views\decorators\csrf.py", line 55, in wrapped_view
    return view_func(*args, **kwargs)
           ^^^^^^^^^^^^^^^^^^^^^^^^^^
  File "C:\Python311\Lib\site-packages\django\views\generic\base.py", line 103, in view
    return self.dispatch(request, *args, **kwargs)
           ^^^^^^^^^^^^^^^^^^^^^^^^^^^^^^^^^^^^^^^
  File "C:\Python311\Lib\site-packages\rest_framework\views.py", line 509, in dispatch
    response = self.handle_exception(exc)
               ^^^^^^^^^^^^^^^^^^^^^^^^^^
  File "C:\Python311\Lib\site-packages\rest_framework\views.py", line 469, in handle_exception
    self.raise_uncaught_exception(exc)
  File "C:\Python311\Lib\site-packages\rest_framework\views.py", line 480, in raise_uncaught_exception
    raise exc
  File "C:\Python311\Lib\site-packages\rest_framework\views.py", line 506, in dispatch
    response = handler(request, *args, **kwargs)
               ^^^^^^^^^^^^^^^^^^^^^^^^^^^^^^^^^
  File "C:\Python311\Lib\site-packages\rest_framework\generics.py", line 226, in put
    return self.update(request, *args, **kwargs)
           ^^^^^^^^^^^^^^^^^^^^^^^^^^^^^^^^^^^^^
  File "C:\Python311\Lib\site-packages\rest_framework\mixins.py", line 66, in update
    serializer = self.get_serializer(instance, data=request.data, partial=partial)
                 ^^^^^^^^^^^^^^^^^^^^^^^^^^^^^^^^^^^^^^^^^^^^^^^^^^^^^^^^^^^^^^^^^
  File "C:\Python311\Lib\site-packages\rest_framework\generics.py", line 110, in get_serializer
    return serializer_class(*args, **kwargs)
           ^^^^^^^^^^^^^^^^^^^^^^^^^^^^^^^^^
  File "C:\Users\Maryam\Documents\GitHub\Enigma_BackEnd\Enigma\MyUser\serializers.py", line 71, in __init__
    self.fields['name'].default = self.instance.name
    ^^^^^^^^^^^
  File "C:\Python311\Lib\site-packages\django\utils\functional.py", line 57, in __get__
    res = instance.__dict__[self.name] = self.func(instance)
                                         ^^^^^^^^^^^^^^^^^^^
  File "C:\Python311\Lib\site-packages\rest_framework\serializers.py", line 356, in fields
    for key, value in self.get_fields().items():
                      ^^^^^^^^^^^^^^^^^
  File "C:\Python311\Lib\site-packages\rest_framework\serializers.py", line 1052, in get_fields
    field_names = self.get_field_names(declared_fields, info)
                  ^^^^^^^^^^^^^^^^^^^^^^^^^^^^^^^^^^^^^^^^^^^
  File "C:\Python311\Lib\site-packages\rest_framework\serializers.py", line 1117, in get_field_names
    assert not (fields and exclude), (
AssertionError: Cannot set both 'fields' and 'exclude' options on serializer UpdateUserSerializer.
ERROR 2023-05-15 01:26:27,748 log 9056 14012 Internal Server Error: /auth/EditProfile/
Traceback (most recent call last):
  File "C:\Python311\Lib\site-packages\django\core\handlers\exception.py", line 56, in inner
    response = get_response(request)
               ^^^^^^^^^^^^^^^^^^^^^
  File "C:\Python311\Lib\site-packages\django\core\handlers\base.py", line 197, in _get_response
    response = wrapped_callback(request, *callback_args, **callback_kwargs)
               ^^^^^^^^^^^^^^^^^^^^^^^^^^^^^^^^^^^^^^^^^^^^^^^^^^^^^^^^^^^^
  File "C:\Python311\Lib\site-packages\django\views\decorators\csrf.py", line 55, in wrapped_view
    return view_func(*args, **kwargs)
           ^^^^^^^^^^^^^^^^^^^^^^^^^^
  File "C:\Python311\Lib\site-packages\django\views\generic\base.py", line 103, in view
    return self.dispatch(request, *args, **kwargs)
           ^^^^^^^^^^^^^^^^^^^^^^^^^^^^^^^^^^^^^^^
  File "C:\Python311\Lib\site-packages\rest_framework\views.py", line 509, in dispatch
    response = self.handle_exception(exc)
               ^^^^^^^^^^^^^^^^^^^^^^^^^^
  File "C:\Python311\Lib\site-packages\rest_framework\views.py", line 469, in handle_exception
    self.raise_uncaught_exception(exc)
  File "C:\Python311\Lib\site-packages\rest_framework\views.py", line 480, in raise_uncaught_exception
    raise exc
  File "C:\Python311\Lib\site-packages\rest_framework\views.py", line 506, in dispatch
    response = handler(request, *args, **kwargs)
               ^^^^^^^^^^^^^^^^^^^^^^^^^^^^^^^^^
  File "C:\Python311\Lib\site-packages\rest_framework\generics.py", line 226, in put
    return self.update(request, *args, **kwargs)
           ^^^^^^^^^^^^^^^^^^^^^^^^^^^^^^^^^^^^^
  File "C:\Python311\Lib\site-packages\rest_framework\mixins.py", line 66, in update
    serializer = self.get_serializer(instance, data=request.data, partial=partial)
                 ^^^^^^^^^^^^^^^^^^^^^^^^^^^^^^^^^^^^^^^^^^^^^^^^^^^^^^^^^^^^^^^^^
  File "C:\Python311\Lib\site-packages\rest_framework\generics.py", line 110, in get_serializer
    return serializer_class(*args, **kwargs)
           ^^^^^^^^^^^^^^^^^^^^^^^^^^^^^^^^^
  File "C:\Users\Maryam\Documents\GitHub\Enigma_BackEnd\Enigma\MyUser\serializers.py", line 71, in __init__
    self.fields['name'].default = self.instance.name
    ^^^^^^^^^^^
  File "C:\Python311\Lib\site-packages\django\utils\functional.py", line 57, in __get__
    res = instance.__dict__[self.name] = self.func(instance)
                                         ^^^^^^^^^^^^^^^^^^^
  File "C:\Python311\Lib\site-packages\rest_framework\serializers.py", line 356, in fields
    for key, value in self.get_fields().items():
                      ^^^^^^^^^^^^^^^^^
  File "C:\Python311\Lib\site-packages\rest_framework\serializers.py", line 1052, in get_fields
    field_names = self.get_field_names(declared_fields, info)
                  ^^^^^^^^^^^^^^^^^^^^^^^^^^^^^^^^^^^^^^^^^^^
  File "C:\Python311\Lib\site-packages\rest_framework\serializers.py", line 1117, in get_field_names
    assert not (fields and exclude), (
AssertionError: Cannot set both 'fields' and 'exclude' options on serializer UpdateUserSerializer.
ERROR 2023-05-15 01:26:27,752 log 9056 14012 Internal Server Error: /auth/EditProfile/
Traceback (most recent call last):
  File "C:\Python311\Lib\site-packages\django\core\handlers\exception.py", line 56, in inner
    response = get_response(request)
               ^^^^^^^^^^^^^^^^^^^^^
  File "C:\Python311\Lib\site-packages\django\core\handlers\base.py", line 197, in _get_response
    response = wrapped_callback(request, *callback_args, **callback_kwargs)
               ^^^^^^^^^^^^^^^^^^^^^^^^^^^^^^^^^^^^^^^^^^^^^^^^^^^^^^^^^^^^
  File "C:\Python311\Lib\site-packages\django\views\decorators\csrf.py", line 55, in wrapped_view
    return view_func(*args, **kwargs)
           ^^^^^^^^^^^^^^^^^^^^^^^^^^
  File "C:\Python311\Lib\site-packages\django\views\generic\base.py", line 103, in view
    return self.dispatch(request, *args, **kwargs)
           ^^^^^^^^^^^^^^^^^^^^^^^^^^^^^^^^^^^^^^^
  File "C:\Python311\Lib\site-packages\rest_framework\views.py", line 509, in dispatch
    response = self.handle_exception(exc)
               ^^^^^^^^^^^^^^^^^^^^^^^^^^
  File "C:\Python311\Lib\site-packages\rest_framework\views.py", line 469, in handle_exception
    self.raise_uncaught_exception(exc)
  File "C:\Python311\Lib\site-packages\rest_framework\views.py", line 480, in raise_uncaught_exception
    raise exc
  File "C:\Python311\Lib\site-packages\rest_framework\views.py", line 506, in dispatch
    response = handler(request, *args, **kwargs)
               ^^^^^^^^^^^^^^^^^^^^^^^^^^^^^^^^^
  File "C:\Python311\Lib\site-packages\rest_framework\generics.py", line 226, in put
    return self.update(request, *args, **kwargs)
           ^^^^^^^^^^^^^^^^^^^^^^^^^^^^^^^^^^^^^
  File "C:\Python311\Lib\site-packages\rest_framework\mixins.py", line 66, in update
    serializer = self.get_serializer(instance, data=request.data, partial=partial)
                 ^^^^^^^^^^^^^^^^^^^^^^^^^^^^^^^^^^^^^^^^^^^^^^^^^^^^^^^^^^^^^^^^^
  File "C:\Python311\Lib\site-packages\rest_framework\generics.py", line 110, in get_serializer
    return serializer_class(*args, **kwargs)
           ^^^^^^^^^^^^^^^^^^^^^^^^^^^^^^^^^
  File "C:\Users\Maryam\Documents\GitHub\Enigma_BackEnd\Enigma\MyUser\serializers.py", line 71, in __init__
    self.fields['name'].default = self.instance.name
    ^^^^^^^^^^^
  File "C:\Python311\Lib\site-packages\django\utils\functional.py", line 57, in __get__
    res = instance.__dict__[self.name] = self.func(instance)
                                         ^^^^^^^^^^^^^^^^^^^
  File "C:\Python311\Lib\site-packages\rest_framework\serializers.py", line 356, in fields
    for key, value in self.get_fields().items():
                      ^^^^^^^^^^^^^^^^^
  File "C:\Python311\Lib\site-packages\rest_framework\serializers.py", line 1052, in get_fields
    field_names = self.get_field_names(declared_fields, info)
                  ^^^^^^^^^^^^^^^^^^^^^^^^^^^^^^^^^^^^^^^^^^^
  File "C:\Python311\Lib\site-packages\rest_framework\serializers.py", line 1117, in get_field_names
    assert not (fields and exclude), (
AssertionError: Cannot set both 'fields' and 'exclude' options on serializer UpdateUserSerializer.
ERROR 2023-05-15 01:26:27,756 log 9056 14012 Internal Server Error: /auth/EditProfile/
Traceback (most recent call last):
  File "C:\Python311\Lib\site-packages\django\core\handlers\exception.py", line 56, in inner
    response = get_response(request)
               ^^^^^^^^^^^^^^^^^^^^^
  File "C:\Python311\Lib\site-packages\django\core\handlers\base.py", line 197, in _get_response
    response = wrapped_callback(request, *callback_args, **callback_kwargs)
               ^^^^^^^^^^^^^^^^^^^^^^^^^^^^^^^^^^^^^^^^^^^^^^^^^^^^^^^^^^^^
  File "C:\Python311\Lib\site-packages\django\views\decorators\csrf.py", line 55, in wrapped_view
    return view_func(*args, **kwargs)
           ^^^^^^^^^^^^^^^^^^^^^^^^^^
  File "C:\Python311\Lib\site-packages\django\views\generic\base.py", line 103, in view
    return self.dispatch(request, *args, **kwargs)
           ^^^^^^^^^^^^^^^^^^^^^^^^^^^^^^^^^^^^^^^
  File "C:\Python311\Lib\site-packages\rest_framework\views.py", line 509, in dispatch
    response = self.handle_exception(exc)
               ^^^^^^^^^^^^^^^^^^^^^^^^^^
  File "C:\Python311\Lib\site-packages\rest_framework\views.py", line 469, in handle_exception
    self.raise_uncaught_exception(exc)
  File "C:\Python311\Lib\site-packages\rest_framework\views.py", line 480, in raise_uncaught_exception
    raise exc
  File "C:\Python311\Lib\site-packages\rest_framework\views.py", line 506, in dispatch
    response = handler(request, *args, **kwargs)
               ^^^^^^^^^^^^^^^^^^^^^^^^^^^^^^^^^
  File "C:\Python311\Lib\site-packages\rest_framework\generics.py", line 226, in put
    return self.update(request, *args, **kwargs)
           ^^^^^^^^^^^^^^^^^^^^^^^^^^^^^^^^^^^^^
  File "C:\Python311\Lib\site-packages\rest_framework\mixins.py", line 66, in update
    serializer = self.get_serializer(instance, data=request.data, partial=partial)
                 ^^^^^^^^^^^^^^^^^^^^^^^^^^^^^^^^^^^^^^^^^^^^^^^^^^^^^^^^^^^^^^^^^
  File "C:\Python311\Lib\site-packages\rest_framework\generics.py", line 110, in get_serializer
    return serializer_class(*args, **kwargs)
           ^^^^^^^^^^^^^^^^^^^^^^^^^^^^^^^^^
  File "C:\Users\Maryam\Documents\GitHub\Enigma_BackEnd\Enigma\MyUser\serializers.py", line 71, in __init__
    self.fields['name'].default = self.instance.name
    ^^^^^^^^^^^
  File "C:\Python311\Lib\site-packages\django\utils\functional.py", line 57, in __get__
    res = instance.__dict__[self.name] = self.func(instance)
                                         ^^^^^^^^^^^^^^^^^^^
  File "C:\Python311\Lib\site-packages\rest_framework\serializers.py", line 356, in fields
    for key, value in self.get_fields().items():
                      ^^^^^^^^^^^^^^^^^
  File "C:\Python311\Lib\site-packages\rest_framework\serializers.py", line 1052, in get_fields
    field_names = self.get_field_names(declared_fields, info)
                  ^^^^^^^^^^^^^^^^^^^^^^^^^^^^^^^^^^^^^^^^^^^
  File "C:\Python311\Lib\site-packages\rest_framework\serializers.py", line 1117, in get_field_names
    assert not (fields and exclude), (
AssertionError: Cannot set both 'fields' and 'exclude' options on serializer UpdateUserSerializer.
ERROR 2023-05-15 01:26:27,760 log 9056 14012 Internal Server Error: /auth/EditProfile/
Traceback (most recent call last):
  File "C:\Python311\Lib\site-packages\django\core\handlers\exception.py", line 56, in inner
    response = get_response(request)
               ^^^^^^^^^^^^^^^^^^^^^
  File "C:\Python311\Lib\site-packages\django\core\handlers\base.py", line 197, in _get_response
    response = wrapped_callback(request, *callback_args, **callback_kwargs)
               ^^^^^^^^^^^^^^^^^^^^^^^^^^^^^^^^^^^^^^^^^^^^^^^^^^^^^^^^^^^^
  File "C:\Python311\Lib\site-packages\django\views\decorators\csrf.py", line 55, in wrapped_view
    return view_func(*args, **kwargs)
           ^^^^^^^^^^^^^^^^^^^^^^^^^^
  File "C:\Python311\Lib\site-packages\django\views\generic\base.py", line 103, in view
    return self.dispatch(request, *args, **kwargs)
           ^^^^^^^^^^^^^^^^^^^^^^^^^^^^^^^^^^^^^^^
  File "C:\Python311\Lib\site-packages\rest_framework\views.py", line 509, in dispatch
    response = self.handle_exception(exc)
               ^^^^^^^^^^^^^^^^^^^^^^^^^^
  File "C:\Python311\Lib\site-packages\rest_framework\views.py", line 469, in handle_exception
    self.raise_uncaught_exception(exc)
  File "C:\Python311\Lib\site-packages\rest_framework\views.py", line 480, in raise_uncaught_exception
    raise exc
  File "C:\Python311\Lib\site-packages\rest_framework\views.py", line 506, in dispatch
    response = handler(request, *args, **kwargs)
               ^^^^^^^^^^^^^^^^^^^^^^^^^^^^^^^^^
  File "C:\Python311\Lib\site-packages\rest_framework\generics.py", line 226, in put
    return self.update(request, *args, **kwargs)
           ^^^^^^^^^^^^^^^^^^^^^^^^^^^^^^^^^^^^^
  File "C:\Python311\Lib\site-packages\rest_framework\mixins.py", line 66, in update
    serializer = self.get_serializer(instance, data=request.data, partial=partial)
                 ^^^^^^^^^^^^^^^^^^^^^^^^^^^^^^^^^^^^^^^^^^^^^^^^^^^^^^^^^^^^^^^^^
  File "C:\Python311\Lib\site-packages\rest_framework\generics.py", line 110, in get_serializer
    return serializer_class(*args, **kwargs)
           ^^^^^^^^^^^^^^^^^^^^^^^^^^^^^^^^^
  File "C:\Users\Maryam\Documents\GitHub\Enigma_BackEnd\Enigma\MyUser\serializers.py", line 71, in __init__
    self.fields['name'].default = self.instance.name
    ^^^^^^^^^^^
  File "C:\Python311\Lib\site-packages\django\utils\functional.py", line 57, in __get__
    res = instance.__dict__[self.name] = self.func(instance)
                                         ^^^^^^^^^^^^^^^^^^^
  File "C:\Python311\Lib\site-packages\rest_framework\serializers.py", line 356, in fields
    for key, value in self.get_fields().items():
                      ^^^^^^^^^^^^^^^^^
  File "C:\Python311\Lib\site-packages\rest_framework\serializers.py", line 1052, in get_fields
    field_names = self.get_field_names(declared_fields, info)
                  ^^^^^^^^^^^^^^^^^^^^^^^^^^^^^^^^^^^^^^^^^^^
  File "C:\Python311\Lib\site-packages\rest_framework\serializers.py", line 1117, in get_field_names
    assert not (fields and exclude), (
AssertionError: Cannot set both 'fields' and 'exclude' options on serializer UpdateUserSerializer.
ERROR 2023-05-15 01:26:27,764 log 9056 14012 Internal Server Error: /auth/EditProfile/
Traceback (most recent call last):
  File "C:\Python311\Lib\site-packages\django\core\handlers\exception.py", line 56, in inner
    response = get_response(request)
               ^^^^^^^^^^^^^^^^^^^^^
  File "C:\Python311\Lib\site-packages\django\core\handlers\base.py", line 197, in _get_response
    response = wrapped_callback(request, *callback_args, **callback_kwargs)
               ^^^^^^^^^^^^^^^^^^^^^^^^^^^^^^^^^^^^^^^^^^^^^^^^^^^^^^^^^^^^
  File "C:\Python311\Lib\site-packages\django\views\decorators\csrf.py", line 55, in wrapped_view
    return view_func(*args, **kwargs)
           ^^^^^^^^^^^^^^^^^^^^^^^^^^
  File "C:\Python311\Lib\site-packages\django\views\generic\base.py", line 103, in view
    return self.dispatch(request, *args, **kwargs)
           ^^^^^^^^^^^^^^^^^^^^^^^^^^^^^^^^^^^^^^^
  File "C:\Python311\Lib\site-packages\rest_framework\views.py", line 509, in dispatch
    response = self.handle_exception(exc)
               ^^^^^^^^^^^^^^^^^^^^^^^^^^
  File "C:\Python311\Lib\site-packages\rest_framework\views.py", line 469, in handle_exception
    self.raise_uncaught_exception(exc)
  File "C:\Python311\Lib\site-packages\rest_framework\views.py", line 480, in raise_uncaught_exception
    raise exc
  File "C:\Python311\Lib\site-packages\rest_framework\views.py", line 506, in dispatch
    response = handler(request, *args, **kwargs)
               ^^^^^^^^^^^^^^^^^^^^^^^^^^^^^^^^^
  File "C:\Python311\Lib\site-packages\rest_framework\generics.py", line 226, in put
    return self.update(request, *args, **kwargs)
           ^^^^^^^^^^^^^^^^^^^^^^^^^^^^^^^^^^^^^
  File "C:\Python311\Lib\site-packages\rest_framework\mixins.py", line 66, in update
    serializer = self.get_serializer(instance, data=request.data, partial=partial)
                 ^^^^^^^^^^^^^^^^^^^^^^^^^^^^^^^^^^^^^^^^^^^^^^^^^^^^^^^^^^^^^^^^^
  File "C:\Python311\Lib\site-packages\rest_framework\generics.py", line 110, in get_serializer
    return serializer_class(*args, **kwargs)
           ^^^^^^^^^^^^^^^^^^^^^^^^^^^^^^^^^
  File "C:\Users\Maryam\Documents\GitHub\Enigma_BackEnd\Enigma\MyUser\serializers.py", line 71, in __init__
    self.fields['name'].default = self.instance.name
    ^^^^^^^^^^^
  File "C:\Python311\Lib\site-packages\django\utils\functional.py", line 57, in __get__
    res = instance.__dict__[self.name] = self.func(instance)
                                         ^^^^^^^^^^^^^^^^^^^
  File "C:\Python311\Lib\site-packages\rest_framework\serializers.py", line 356, in fields
    for key, value in self.get_fields().items():
                      ^^^^^^^^^^^^^^^^^
  File "C:\Python311\Lib\site-packages\rest_framework\serializers.py", line 1052, in get_fields
    field_names = self.get_field_names(declared_fields, info)
                  ^^^^^^^^^^^^^^^^^^^^^^^^^^^^^^^^^^^^^^^^^^^
  File "C:\Python311\Lib\site-packages\rest_framework\serializers.py", line 1117, in get_field_names
    assert not (fields and exclude), (
AssertionError: Cannot set both 'fields' and 'exclude' options on serializer UpdateUserSerializer.
ERROR 2023-05-15 01:26:27,768 log 9056 14012 Internal Server Error: /auth/EditProfile/
Traceback (most recent call last):
  File "C:\Python311\Lib\site-packages\django\core\handlers\exception.py", line 56, in inner
    response = get_response(request)
               ^^^^^^^^^^^^^^^^^^^^^
  File "C:\Python311\Lib\site-packages\django\core\handlers\base.py", line 197, in _get_response
    response = wrapped_callback(request, *callback_args, **callback_kwargs)
               ^^^^^^^^^^^^^^^^^^^^^^^^^^^^^^^^^^^^^^^^^^^^^^^^^^^^^^^^^^^^
  File "C:\Python311\Lib\site-packages\django\views\decorators\csrf.py", line 55, in wrapped_view
    return view_func(*args, **kwargs)
           ^^^^^^^^^^^^^^^^^^^^^^^^^^
  File "C:\Python311\Lib\site-packages\django\views\generic\base.py", line 103, in view
    return self.dispatch(request, *args, **kwargs)
           ^^^^^^^^^^^^^^^^^^^^^^^^^^^^^^^^^^^^^^^
  File "C:\Python311\Lib\site-packages\rest_framework\views.py", line 509, in dispatch
    response = self.handle_exception(exc)
               ^^^^^^^^^^^^^^^^^^^^^^^^^^
  File "C:\Python311\Lib\site-packages\rest_framework\views.py", line 469, in handle_exception
    self.raise_uncaught_exception(exc)
  File "C:\Python311\Lib\site-packages\rest_framework\views.py", line 480, in raise_uncaught_exception
    raise exc
  File "C:\Python311\Lib\site-packages\rest_framework\views.py", line 506, in dispatch
    response = handler(request, *args, **kwargs)
               ^^^^^^^^^^^^^^^^^^^^^^^^^^^^^^^^^
  File "C:\Python311\Lib\site-packages\rest_framework\generics.py", line 226, in put
    return self.update(request, *args, **kwargs)
           ^^^^^^^^^^^^^^^^^^^^^^^^^^^^^^^^^^^^^
  File "C:\Python311\Lib\site-packages\rest_framework\mixins.py", line 66, in update
    serializer = self.get_serializer(instance, data=request.data, partial=partial)
                 ^^^^^^^^^^^^^^^^^^^^^^^^^^^^^^^^^^^^^^^^^^^^^^^^^^^^^^^^^^^^^^^^^
  File "C:\Python311\Lib\site-packages\rest_framework\generics.py", line 110, in get_serializer
    return serializer_class(*args, **kwargs)
           ^^^^^^^^^^^^^^^^^^^^^^^^^^^^^^^^^
  File "C:\Users\Maryam\Documents\GitHub\Enigma_BackEnd\Enigma\MyUser\serializers.py", line 71, in __init__
    self.fields['name'].default = self.instance.name
    ^^^^^^^^^^^
  File "C:\Python311\Lib\site-packages\django\utils\functional.py", line 57, in __get__
    res = instance.__dict__[self.name] = self.func(instance)
                                         ^^^^^^^^^^^^^^^^^^^
  File "C:\Python311\Lib\site-packages\rest_framework\serializers.py", line 356, in fields
    for key, value in self.get_fields().items():
                      ^^^^^^^^^^^^^^^^^
  File "C:\Python311\Lib\site-packages\rest_framework\serializers.py", line 1052, in get_fields
    field_names = self.get_field_names(declared_fields, info)
                  ^^^^^^^^^^^^^^^^^^^^^^^^^^^^^^^^^^^^^^^^^^^
  File "C:\Python311\Lib\site-packages\rest_framework\serializers.py", line 1117, in get_field_names
    assert not (fields and exclude), (
AssertionError: Cannot set both 'fields' and 'exclude' options on serializer UpdateUserSerializer.
WARNING 2023-05-15 01:28:24,457 log 1952 12180 Bad Request: /auth/EditProfile/
WARNING 2023-05-15 01:28:24,459 log 1952 12180 Bad Request: /auth/EditProfile/
WARNING 2023-05-15 01:30:22,233 log 10744 18284 Bad Request: /auth/EditProfile/
WARNING 2023-05-15 01:30:22,237 log 10744 18284 Bad Request: /auth/EditProfile/
WARNING 2023-05-15 01:31:20,029 log 7248 11472 Bad Request: /auth/EditProfile/
WARNING 2023-05-15 01:31:20,032 log 7248 11472 Bad Request: /auth/EditProfile/
WARNING 2023-05-15 01:37:07,360 log 11400 17552 Bad Request: /auth/EditProfile/
WARNING 2023-05-15 01:37:07,362 log 11400 17552 Bad Request: /auth/EditProfile/
WARNING 2023-05-15 08:17:26,779 log 12300 9176 Bad Request: /auth/EditProfile/
WARNING 2023-05-15 08:17:26,782 log 12300 9176 Bad Request: /auth/EditProfile/
WARNING 2023-05-15 08:18:28,812 log 17656 18288 Bad Request: /auth/EditProfile/
WARNING 2023-05-15 08:18:28,814 log 17656 18288 Bad Request: /auth/EditProfile/
WARNING 2023-05-15 08:18:59,780 log 7680 17848 Bad Request: /auth/EditProfile/
WARNING 2023-05-15 08:18:59,782 log 7680 17848 Bad Request: /auth/EditProfile/
ERROR 2023-05-15 08:23:58,748 log 7108 16260 Internal Server Error: /auth/EditProfile/
Traceback (most recent call last):
  File "C:\Python311\Lib\site-packages\django\core\handlers\exception.py", line 56, in inner
    response = get_response(request)
               ^^^^^^^^^^^^^^^^^^^^^
  File "C:\Python311\Lib\site-packages\django\core\handlers\base.py", line 197, in _get_response
    response = wrapped_callback(request, *callback_args, **callback_kwargs)
               ^^^^^^^^^^^^^^^^^^^^^^^^^^^^^^^^^^^^^^^^^^^^^^^^^^^^^^^^^^^^
  File "C:\Python311\Lib\site-packages\django\views\decorators\csrf.py", line 55, in wrapped_view
    return view_func(*args, **kwargs)
           ^^^^^^^^^^^^^^^^^^^^^^^^^^
  File "C:\Python311\Lib\site-packages\django\views\generic\base.py", line 103, in view
    return self.dispatch(request, *args, **kwargs)
           ^^^^^^^^^^^^^^^^^^^^^^^^^^^^^^^^^^^^^^^
  File "C:\Python311\Lib\site-packages\rest_framework\views.py", line 509, in dispatch
    response = self.handle_exception(exc)
               ^^^^^^^^^^^^^^^^^^^^^^^^^^
  File "C:\Python311\Lib\site-packages\rest_framework\views.py", line 469, in handle_exception
    self.raise_uncaught_exception(exc)
  File "C:\Python311\Lib\site-packages\rest_framework\views.py", line 480, in raise_uncaught_exception
    raise exc
  File "C:\Python311\Lib\site-packages\rest_framework\views.py", line 506, in dispatch
    response = handler(request, *args, **kwargs)
               ^^^^^^^^^^^^^^^^^^^^^^^^^^^^^^^^^
  File "C:\Python311\Lib\site-packages\rest_framework\generics.py", line 226, in put
    return self.update(request, *args, **kwargs)
           ^^^^^^^^^^^^^^^^^^^^^^^^^^^^^^^^^^^^^
  File "C:\Python311\Lib\site-packages\rest_framework\mixins.py", line 68, in update
    self.perform_update(serializer)
  File "C:\Users\Maryam\Documents\GitHub\Enigma_BackEnd\Enigma\MyUser\views.py", line 81, in perform_update
    if 'name' not in self.request.user and 'picture_id'not in self.request.user:
       ^^^^^^^^^^^^^^^^^^^^^^^^^^^^^^^
TypeError: argument of type 'MyUser' is not iterable
ERROR 2023-05-15 08:23:58,758 log 7108 16260 Internal Server Error: /auth/EditProfile/
Traceback (most recent call last):
  File "C:\Python311\Lib\site-packages\django\core\handlers\exception.py", line 56, in inner
    response = get_response(request)
               ^^^^^^^^^^^^^^^^^^^^^
  File "C:\Python311\Lib\site-packages\django\core\handlers\base.py", line 197, in _get_response
    response = wrapped_callback(request, *callback_args, **callback_kwargs)
               ^^^^^^^^^^^^^^^^^^^^^^^^^^^^^^^^^^^^^^^^^^^^^^^^^^^^^^^^^^^^
  File "C:\Python311\Lib\site-packages\django\views\decorators\csrf.py", line 55, in wrapped_view
    return view_func(*args, **kwargs)
           ^^^^^^^^^^^^^^^^^^^^^^^^^^
  File "C:\Python311\Lib\site-packages\django\views\generic\base.py", line 103, in view
    return self.dispatch(request, *args, **kwargs)
           ^^^^^^^^^^^^^^^^^^^^^^^^^^^^^^^^^^^^^^^
  File "C:\Python311\Lib\site-packages\rest_framework\views.py", line 509, in dispatch
    response = self.handle_exception(exc)
               ^^^^^^^^^^^^^^^^^^^^^^^^^^
  File "C:\Python311\Lib\site-packages\rest_framework\views.py", line 469, in handle_exception
    self.raise_uncaught_exception(exc)
  File "C:\Python311\Lib\site-packages\rest_framework\views.py", line 480, in raise_uncaught_exception
    raise exc
  File "C:\Python311\Lib\site-packages\rest_framework\views.py", line 506, in dispatch
    response = handler(request, *args, **kwargs)
               ^^^^^^^^^^^^^^^^^^^^^^^^^^^^^^^^^
  File "C:\Python311\Lib\site-packages\rest_framework\generics.py", line 226, in put
    return self.update(request, *args, **kwargs)
           ^^^^^^^^^^^^^^^^^^^^^^^^^^^^^^^^^^^^^
  File "C:\Python311\Lib\site-packages\rest_framework\mixins.py", line 68, in update
    self.perform_update(serializer)
  File "C:\Users\Maryam\Documents\GitHub\Enigma_BackEnd\Enigma\MyUser\views.py", line 81, in perform_update
    if 'name' not in self.request.user and 'picture_id'not in self.request.user:
       ^^^^^^^^^^^^^^^^^^^^^^^^^^^^^^^
TypeError: argument of type 'MyUser' is not iterable
ERROR 2023-05-15 08:23:58,763 log 7108 16260 Internal Server Error: /auth/EditProfile/
Traceback (most recent call last):
  File "C:\Python311\Lib\site-packages\django\core\handlers\exception.py", line 56, in inner
    response = get_response(request)
               ^^^^^^^^^^^^^^^^^^^^^
  File "C:\Python311\Lib\site-packages\django\core\handlers\base.py", line 197, in _get_response
    response = wrapped_callback(request, *callback_args, **callback_kwargs)
               ^^^^^^^^^^^^^^^^^^^^^^^^^^^^^^^^^^^^^^^^^^^^^^^^^^^^^^^^^^^^
  File "C:\Python311\Lib\site-packages\django\views\decorators\csrf.py", line 55, in wrapped_view
    return view_func(*args, **kwargs)
           ^^^^^^^^^^^^^^^^^^^^^^^^^^
  File "C:\Python311\Lib\site-packages\django\views\generic\base.py", line 103, in view
    return self.dispatch(request, *args, **kwargs)
           ^^^^^^^^^^^^^^^^^^^^^^^^^^^^^^^^^^^^^^^
  File "C:\Python311\Lib\site-packages\rest_framework\views.py", line 509, in dispatch
    response = self.handle_exception(exc)
               ^^^^^^^^^^^^^^^^^^^^^^^^^^
  File "C:\Python311\Lib\site-packages\rest_framework\views.py", line 469, in handle_exception
    self.raise_uncaught_exception(exc)
  File "C:\Python311\Lib\site-packages\rest_framework\views.py", line 480, in raise_uncaught_exception
    raise exc
  File "C:\Python311\Lib\site-packages\rest_framework\views.py", line 506, in dispatch
    response = handler(request, *args, **kwargs)
               ^^^^^^^^^^^^^^^^^^^^^^^^^^^^^^^^^
  File "C:\Python311\Lib\site-packages\rest_framework\generics.py", line 226, in put
    return self.update(request, *args, **kwargs)
           ^^^^^^^^^^^^^^^^^^^^^^^^^^^^^^^^^^^^^
  File "C:\Python311\Lib\site-packages\rest_framework\mixins.py", line 68, in update
    self.perform_update(serializer)
  File "C:\Users\Maryam\Documents\GitHub\Enigma_BackEnd\Enigma\MyUser\views.py", line 81, in perform_update
    if 'name' not in self.request.user and 'picture_id'not in self.request.user:
       ^^^^^^^^^^^^^^^^^^^^^^^^^^^^^^^
TypeError: argument of type 'MyUser' is not iterable
WARNING 2023-05-15 08:23:58,767 log 7108 16260 Bad Request: /auth/EditProfile/
WARNING 2023-05-15 08:23:58,768 log 7108 16260 Bad Request: /auth/EditProfile/
ERROR 2023-05-15 08:23:58,771 log 7108 16260 Internal Server Error: /auth/EditProfile/
Traceback (most recent call last):
  File "C:\Python311\Lib\site-packages\django\core\handlers\exception.py", line 56, in inner
    response = get_response(request)
               ^^^^^^^^^^^^^^^^^^^^^
  File "C:\Python311\Lib\site-packages\django\core\handlers\base.py", line 197, in _get_response
    response = wrapped_callback(request, *callback_args, **callback_kwargs)
               ^^^^^^^^^^^^^^^^^^^^^^^^^^^^^^^^^^^^^^^^^^^^^^^^^^^^^^^^^^^^
  File "C:\Python311\Lib\site-packages\django\views\decorators\csrf.py", line 55, in wrapped_view
    return view_func(*args, **kwargs)
           ^^^^^^^^^^^^^^^^^^^^^^^^^^
  File "C:\Python311\Lib\site-packages\django\views\generic\base.py", line 103, in view
    return self.dispatch(request, *args, **kwargs)
           ^^^^^^^^^^^^^^^^^^^^^^^^^^^^^^^^^^^^^^^
  File "C:\Python311\Lib\site-packages\rest_framework\views.py", line 509, in dispatch
    response = self.handle_exception(exc)
               ^^^^^^^^^^^^^^^^^^^^^^^^^^
  File "C:\Python311\Lib\site-packages\rest_framework\views.py", line 469, in handle_exception
    self.raise_uncaught_exception(exc)
  File "C:\Python311\Lib\site-packages\rest_framework\views.py", line 480, in raise_uncaught_exception
    raise exc
  File "C:\Python311\Lib\site-packages\rest_framework\views.py", line 506, in dispatch
    response = handler(request, *args, **kwargs)
               ^^^^^^^^^^^^^^^^^^^^^^^^^^^^^^^^^
  File "C:\Python311\Lib\site-packages\rest_framework\generics.py", line 226, in put
    return self.update(request, *args, **kwargs)
           ^^^^^^^^^^^^^^^^^^^^^^^^^^^^^^^^^^^^^
  File "C:\Python311\Lib\site-packages\rest_framework\mixins.py", line 68, in update
    self.perform_update(serializer)
  File "C:\Users\Maryam\Documents\GitHub\Enigma_BackEnd\Enigma\MyUser\views.py", line 81, in perform_update
    if 'name' not in self.request.user and 'picture_id'not in self.request.user:
       ^^^^^^^^^^^^^^^^^^^^^^^^^^^^^^^
TypeError: argument of type 'MyUser' is not iterable
WARNING 2023-05-15 08:32:25,993 log 9196 9120 Bad Request: /auth/EditProfile/
WARNING 2023-05-15 08:32:25,995 log 9196 9120 Bad Request: /auth/EditProfile/
WARNING 2023-05-15 08:33:38,518 log 17420 6364 Bad Request: /auth/EditProfile/
WARNING 2023-05-15 08:33:38,521 log 17420 6364 Bad Request: /auth/EditProfile/
