INFO 2023-05-13 18:49:04,915 autoreload 5080 492 Watching for file changes with StatReloader
INFO 2023-05-13 18:52:57,793 autoreload 14068 3132 Watching for file changes with StatReloader
WARNING 2023-05-13 18:53:20,871 log 14068 8360 Not Found: /
WARNING 2023-05-13 18:53:20,871 basehttp 14068 8360 "GET / HTTP/1.1" 404 2374
WARNING 2023-05-13 18:53:20,938 log 14068 8360 Not Found: /favicon.ico
INFO 2023-05-13 18:53:20,939 basehttp 14068 8360 - Broken pipe from ('127.0.0.1', 59487)
INFO 2023-05-13 18:54:04,296 basehttp 14068 8716 "GET /auth/register HTTP/1.1" 301 0
WARNING 2023-05-13 18:54:04,470 log 14068 8716 Method Not Allowed: /auth/register/
WARNING 2023-05-13 18:54:04,471 basehttp 14068 8716 "GET /auth/register/ HTTP/1.1" 405 8050
INFO 2023-05-13 18:54:04,704 basehttp 14068 2028 - Broken pipe from ('127.0.0.1', 60362)
INFO 2023-05-13 18:54:04,740 basehttp 14068 7120 - Broken pipe from ('127.0.0.1', 60364)
INFO 2023-05-13 18:54:04,745 basehttp 14068 8716 - Broken pipe from ('127.0.0.1', 60358)
INFO 2023-05-13 18:54:04,756 basehttp 14068 2276 - Broken pipe from ('127.0.0.1', 60366)
INFO 2023-05-13 18:54:04,786 basehttp 14068 9592 - Broken pipe from ('127.0.0.1', 60363)
WARNING 2023-05-13 18:54:26,709 log 14068 3504 Bad Request: /auth/register/
WARNING 2023-05-13 18:54:26,710 basehttp 14068 3504 "POST /auth/register/ HTTP/1.1" 400 8163
INFO 2023-05-13 18:55:16,605 basehttp 14068 3504 "POST /auth/register/ HTTP/1.1" 201 8231
INFO 2023-05-13 18:56:17,049 basehttp 14068 8500 "POST /auth/token/ HTTP/1.1" 200 52
ERROR 2023-05-13 18:58:37,213 log 14068 4572 Internal Server Error: /group/CreateGroup/
Traceback (most recent call last):
  File "C:\Users\Acer\AppData\Local\Programs\Python\Python311\Lib\site-packages\django\utils\datastructures.py", line 84, in __getitem__
    list_ = super().__getitem__(key)
            ^^^^^^^^^^^^^^^^^^^^^^^^
KeyError: 'emails'

During handling of the above exception, another exception occurred:

Traceback (most recent call last):
  File "C:\Users\Acer\AppData\Local\Programs\Python\Python311\Lib\site-packages\django\core\handlers\exception.py", line 56, in inner
    response = get_response(request)
               ^^^^^^^^^^^^^^^^^^^^^
  File "C:\Users\Acer\AppData\Local\Programs\Python\Python311\Lib\site-packages\django\core\handlers\base.py", line 197, in _get_response
    response = wrapped_callback(request, *callback_args, **callback_kwargs)
               ^^^^^^^^^^^^^^^^^^^^^^^^^^^^^^^^^^^^^^^^^^^^^^^^^^^^^^^^^^^^
  File "C:\Users\Acer\AppData\Local\Programs\Python\Python311\Lib\site-packages\django\views\decorators\csrf.py", line 55, in wrapped_view
    return view_func(*args, **kwargs)
           ^^^^^^^^^^^^^^^^^^^^^^^^^^
  File "C:\Users\Acer\AppData\Local\Programs\Python\Python311\Lib\site-packages\django\views\generic\base.py", line 103, in view
    return self.dispatch(request, *args, **kwargs)
           ^^^^^^^^^^^^^^^^^^^^^^^^^^^^^^^^^^^^^^^
  File "C:\Users\Acer\AppData\Local\Programs\Python\Python311\Lib\site-packages\rest_framework\views.py", line 509, in dispatch
    response = self.handle_exception(exc)
               ^^^^^^^^^^^^^^^^^^^^^^^^^^
  File "C:\Users\Acer\AppData\Local\Programs\Python\Python311\Lib\site-packages\rest_framework\views.py", line 469, in handle_exception
    self.raise_uncaught_exception(exc)
  File "C:\Users\Acer\AppData\Local\Programs\Python\Python311\Lib\site-packages\rest_framework\views.py", line 480, in raise_uncaught_exception
    raise exc
  File "C:\Users\Acer\AppData\Local\Programs\Python\Python311\Lib\site-packages\rest_framework\views.py", line 506, in dispatch
    response = handler(request, *args, **kwargs)
               ^^^^^^^^^^^^^^^^^^^^^^^^^^^^^^^^^
  File "E:\uni\8\OOD\Enigma_BackEnd\Enigma\Group\views.py", line 24, in post
    data["emails"] = request.data['emails']
                     ~~~~~~~~~~~~^^^^^^^^^^
  File "C:\Users\Acer\AppData\Local\Programs\Python\Python311\Lib\site-packages\django\utils\datastructures.py", line 86, in __getitem__
    raise MultiValueDictKeyError(key)
django.utils.datastructures.MultiValueDictKeyError: 'emails'
ERROR 2023-05-13 18:58:37,216 basehttp 14068 4572 "POST /group/CreateGroup/ HTTP/1.1" 500 106419
ERROR 2023-05-13 18:59:26,194 log 14068 4572 Internal Server Error: /group/CreateGroup/
Traceback (most recent call last):
  File "C:\Users\Acer\AppData\Local\Programs\Python\Python311\Lib\site-packages\django\core\handlers\exception.py", line 56, in inner
    response = get_response(request)
               ^^^^^^^^^^^^^^^^^^^^^
  File "C:\Users\Acer\AppData\Local\Programs\Python\Python311\Lib\site-packages\django\core\handlers\base.py", line 197, in _get_response
    response = wrapped_callback(request, *callback_args, **callback_kwargs)
               ^^^^^^^^^^^^^^^^^^^^^^^^^^^^^^^^^^^^^^^^^^^^^^^^^^^^^^^^^^^^
  File "C:\Users\Acer\AppData\Local\Programs\Python\Python311\Lib\site-packages\django\views\decorators\csrf.py", line 55, in wrapped_view
    return view_func(*args, **kwargs)
           ^^^^^^^^^^^^^^^^^^^^^^^^^^
  File "C:\Users\Acer\AppData\Local\Programs\Python\Python311\Lib\site-packages\django\views\generic\base.py", line 103, in view
    return self.dispatch(request, *args, **kwargs)
           ^^^^^^^^^^^^^^^^^^^^^^^^^^^^^^^^^^^^^^^
  File "C:\Users\Acer\AppData\Local\Programs\Python\Python311\Lib\site-packages\rest_framework\views.py", line 509, in dispatch
    response = self.handle_exception(exc)
               ^^^^^^^^^^^^^^^^^^^^^^^^^^
  File "C:\Users\Acer\AppData\Local\Programs\Python\Python311\Lib\site-packages\rest_framework\views.py", line 469, in handle_exception
    self.raise_uncaught_exception(exc)
  File "C:\Users\Acer\AppData\Local\Programs\Python\Python311\Lib\site-packages\rest_framework\views.py", line 480, in raise_uncaught_exception
    raise exc
  File "C:\Users\Acer\AppData\Local\Programs\Python\Python311\Lib\site-packages\rest_framework\views.py", line 506, in dispatch
    response = handler(request, *args, **kwargs)
               ^^^^^^^^^^^^^^^^^^^^^^^^^^^^^^^^^
  File "E:\uni\8\OOD\Enigma_BackEnd\Enigma\Group\views.py", line 25, in post
    data["emails"].append(str(self.request.user.email))
    ^^^^^^^^^^^^^^^^^^^^^
AttributeError: 'str' object has no attribute 'append'
ERROR 2023-05-13 18:59:26,195 basehttp 14068 4572 "POST /group/CreateGroup/ HTTP/1.1" 500 98367
ERROR 2023-05-13 18:59:32,256 log 14068 4572 Internal Server Error: /group/CreateGroup/
Traceback (most recent call last):
  File "C:\Users\Acer\AppData\Local\Programs\Python\Python311\Lib\site-packages\django\core\handlers\exception.py", line 56, in inner
    response = get_response(request)
               ^^^^^^^^^^^^^^^^^^^^^
  File "C:\Users\Acer\AppData\Local\Programs\Python\Python311\Lib\site-packages\django\core\handlers\base.py", line 197, in _get_response
    response = wrapped_callback(request, *callback_args, **callback_kwargs)
               ^^^^^^^^^^^^^^^^^^^^^^^^^^^^^^^^^^^^^^^^^^^^^^^^^^^^^^^^^^^^
  File "C:\Users\Acer\AppData\Local\Programs\Python\Python311\Lib\site-packages\django\views\decorators\csrf.py", line 55, in wrapped_view
    return view_func(*args, **kwargs)
           ^^^^^^^^^^^^^^^^^^^^^^^^^^
  File "C:\Users\Acer\AppData\Local\Programs\Python\Python311\Lib\site-packages\django\views\generic\base.py", line 103, in view
    return self.dispatch(request, *args, **kwargs)
           ^^^^^^^^^^^^^^^^^^^^^^^^^^^^^^^^^^^^^^^
  File "C:\Users\Acer\AppData\Local\Programs\Python\Python311\Lib\site-packages\rest_framework\views.py", line 509, in dispatch
    response = self.handle_exception(exc)
               ^^^^^^^^^^^^^^^^^^^^^^^^^^
  File "C:\Users\Acer\AppData\Local\Programs\Python\Python311\Lib\site-packages\rest_framework\views.py", line 469, in handle_exception
    self.raise_uncaught_exception(exc)
  File "C:\Users\Acer\AppData\Local\Programs\Python\Python311\Lib\site-packages\rest_framework\views.py", line 480, in raise_uncaught_exception
    raise exc
  File "C:\Users\Acer\AppData\Local\Programs\Python\Python311\Lib\site-packages\rest_framework\views.py", line 506, in dispatch
    response = handler(request, *args, **kwargs)
               ^^^^^^^^^^^^^^^^^^^^^^^^^^^^^^^^^
  File "E:\uni\8\OOD\Enigma_BackEnd\Enigma\Group\views.py", line 25, in post
    data["emails"].append(str(self.request.user.email))
    ^^^^^^^^^^^^^^^^^^^^^
AttributeError: 'str' object has no attribute 'append'
ERROR 2023-05-13 18:59:32,258 basehttp 14068 4572 "POST /group/CreateGroup/ HTTP/1.1" 500 98402
ERROR 2023-05-13 18:59:36,911 log 14068 4572 Internal Server Error: /group/CreateGroup/
Traceback (most recent call last):
  File "C:\Users\Acer\AppData\Local\Programs\Python\Python311\Lib\site-packages\django\core\handlers\exception.py", line 56, in inner
    response = get_response(request)
               ^^^^^^^^^^^^^^^^^^^^^
  File "C:\Users\Acer\AppData\Local\Programs\Python\Python311\Lib\site-packages\django\core\handlers\base.py", line 197, in _get_response
    response = wrapped_callback(request, *callback_args, **callback_kwargs)
               ^^^^^^^^^^^^^^^^^^^^^^^^^^^^^^^^^^^^^^^^^^^^^^^^^^^^^^^^^^^^
  File "C:\Users\Acer\AppData\Local\Programs\Python\Python311\Lib\site-packages\django\views\decorators\csrf.py", line 55, in wrapped_view
    return view_func(*args, **kwargs)
           ^^^^^^^^^^^^^^^^^^^^^^^^^^
  File "C:\Users\Acer\AppData\Local\Programs\Python\Python311\Lib\site-packages\django\views\generic\base.py", line 103, in view
    return self.dispatch(request, *args, **kwargs)
           ^^^^^^^^^^^^^^^^^^^^^^^^^^^^^^^^^^^^^^^
  File "C:\Users\Acer\AppData\Local\Programs\Python\Python311\Lib\site-packages\rest_framework\views.py", line 509, in dispatch
    response = self.handle_exception(exc)
               ^^^^^^^^^^^^^^^^^^^^^^^^^^
  File "C:\Users\Acer\AppData\Local\Programs\Python\Python311\Lib\site-packages\rest_framework\views.py", line 469, in handle_exception
    self.raise_uncaught_exception(exc)
  File "C:\Users\Acer\AppData\Local\Programs\Python\Python311\Lib\site-packages\rest_framework\views.py", line 480, in raise_uncaught_exception
    raise exc
  File "C:\Users\Acer\AppData\Local\Programs\Python\Python311\Lib\site-packages\rest_framework\views.py", line 506, in dispatch
    response = handler(request, *args, **kwargs)
               ^^^^^^^^^^^^^^^^^^^^^^^^^^^^^^^^^
  File "E:\uni\8\OOD\Enigma_BackEnd\Enigma\Group\views.py", line 25, in post
    data["emails"].append(str(self.request.user.email))
    ^^^^^^^^^^^^^^^^^^^^^
AttributeError: 'str' object has no attribute 'append'
ERROR 2023-05-13 18:59:36,912 basehttp 14068 4572 "POST /group/CreateGroup/ HTTP/1.1" 500 98375
INFO 2023-05-13 19:00:23,051 autoreload 14068 3132 E:\uni\8\OOD\Enigma_BackEnd\Enigma\Enigma\settings.py changed, reloading.
INFO 2023-05-14 00:12:17,583 autoreload 13032 2848 Watching for file changes with StatReloader
INFO 2023-05-14 00:12:25,013 autoreload 13032 2848 E:\uni\8\OOD\Enigma_BackEnd\Enigma\Enigma\settings.py changed, reloading.
INFO 2023-05-14 00:12:25,949 autoreload 16628 8300 Watching for file changes with StatReloader
WARNING 2023-05-14 00:31:51,563 log 2652 14600 Not Found: /group/DeleteGroup/
WARNING 2023-05-14 00:31:51,573 log 2652 14600 Forbidden: /group/DeleteGroup/
ERROR 2023-05-14 00:31:51,576 log 2652 14600 Internal Server Error: /group/GroupInfo/
ERROR 2023-05-14 00:31:51,578 log 2652 14600 Internal Server Error: /group/GroupInfo/
WARNING 2023-05-14 00:31:51,581 log 2652 14600 Not Found: /group/GroupInfo/
WARNING 2023-05-14 00:31:51,587 log 2652 14600 Unauthorized: /group/GroupInfo/
WARNING 2023-05-14 00:31:51,590 log 2652 14600 Not Found: /group/GroupInfo/
ERROR 2023-05-14 00:31:51,592 log 2652 14600 Internal Server Error: /group/ShowGroups/
WARNING 2023-05-14 00:31:51,594 log 2652 14600 Method Not Allowed: /group/ShowGroups/
WARNING 2023-05-14 00:31:51,596 log 2652 14600 Not Found: /group/ShowGroups/
WARNING 2023-05-14 00:31:51,603 log 2652 14600 Unauthorized: /group/ShowGroups/
ERROR 2023-05-14 00:31:51,608 log 2652 14600 Internal Server Error: /group/ShowMembers/
WARNING 2023-05-14 00:31:51,612 log 2652 14600 Forbidden: /group/ShowMembers/
WARNING 2023-05-14 00:31:51,617 log 2652 14600 Forbidden: /group/ShowMembers/
WARNING 2023-05-14 00:31:51,627 log 2652 14600 Forbidden: /group/ShowMembers/
WARNING 2023-05-14 00:31:52,657 log 2652 14600 Bad Request: /auth/token/
WARNING 2023-05-14 00:31:53,181 log 2652 14600 Bad Request: /auth/token/
WARNING 2023-05-14 00:31:53,184 log 2652 14600 Bad Request: /auth/register/
WARNING 2023-05-14 00:31:53,188 log 2652 14600 Bad Request: /auth/register/
WARNING 2023-05-14 00:32:52,307 log 13468 2160 Not Found: /group/DeleteGroup/
WARNING 2023-05-14 00:32:52,315 log 13468 2160 Forbidden: /group/DeleteGroup/
ERROR 2023-05-14 00:32:52,318 log 13468 2160 Internal Server Error: /group/GroupInfo/
ERROR 2023-05-14 00:32:52,321 log 13468 2160 Internal Server Error: /group/GroupInfo/
WARNING 2023-05-14 00:32:52,323 log 13468 2160 Not Found: /group/GroupInfo/
WARNING 2023-05-14 00:32:52,329 log 13468 2160 Unauthorized: /group/GroupInfo/
WARNING 2023-05-14 00:32:52,332 log 13468 2160 Not Found: /group/GroupInfo/
ERROR 2023-05-14 00:32:52,334 log 13468 2160 Internal Server Error: /group/ShowGroups/
WARNING 2023-05-14 00:32:52,336 log 13468 2160 Method Not Allowed: /group/ShowGroups/
WARNING 2023-05-14 00:32:52,339 log 13468 2160 Not Found: /group/ShowGroups/
WARNING 2023-05-14 00:32:52,345 log 13468 2160 Unauthorized: /group/ShowGroups/
ERROR 2023-05-14 00:32:52,353 log 13468 2160 Internal Server Error: /group/ShowMembers/
WARNING 2023-05-14 00:32:52,359 log 13468 2160 Forbidden: /group/ShowMembers/
WARNING 2023-05-14 00:32:52,362 log 13468 2160 Forbidden: /group/ShowMembers/
WARNING 2023-05-14 00:32:52,372 log 13468 2160 Forbidden: /group/ShowMembers/
WARNING 2023-05-14 00:32:53,435 log 13468 2160 Bad Request: /auth/token/
WARNING 2023-05-14 00:32:53,925 log 13468 2160 Bad Request: /auth/token/
WARNING 2023-05-14 00:32:53,927 log 13468 2160 Bad Request: /auth/register/
WARNING 2023-05-14 00:32:53,929 log 13468 2160 Bad Request: /auth/register/
WARNING 2023-05-14 05:22:18,351 log 9684 11896 Forbidden: /group/AddUserGroup/
ERROR 2023-05-14 05:32:59,909 log 14164 17200 Internal Server Error: /group/AddUserGroup/
Traceback (most recent call last):
  File "C:\Python311\Lib\site-packages\django\core\handlers\exception.py", line 56, in inner
    response = get_response(request)
               ^^^^^^^^^^^^^^^^^^^^^
  File "C:\Python311\Lib\site-packages\django\core\handlers\base.py", line 197, in _get_response
    response = wrapped_callback(request, *callback_args, **callback_kwargs)
               ^^^^^^^^^^^^^^^^^^^^^^^^^^^^^^^^^^^^^^^^^^^^^^^^^^^^^^^^^^^^
  File "C:\Python311\Lib\site-packages\django\views\decorators\csrf.py", line 55, in wrapped_view
    return view_func(*args, **kwargs)
           ^^^^^^^^^^^^^^^^^^^^^^^^^^
  File "C:\Python311\Lib\site-packages\django\views\generic\base.py", line 103, in view
    return self.dispatch(request, *args, **kwargs)
           ^^^^^^^^^^^^^^^^^^^^^^^^^^^^^^^^^^^^^^^
  File "C:\Python311\Lib\site-packages\rest_framework\views.py", line 509, in dispatch
    response = self.handle_exception(exc)
               ^^^^^^^^^^^^^^^^^^^^^^^^^^
  File "C:\Python311\Lib\site-packages\rest_framework\views.py", line 469, in handle_exception
    self.raise_uncaught_exception(exc)
  File "C:\Python311\Lib\site-packages\rest_framework\views.py", line 480, in raise_uncaught_exception
    raise exc
  File "C:\Python311\Lib\site-packages\rest_framework\views.py", line 497, in dispatch
    self.initial(request, *args, **kwargs)
  File "C:\Python311\Lib\site-packages\rest_framework\views.py", line 415, in initial
    self.check_permissions(request)
  File "C:\Python311\Lib\site-packages\rest_framework\views.py", line 332, in check_permissions
    if not permission.has_permission(request, self):
           ^^^^^^^^^^^^^^^^^^^^^^^^^^^^^^^^^^^^^^^^
  File "C:\Users\Maryam\Documents\GitHub\Enigma_BackEnd\Enigma\Group\permissions.py", line 10, in has_permission
    members = Members.objects.filter(userID=request.user, groupID=request.data['groupID'])
                                                                  ~~~~~~~~~~~~^^^^^^^^^^^
KeyError: 'groupID'
ERROR 2023-05-14 05:34:50,915 log 15080 2228 Internal Server Error: /group/AddUserGroup/
Traceback (most recent call last):
  File "C:\Python311\Lib\site-packages\django\core\handlers\exception.py", line 56, in inner
    response = get_response(request)
               ^^^^^^^^^^^^^^^^^^^^^
  File "C:\Python311\Lib\site-packages\django\core\handlers\base.py", line 197, in _get_response
    response = wrapped_callback(request, *callback_args, **callback_kwargs)
               ^^^^^^^^^^^^^^^^^^^^^^^^^^^^^^^^^^^^^^^^^^^^^^^^^^^^^^^^^^^^
  File "C:\Python311\Lib\site-packages\django\views\decorators\csrf.py", line 55, in wrapped_view
    return view_func(*args, **kwargs)
           ^^^^^^^^^^^^^^^^^^^^^^^^^^
  File "C:\Python311\Lib\site-packages\django\views\generic\base.py", line 103, in view
    return self.dispatch(request, *args, **kwargs)
           ^^^^^^^^^^^^^^^^^^^^^^^^^^^^^^^^^^^^^^^
  File "C:\Python311\Lib\site-packages\rest_framework\views.py", line 509, in dispatch
    response = self.handle_exception(exc)
               ^^^^^^^^^^^^^^^^^^^^^^^^^^
  File "C:\Python311\Lib\site-packages\rest_framework\views.py", line 469, in handle_exception
    self.raise_uncaught_exception(exc)
  File "C:\Python311\Lib\site-packages\rest_framework\views.py", line 480, in raise_uncaught_exception
    raise exc
  File "C:\Python311\Lib\site-packages\rest_framework\views.py", line 497, in dispatch
    self.initial(request, *args, **kwargs)
  File "C:\Python311\Lib\site-packages\rest_framework\views.py", line 415, in initial
    self.check_permissions(request)
  File "C:\Python311\Lib\site-packages\rest_framework\views.py", line 332, in check_permissions
    if not permission.has_permission(request, self):
           ^^^^^^^^^^^^^^^^^^^^^^^^^^^^^^^^^^^^^^^^
  File "C:\Users\Maryam\Documents\GitHub\Enigma_BackEnd\Enigma\Group\permissions.py", line 10, in has_permission
    members = Members.objects.filter(userID=request.user, groupID=request.data['groupID'])
                                                                  ~~~~~~~~~~~~^^^^^^^^^^^
KeyError: 'groupID'
ERROR 2023-05-14 05:35:55,986 log 13784 14472 Internal Server Error: /group/AddUserGroup/
Traceback (most recent call last):
  File "C:\Python311\Lib\site-packages\django\core\handlers\exception.py", line 56, in inner
    response = get_response(request)
               ^^^^^^^^^^^^^^^^^^^^^
  File "C:\Python311\Lib\site-packages\django\core\handlers\base.py", line 197, in _get_response
    response = wrapped_callback(request, *callback_args, **callback_kwargs)
               ^^^^^^^^^^^^^^^^^^^^^^^^^^^^^^^^^^^^^^^^^^^^^^^^^^^^^^^^^^^^
  File "C:\Python311\Lib\site-packages\django\views\decorators\csrf.py", line 55, in wrapped_view
    return view_func(*args, **kwargs)
           ^^^^^^^^^^^^^^^^^^^^^^^^^^
  File "C:\Python311\Lib\site-packages\django\views\generic\base.py", line 103, in view
    return self.dispatch(request, *args, **kwargs)
           ^^^^^^^^^^^^^^^^^^^^^^^^^^^^^^^^^^^^^^^
  File "C:\Python311\Lib\site-packages\rest_framework\views.py", line 509, in dispatch
    response = self.handle_exception(exc)
               ^^^^^^^^^^^^^^^^^^^^^^^^^^
  File "C:\Python311\Lib\site-packages\rest_framework\views.py", line 469, in handle_exception
    self.raise_uncaught_exception(exc)
  File "C:\Python311\Lib\site-packages\rest_framework\views.py", line 480, in raise_uncaught_exception
    raise exc
  File "C:\Python311\Lib\site-packages\rest_framework\views.py", line 497, in dispatch
    self.initial(request, *args, **kwargs)
  File "C:\Python311\Lib\site-packages\rest_framework\views.py", line 415, in initial
    self.check_permissions(request)
  File "C:\Python311\Lib\site-packages\rest_framework\views.py", line 332, in check_permissions
    if not permission.has_permission(request, self):
           ^^^^^^^^^^^^^^^^^^^^^^^^^^^^^^^^^^^^^^^^
  File "C:\Users\Maryam\Documents\GitHub\Enigma_BackEnd\Enigma\Group\permissions.py", line 10, in has_permission
    members = Members.objects.filter(userID=request.user, groupID=request.data['groupID'])
                                                                  ~~~~~~~~~~~~^^^^^^^^^^^
KeyError: 'groupID'
ERROR 2023-05-14 05:36:16,694 log 9172 14428 Internal Server Error: /group/AddUserGroup/
Traceback (most recent call last):
  File "C:\Python311\Lib\site-packages\django\core\handlers\exception.py", line 56, in inner
    response = get_response(request)
               ^^^^^^^^^^^^^^^^^^^^^
  File "C:\Python311\Lib\site-packages\django\core\handlers\base.py", line 197, in _get_response
    response = wrapped_callback(request, *callback_args, **callback_kwargs)
               ^^^^^^^^^^^^^^^^^^^^^^^^^^^^^^^^^^^^^^^^^^^^^^^^^^^^^^^^^^^^
  File "C:\Python311\Lib\site-packages\django\views\decorators\csrf.py", line 55, in wrapped_view
    return view_func(*args, **kwargs)
           ^^^^^^^^^^^^^^^^^^^^^^^^^^
  File "C:\Python311\Lib\site-packages\django\views\generic\base.py", line 103, in view
    return self.dispatch(request, *args, **kwargs)
           ^^^^^^^^^^^^^^^^^^^^^^^^^^^^^^^^^^^^^^^
  File "C:\Python311\Lib\site-packages\rest_framework\views.py", line 509, in dispatch
    response = self.handle_exception(exc)
               ^^^^^^^^^^^^^^^^^^^^^^^^^^
  File "C:\Python311\Lib\site-packages\rest_framework\views.py", line 469, in handle_exception
    self.raise_uncaught_exception(exc)
  File "C:\Python311\Lib\site-packages\rest_framework\views.py", line 480, in raise_uncaught_exception
    raise exc
  File "C:\Python311\Lib\site-packages\rest_framework\views.py", line 497, in dispatch
    self.initial(request, *args, **kwargs)
  File "C:\Python311\Lib\site-packages\rest_framework\views.py", line 415, in initial
    self.check_permissions(request)
  File "C:\Python311\Lib\site-packages\rest_framework\views.py", line 332, in check_permissions
    if not permission.has_permission(request, self):
           ^^^^^^^^^^^^^^^^^^^^^^^^^^^^^^^^^^^^^^^^
  File "C:\Users\Maryam\Documents\GitHub\Enigma_BackEnd\Enigma\Group\permissions.py", line 10, in has_permission
    members = Members.objects.filter(userID=request.user, groupID=request.data['groupID'])
                                                                  ~~~~~~~~~~~~^^^^^^^^^^^
KeyError: 'groupID'
ERROR 2023-05-14 05:36:57,901 log 9760 11652 Internal Server Error: /group/AddUserGroup/
Traceback (most recent call last):
  File "C:\Python311\Lib\site-packages\django\core\handlers\exception.py", line 56, in inner
    response = get_response(request)
               ^^^^^^^^^^^^^^^^^^^^^
  File "C:\Python311\Lib\site-packages\django\core\handlers\base.py", line 197, in _get_response
    response = wrapped_callback(request, *callback_args, **callback_kwargs)
               ^^^^^^^^^^^^^^^^^^^^^^^^^^^^^^^^^^^^^^^^^^^^^^^^^^^^^^^^^^^^
  File "C:\Python311\Lib\site-packages\django\views\decorators\csrf.py", line 55, in wrapped_view
    return view_func(*args, **kwargs)
           ^^^^^^^^^^^^^^^^^^^^^^^^^^
  File "C:\Python311\Lib\site-packages\django\views\generic\base.py", line 103, in view
    return self.dispatch(request, *args, **kwargs)
           ^^^^^^^^^^^^^^^^^^^^^^^^^^^^^^^^^^^^^^^
  File "C:\Python311\Lib\site-packages\rest_framework\views.py", line 509, in dispatch
    response = self.handle_exception(exc)
               ^^^^^^^^^^^^^^^^^^^^^^^^^^
  File "C:\Python311\Lib\site-packages\rest_framework\views.py", line 469, in handle_exception
    self.raise_uncaught_exception(exc)
  File "C:\Python311\Lib\site-packages\rest_framework\views.py", line 480, in raise_uncaught_exception
    raise exc
  File "C:\Python311\Lib\site-packages\rest_framework\views.py", line 497, in dispatch
    self.initial(request, *args, **kwargs)
  File "C:\Python311\Lib\site-packages\rest_framework\views.py", line 415, in initial
    self.check_permissions(request)
  File "C:\Python311\Lib\site-packages\rest_framework\views.py", line 332, in check_permissions
    if not permission.has_permission(request, self):
           ^^^^^^^^^^^^^^^^^^^^^^^^^^^^^^^^^^^^^^^^
  File "C:\Users\Maryam\Documents\GitHub\Enigma_BackEnd\Enigma\Group\permissions.py", line 10, in has_permission
    members = Members.objects.filter(userID=request.user, groupID=request.data['groupID'])
                                                                  ~~~~~~~~~~~~^^^^^^^^^^^
KeyError: 'groupID'
ERROR 2023-05-14 05:38:42,031 log 12500 10796 Internal Server Error: /group/AddUserGroup/
Traceback (most recent call last):
  File "C:\Python311\Lib\site-packages\django\core\handlers\exception.py", line 56, in inner
    response = get_response(request)
               ^^^^^^^^^^^^^^^^^^^^^
  File "C:\Python311\Lib\site-packages\django\core\handlers\base.py", line 197, in _get_response
    response = wrapped_callback(request, *callback_args, **callback_kwargs)
               ^^^^^^^^^^^^^^^^^^^^^^^^^^^^^^^^^^^^^^^^^^^^^^^^^^^^^^^^^^^^
  File "C:\Python311\Lib\site-packages\django\views\decorators\csrf.py", line 55, in wrapped_view
    return view_func(*args, **kwargs)
           ^^^^^^^^^^^^^^^^^^^^^^^^^^
  File "C:\Python311\Lib\site-packages\django\views\generic\base.py", line 103, in view
    return self.dispatch(request, *args, **kwargs)
           ^^^^^^^^^^^^^^^^^^^^^^^^^^^^^^^^^^^^^^^
  File "C:\Python311\Lib\site-packages\rest_framework\views.py", line 509, in dispatch
    response = self.handle_exception(exc)
               ^^^^^^^^^^^^^^^^^^^^^^^^^^
  File "C:\Python311\Lib\site-packages\rest_framework\views.py", line 469, in handle_exception
    self.raise_uncaught_exception(exc)
  File "C:\Python311\Lib\site-packages\rest_framework\views.py", line 480, in raise_uncaught_exception
    raise exc
  File "C:\Python311\Lib\site-packages\rest_framework\views.py", line 497, in dispatch
    self.initial(request, *args, **kwargs)
  File "C:\Python311\Lib\site-packages\rest_framework\views.py", line 415, in initial
    self.check_permissions(request)
  File "C:\Python311\Lib\site-packages\rest_framework\views.py", line 332, in check_permissions
    if not permission.has_permission(request, self):
           ^^^^^^^^^^^^^^^^^^^^^^^^^^^^^^^^^^^^^^^^
  File "C:\Users\Maryam\Documents\GitHub\Enigma_BackEnd\Enigma\Group\permissions.py", line 10, in has_permission
    members = Members.objects.filter(userID=request.user, groupID=request.data['groupID'])
                                                                  ~~~~~~~~~~~~^^^^^^^^^^^
KeyError: 'groupID'
WARNING 2023-05-14 05:40:39,303 log 7152 4832 Forbidden: /group/AddUserGroup/
WARNING 2023-05-14 05:44:13,446 log 9288 13716 Forbidden: /group/AddUserGroup/
WARNING 2023-05-14 05:45:10,814 log 12084 11616 Forbidden: /group/AddUserGroup/
WARNING 2023-05-14 05:50:07,448 log 12588 10220 Not Found: /group/AddUserGroup/
WARNING 2023-05-14 05:53:24,905 log 3332 15896 Not Found: /group/AddUserGroup/
WARNING 2023-05-14 05:54:53,591 log 4544 6108 Not Found: /group/AddUserGroup/
WARNING 2023-05-14 06:03:22,454 log 8700 4504 Not Found: /group/AddUserGroup/
WARNING 2023-05-14 06:05:16,565 log 2232 3636 Forbidden: /group/AddUserGroup/
WARNING 2023-05-14 06:09:36,497 log 8440 9768 Not Found: /group/AddUserGroup/
WARNING 2023-05-14 06:10:10,814 log 15676 14068 Not Found: /group/AddUserGroup/
WARNING 2023-05-14 06:10:49,818 log 17516 10844 Not Found: /group/AddUserGroup/
WARNING 2023-05-14 06:15:54,968 log 1776 17584 Not Found: /group/AddUserGroup/
ERROR 2023-05-14 06:15:54,989 log 1776 17584 Internal Server Error: /group/AddUserGroup/
Traceback (most recent call last):
  File "C:\Python311\Lib\site-packages\django\core\handlers\exception.py", line 56, in inner
    response = get_response(request)
               ^^^^^^^^^^^^^^^^^^^^^
  File "C:\Python311\Lib\site-packages\django\core\handlers\base.py", line 197, in _get_response
    response = wrapped_callback(request, *callback_args, **callback_kwargs)
               ^^^^^^^^^^^^^^^^^^^^^^^^^^^^^^^^^^^^^^^^^^^^^^^^^^^^^^^^^^^^
  File "C:\Python311\Lib\site-packages\django\views\decorators\csrf.py", line 55, in wrapped_view
    return view_func(*args, **kwargs)
           ^^^^^^^^^^^^^^^^^^^^^^^^^^
  File "C:\Python311\Lib\site-packages\django\views\generic\base.py", line 103, in view
    return self.dispatch(request, *args, **kwargs)
           ^^^^^^^^^^^^^^^^^^^^^^^^^^^^^^^^^^^^^^^
  File "C:\Python311\Lib\site-packages\rest_framework\views.py", line 509, in dispatch
    response = self.handle_exception(exc)
               ^^^^^^^^^^^^^^^^^^^^^^^^^^
  File "C:\Python311\Lib\site-packages\rest_framework\views.py", line 469, in handle_exception
    self.raise_uncaught_exception(exc)
  File "C:\Python311\Lib\site-packages\rest_framework\views.py", line 480, in raise_uncaught_exception
    raise exc
  File "C:\Python311\Lib\site-packages\rest_framework\views.py", line 506, in dispatch
    response = handler(request, *args, **kwargs)
               ^^^^^^^^^^^^^^^^^^^^^^^^^^^^^^^^^
  File "C:\Users\Maryam\Documents\GitHub\Enigma_BackEnd\Enigma\Group\views.py", line 39, in post
    for emailUser in data['emails']:
                     ~~~~^^^^^^^^^^
KeyError: 'emails'
WARNING 2023-05-14 06:19:04,384 log 1972 9420 Not Found: /group/AddUserGroup/
ERROR 2023-05-14 06:19:04,404 log 1972 9420 Internal Server Error: /group/AddUserGroup/
Traceback (most recent call last):
  File "C:\Python311\Lib\site-packages\django\core\handlers\exception.py", line 56, in inner
    response = get_response(request)
               ^^^^^^^^^^^^^^^^^^^^^
  File "C:\Python311\Lib\site-packages\django\core\handlers\base.py", line 197, in _get_response
    response = wrapped_callback(request, *callback_args, **callback_kwargs)
               ^^^^^^^^^^^^^^^^^^^^^^^^^^^^^^^^^^^^^^^^^^^^^^^^^^^^^^^^^^^^
  File "C:\Python311\Lib\site-packages\django\views\decorators\csrf.py", line 55, in wrapped_view
    return view_func(*args, **kwargs)
           ^^^^^^^^^^^^^^^^^^^^^^^^^^
  File "C:\Python311\Lib\site-packages\django\views\generic\base.py", line 103, in view
    return self.dispatch(request, *args, **kwargs)
           ^^^^^^^^^^^^^^^^^^^^^^^^^^^^^^^^^^^^^^^
  File "C:\Python311\Lib\site-packages\rest_framework\views.py", line 509, in dispatch
    response = self.handle_exception(exc)
               ^^^^^^^^^^^^^^^^^^^^^^^^^^
  File "C:\Python311\Lib\site-packages\rest_framework\views.py", line 469, in handle_exception
    self.raise_uncaught_exception(exc)
  File "C:\Python311\Lib\site-packages\rest_framework\views.py", line 480, in raise_uncaught_exception
    raise exc
  File "C:\Python311\Lib\site-packages\rest_framework\views.py", line 506, in dispatch
    response = handler(request, *args, **kwargs)
               ^^^^^^^^^^^^^^^^^^^^^^^^^^^^^^^^^
  File "C:\Users\Maryam\Documents\GitHub\Enigma_BackEnd\Enigma\Group\views.py", line 39, in post
    for emailUser in data['emails']:
                     ~~~~^^^^^^^^^^
KeyError: 'emails'
WARNING 2023-05-14 06:19:31,750 log 8760 13012 Not Found: /group/AddUserGroup/
ERROR 2023-05-14 06:19:31,769 log 8760 13012 Internal Server Error: /group/AddUserGroup/
Traceback (most recent call last):
  File "C:\Python311\Lib\site-packages\django\core\handlers\exception.py", line 56, in inner
    response = get_response(request)
               ^^^^^^^^^^^^^^^^^^^^^
  File "C:\Python311\Lib\site-packages\django\core\handlers\base.py", line 197, in _get_response
    response = wrapped_callback(request, *callback_args, **callback_kwargs)
               ^^^^^^^^^^^^^^^^^^^^^^^^^^^^^^^^^^^^^^^^^^^^^^^^^^^^^^^^^^^^
  File "C:\Python311\Lib\site-packages\django\views\decorators\csrf.py", line 55, in wrapped_view
    return view_func(*args, **kwargs)
           ^^^^^^^^^^^^^^^^^^^^^^^^^^
  File "C:\Python311\Lib\site-packages\django\views\generic\base.py", line 103, in view
    return self.dispatch(request, *args, **kwargs)
           ^^^^^^^^^^^^^^^^^^^^^^^^^^^^^^^^^^^^^^^
  File "C:\Python311\Lib\site-packages\rest_framework\views.py", line 509, in dispatch
    response = self.handle_exception(exc)
               ^^^^^^^^^^^^^^^^^^^^^^^^^^
  File "C:\Python311\Lib\site-packages\rest_framework\views.py", line 469, in handle_exception
    self.raise_uncaught_exception(exc)
  File "C:\Python311\Lib\site-packages\rest_framework\views.py", line 480, in raise_uncaught_exception
    raise exc
  File "C:\Python311\Lib\site-packages\rest_framework\views.py", line 506, in dispatch
    response = handler(request, *args, **kwargs)
               ^^^^^^^^^^^^^^^^^^^^^^^^^^^^^^^^^
  File "C:\Users\Maryam\Documents\GitHub\Enigma_BackEnd\Enigma\Group\views.py", line 39, in post
    for emailUser in data['emails']:
                     ~~~~^^^^^^^^^^
KeyError: 'emails'
WARNING 2023-05-14 06:19:57,043 log 10816 9628 Not Found: /group/AddUserGroup/
ERROR 2023-05-14 06:19:57,063 log 10816 9628 Internal Server Error: /group/AddUserGroup/
Traceback (most recent call last):
  File "C:\Python311\Lib\site-packages\django\core\handlers\exception.py", line 56, in inner
    response = get_response(request)
               ^^^^^^^^^^^^^^^^^^^^^
  File "C:\Python311\Lib\site-packages\django\core\handlers\base.py", line 197, in _get_response
    response = wrapped_callback(request, *callback_args, **callback_kwargs)
               ^^^^^^^^^^^^^^^^^^^^^^^^^^^^^^^^^^^^^^^^^^^^^^^^^^^^^^^^^^^^
  File "C:\Python311\Lib\site-packages\django\views\decorators\csrf.py", line 55, in wrapped_view
    return view_func(*args, **kwargs)
           ^^^^^^^^^^^^^^^^^^^^^^^^^^
  File "C:\Python311\Lib\site-packages\django\views\generic\base.py", line 103, in view
    return self.dispatch(request, *args, **kwargs)
           ^^^^^^^^^^^^^^^^^^^^^^^^^^^^^^^^^^^^^^^
  File "C:\Python311\Lib\site-packages\rest_framework\views.py", line 509, in dispatch
    response = self.handle_exception(exc)
               ^^^^^^^^^^^^^^^^^^^^^^^^^^
  File "C:\Python311\Lib\site-packages\rest_framework\views.py", line 469, in handle_exception
    self.raise_uncaught_exception(exc)
  File "C:\Python311\Lib\site-packages\rest_framework\views.py", line 480, in raise_uncaught_exception
    raise exc
  File "C:\Python311\Lib\site-packages\rest_framework\views.py", line 506, in dispatch
    response = handler(request, *args, **kwargs)
               ^^^^^^^^^^^^^^^^^^^^^^^^^^^^^^^^^
  File "C:\Users\Maryam\Documents\GitHub\Enigma_BackEnd\Enigma\Group\views.py", line 39, in post
    for emailUser in data['emails']:
                     ~~~~^^^^^^^^^^
KeyError: 'emails'
WARNING 2023-05-14 06:20:23,088 log 4308 10936 Not Found: /group/AddUserGroup/
ERROR 2023-05-14 06:20:23,110 log 4308 10936 Internal Server Error: /group/AddUserGroup/
Traceback (most recent call last):
  File "C:\Python311\Lib\site-packages\django\core\handlers\exception.py", line 56, in inner
    response = get_response(request)
               ^^^^^^^^^^^^^^^^^^^^^
  File "C:\Python311\Lib\site-packages\django\core\handlers\base.py", line 197, in _get_response
    response = wrapped_callback(request, *callback_args, **callback_kwargs)
               ^^^^^^^^^^^^^^^^^^^^^^^^^^^^^^^^^^^^^^^^^^^^^^^^^^^^^^^^^^^^
  File "C:\Python311\Lib\site-packages\django\views\decorators\csrf.py", line 55, in wrapped_view
    return view_func(*args, **kwargs)
           ^^^^^^^^^^^^^^^^^^^^^^^^^^
  File "C:\Python311\Lib\site-packages\django\views\generic\base.py", line 103, in view
    return self.dispatch(request, *args, **kwargs)
           ^^^^^^^^^^^^^^^^^^^^^^^^^^^^^^^^^^^^^^^
  File "C:\Python311\Lib\site-packages\rest_framework\views.py", line 509, in dispatch
    response = self.handle_exception(exc)
               ^^^^^^^^^^^^^^^^^^^^^^^^^^
  File "C:\Python311\Lib\site-packages\rest_framework\views.py", line 469, in handle_exception
    self.raise_uncaught_exception(exc)
  File "C:\Python311\Lib\site-packages\rest_framework\views.py", line 480, in raise_uncaught_exception
    raise exc
  File "C:\Python311\Lib\site-packages\rest_framework\views.py", line 506, in dispatch
    response = handler(request, *args, **kwargs)
               ^^^^^^^^^^^^^^^^^^^^^^^^^^^^^^^^^
  File "C:\Users\Maryam\Documents\GitHub\Enigma_BackEnd\Enigma\Group\views.py", line 39, in post
    for emailUser in data['emails']:
                     ~~~~^^^^^^^^^^
KeyError: 'emails'
WARNING 2023-05-14 06:22:28,572 log 844 12556 Not Found: /group/AddUserGroup/
WARNING 2023-05-14 06:26:09,999 log 13816 10112 Not Found: /group/AddUserGroup/
WARNING 2023-05-14 06:26:10,017 log 13816 10112 Not Found: /group/AddUserGroup/
WARNING 2023-05-14 06:27:48,209 log 1796 1104 Not Found: /group/AddUserGroup/
WARNING 2023-05-14 07:23:03,694 log 1396 15248 Not Found: /group/AddUserGroup/
WARNING 2023-05-14 07:23:03,716 log 1396 15248 Not Found: /group/AddUserGroup/
WARNING 2023-05-14 07:23:26,510 log 10436 14744 Not Found: /group/AddUserGroup/
WARNING 2023-05-14 07:23:26,515 log 10436 14744 Forbidden: /group/AddUserGroup/
WARNING 2023-05-14 07:23:26,536 log 10436 14744 Not Found: /group/AddUserGroup/
WARNING 2023-05-14 07:45:12,174 log 6768 16656 Not Found: /group/AddUserGroup/
WARNING 2023-05-14 07:45:12,181 log 6768 16656 Forbidden: /group/AddUserGroup/
WARNING 2023-05-14 07:45:12,204 log 6768 16656 Not Found: /group/AddUserGroup/
WARNING 2023-05-14 07:47:05,774 log 11640 15652 Not Found: /group/AddUserGroup/
WARNING 2023-05-14 07:47:05,785 log 11640 15652 Forbidden: /group/AddUserGroup/
WARNING 2023-05-14 07:47:05,814 log 11640 15652 Not Found: /group/AddUserGroup/
ERROR 2023-05-14 07:48:53,089 log 18008 6256 Internal Server Error: /group/AddUserGroup/
Traceback (most recent call last):
  File "C:\Python311\Lib\site-packages\django\core\handlers\exception.py", line 56, in inner
    response = get_response(request)
               ^^^^^^^^^^^^^^^^^^^^^
  File "C:\Python311\Lib\site-packages\django\core\handlers\base.py", line 197, in _get_response
    response = wrapped_callback(request, *callback_args, **callback_kwargs)
               ^^^^^^^^^^^^^^^^^^^^^^^^^^^^^^^^^^^^^^^^^^^^^^^^^^^^^^^^^^^^
  File "C:\Python311\Lib\site-packages\django\views\decorators\csrf.py", line 55, in wrapped_view
    return view_func(*args, **kwargs)
           ^^^^^^^^^^^^^^^^^^^^^^^^^^
  File "C:\Python311\Lib\site-packages\django\views\generic\base.py", line 103, in view
    return self.dispatch(request, *args, **kwargs)
           ^^^^^^^^^^^^^^^^^^^^^^^^^^^^^^^^^^^^^^^
  File "C:\Python311\Lib\site-packages\rest_framework\views.py", line 509, in dispatch
    response = self.handle_exception(exc)
               ^^^^^^^^^^^^^^^^^^^^^^^^^^
  File "C:\Python311\Lib\site-packages\rest_framework\views.py", line 469, in handle_exception
    self.raise_uncaught_exception(exc)
  File "C:\Python311\Lib\site-packages\rest_framework\views.py", line 480, in raise_uncaught_exception
    raise exc
  File "C:\Python311\Lib\site-packages\rest_framework\views.py", line 506, in dispatch
    response = handler(request, *args, **kwargs)
               ^^^^^^^^^^^^^^^^^^^^^^^^^^^^^^^^^
  File "C:\Users\Maryam\Documents\GitHub\Enigma_BackEnd\Enigma\Group\views.py", line 45, in post
    if not Members.objects.get(groupID=group, userID=user):
           ^^^^^^^^^^^^^^^^^^^^^^^^^^^^^^^^^^^^^^^^^^^^^^^
  File "C:\Python311\Lib\site-packages\django\db\models\manager.py", line 85, in manager_method
    return getattr(self.get_queryset(), name)(*args, **kwargs)
           ^^^^^^^^^^^^^^^^^^^^^^^^^^^^^^^^^^^^^^^^^^^^^^^^^^^
  File "C:\Python311\Lib\site-packages\django\db\models\query.py", line 650, in get
    raise self.model.DoesNotExist(
Group.models.Members.DoesNotExist: Members matching query does not exist.
WARNING 2023-05-14 07:48:53,104 log 18008 6256 Forbidden: /group/AddUserGroup/
ERROR 2023-05-14 07:48:53,112 log 18008 6256 Internal Server Error: /group/AddUserGroup/
Traceback (most recent call last):
  File "C:\Python311\Lib\site-packages\django\core\handlers\exception.py", line 56, in inner
    response = get_response(request)
               ^^^^^^^^^^^^^^^^^^^^^
  File "C:\Python311\Lib\site-packages\django\core\handlers\base.py", line 197, in _get_response
    response = wrapped_callback(request, *callback_args, **callback_kwargs)
               ^^^^^^^^^^^^^^^^^^^^^^^^^^^^^^^^^^^^^^^^^^^^^^^^^^^^^^^^^^^^
  File "C:\Python311\Lib\site-packages\django\views\decorators\csrf.py", line 55, in wrapped_view
    return view_func(*args, **kwargs)
           ^^^^^^^^^^^^^^^^^^^^^^^^^^
  File "C:\Python311\Lib\site-packages\django\views\generic\base.py", line 103, in view
    return self.dispatch(request, *args, **kwargs)
           ^^^^^^^^^^^^^^^^^^^^^^^^^^^^^^^^^^^^^^^
  File "C:\Python311\Lib\site-packages\rest_framework\views.py", line 509, in dispatch
    response = self.handle_exception(exc)
               ^^^^^^^^^^^^^^^^^^^^^^^^^^
  File "C:\Python311\Lib\site-packages\rest_framework\views.py", line 469, in handle_exception
    self.raise_uncaught_exception(exc)
  File "C:\Python311\Lib\site-packages\rest_framework\views.py", line 480, in raise_uncaught_exception
    raise exc
  File "C:\Python311\Lib\site-packages\rest_framework\views.py", line 506, in dispatch
    response = handler(request, *args, **kwargs)
               ^^^^^^^^^^^^^^^^^^^^^^^^^^^^^^^^^
  File "C:\Users\Maryam\Documents\GitHub\Enigma_BackEnd\Enigma\Group\views.py", line 45, in post
    if not Members.objects.get(groupID=group, userID=user):
           ^^^^^^^^^^^^^^^^^^^^^^^^^^^^^^^^^^^^^^^^^^^^^^^
  File "C:\Python311\Lib\site-packages\django\db\models\manager.py", line 85, in manager_method
    return getattr(self.get_queryset(), name)(*args, **kwargs)
           ^^^^^^^^^^^^^^^^^^^^^^^^^^^^^^^^^^^^^^^^^^^^^^^^^^^
  File "C:\Python311\Lib\site-packages\django\db\models\query.py", line 650, in get
    raise self.model.DoesNotExist(
Group.models.Members.DoesNotExist: Members matching query does not exist.
ERROR 2023-05-14 07:48:53,124 log 18008 6256 Internal Server Error: /group/AddUserGroup/
Traceback (most recent call last):
  File "C:\Python311\Lib\site-packages\django\core\handlers\exception.py", line 56, in inner
    response = get_response(request)
               ^^^^^^^^^^^^^^^^^^^^^
  File "C:\Python311\Lib\site-packages\django\core\handlers\base.py", line 197, in _get_response
    response = wrapped_callback(request, *callback_args, **callback_kwargs)
               ^^^^^^^^^^^^^^^^^^^^^^^^^^^^^^^^^^^^^^^^^^^^^^^^^^^^^^^^^^^^
  File "C:\Python311\Lib\site-packages\django\views\decorators\csrf.py", line 55, in wrapped_view
    return view_func(*args, **kwargs)
           ^^^^^^^^^^^^^^^^^^^^^^^^^^
  File "C:\Python311\Lib\site-packages\django\views\generic\base.py", line 103, in view
    return self.dispatch(request, *args, **kwargs)
           ^^^^^^^^^^^^^^^^^^^^^^^^^^^^^^^^^^^^^^^
  File "C:\Python311\Lib\site-packages\rest_framework\views.py", line 509, in dispatch
    response = self.handle_exception(exc)
               ^^^^^^^^^^^^^^^^^^^^^^^^^^
  File "C:\Python311\Lib\site-packages\rest_framework\views.py", line 469, in handle_exception
    self.raise_uncaught_exception(exc)
  File "C:\Python311\Lib\site-packages\rest_framework\views.py", line 480, in raise_uncaught_exception
    raise exc
  File "C:\Python311\Lib\site-packages\rest_framework\views.py", line 506, in dispatch
    response = handler(request, *args, **kwargs)
               ^^^^^^^^^^^^^^^^^^^^^^^^^^^^^^^^^
  File "C:\Users\Maryam\Documents\GitHub\Enigma_BackEnd\Enigma\Group\views.py", line 45, in post
    if not Members.objects.get(groupID=group, userID=user):
           ^^^^^^^^^^^^^^^^^^^^^^^^^^^^^^^^^^^^^^^^^^^^^^^
  File "C:\Python311\Lib\site-packages\django\db\models\manager.py", line 85, in manager_method
    return getattr(self.get_queryset(), name)(*args, **kwargs)
           ^^^^^^^^^^^^^^^^^^^^^^^^^^^^^^^^^^^^^^^^^^^^^^^^^^^
  File "C:\Python311\Lib\site-packages\django\db\models\query.py", line 650, in get
    raise self.model.DoesNotExist(
Group.models.Members.DoesNotExist: Members matching query does not exist.
ERROR 2023-05-14 07:49:30,828 log 18400 8004 Internal Server Error: /group/AddUserGroup/
Traceback (most recent call last):
  File "C:\Python311\Lib\site-packages\django\core\handlers\exception.py", line 56, in inner
    response = get_response(request)
               ^^^^^^^^^^^^^^^^^^^^^
  File "C:\Python311\Lib\site-packages\django\core\handlers\base.py", line 197, in _get_response
    response = wrapped_callback(request, *callback_args, **callback_kwargs)
               ^^^^^^^^^^^^^^^^^^^^^^^^^^^^^^^^^^^^^^^^^^^^^^^^^^^^^^^^^^^^
  File "C:\Python311\Lib\site-packages\django\views\decorators\csrf.py", line 55, in wrapped_view
    return view_func(*args, **kwargs)
           ^^^^^^^^^^^^^^^^^^^^^^^^^^
  File "C:\Python311\Lib\site-packages\django\views\generic\base.py", line 103, in view
    return self.dispatch(request, *args, **kwargs)
           ^^^^^^^^^^^^^^^^^^^^^^^^^^^^^^^^^^^^^^^
  File "C:\Python311\Lib\site-packages\rest_framework\views.py", line 509, in dispatch
    response = self.handle_exception(exc)
               ^^^^^^^^^^^^^^^^^^^^^^^^^^
  File "C:\Python311\Lib\site-packages\rest_framework\views.py", line 469, in handle_exception
    self.raise_uncaught_exception(exc)
  File "C:\Python311\Lib\site-packages\rest_framework\views.py", line 480, in raise_uncaught_exception
    raise exc
  File "C:\Python311\Lib\site-packages\rest_framework\views.py", line 506, in dispatch
    response = handler(request, *args, **kwargs)
               ^^^^^^^^^^^^^^^^^^^^^^^^^^^^^^^^^
  File "C:\Users\Maryam\Documents\GitHub\Enigma_BackEnd\Enigma\Group\views.py", line 45, in post
    if not Members.objects.get(groupID=group, userID=user):
           ^^^^^^^^^^^^^^^^^^^^^^^^^^^^^^^^^^^^^^^^^^^^^^^
  File "C:\Python311\Lib\site-packages\django\db\models\manager.py", line 85, in manager_method
    return getattr(self.get_queryset(), name)(*args, **kwargs)
           ^^^^^^^^^^^^^^^^^^^^^^^^^^^^^^^^^^^^^^^^^^^^^^^^^^^
  File "C:\Python311\Lib\site-packages\django\db\models\query.py", line 650, in get
    raise self.model.DoesNotExist(
Group.models.Members.DoesNotExist: Members matching query does not exist.
WARNING 2023-05-14 07:49:30,842 log 18400 8004 Forbidden: /group/AddUserGroup/
ERROR 2023-05-14 07:49:30,852 log 18400 8004 Internal Server Error: /group/AddUserGroup/
Traceback (most recent call last):
  File "C:\Python311\Lib\site-packages\django\core\handlers\exception.py", line 56, in inner
    response = get_response(request)
               ^^^^^^^^^^^^^^^^^^^^^
  File "C:\Python311\Lib\site-packages\django\core\handlers\base.py", line 197, in _get_response
    response = wrapped_callback(request, *callback_args, **callback_kwargs)
               ^^^^^^^^^^^^^^^^^^^^^^^^^^^^^^^^^^^^^^^^^^^^^^^^^^^^^^^^^^^^
  File "C:\Python311\Lib\site-packages\django\views\decorators\csrf.py", line 55, in wrapped_view
    return view_func(*args, **kwargs)
           ^^^^^^^^^^^^^^^^^^^^^^^^^^
  File "C:\Python311\Lib\site-packages\django\views\generic\base.py", line 103, in view
    return self.dispatch(request, *args, **kwargs)
           ^^^^^^^^^^^^^^^^^^^^^^^^^^^^^^^^^^^^^^^
  File "C:\Python311\Lib\site-packages\rest_framework\views.py", line 509, in dispatch
    response = self.handle_exception(exc)
               ^^^^^^^^^^^^^^^^^^^^^^^^^^
  File "C:\Python311\Lib\site-packages\rest_framework\views.py", line 469, in handle_exception
    self.raise_uncaught_exception(exc)
  File "C:\Python311\Lib\site-packages\rest_framework\views.py", line 480, in raise_uncaught_exception
    raise exc
  File "C:\Python311\Lib\site-packages\rest_framework\views.py", line 506, in dispatch
    response = handler(request, *args, **kwargs)
               ^^^^^^^^^^^^^^^^^^^^^^^^^^^^^^^^^
  File "C:\Users\Maryam\Documents\GitHub\Enigma_BackEnd\Enigma\Group\views.py", line 45, in post
    if not Members.objects.get(groupID=group, userID=user):
           ^^^^^^^^^^^^^^^^^^^^^^^^^^^^^^^^^^^^^^^^^^^^^^^
  File "C:\Python311\Lib\site-packages\django\db\models\manager.py", line 85, in manager_method
    return getattr(self.get_queryset(), name)(*args, **kwargs)
           ^^^^^^^^^^^^^^^^^^^^^^^^^^^^^^^^^^^^^^^^^^^^^^^^^^^
  File "C:\Python311\Lib\site-packages\django\db\models\query.py", line 650, in get
    raise self.model.DoesNotExist(
Group.models.Members.DoesNotExist: Members matching query does not exist.
ERROR 2023-05-14 07:49:30,868 log 18400 8004 Internal Server Error: /group/AddUserGroup/
Traceback (most recent call last):
  File "C:\Python311\Lib\site-packages\django\core\handlers\exception.py", line 56, in inner
    response = get_response(request)
               ^^^^^^^^^^^^^^^^^^^^^
  File "C:\Python311\Lib\site-packages\django\core\handlers\base.py", line 197, in _get_response
    response = wrapped_callback(request, *callback_args, **callback_kwargs)
               ^^^^^^^^^^^^^^^^^^^^^^^^^^^^^^^^^^^^^^^^^^^^^^^^^^^^^^^^^^^^
  File "C:\Python311\Lib\site-packages\django\views\decorators\csrf.py", line 55, in wrapped_view
    return view_func(*args, **kwargs)
           ^^^^^^^^^^^^^^^^^^^^^^^^^^
  File "C:\Python311\Lib\site-packages\django\views\generic\base.py", line 103, in view
    return self.dispatch(request, *args, **kwargs)
           ^^^^^^^^^^^^^^^^^^^^^^^^^^^^^^^^^^^^^^^
  File "C:\Python311\Lib\site-packages\rest_framework\views.py", line 509, in dispatch
    response = self.handle_exception(exc)
               ^^^^^^^^^^^^^^^^^^^^^^^^^^
  File "C:\Python311\Lib\site-packages\rest_framework\views.py", line 469, in handle_exception
    self.raise_uncaught_exception(exc)
  File "C:\Python311\Lib\site-packages\rest_framework\views.py", line 480, in raise_uncaught_exception
    raise exc
  File "C:\Python311\Lib\site-packages\rest_framework\views.py", line 506, in dispatch
    response = handler(request, *args, **kwargs)
               ^^^^^^^^^^^^^^^^^^^^^^^^^^^^^^^^^
  File "C:\Users\Maryam\Documents\GitHub\Enigma_BackEnd\Enigma\Group\views.py", line 45, in post
    if not Members.objects.get(groupID=group, userID=user):
           ^^^^^^^^^^^^^^^^^^^^^^^^^^^^^^^^^^^^^^^^^^^^^^^
  File "C:\Python311\Lib\site-packages\django\db\models\manager.py", line 85, in manager_method
    return getattr(self.get_queryset(), name)(*args, **kwargs)
           ^^^^^^^^^^^^^^^^^^^^^^^^^^^^^^^^^^^^^^^^^^^^^^^^^^^
  File "C:\Python311\Lib\site-packages\django\db\models\query.py", line 650, in get
    raise self.model.DoesNotExist(
Group.models.Members.DoesNotExist: Members matching query does not exist.
ERROR 2023-05-14 07:49:52,539 log 11608 1608 Internal Server Error: /group/AddUserGroup/
Traceback (most recent call last):
  File "C:\Python311\Lib\site-packages\django\core\handlers\exception.py", line 56, in inner
    response = get_response(request)
               ^^^^^^^^^^^^^^^^^^^^^
  File "C:\Python311\Lib\site-packages\django\core\handlers\base.py", line 197, in _get_response
    response = wrapped_callback(request, *callback_args, **callback_kwargs)
               ^^^^^^^^^^^^^^^^^^^^^^^^^^^^^^^^^^^^^^^^^^^^^^^^^^^^^^^^^^^^
  File "C:\Python311\Lib\site-packages\django\views\decorators\csrf.py", line 55, in wrapped_view
    return view_func(*args, **kwargs)
           ^^^^^^^^^^^^^^^^^^^^^^^^^^
  File "C:\Python311\Lib\site-packages\django\views\generic\base.py", line 103, in view
    return self.dispatch(request, *args, **kwargs)
           ^^^^^^^^^^^^^^^^^^^^^^^^^^^^^^^^^^^^^^^
  File "C:\Python311\Lib\site-packages\rest_framework\views.py", line 509, in dispatch
    response = self.handle_exception(exc)
               ^^^^^^^^^^^^^^^^^^^^^^^^^^
  File "C:\Python311\Lib\site-packages\rest_framework\views.py", line 469, in handle_exception
    self.raise_uncaught_exception(exc)
  File "C:\Python311\Lib\site-packages\rest_framework\views.py", line 480, in raise_uncaught_exception
    raise exc
  File "C:\Python311\Lib\site-packages\rest_framework\views.py", line 506, in dispatch
    response = handler(request, *args, **kwargs)
               ^^^^^^^^^^^^^^^^^^^^^^^^^^^^^^^^^
  File "C:\Users\Maryam\Documents\GitHub\Enigma_BackEnd\Enigma\Group\views.py", line 45, in post
    if not Members.objects.get(groupID=group, userID=user):
           ^^^^^^^^^^^^^^^^^^^^^^^^^^^^^^^^^^^^^^^^^^^^^^^
  File "C:\Python311\Lib\site-packages\django\db\models\manager.py", line 85, in manager_method
    return getattr(self.get_queryset(), name)(*args, **kwargs)
           ^^^^^^^^^^^^^^^^^^^^^^^^^^^^^^^^^^^^^^^^^^^^^^^^^^^
  File "C:\Python311\Lib\site-packages\django\db\models\query.py", line 650, in get
    raise self.model.DoesNotExist(
Group.models.Members.DoesNotExist: Members matching query does not exist.
WARNING 2023-05-14 07:49:52,553 log 11608 1608 Forbidden: /group/AddUserGroup/
ERROR 2023-05-14 07:49:52,563 log 11608 1608 Internal Server Error: /group/AddUserGroup/
Traceback (most recent call last):
  File "C:\Python311\Lib\site-packages\django\core\handlers\exception.py", line 56, in inner
    response = get_response(request)
               ^^^^^^^^^^^^^^^^^^^^^
  File "C:\Python311\Lib\site-packages\django\core\handlers\base.py", line 197, in _get_response
    response = wrapped_callback(request, *callback_args, **callback_kwargs)
               ^^^^^^^^^^^^^^^^^^^^^^^^^^^^^^^^^^^^^^^^^^^^^^^^^^^^^^^^^^^^
  File "C:\Python311\Lib\site-packages\django\views\decorators\csrf.py", line 55, in wrapped_view
    return view_func(*args, **kwargs)
           ^^^^^^^^^^^^^^^^^^^^^^^^^^
  File "C:\Python311\Lib\site-packages\django\views\generic\base.py", line 103, in view
    return self.dispatch(request, *args, **kwargs)
           ^^^^^^^^^^^^^^^^^^^^^^^^^^^^^^^^^^^^^^^
  File "C:\Python311\Lib\site-packages\rest_framework\views.py", line 509, in dispatch
    response = self.handle_exception(exc)
               ^^^^^^^^^^^^^^^^^^^^^^^^^^
  File "C:\Python311\Lib\site-packages\rest_framework\views.py", line 469, in handle_exception
    self.raise_uncaught_exception(exc)
  File "C:\Python311\Lib\site-packages\rest_framework\views.py", line 480, in raise_uncaught_exception
    raise exc
  File "C:\Python311\Lib\site-packages\rest_framework\views.py", line 506, in dispatch
    response = handler(request, *args, **kwargs)
               ^^^^^^^^^^^^^^^^^^^^^^^^^^^^^^^^^
  File "C:\Users\Maryam\Documents\GitHub\Enigma_BackEnd\Enigma\Group\views.py", line 45, in post
    if not Members.objects.get(groupID=group, userID=user):
           ^^^^^^^^^^^^^^^^^^^^^^^^^^^^^^^^^^^^^^^^^^^^^^^
  File "C:\Python311\Lib\site-packages\django\db\models\manager.py", line 85, in manager_method
    return getattr(self.get_queryset(), name)(*args, **kwargs)
           ^^^^^^^^^^^^^^^^^^^^^^^^^^^^^^^^^^^^^^^^^^^^^^^^^^^
  File "C:\Python311\Lib\site-packages\django\db\models\query.py", line 650, in get
    raise self.model.DoesNotExist(
Group.models.Members.DoesNotExist: Members matching query does not exist.
ERROR 2023-05-14 07:49:52,578 log 11608 1608 Internal Server Error: /group/AddUserGroup/
Traceback (most recent call last):
  File "C:\Python311\Lib\site-packages\django\core\handlers\exception.py", line 56, in inner
    response = get_response(request)
               ^^^^^^^^^^^^^^^^^^^^^
  File "C:\Python311\Lib\site-packages\django\core\handlers\base.py", line 197, in _get_response
    response = wrapped_callback(request, *callback_args, **callback_kwargs)
               ^^^^^^^^^^^^^^^^^^^^^^^^^^^^^^^^^^^^^^^^^^^^^^^^^^^^^^^^^^^^
  File "C:\Python311\Lib\site-packages\django\views\decorators\csrf.py", line 55, in wrapped_view
    return view_func(*args, **kwargs)
           ^^^^^^^^^^^^^^^^^^^^^^^^^^
  File "C:\Python311\Lib\site-packages\django\views\generic\base.py", line 103, in view
    return self.dispatch(request, *args, **kwargs)
           ^^^^^^^^^^^^^^^^^^^^^^^^^^^^^^^^^^^^^^^
  File "C:\Python311\Lib\site-packages\rest_framework\views.py", line 509, in dispatch
    response = self.handle_exception(exc)
               ^^^^^^^^^^^^^^^^^^^^^^^^^^
  File "C:\Python311\Lib\site-packages\rest_framework\views.py", line 469, in handle_exception
    self.raise_uncaught_exception(exc)
  File "C:\Python311\Lib\site-packages\rest_framework\views.py", line 480, in raise_uncaught_exception
    raise exc
  File "C:\Python311\Lib\site-packages\rest_framework\views.py", line 506, in dispatch
    response = handler(request, *args, **kwargs)
               ^^^^^^^^^^^^^^^^^^^^^^^^^^^^^^^^^
  File "C:\Users\Maryam\Documents\GitHub\Enigma_BackEnd\Enigma\Group\views.py", line 45, in post
    if not Members.objects.get(groupID=group, userID=user):
           ^^^^^^^^^^^^^^^^^^^^^^^^^^^^^^^^^^^^^^^^^^^^^^^
  File "C:\Python311\Lib\site-packages\django\db\models\manager.py", line 85, in manager_method
    return getattr(self.get_queryset(), name)(*args, **kwargs)
           ^^^^^^^^^^^^^^^^^^^^^^^^^^^^^^^^^^^^^^^^^^^^^^^^^^^
  File "C:\Python311\Lib\site-packages\django\db\models\query.py", line 650, in get
    raise self.model.DoesNotExist(
Group.models.Members.DoesNotExist: Members matching query does not exist.
INFO 2023-05-14 07:51:57,897 autoreload 1088 9064 Watching for file changes with StatReloader
ERROR 2023-05-14 07:53:59,800 log 13104 8364 Internal Server Error: /group/AddUserGroup/
Traceback (most recent call last):
  File "C:\Python311\Lib\site-packages\django\core\handlers\exception.py", line 56, in inner
    response = get_response(request)
               ^^^^^^^^^^^^^^^^^^^^^
  File "C:\Python311\Lib\site-packages\django\core\handlers\base.py", line 197, in _get_response
    response = wrapped_callback(request, *callback_args, **callback_kwargs)
               ^^^^^^^^^^^^^^^^^^^^^^^^^^^^^^^^^^^^^^^^^^^^^^^^^^^^^^^^^^^^
  File "C:\Python311\Lib\site-packages\django\views\decorators\csrf.py", line 55, in wrapped_view
    return view_func(*args, **kwargs)
           ^^^^^^^^^^^^^^^^^^^^^^^^^^
  File "C:\Python311\Lib\site-packages\django\views\generic\base.py", line 103, in view
    return self.dispatch(request, *args, **kwargs)
           ^^^^^^^^^^^^^^^^^^^^^^^^^^^^^^^^^^^^^^^
  File "C:\Python311\Lib\site-packages\rest_framework\views.py", line 509, in dispatch
    response = self.handle_exception(exc)
               ^^^^^^^^^^^^^^^^^^^^^^^^^^
  File "C:\Python311\Lib\site-packages\rest_framework\views.py", line 469, in handle_exception
    self.raise_uncaught_exception(exc)
  File "C:\Python311\Lib\site-packages\rest_framework\views.py", line 480, in raise_uncaught_exception
    raise exc
  File "C:\Python311\Lib\site-packages\rest_framework\views.py", line 506, in dispatch
    response = handler(request, *args, **kwargs)
               ^^^^^^^^^^^^^^^^^^^^^^^^^^^^^^^^^
  File "C:\Users\Maryam\Documents\GitHub\Enigma_BackEnd\Enigma\Group\views.py", line 45, in post
    if not Members.objects.get(groupID=group, userID=user):
           ^^^^^^^^^^^^^^^^^^^^^^^^^^^^^^^^^^^^^^^^^^^^^^^
  File "C:\Python311\Lib\site-packages\django\db\models\manager.py", line 85, in manager_method
    return getattr(self.get_queryset(), name)(*args, **kwargs)
           ^^^^^^^^^^^^^^^^^^^^^^^^^^^^^^^^^^^^^^^^^^^^^^^^^^^
  File "C:\Python311\Lib\site-packages\django\db\models\query.py", line 650, in get
    raise self.model.DoesNotExist(
Group.models.Members.DoesNotExist: Members matching query does not exist.
WARNING 2023-05-14 07:53:59,814 log 13104 8364 Forbidden: /group/AddUserGroup/
ERROR 2023-05-14 07:53:59,823 log 13104 8364 Internal Server Error: /group/AddUserGroup/
Traceback (most recent call last):
  File "C:\Python311\Lib\site-packages\django\core\handlers\exception.py", line 56, in inner
    response = get_response(request)
               ^^^^^^^^^^^^^^^^^^^^^
  File "C:\Python311\Lib\site-packages\django\core\handlers\base.py", line 197, in _get_response
    response = wrapped_callback(request, *callback_args, **callback_kwargs)
               ^^^^^^^^^^^^^^^^^^^^^^^^^^^^^^^^^^^^^^^^^^^^^^^^^^^^^^^^^^^^
  File "C:\Python311\Lib\site-packages\django\views\decorators\csrf.py", line 55, in wrapped_view
    return view_func(*args, **kwargs)
           ^^^^^^^^^^^^^^^^^^^^^^^^^^
  File "C:\Python311\Lib\site-packages\django\views\generic\base.py", line 103, in view
    return self.dispatch(request, *args, **kwargs)
           ^^^^^^^^^^^^^^^^^^^^^^^^^^^^^^^^^^^^^^^
  File "C:\Python311\Lib\site-packages\rest_framework\views.py", line 509, in dispatch
    response = self.handle_exception(exc)
               ^^^^^^^^^^^^^^^^^^^^^^^^^^
  File "C:\Python311\Lib\site-packages\rest_framework\views.py", line 469, in handle_exception
    self.raise_uncaught_exception(exc)
  File "C:\Python311\Lib\site-packages\rest_framework\views.py", line 480, in raise_uncaught_exception
    raise exc
  File "C:\Python311\Lib\site-packages\rest_framework\views.py", line 506, in dispatch
    response = handler(request, *args, **kwargs)
               ^^^^^^^^^^^^^^^^^^^^^^^^^^^^^^^^^
  File "C:\Users\Maryam\Documents\GitHub\Enigma_BackEnd\Enigma\Group\views.py", line 45, in post
    if not Members.objects.get(groupID=group, userID=user):
           ^^^^^^^^^^^^^^^^^^^^^^^^^^^^^^^^^^^^^^^^^^^^^^^
  File "C:\Python311\Lib\site-packages\django\db\models\manager.py", line 85, in manager_method
    return getattr(self.get_queryset(), name)(*args, **kwargs)
           ^^^^^^^^^^^^^^^^^^^^^^^^^^^^^^^^^^^^^^^^^^^^^^^^^^^
  File "C:\Python311\Lib\site-packages\django\db\models\query.py", line 650, in get
    raise self.model.DoesNotExist(
Group.models.Members.DoesNotExist: Members matching query does not exist.
ERROR 2023-05-14 07:53:59,836 log 13104 8364 Internal Server Error: /group/AddUserGroup/
Traceback (most recent call last):
  File "C:\Python311\Lib\site-packages\django\core\handlers\exception.py", line 56, in inner
    response = get_response(request)
               ^^^^^^^^^^^^^^^^^^^^^
  File "C:\Python311\Lib\site-packages\django\core\handlers\base.py", line 197, in _get_response
    response = wrapped_callback(request, *callback_args, **callback_kwargs)
               ^^^^^^^^^^^^^^^^^^^^^^^^^^^^^^^^^^^^^^^^^^^^^^^^^^^^^^^^^^^^
  File "C:\Python311\Lib\site-packages\django\views\decorators\csrf.py", line 55, in wrapped_view
    return view_func(*args, **kwargs)
           ^^^^^^^^^^^^^^^^^^^^^^^^^^
  File "C:\Python311\Lib\site-packages\django\views\generic\base.py", line 103, in view
    return self.dispatch(request, *args, **kwargs)
           ^^^^^^^^^^^^^^^^^^^^^^^^^^^^^^^^^^^^^^^
  File "C:\Python311\Lib\site-packages\rest_framework\views.py", line 509, in dispatch
    response = self.handle_exception(exc)
               ^^^^^^^^^^^^^^^^^^^^^^^^^^
  File "C:\Python311\Lib\site-packages\rest_framework\views.py", line 469, in handle_exception
    self.raise_uncaught_exception(exc)
  File "C:\Python311\Lib\site-packages\rest_framework\views.py", line 480, in raise_uncaught_exception
    raise exc
  File "C:\Python311\Lib\site-packages\rest_framework\views.py", line 506, in dispatch
    response = handler(request, *args, **kwargs)
               ^^^^^^^^^^^^^^^^^^^^^^^^^^^^^^^^^
  File "C:\Users\Maryam\Documents\GitHub\Enigma_BackEnd\Enigma\Group\views.py", line 45, in post
    if not Members.objects.get(groupID=group, userID=user):
           ^^^^^^^^^^^^^^^^^^^^^^^^^^^^^^^^^^^^^^^^^^^^^^^
  File "C:\Python311\Lib\site-packages\django\db\models\manager.py", line 85, in manager_method
    return getattr(self.get_queryset(), name)(*args, **kwargs)
           ^^^^^^^^^^^^^^^^^^^^^^^^^^^^^^^^^^^^^^^^^^^^^^^^^^^
  File "C:\Python311\Lib\site-packages\django\db\models\query.py", line 650, in get
    raise self.model.DoesNotExist(
Group.models.Members.DoesNotExist: Members matching query does not exist.
ERROR 2023-05-14 07:55:41,467 log 16772 12204 Internal Server Error: /group/AddUserGroup/
Traceback (most recent call last):
  File "C:\Python311\Lib\site-packages\django\core\handlers\exception.py", line 56, in inner
    response = get_response(request)
               ^^^^^^^^^^^^^^^^^^^^^
  File "C:\Python311\Lib\site-packages\django\core\handlers\base.py", line 197, in _get_response
    response = wrapped_callback(request, *callback_args, **callback_kwargs)
               ^^^^^^^^^^^^^^^^^^^^^^^^^^^^^^^^^^^^^^^^^^^^^^^^^^^^^^^^^^^^
  File "C:\Python311\Lib\site-packages\django\views\decorators\csrf.py", line 55, in wrapped_view
    return view_func(*args, **kwargs)
           ^^^^^^^^^^^^^^^^^^^^^^^^^^
  File "C:\Python311\Lib\site-packages\django\views\generic\base.py", line 103, in view
    return self.dispatch(request, *args, **kwargs)
           ^^^^^^^^^^^^^^^^^^^^^^^^^^^^^^^^^^^^^^^
  File "C:\Python311\Lib\site-packages\rest_framework\views.py", line 509, in dispatch
    response = self.handle_exception(exc)
               ^^^^^^^^^^^^^^^^^^^^^^^^^^
  File "C:\Python311\Lib\site-packages\rest_framework\views.py", line 469, in handle_exception
    self.raise_uncaught_exception(exc)
  File "C:\Python311\Lib\site-packages\rest_framework\views.py", line 480, in raise_uncaught_exception
    raise exc
  File "C:\Python311\Lib\site-packages\rest_framework\views.py", line 506, in dispatch
    response = handler(request, *args, **kwargs)
               ^^^^^^^^^^^^^^^^^^^^^^^^^^^^^^^^^
  File "C:\Users\Maryam\Documents\GitHub\Enigma_BackEnd\Enigma\Group\views.py", line 46, in post
    if not Members.objects.get(groupID=group, userID=user):
           ^^^^^^^^^^^^^^^^^^^^^^^^^^^^^^^^^^^^^^^^^^^^^^^
  File "C:\Python311\Lib\site-packages\django\db\models\manager.py", line 85, in manager_method
    return getattr(self.get_queryset(), name)(*args, **kwargs)
           ^^^^^^^^^^^^^^^^^^^^^^^^^^^^^^^^^^^^^^^^^^^^^^^^^^^
  File "C:\Python311\Lib\site-packages\django\db\models\query.py", line 650, in get
    raise self.model.DoesNotExist(
Group.models.Members.DoesNotExist: Members matching query does not exist.
WARNING 2023-05-14 07:55:41,482 log 16772 12204 Forbidden: /group/AddUserGroup/
ERROR 2023-05-14 07:55:41,490 log 16772 12204 Internal Server Error: /group/AddUserGroup/
Traceback (most recent call last):
  File "C:\Python311\Lib\site-packages\django\core\handlers\exception.py", line 56, in inner
    response = get_response(request)
               ^^^^^^^^^^^^^^^^^^^^^
  File "C:\Python311\Lib\site-packages\django\core\handlers\base.py", line 197, in _get_response
    response = wrapped_callback(request, *callback_args, **callback_kwargs)
               ^^^^^^^^^^^^^^^^^^^^^^^^^^^^^^^^^^^^^^^^^^^^^^^^^^^^^^^^^^^^
  File "C:\Python311\Lib\site-packages\django\views\decorators\csrf.py", line 55, in wrapped_view
    return view_func(*args, **kwargs)
           ^^^^^^^^^^^^^^^^^^^^^^^^^^
  File "C:\Python311\Lib\site-packages\django\views\generic\base.py", line 103, in view
    return self.dispatch(request, *args, **kwargs)
           ^^^^^^^^^^^^^^^^^^^^^^^^^^^^^^^^^^^^^^^
  File "C:\Python311\Lib\site-packages\rest_framework\views.py", line 509, in dispatch
    response = self.handle_exception(exc)
               ^^^^^^^^^^^^^^^^^^^^^^^^^^
  File "C:\Python311\Lib\site-packages\rest_framework\views.py", line 469, in handle_exception
    self.raise_uncaught_exception(exc)
  File "C:\Python311\Lib\site-packages\rest_framework\views.py", line 480, in raise_uncaught_exception
    raise exc
  File "C:\Python311\Lib\site-packages\rest_framework\views.py", line 506, in dispatch
    response = handler(request, *args, **kwargs)
               ^^^^^^^^^^^^^^^^^^^^^^^^^^^^^^^^^
  File "C:\Users\Maryam\Documents\GitHub\Enigma_BackEnd\Enigma\Group\views.py", line 46, in post
    if not Members.objects.get(groupID=group, userID=user):
           ^^^^^^^^^^^^^^^^^^^^^^^^^^^^^^^^^^^^^^^^^^^^^^^
  File "C:\Python311\Lib\site-packages\django\db\models\manager.py", line 85, in manager_method
    return getattr(self.get_queryset(), name)(*args, **kwargs)
           ^^^^^^^^^^^^^^^^^^^^^^^^^^^^^^^^^^^^^^^^^^^^^^^^^^^
  File "C:\Python311\Lib\site-packages\django\db\models\query.py", line 650, in get
    raise self.model.DoesNotExist(
Group.models.Members.DoesNotExist: Members matching query does not exist.
ERROR 2023-05-14 07:55:41,504 log 16772 12204 Internal Server Error: /group/AddUserGroup/
Traceback (most recent call last):
  File "C:\Python311\Lib\site-packages\django\core\handlers\exception.py", line 56, in inner
    response = get_response(request)
               ^^^^^^^^^^^^^^^^^^^^^
  File "C:\Python311\Lib\site-packages\django\core\handlers\base.py", line 197, in _get_response
    response = wrapped_callback(request, *callback_args, **callback_kwargs)
               ^^^^^^^^^^^^^^^^^^^^^^^^^^^^^^^^^^^^^^^^^^^^^^^^^^^^^^^^^^^^
  File "C:\Python311\Lib\site-packages\django\views\decorators\csrf.py", line 55, in wrapped_view
    return view_func(*args, **kwargs)
           ^^^^^^^^^^^^^^^^^^^^^^^^^^
  File "C:\Python311\Lib\site-packages\django\views\generic\base.py", line 103, in view
    return self.dispatch(request, *args, **kwargs)
           ^^^^^^^^^^^^^^^^^^^^^^^^^^^^^^^^^^^^^^^
  File "C:\Python311\Lib\site-packages\rest_framework\views.py", line 509, in dispatch
    response = self.handle_exception(exc)
               ^^^^^^^^^^^^^^^^^^^^^^^^^^
  File "C:\Python311\Lib\site-packages\rest_framework\views.py", line 469, in handle_exception
    self.raise_uncaught_exception(exc)
  File "C:\Python311\Lib\site-packages\rest_framework\views.py", line 480, in raise_uncaught_exception
    raise exc
  File "C:\Python311\Lib\site-packages\rest_framework\views.py", line 506, in dispatch
    response = handler(request, *args, **kwargs)
               ^^^^^^^^^^^^^^^^^^^^^^^^^^^^^^^^^
  File "C:\Users\Maryam\Documents\GitHub\Enigma_BackEnd\Enigma\Group\views.py", line 46, in post
    if not Members.objects.get(groupID=group, userID=user):
           ^^^^^^^^^^^^^^^^^^^^^^^^^^^^^^^^^^^^^^^^^^^^^^^
  File "C:\Python311\Lib\site-packages\django\db\models\manager.py", line 85, in manager_method
    return getattr(self.get_queryset(), name)(*args, **kwargs)
           ^^^^^^^^^^^^^^^^^^^^^^^^^^^^^^^^^^^^^^^^^^^^^^^^^^^
  File "C:\Python311\Lib\site-packages\django\db\models\query.py", line 650, in get
    raise self.model.DoesNotExist(
Group.models.Members.DoesNotExist: Members matching query does not exist.
WARNING 2023-05-14 07:59:18,350 log 6704 1308 Not Found: /group/AddUserGroup/
WARNING 2023-05-14 07:59:18,356 log 6704 1308 Forbidden: /group/AddUserGroup/
WARNING 2023-05-14 07:59:18,382 log 6704 1308 Not Found: /group/AddUserGroup/
WARNING 2023-05-14 08:02:29,472 log 5600 14084 Not Found: /group/AddUserGroup/
WARNING 2023-05-14 08:02:29,480 log 5600 14084 Forbidden: /group/AddUserGroup/
WARNING 2023-05-14 08:02:29,502 log 5600 14084 Not Found: /group/AddUserGroup/
WARNING 2023-05-14 12:00:37,040 log 960 1744 Not Found: /group/AddUserGroup/
WARNING 2023-05-14 12:00:37,046 log 960 1744 Forbidden: /group/AddUserGroup/
ERROR 2023-05-14 12:00:37,055 log 960 1744 Internal Server Error: /group/AddUserGroup/
Traceback (most recent call last):
  File "C:\Python311\Lib\site-packages\django\core\handlers\exception.py", line 56, in inner
    response = get_response(request)
               ^^^^^^^^^^^^^^^^^^^^^
  File "C:\Python311\Lib\site-packages\django\core\handlers\base.py", line 197, in _get_response
    response = wrapped_callback(request, *callback_args, **callback_kwargs)
               ^^^^^^^^^^^^^^^^^^^^^^^^^^^^^^^^^^^^^^^^^^^^^^^^^^^^^^^^^^^^
  File "C:\Python311\Lib\site-packages\django\views\decorators\csrf.py", line 55, in wrapped_view
    return view_func(*args, **kwargs)
           ^^^^^^^^^^^^^^^^^^^^^^^^^^
  File "C:\Python311\Lib\site-packages\django\views\generic\base.py", line 103, in view
    return self.dispatch(request, *args, **kwargs)
           ^^^^^^^^^^^^^^^^^^^^^^^^^^^^^^^^^^^^^^^
  File "C:\Python311\Lib\site-packages\rest_framework\views.py", line 509, in dispatch
    response = self.handle_exception(exc)
               ^^^^^^^^^^^^^^^^^^^^^^^^^^
  File "C:\Python311\Lib\site-packages\rest_framework\views.py", line 469, in handle_exception
    self.raise_uncaught_exception(exc)
  File "C:\Python311\Lib\site-packages\rest_framework\views.py", line 480, in raise_uncaught_exception
    raise exc
  File "C:\Python311\Lib\site-packages\rest_framework\views.py", line 497, in dispatch
    self.initial(request, *args, **kwargs)
  File "C:\Python311\Lib\site-packages\rest_framework\views.py", line 415, in initial
    self.check_permissions(request)
  File "C:\Python311\Lib\site-packages\rest_framework\views.py", line 332, in check_permissions
    if not permission.has_permission(request, self):
           ^^^^^^^^^^^^^^^^^^^^^^^^^^^^^^^^^^^^^^^^
  File "C:\Users\Maryam\Documents\GitHub\Enigma_BackEnd\Enigma\Group\permissions.py", line 10, in has_permission
    members = Members.objects.filter(userID=request.user, groupID=request.data['groupID'])
                                                                  ~~~~~~~~~~~~^^^^^^^^^^^
TypeError: list indices must be integers or slices, not str
WARNING 2023-05-14 12:00:37,089 log 960 1744 Not Found: /group/AddUserGroup/
WARNING 2023-05-14 12:05:43,887 log 6728 13200 Not Found: /group/AddUserGroup/
WARNING 2023-05-14 12:05:43,895 log 6728 13200 Forbidden: /group/AddUserGroup/
ERROR 2023-05-14 12:05:43,905 log 6728 13200 Internal Server Error: /group/AddUserGroup/
Traceback (most recent call last):
  File "C:\Python311\Lib\site-packages\django\core\handlers\exception.py", line 56, in inner
    response = get_response(request)
               ^^^^^^^^^^^^^^^^^^^^^
  File "C:\Python311\Lib\site-packages\django\core\handlers\base.py", line 197, in _get_response
    response = wrapped_callback(request, *callback_args, **callback_kwargs)
               ^^^^^^^^^^^^^^^^^^^^^^^^^^^^^^^^^^^^^^^^^^^^^^^^^^^^^^^^^^^^
  File "C:\Python311\Lib\site-packages\django\views\decorators\csrf.py", line 55, in wrapped_view
    return view_func(*args, **kwargs)
           ^^^^^^^^^^^^^^^^^^^^^^^^^^
  File "C:\Python311\Lib\site-packages\django\views\generic\base.py", line 103, in view
    return self.dispatch(request, *args, **kwargs)
           ^^^^^^^^^^^^^^^^^^^^^^^^^^^^^^^^^^^^^^^
  File "C:\Python311\Lib\site-packages\rest_framework\views.py", line 509, in dispatch
    response = self.handle_exception(exc)
               ^^^^^^^^^^^^^^^^^^^^^^^^^^
  File "C:\Python311\Lib\site-packages\rest_framework\views.py", line 469, in handle_exception
    self.raise_uncaught_exception(exc)
  File "C:\Python311\Lib\site-packages\rest_framework\views.py", line 480, in raise_uncaught_exception
    raise exc
  File "C:\Python311\Lib\site-packages\rest_framework\views.py", line 497, in dispatch
    self.initial(request, *args, **kwargs)
  File "C:\Python311\Lib\site-packages\rest_framework\views.py", line 415, in initial
    self.check_permissions(request)
  File "C:\Python311\Lib\site-packages\rest_framework\views.py", line 332, in check_permissions
    if not permission.has_permission(request, self):
           ^^^^^^^^^^^^^^^^^^^^^^^^^^^^^^^^^^^^^^^^
  File "C:\Users\Maryam\Documents\GitHub\Enigma_BackEnd\Enigma\Group\permissions.py", line 10, in has_permission
    members = Members.objects.filter(userID=request.user, groupID=request.data['groupID'])
                                                                  ~~~~~~~~~~~~^^^^^^^^^^^
TypeError: list indices must be integers or slices, not str
WARNING 2023-05-14 12:05:43,939 log 6728 13200 Not Found: /group/AddUserGroup/
WARNING 2023-05-14 12:07:15,317 log 7608 6128 Not Found: /group/AddUserGroup/
WARNING 2023-05-14 12:07:15,324 log 7608 6128 Forbidden: /group/AddUserGroup/
ERROR 2023-05-14 12:07:15,332 log 7608 6128 Internal Server Error: /group/AddUserGroup/
Traceback (most recent call last):
  File "C:\Python311\Lib\site-packages\django\core\handlers\exception.py", line 56, in inner
    response = get_response(request)
               ^^^^^^^^^^^^^^^^^^^^^
  File "C:\Python311\Lib\site-packages\django\core\handlers\base.py", line 197, in _get_response
    response = wrapped_callback(request, *callback_args, **callback_kwargs)
               ^^^^^^^^^^^^^^^^^^^^^^^^^^^^^^^^^^^^^^^^^^^^^^^^^^^^^^^^^^^^
  File "C:\Python311\Lib\site-packages\django\views\decorators\csrf.py", line 55, in wrapped_view
    return view_func(*args, **kwargs)
           ^^^^^^^^^^^^^^^^^^^^^^^^^^
  File "C:\Python311\Lib\site-packages\django\views\generic\base.py", line 103, in view
    return self.dispatch(request, *args, **kwargs)
           ^^^^^^^^^^^^^^^^^^^^^^^^^^^^^^^^^^^^^^^
  File "C:\Python311\Lib\site-packages\rest_framework\views.py", line 509, in dispatch
    response = self.handle_exception(exc)
               ^^^^^^^^^^^^^^^^^^^^^^^^^^
  File "C:\Python311\Lib\site-packages\rest_framework\views.py", line 469, in handle_exception
    self.raise_uncaught_exception(exc)
  File "C:\Python311\Lib\site-packages\rest_framework\views.py", line 480, in raise_uncaught_exception
    raise exc
  File "C:\Python311\Lib\site-packages\rest_framework\views.py", line 497, in dispatch
    self.initial(request, *args, **kwargs)
  File "C:\Python311\Lib\site-packages\rest_framework\views.py", line 415, in initial
    self.check_permissions(request)
  File "C:\Python311\Lib\site-packages\rest_framework\views.py", line 332, in check_permissions
    if not permission.has_permission(request, self):
           ^^^^^^^^^^^^^^^^^^^^^^^^^^^^^^^^^^^^^^^^
  File "C:\Users\Maryam\Documents\GitHub\Enigma_BackEnd\Enigma\Group\permissions.py", line 10, in has_permission
    members = Members.objects.filter(userID=request.user, groupID=request.data['groupID'])
                                                                  ~~~~~~~~~~~~^^^^^^^^^^^
TypeError: list indices must be integers or slices, not str
WARNING 2023-05-14 12:07:15,365 log 7608 6128 Not Found: /group/AddUserGroup/
WARNING 2023-05-14 12:07:39,762 log 4068 2212 Not Found: /group/AddUserGroup/
WARNING 2023-05-14 12:07:39,770 log 4068 2212 Forbidden: /group/AddUserGroup/
ERROR 2023-05-14 12:07:39,779 log 4068 2212 Internal Server Error: /group/AddUserGroup/
Traceback (most recent call last):
  File "C:\Python311\Lib\site-packages\django\core\handlers\exception.py", line 56, in inner
    response = get_response(request)
               ^^^^^^^^^^^^^^^^^^^^^
  File "C:\Python311\Lib\site-packages\django\core\handlers\base.py", line 197, in _get_response
    response = wrapped_callback(request, *callback_args, **callback_kwargs)
               ^^^^^^^^^^^^^^^^^^^^^^^^^^^^^^^^^^^^^^^^^^^^^^^^^^^^^^^^^^^^
  File "C:\Python311\Lib\site-packages\django\views\decorators\csrf.py", line 55, in wrapped_view
    return view_func(*args, **kwargs)
           ^^^^^^^^^^^^^^^^^^^^^^^^^^
  File "C:\Python311\Lib\site-packages\django\views\generic\base.py", line 103, in view
    return self.dispatch(request, *args, **kwargs)
           ^^^^^^^^^^^^^^^^^^^^^^^^^^^^^^^^^^^^^^^
  File "C:\Python311\Lib\site-packages\rest_framework\views.py", line 509, in dispatch
    response = self.handle_exception(exc)
               ^^^^^^^^^^^^^^^^^^^^^^^^^^
  File "C:\Python311\Lib\site-packages\rest_framework\views.py", line 469, in handle_exception
    self.raise_uncaught_exception(exc)
  File "C:\Python311\Lib\site-packages\rest_framework\views.py", line 480, in raise_uncaught_exception
    raise exc
  File "C:\Python311\Lib\site-packages\rest_framework\views.py", line 497, in dispatch
    self.initial(request, *args, **kwargs)
  File "C:\Python311\Lib\site-packages\rest_framework\views.py", line 415, in initial
    self.check_permissions(request)
  File "C:\Python311\Lib\site-packages\rest_framework\views.py", line 332, in check_permissions
    if not permission.has_permission(request, self):
           ^^^^^^^^^^^^^^^^^^^^^^^^^^^^^^^^^^^^^^^^
  File "C:\Users\Maryam\Documents\GitHub\Enigma_BackEnd\Enigma\Group\permissions.py", line 10, in has_permission
    members = Members.objects.filter(userID=request.user, groupID=request.data['groupID'])
                                                                  ~~~~~~~~~~~~^^^^^^^^^^^
TypeError: list indices must be integers or slices, not str
WARNING 2023-05-14 12:07:39,812 log 4068 2212 Not Found: /group/AddUserGroup/
WARNING 2023-05-14 12:08:00,961 log 15812 15544 Not Found: /group/AddUserGroup/
WARNING 2023-05-14 12:08:00,968 log 15812 15544 Forbidden: /group/AddUserGroup/
ERROR 2023-05-14 12:08:00,978 log 15812 15544 Internal Server Error: /group/AddUserGroup/
Traceback (most recent call last):
  File "C:\Python311\Lib\site-packages\django\core\handlers\exception.py", line 56, in inner
    response = get_response(request)
               ^^^^^^^^^^^^^^^^^^^^^
  File "C:\Python311\Lib\site-packages\django\core\handlers\base.py", line 197, in _get_response
    response = wrapped_callback(request, *callback_args, **callback_kwargs)
               ^^^^^^^^^^^^^^^^^^^^^^^^^^^^^^^^^^^^^^^^^^^^^^^^^^^^^^^^^^^^
  File "C:\Python311\Lib\site-packages\django\views\decorators\csrf.py", line 55, in wrapped_view
    return view_func(*args, **kwargs)
           ^^^^^^^^^^^^^^^^^^^^^^^^^^
  File "C:\Python311\Lib\site-packages\django\views\generic\base.py", line 103, in view
    return self.dispatch(request, *args, **kwargs)
           ^^^^^^^^^^^^^^^^^^^^^^^^^^^^^^^^^^^^^^^
  File "C:\Python311\Lib\site-packages\rest_framework\views.py", line 509, in dispatch
    response = self.handle_exception(exc)
               ^^^^^^^^^^^^^^^^^^^^^^^^^^
  File "C:\Python311\Lib\site-packages\rest_framework\views.py", line 469, in handle_exception
    self.raise_uncaught_exception(exc)
  File "C:\Python311\Lib\site-packages\rest_framework\views.py", line 480, in raise_uncaught_exception
    raise exc
  File "C:\Python311\Lib\site-packages\rest_framework\views.py", line 497, in dispatch
    self.initial(request, *args, **kwargs)
  File "C:\Python311\Lib\site-packages\rest_framework\views.py", line 415, in initial
    self.check_permissions(request)
  File "C:\Python311\Lib\site-packages\rest_framework\views.py", line 332, in check_permissions
    if not permission.has_permission(request, self):
           ^^^^^^^^^^^^^^^^^^^^^^^^^^^^^^^^^^^^^^^^
  File "C:\Users\Maryam\Documents\GitHub\Enigma_BackEnd\Enigma\Group\permissions.py", line 10, in has_permission
    members = Members.objects.filter(userID=request.user, groupID=request.data['groupID'])
                                                                  ~~~~~~~~~~~~^^^^^^^^^^^
TypeError: list indices must be integers or slices, not str
WARNING 2023-05-14 12:08:01,011 log 15812 15544 Not Found: /group/AddUserGroup/
WARNING 2023-05-14 12:08:57,151 log 13424 15240 Not Found: /group/AddUserGroup/
WARNING 2023-05-14 12:08:57,158 log 13424 15240 Forbidden: /group/AddUserGroup/
ERROR 2023-05-14 12:08:57,167 log 13424 15240 Internal Server Error: /group/AddUserGroup/
Traceback (most recent call last):
  File "C:\Python311\Lib\site-packages\django\core\handlers\exception.py", line 56, in inner
    response = get_response(request)
               ^^^^^^^^^^^^^^^^^^^^^
  File "C:\Python311\Lib\site-packages\django\core\handlers\base.py", line 197, in _get_response
    response = wrapped_callback(request, *callback_args, **callback_kwargs)
               ^^^^^^^^^^^^^^^^^^^^^^^^^^^^^^^^^^^^^^^^^^^^^^^^^^^^^^^^^^^^
  File "C:\Python311\Lib\site-packages\django\views\decorators\csrf.py", line 55, in wrapped_view
    return view_func(*args, **kwargs)
           ^^^^^^^^^^^^^^^^^^^^^^^^^^
  File "C:\Python311\Lib\site-packages\django\views\generic\base.py", line 103, in view
    return self.dispatch(request, *args, **kwargs)
           ^^^^^^^^^^^^^^^^^^^^^^^^^^^^^^^^^^^^^^^
  File "C:\Python311\Lib\site-packages\rest_framework\views.py", line 509, in dispatch
    response = self.handle_exception(exc)
               ^^^^^^^^^^^^^^^^^^^^^^^^^^
  File "C:\Python311\Lib\site-packages\rest_framework\views.py", line 469, in handle_exception
    self.raise_uncaught_exception(exc)
  File "C:\Python311\Lib\site-packages\rest_framework\views.py", line 480, in raise_uncaught_exception
    raise exc
  File "C:\Python311\Lib\site-packages\rest_framework\views.py", line 497, in dispatch
    self.initial(request, *args, **kwargs)
  File "C:\Python311\Lib\site-packages\rest_framework\views.py", line 415, in initial
    self.check_permissions(request)
  File "C:\Python311\Lib\site-packages\rest_framework\views.py", line 332, in check_permissions
    if not permission.has_permission(request, self):
           ^^^^^^^^^^^^^^^^^^^^^^^^^^^^^^^^^^^^^^^^
  File "C:\Users\Maryam\Documents\GitHub\Enigma_BackEnd\Enigma\Group\permissions.py", line 10, in has_permission
    members = Members.objects.filter(userID=request.user, groupID=request.data['groupID'])
                                                                  ~~~~~~~~~~~~^^^^^^^^^^^
KeyError: 'groupID'
WARNING 2023-05-14 12:08:57,198 log 13424 15240 Not Found: /group/AddUserGroup/
WARNING 2023-05-14 12:54:30,159 log 11092 10264 Not Found: /group/AddUserGroup/
WARNING 2023-05-14 12:54:30,165 log 11092 10264 Forbidden: /group/AddUserGroup/
ERROR 2023-05-14 12:54:30,171 log 11092 10264 Internal Server Error: /group/AddUserGroup/
Traceback (most recent call last):
  File "C:\Python311\Lib\site-packages\django\core\handlers\exception.py", line 56, in inner
    response = get_response(request)
               ^^^^^^^^^^^^^^^^^^^^^
  File "C:\Python311\Lib\site-packages\django\core\handlers\base.py", line 197, in _get_response
    response = wrapped_callback(request, *callback_args, **callback_kwargs)
               ^^^^^^^^^^^^^^^^^^^^^^^^^^^^^^^^^^^^^^^^^^^^^^^^^^^^^^^^^^^^
  File "C:\Python311\Lib\site-packages\django\views\decorators\csrf.py", line 55, in wrapped_view
    return view_func(*args, **kwargs)
           ^^^^^^^^^^^^^^^^^^^^^^^^^^
  File "C:\Python311\Lib\site-packages\django\views\generic\base.py", line 103, in view
    return self.dispatch(request, *args, **kwargs)
           ^^^^^^^^^^^^^^^^^^^^^^^^^^^^^^^^^^^^^^^
  File "C:\Python311\Lib\site-packages\rest_framework\views.py", line 509, in dispatch
    response = self.handle_exception(exc)
               ^^^^^^^^^^^^^^^^^^^^^^^^^^
  File "C:\Python311\Lib\site-packages\rest_framework\views.py", line 469, in handle_exception
    self.raise_uncaught_exception(exc)
  File "C:\Python311\Lib\site-packages\rest_framework\views.py", line 480, in raise_uncaught_exception
    raise exc
  File "C:\Python311\Lib\site-packages\rest_framework\views.py", line 497, in dispatch
    self.initial(request, *args, **kwargs)
  File "C:\Python311\Lib\site-packages\rest_framework\views.py", line 415, in initial
    self.check_permissions(request)
  File "C:\Python311\Lib\site-packages\rest_framework\views.py", line 332, in check_permissions
    if not permission.has_permission(request, self):
           ^^^^^^^^^^^^^^^^^^^^^^^^^^^^^^^^^^^^^^^^
  File "C:\Users\Maryam\Documents\GitHub\Enigma_BackEnd\Enigma\Group\permissions.py", line 10, in has_permission
    members = Members.objects.filter(userID=request.user, groupID=request.data['groupID'])
                                                                  ~~~~~~~~~~~~^^^^^^^^^^^
KeyError: 'groupID'
WARNING 2023-05-14 12:54:30,243 log 11092 10264 Not Found: /group/AddUserGroup/
WARNING 2023-05-14 13:10:51,193 log 4044 9896 Not Found: /group/AddUserGroup/
WARNING 2023-05-14 13:10:51,200 log 4044 9896 Forbidden: /group/AddUserGroup/
ERROR 2023-05-14 13:10:51,207 log 4044 9896 Internal Server Error: /group/AddUserGroup/
Traceback (most recent call last):
  File "C:\Python311\Lib\site-packages\django\core\handlers\exception.py", line 56, in inner
    response = get_response(request)
               ^^^^^^^^^^^^^^^^^^^^^
  File "C:\Python311\Lib\site-packages\django\core\handlers\base.py", line 197, in _get_response
    response = wrapped_callback(request, *callback_args, **callback_kwargs)
               ^^^^^^^^^^^^^^^^^^^^^^^^^^^^^^^^^^^^^^^^^^^^^^^^^^^^^^^^^^^^
  File "C:\Python311\Lib\site-packages\django\views\decorators\csrf.py", line 55, in wrapped_view
    return view_func(*args, **kwargs)
           ^^^^^^^^^^^^^^^^^^^^^^^^^^
  File "C:\Python311\Lib\site-packages\django\views\generic\base.py", line 103, in view
    return self.dispatch(request, *args, **kwargs)
           ^^^^^^^^^^^^^^^^^^^^^^^^^^^^^^^^^^^^^^^
  File "C:\Python311\Lib\site-packages\rest_framework\views.py", line 509, in dispatch
    response = self.handle_exception(exc)
               ^^^^^^^^^^^^^^^^^^^^^^^^^^
  File "C:\Python311\Lib\site-packages\rest_framework\views.py", line 469, in handle_exception
    self.raise_uncaught_exception(exc)
  File "C:\Python311\Lib\site-packages\rest_framework\views.py", line 480, in raise_uncaught_exception
    raise exc
  File "C:\Python311\Lib\site-packages\rest_framework\views.py", line 497, in dispatch
    self.initial(request, *args, **kwargs)
  File "C:\Python311\Lib\site-packages\rest_framework\views.py", line 415, in initial
    self.check_permissions(request)
  File "C:\Python311\Lib\site-packages\rest_framework\views.py", line 332, in check_permissions
    if not permission.has_permission(request, self):
           ^^^^^^^^^^^^^^^^^^^^^^^^^^^^^^^^^^^^^^^^
  File "C:\Users\Maryam\Documents\GitHub\Enigma_BackEnd\Enigma\Group\permissions.py", line 10, in has_permission
    members = Members.objects.filter(userID=request.user, groupID=request.data['groupID'])
                                                                  ~~~~~~~~~~~~^^^^^^^^^^^
KeyError: 'groupID'
WARNING 2023-05-14 13:10:51,239 log 4044 9896 Not Found: /group/AddUserGroup/
WARNING 2023-05-14 13:13:49,506 log 9784 292 Not Found: /group/AddUserGroup/
WARNING 2023-05-14 13:13:49,516 log 9784 292 Forbidden: /group/AddUserGroup/
ERROR 2023-05-14 13:13:49,526 log 9784 292 Internal Server Error: /group/AddUserGroup/
Traceback (most recent call last):
  File "C:\Python311\Lib\site-packages\django\db\models\fields\__init__.py", line 2018, in get_prep_value
    return int(value)
           ^^^^^^^^^^
  File "C:\Python311\Lib\site-packages\django\contrib\auth\models.py", line 437, in __int__
    raise TypeError(
TypeError: Cannot cast AnonymousUser to int. Are you trying to use it in place of User?

The above exception was the direct cause of the following exception:

Traceback (most recent call last):
  File "C:\Python311\Lib\site-packages\django\core\handlers\exception.py", line 56, in inner
    response = get_response(request)
               ^^^^^^^^^^^^^^^^^^^^^
  File "C:\Python311\Lib\site-packages\django\core\handlers\base.py", line 197, in _get_response
    response = wrapped_callback(request, *callback_args, **callback_kwargs)
               ^^^^^^^^^^^^^^^^^^^^^^^^^^^^^^^^^^^^^^^^^^^^^^^^^^^^^^^^^^^^
  File "C:\Python311\Lib\site-packages\django\views\decorators\csrf.py", line 55, in wrapped_view
    return view_func(*args, **kwargs)
           ^^^^^^^^^^^^^^^^^^^^^^^^^^
  File "C:\Python311\Lib\site-packages\django\views\generic\base.py", line 103, in view
    return self.dispatch(request, *args, **kwargs)
           ^^^^^^^^^^^^^^^^^^^^^^^^^^^^^^^^^^^^^^^
  File "C:\Python311\Lib\site-packages\rest_framework\views.py", line 509, in dispatch
    response = self.handle_exception(exc)
               ^^^^^^^^^^^^^^^^^^^^^^^^^^
  File "C:\Python311\Lib\site-packages\rest_framework\views.py", line 469, in handle_exception
    self.raise_uncaught_exception(exc)
  File "C:\Python311\Lib\site-packages\rest_framework\views.py", line 480, in raise_uncaught_exception
    raise exc
  File "C:\Python311\Lib\site-packages\rest_framework\views.py", line 497, in dispatch
    self.initial(request, *args, **kwargs)
  File "C:\Python311\Lib\site-packages\rest_framework\views.py", line 415, in initial
    self.check_permissions(request)
  File "C:\Python311\Lib\site-packages\rest_framework\views.py", line 332, in check_permissions
    if not permission.has_permission(request, self):
           ^^^^^^^^^^^^^^^^^^^^^^^^^^^^^^^^^^^^^^^^
  File "C:\Users\Maryam\Documents\GitHub\Enigma_BackEnd\Enigma\Group\permissions.py", line 10, in has_permission
    members = Members.objects.filter(userID=request.user, groupID=request.data.get('groupID'))
              ^^^^^^^^^^^^^^^^^^^^^^^^^^^^^^^^^^^^^^^^^^^^^^^^^^^^^^^^^^^^^^^^^^^^^^^^^^^^^^^^
  File "C:\Python311\Lib\site-packages\django\db\models\manager.py", line 85, in manager_method
    return getattr(self.get_queryset(), name)(*args, **kwargs)
           ^^^^^^^^^^^^^^^^^^^^^^^^^^^^^^^^^^^^^^^^^^^^^^^^^^^
  File "C:\Python311\Lib\site-packages\django\db\models\query.py", line 1421, in filter
    return self._filter_or_exclude(False, args, kwargs)
           ^^^^^^^^^^^^^^^^^^^^^^^^^^^^^^^^^^^^^^^^^^^^
  File "C:\Python311\Lib\site-packages\django\db\models\query.py", line 1439, in _filter_or_exclude
    clone._filter_or_exclude_inplace(negate, args, kwargs)
  File "C:\Python311\Lib\site-packages\django\db\models\query.py", line 1446, in _filter_or_exclude_inplace
    self._query.add_q(Q(*args, **kwargs))
  File "C:\Python311\Lib\site-packages\django\db\models\sql\query.py", line 1532, in add_q
    clause, _ = self._add_q(q_object, self.used_aliases)
                ^^^^^^^^^^^^^^^^^^^^^^^^^^^^^^^^^^^^^^^^
  File "C:\Python311\Lib\site-packages\django\db\models\sql\query.py", line 1562, in _add_q
    child_clause, needed_inner = self.build_filter(
                                 ^^^^^^^^^^^^^^^^^^
  File "C:\Python311\Lib\site-packages\django\db\models\sql\query.py", line 1478, in build_filter
    condition = self.build_lookup(lookups, col, value)
                ^^^^^^^^^^^^^^^^^^^^^^^^^^^^^^^^^^^^^^
  File "C:\Python311\Lib\site-packages\django\db\models\sql\query.py", line 1303, in build_lookup
    lookup = lookup_class(lhs, rhs)
             ^^^^^^^^^^^^^^^^^^^^^^
  File "C:\Python311\Lib\site-packages\django\db\models\lookups.py", line 27, in __init__
    self.rhs = self.get_prep_lookup()
               ^^^^^^^^^^^^^^^^^^^^^^
  File "C:\Python311\Lib\site-packages\django\db\models\fields\related_lookups.py", line 166, in get_prep_lookup
    self.rhs = target_field.get_prep_value(self.rhs)
               ^^^^^^^^^^^^^^^^^^^^^^^^^^^^^^^^^^^^^
  File "C:\Python311\Lib\site-packages\django\db\models\fields\__init__.py", line 2020, in get_prep_value
    raise e.__class__(
TypeError: Field 'user_id' expected a number but got <django.contrib.auth.models.AnonymousUser object at 0x000001E121F3E890>.
WARNING 2023-05-14 13:13:49,632 log 9784 292 Not Found: /group/AddUserGroup/
WARNING 2023-05-14 13:18:42,884 log 4892 7084 Not Found: /group/AddUserGroup/
WARNING 2023-05-14 13:18:42,890 log 4892 7084 Forbidden: /group/AddUserGroup/
ERROR 2023-05-14 13:18:42,896 log 4892 7084 Internal Server Error: /group/AddUserGroup/
Traceback (most recent call last):
  File "C:\Python311\Lib\site-packages\django\core\handlers\exception.py", line 56, in inner
    response = get_response(request)
               ^^^^^^^^^^^^^^^^^^^^^
  File "C:\Python311\Lib\site-packages\django\core\handlers\base.py", line 197, in _get_response
    response = wrapped_callback(request, *callback_args, **callback_kwargs)
               ^^^^^^^^^^^^^^^^^^^^^^^^^^^^^^^^^^^^^^^^^^^^^^^^^^^^^^^^^^^^
  File "C:\Python311\Lib\site-packages\django\views\decorators\csrf.py", line 55, in wrapped_view
    return view_func(*args, **kwargs)
           ^^^^^^^^^^^^^^^^^^^^^^^^^^
  File "C:\Python311\Lib\site-packages\django\views\generic\base.py", line 103, in view
    return self.dispatch(request, *args, **kwargs)
           ^^^^^^^^^^^^^^^^^^^^^^^^^^^^^^^^^^^^^^^
  File "C:\Python311\Lib\site-packages\rest_framework\views.py", line 509, in dispatch
    response = self.handle_exception(exc)
               ^^^^^^^^^^^^^^^^^^^^^^^^^^
  File "C:\Python311\Lib\site-packages\rest_framework\views.py", line 469, in handle_exception
    self.raise_uncaught_exception(exc)
  File "C:\Python311\Lib\site-packages\rest_framework\views.py", line 480, in raise_uncaught_exception
    raise exc
  File "C:\Python311\Lib\site-packages\rest_framework\views.py", line 497, in dispatch
    self.initial(request, *args, **kwargs)
  File "C:\Python311\Lib\site-packages\rest_framework\views.py", line 415, in initial
    self.check_permissions(request)
  File "C:\Python311\Lib\site-packages\rest_framework\views.py", line 332, in check_permissions
    if not permission.has_permission(request, self):
           ^^^^^^^^^^^^^^^^^^^^^^^^^^^^^^^^^^^^^^^^
  File "C:\Users\Maryam\Documents\GitHub\Enigma_BackEnd\Enigma\Group\permissions.py", line 12, in has_permission
    members = Members.objects.filter(userID=request.user, groupID=request.data['groupID'])
                                                                  ~~~~~~~~~~~~^^^^^^^^^^^
KeyError: 'groupID'
WARNING 2023-05-14 13:18:42,930 log 4892 7084 Not Found: /group/AddUserGroup/
WARNING 2023-05-14 13:19:17,508 log 17552 13356 Not Found: /group/AddUserGroup/
WARNING 2023-05-14 13:19:17,517 log 17552 13356 Forbidden: /group/AddUserGroup/
WARNING 2023-05-14 13:19:17,522 log 17552 13356 Not Found: /group/AddUserGroup/
WARNING 2023-05-14 13:19:17,548 log 17552 13356 Not Found: /group/AddUserGroup/
WARNING 2023-05-14 13:21:41,147 log 15616 1668 Not Found: /group/AddUserGroup/
WARNING 2023-05-14 13:21:41,156 log 15616 1668 Forbidden: /group/AddUserGroup/
WARNING 2023-05-14 13:21:41,162 log 15616 1668 Not Found: /group/AddUserGroup/
WARNING 2023-05-14 13:21:41,189 log 15616 1668 Not Found: /group/AddUserGroup/
WARNING 2023-05-14 13:34:23,711 log 17000 17300 Not Found: /group/AddUserGroup/
WARNING 2023-05-14 13:34:23,718 log 17000 17300 Forbidden: /group/AddUserGroup/
WARNING 2023-05-14 13:34:23,720 log 17000 17300 Forbidden: /group/AddUserGroup/
WARNING 2023-05-14 13:34:23,746 log 17000 17300 Not Found: /group/AddUserGroup/
WARNING 2023-05-14 13:35:34,375 log 16712 11868 Not Found: /group/AddUserGroup/
WARNING 2023-05-14 13:35:34,383 log 16712 11868 Forbidden: /group/AddUserGroup/
WARNING 2023-05-14 13:35:34,387 log 16712 11868 Forbidden: /group/AddUserGroup/
WARNING 2023-05-14 13:35:34,413 log 16712 11868 Not Found: /group/AddUserGroup/
WARNING 2023-05-14 13:35:56,896 log 10108 8040 Not Found: /group/AddUserGroup/
WARNING 2023-05-14 13:35:56,902 log 10108 8040 Forbidden: /group/AddUserGroup/
WARNING 2023-05-14 13:35:56,904 log 10108 8040 Forbidden: /group/AddUserGroup/
WARNING 2023-05-14 13:35:56,928 log 10108 8040 Not Found: /group/AddUserGroup/
WARNING 2023-05-14 13:36:17,635 log 6704 5252 Not Found: /group/AddUserGroup/
WARNING 2023-05-14 13:36:17,641 log 6704 5252 Forbidden: /group/AddUserGroup/
WARNING 2023-05-14 13:36:17,644 log 6704 5252 Forbidden: /group/AddUserGroup/
WARNING 2023-05-14 13:36:17,668 log 6704 5252 Not Found: /group/AddUserGroup/
WARNING 2023-05-14 13:41:16,413 log 17056 17036 Not Found: /group/AddUserGroup/
WARNING 2023-05-14 13:41:16,436 log 17056 17036 Forbidden: /group/AddUserGroup/
WARNING 2023-05-14 13:41:16,438 log 17056 17036 Forbidden: /group/AddUserGroup/
WARNING 2023-05-14 13:41:16,462 log 17056 17036 Not Found: /group/AddUserGroup/
WARNING 2023-05-14 13:42:00,682 log 14932 16072 Not Found: /group/AddUserGroup/
WARNING 2023-05-14 13:42:00,689 log 14932 16072 Forbidden: /group/AddUserGroup/
WARNING 2023-05-14 13:42:00,691 log 14932 16072 Forbidden: /group/AddUserGroup/
WARNING 2023-05-14 13:42:00,718 log 14932 16072 Not Found: /group/AddUserGroup/
WARNING 2023-05-14 14:13:14,652 log 13556 12028 Not Found: /group/AddUserGroup/
WARNING 2023-05-14 14:13:14,657 log 13556 12028 Forbidden: /group/AddUserGroup/
WARNING 2023-05-14 14:13:14,660 log 13556 12028 Forbidden: /group/AddUserGroup/
WARNING 2023-05-14 14:13:14,662 log 13556 12028 Forbidden: /group/AddUserGroup/
WARNING 2023-05-14 14:13:14,681 log 13556 12028 Not Found: /group/AddUserGroup/
WARNING 2023-05-14 14:19:46,660 log 16496 5992 Not Found: /group/AddUserGroup/
WARNING 2023-05-14 14:19:46,664 log 16496 5992 Forbidden: /group/AddUserGroup/
WARNING 2023-05-14 14:19:46,668 log 16496 5992 Forbidden: /group/AddUserGroup/
WARNING 2023-05-14 14:19:46,670 log 16496 5992 Forbidden: /group/AddUserGroup/
WARNING 2023-05-14 14:19:46,693 log 16496 5992 Not Found: /group/AddUserGroup/
WARNING 2023-05-14 14:20:23,869 log 13356 14172 Not Found: /group/AddUserGroup/
WARNING 2023-05-14 14:20:23,875 log 13356 14172 Forbidden: /group/AddUserGroup/
WARNING 2023-05-14 14:20:23,879 log 13356 14172 Forbidden: /group/AddUserGroup/
WARNING 2023-05-14 14:20:23,883 log 13356 14172 Forbidden: /group/AddUserGroup/
WARNING 2023-05-14 14:20:23,913 log 13356 14172 Not Found: /group/AddUserGroup/
WARNING 2023-05-14 18:40:34,597 log 12240 15556 Not Found: /group/AddUserGroup/
WARNING 2023-05-14 18:40:34,605 log 12240 15556 Forbidden: /group/AddUserGroup/
WARNING 2023-05-14 18:40:34,613 log 12240 15556 Forbidden: /group/AddUserGroup/
WARNING 2023-05-14 18:40:34,645 log 12240 15556 Not Found: /group/AddUserGroup/
WARNING 2023-05-14 18:40:34,661 log 12240 15556 Forbidden: /group/DeleteGroup/
ERROR 2023-05-14 18:40:34,669 log 12240 15556 Internal Server Error: /group/DeleteGroup/
WARNING 2023-05-14 18:40:34,677 log 12240 15556 Forbidden: /group/DeleteGroup/
ERROR 2023-05-14 18:40:34,677 log 12240 15556 Internal Server Error: /group/GroupInfo/
ERROR 2023-05-14 18:40:34,685 log 12240 15556 Internal Server Error: /group/GroupInfo/
WARNING 2023-05-14 18:40:34,685 log 12240 15556 Not Found: /group/GroupInfo/
WARNING 2023-05-14 18:40:34,701 log 12240 15556 Unauthorized: /group/GroupInfo/
WARNING 2023-05-14 18:40:34,701 log 12240 15556 Not Found: /group/GroupInfo/
WARNING 2023-05-14 18:40:34,701 log 12240 15556 Forbidden: /group/GroupInfo/
ERROR 2023-05-14 18:40:34,709 log 12240 15556 Internal Server Error: /group/ShowGroups/
WARNING 2023-05-14 18:40:34,717 log 12240 15556 Method Not Allowed: /group/ShowGroups/
WARNING 2023-05-14 18:40:34,717 log 12240 15556 Not Found: /group/ShowGroups/
WARNING 2023-05-14 18:40:34,725 log 12240 15556 Unauthorized: /group/ShowGroups/
WARNING 2023-05-14 18:40:34,733 log 12240 15556 Not Found: /group/ShowGroups/
ERROR 2023-05-14 18:40:34,749 log 12240 15556 Internal Server Error: /group/ShowMembers/
WARNING 2023-05-14 18:40:34,749 log 12240 15556 Forbidden: /group/ShowMembers/
WARNING 2023-05-14 18:40:34,765 log 12240 15556 Forbidden: /group/ShowMembers/
WARNING 2023-05-14 18:40:34,789 log 12240 15556 Forbidden: /group/ShowMembers/
ERROR 2023-05-14 18:40:34,869 log 12240 15556 Internal Server Error: /group/CreateGroup/
Traceback (most recent call last):
  File "C:\Users\PASARGAD\AppData\Local\Programs\Python\Python311\Lib\site-packages\django\core\handlers\exception.py", line 55, in inner
    response = get_response(request)
               ^^^^^^^^^^^^^^^^^^^^^
  File "C:\Users\PASARGAD\AppData\Local\Programs\Python\Python311\Lib\site-packages\django\core\handlers\base.py", line 197, in _get_response
    response = wrapped_callback(request, *callback_args, **callback_kwargs)
               ^^^^^^^^^^^^^^^^^^^^^^^^^^^^^^^^^^^^^^^^^^^^^^^^^^^^^^^^^^^^
  File "C:\Users\PASARGAD\AppData\Local\Programs\Python\Python311\Lib\site-packages\django\views\decorators\csrf.py", line 54, in wrapped_view
    return view_func(*args, **kwargs)
           ^^^^^^^^^^^^^^^^^^^^^^^^^^
  File "C:\Users\PASARGAD\AppData\Local\Programs\Python\Python311\Lib\site-packages\django\views\generic\base.py", line 103, in view
    return self.dispatch(request, *args, **kwargs)
           ^^^^^^^^^^^^^^^^^^^^^^^^^^^^^^^^^^^^^^^
  File "C:\Users\PASARGAD\AppData\Local\Programs\Python\Python311\Lib\site-packages\rest_framework\views.py", line 509, in dispatch
    response = self.handle_exception(exc)
               ^^^^^^^^^^^^^^^^^^^^^^^^^^
  File "C:\Users\PASARGAD\AppData\Local\Programs\Python\Python311\Lib\site-packages\rest_framework\views.py", line 469, in handle_exception
    self.raise_uncaught_exception(exc)
  File "C:\Users\PASARGAD\AppData\Local\Programs\Python\Python311\Lib\site-packages\rest_framework\views.py", line 480, in raise_uncaught_exception
    raise exc
  File "C:\Users\PASARGAD\AppData\Local\Programs\Python\Python311\Lib\site-packages\rest_framework\views.py", line 506, in dispatch
    response = handler(request, *args, **kwargs)
               ^^^^^^^^^^^^^^^^^^^^^^^^^^^^^^^^^
  File "E:\Exe-T8\design\Enigma_BackEnd\Enigma\Group\views.py", line 25, in post
    data["emails"] = request.data['emails']
                     ~~~~~~~~~~~~^^^^^^^^^^
KeyError: 'emails'
WARNING 2023-05-14 18:41:00,151 log 5312 3388 Forbidden: /group/DeleteGroup/
ERROR 2023-05-14 18:41:00,159 log 5312 3388 Internal Server Error: /group/DeleteGroup/
WARNING 2023-05-14 18:41:00,159 log 5312 3388 Forbidden: /group/DeleteGroup/
ERROR 2023-05-14 18:41:00,167 log 5312 3388 Internal Server Error: /group/GroupInfo/
ERROR 2023-05-14 18:41:00,175 log 5312 3388 Internal Server Error: /group/GroupInfo/
WARNING 2023-05-14 18:41:00,175 log 5312 3388 Not Found: /group/GroupInfo/
WARNING 2023-05-14 18:41:00,191 log 5312 3388 Unauthorized: /group/GroupInfo/
WARNING 2023-05-14 18:41:00,191 log 5312 3388 Not Found: /group/GroupInfo/
WARNING 2023-05-14 18:41:00,199 log 5312 3388 Forbidden: /group/GroupInfo/
ERROR 2023-05-14 18:41:00,199 log 5312 3388 Internal Server Error: /group/ShowGroups/
WARNING 2023-05-14 18:41:00,207 log 5312 3388 Method Not Allowed: /group/ShowGroups/
WARNING 2023-05-14 18:41:00,207 log 5312 3388 Not Found: /group/ShowGroups/
WARNING 2023-05-14 18:41:00,215 log 5312 3388 Unauthorized: /group/ShowGroups/
WARNING 2023-05-14 18:41:00,223 log 5312 3388 Not Found: /group/ShowGroups/
ERROR 2023-05-14 18:41:00,231 log 5312 3388 Internal Server Error: /group/ShowMembers/
WARNING 2023-05-14 18:41:00,243 log 5312 3388 Forbidden: /group/ShowMembers/
WARNING 2023-05-14 18:41:00,247 log 5312 3388 Forbidden: /group/ShowMembers/
WARNING 2023-05-14 18:41:00,275 log 5312 3388 Forbidden: /group/ShowMembers/
ERROR 2023-05-14 18:41:15,634 log 6344 10992 Internal Server Error: /group/CreateGroup/
Traceback (most recent call last):
  File "C:\Users\PASARGAD\AppData\Local\Programs\Python\Python311\Lib\site-packages\django\core\handlers\exception.py", line 55, in inner
    response = get_response(request)
               ^^^^^^^^^^^^^^^^^^^^^
  File "C:\Users\PASARGAD\AppData\Local\Programs\Python\Python311\Lib\site-packages\django\core\handlers\base.py", line 197, in _get_response
    response = wrapped_callback(request, *callback_args, **callback_kwargs)
               ^^^^^^^^^^^^^^^^^^^^^^^^^^^^^^^^^^^^^^^^^^^^^^^^^^^^^^^^^^^^
  File "C:\Users\PASARGAD\AppData\Local\Programs\Python\Python311\Lib\site-packages\django\views\decorators\csrf.py", line 54, in wrapped_view
    return view_func(*args, **kwargs)
           ^^^^^^^^^^^^^^^^^^^^^^^^^^
  File "C:\Users\PASARGAD\AppData\Local\Programs\Python\Python311\Lib\site-packages\django\views\generic\base.py", line 103, in view
    return self.dispatch(request, *args, **kwargs)
           ^^^^^^^^^^^^^^^^^^^^^^^^^^^^^^^^^^^^^^^
  File "C:\Users\PASARGAD\AppData\Local\Programs\Python\Python311\Lib\site-packages\rest_framework\views.py", line 509, in dispatch
    response = self.handle_exception(exc)
               ^^^^^^^^^^^^^^^^^^^^^^^^^^
  File "C:\Users\PASARGAD\AppData\Local\Programs\Python\Python311\Lib\site-packages\rest_framework\views.py", line 469, in handle_exception
    self.raise_uncaught_exception(exc)
  File "C:\Users\PASARGAD\AppData\Local\Programs\Python\Python311\Lib\site-packages\rest_framework\views.py", line 480, in raise_uncaught_exception
    raise exc
  File "C:\Users\PASARGAD\AppData\Local\Programs\Python\Python311\Lib\site-packages\rest_framework\views.py", line 506, in dispatch
    response = handler(request, *args, **kwargs)
               ^^^^^^^^^^^^^^^^^^^^^^^^^^^^^^^^^
  File "E:\Exe-T8\design\Enigma_BackEnd\Enigma\Group\views.py", line 25, in post
    data["emails"] = request.data['emails']
                     ~~~~~~~~~~~~^^^^^^^^^^
KeyError: 'emails'
WARNING 2023-05-14 18:41:52,689 log 10644 15184 Not Found: /group/AddUserGroup/
WARNING 2023-05-14 18:41:52,697 log 10644 15184 Forbidden: /group/AddUserGroup/
WARNING 2023-05-14 18:41:52,705 log 10644 15184 Forbidden: /group/AddUserGroup/
WARNING 2023-05-14 18:41:52,741 log 10644 15184 Not Found: /group/AddUserGroup/
WARNING 2023-05-14 18:55:36,618 log 6704 1404 Bad Request: /buy/UserGroupBuys/
ERROR 2023-05-14 18:55:36,634 log 6704 1404 Internal Server Error: /buy/UserGroupBuys/
WARNING 2023-05-14 18:55:36,666 log 6704 1404 Bad Request: /buy/UserGroupBuys/
WARNING 2023-05-14 18:55:36,674 log 6704 1404 Unauthorized: /buy/UserGroupBuys/
WARNING 2023-05-14 18:55:36,751 log 6704 1404 Forbidden: /buy/UserGroupBuys/
WARNING 2023-05-14 18:56:17,344 log 10596 9308 Forbidden: /buy/GetGroupBuys/
WARNING 2023-05-14 18:56:17,360 log 10596 9308 Bad Request: /buy/UserGroupBuys/
ERROR 2023-05-14 18:56:17,376 log 10596 9308 Internal Server Error: /buy/UserGroupBuys/
WARNING 2023-05-14 18:56:17,408 log 10596 9308 Bad Request: /buy/UserGroupBuys/
WARNING 2023-05-14 18:56:17,408 log 10596 9308 Unauthorized: /buy/UserGroupBuys/
WARNING 2023-05-14 18:56:17,472 log 10596 9308 Forbidden: /buy/UserGroupBuys/
WARNING 2023-05-14 18:57:04,545 log 5672 17172 Bad Request: /buy/UserGroupBuys/
ERROR 2023-05-14 18:57:04,553 log 5672 17172 Internal Server Error: /buy/UserGroupBuys/
WARNING 2023-05-14 18:57:04,593 log 5672 17172 Bad Request: /buy/UserGroupBuys/
WARNING 2023-05-14 18:57:04,601 log 5672 17172 Unauthorized: /buy/UserGroupBuys/
WARNING 2023-05-14 18:57:04,665 log 5672 17172 Forbidden: /buy/UserGroupBuys/
WARNING 2023-05-14 18:57:17,088 log 8240 8872 Bad Request: /buy/UserGroupBuys/
ERROR 2023-05-14 18:57:17,096 log 8240 8872 Internal Server Error: /buy/UserGroupBuys/
WARNING 2023-05-14 18:57:17,136 log 8240 8872 Bad Request: /buy/UserGroupBuys/
WARNING 2023-05-14 18:57:17,136 log 8240 8872 Unauthorized: /buy/UserGroupBuys/
WARNING 2023-05-14 18:57:17,208 log 8240 8872 Forbidden: /buy/UserGroupBuys/
WARNING 2023-05-14 18:59:06,095 log 9896 16936 Bad Request: /buy/UserGroupBuys/
ERROR 2023-05-14 18:59:06,103 log 9896 16936 Internal Server Error: /buy/UserGroupBuys/
WARNING 2023-05-14 18:59:06,135 log 9896 16936 Bad Request: /buy/UserGroupBuys/
WARNING 2023-05-14 18:59:06,143 log 9896 16936 Unauthorized: /buy/UserGroupBuys/
WARNING 2023-05-14 18:59:06,207 log 9896 16936 Forbidden: /buy/UserGroupBuys/
WARNING 2023-05-14 19:00:31,154 log 4976 12800 Forbidden: /buy/GetGroupBuys/
WARNING 2023-05-14 19:00:31,178 log 4976 12800 Bad Request: /buy/UserGroupBuys/
ERROR 2023-05-14 19:00:31,187 log 4976 12800 Internal Server Error: /buy/UserGroupBuys/
WARNING 2023-05-14 19:00:31,218 log 4976 12800 Bad Request: /buy/UserGroupBuys/
WARNING 2023-05-14 19:00:31,227 log 4976 12800 Unauthorized: /buy/UserGroupBuys/
WARNING 2023-05-14 19:00:31,290 log 4976 12800 Forbidden: /buy/UserGroupBuys/
INFO 2023-05-14 19:06:54,710 autoreload 9572 16780 Watching for file changes with StatReloader
WARNING 2023-05-14 19:07:17,024 log 9572 13076 Bad Request: /auth/token/
WARNING 2023-05-14 19:07:17,024 basehttp 9572 13076 "POST /auth/token/?access_token=151d1f4eddc4f0c37baa37133170c17ff9d287fb HTTP/1.1" 400 68
INFO 2023-05-14 19:07:29,603 basehttp 9572 13076 "POST /auth/register/ HTTP/1.1" 201 65
INFO 2023-05-14 19:07:34,641 basehttp 9572 13076 "POST /auth/token/?access_token=151d1f4eddc4f0c37baa37133170c17ff9d287fb HTTP/1.1" 200 52
INFO 2023-05-14 19:10:18,482 autoreload 9572 16780 E:\Exe-T8\design\Enigma_BackEnd\Enigma\buy\views.py changed, reloading.
INFO 2023-05-14 19:10:19,901 autoreload 14540 16992 Watching for file changes with StatReloader
WARNING 2023-05-14 19:15:13,717 log 5852 13252 Forbidden: /buy/GetGroupBuys/
WARNING 2023-05-14 19:15:13,736 log 5852 13252 Bad Request: /buy/UserGroupBuys/
ERROR 2023-05-14 19:15:13,749 log 5852 13252 Internal Server Error: /buy/UserGroupBuys/
WARNING 2023-05-14 19:15:13,813 log 5852 13252 Bad Request: /buy/UserGroupBuys/
WARNING 2023-05-14 19:15:13,850 log 5852 13252 Unauthorized: /buy/UserGroupBuys/
WARNING 2023-05-14 19:15:13,933 log 5852 13252 Forbidden: /buy/UserGroupBuys/
WARNING 2023-05-14 19:15:43,767 log 8316 4976 Forbidden: /buy/GetGroupBuys/
WARNING 2023-05-14 19:15:43,785 log 8316 4976 Bad Request: /buy/UserGroupBuys/
ERROR 2023-05-14 19:15:43,792 log 8316 4976 Internal Server Error: /buy/UserGroupBuys/
WARNING 2023-05-14 19:15:43,826 log 8316 4976 Bad Request: /buy/UserGroupBuys/
WARNING 2023-05-14 19:15:43,834 log 8316 4976 Unauthorized: /buy/UserGroupBuys/
WARNING 2023-05-14 19:15:43,893 log 8316 4976 Forbidden: /buy/UserGroupBuys/
WARNING 2023-05-14 19:16:22,153 log 9672 5732 Forbidden: /buy/GetGroupBuys/
WARNING 2023-05-14 19:16:22,173 log 9672 5732 Forbidden: /buy/GetGroupBuys/
WARNING 2023-05-14 19:16:22,194 log 9672 5732 Bad Request: /buy/UserGroupBuys/
ERROR 2023-05-14 19:16:22,203 log 9672 5732 Internal Server Error: /buy/UserGroupBuys/
WARNING 2023-05-14 19:16:22,236 log 9672 5732 Bad Request: /buy/UserGroupBuys/
WARNING 2023-05-14 19:16:22,242 log 9672 5732 Unauthorized: /buy/UserGroupBuys/
WARNING 2023-05-14 19:16:22,306 log 9672 5732 Forbidden: /buy/UserGroupBuys/
WARNING 2023-05-14 19:17:17,514 log 10884 16852 Forbidden: /buy/GetGroupBuys/
WARNING 2023-05-14 19:17:17,518 log 10884 16852 Forbidden: /buy/GetGroupBuys/
WARNING 2023-05-14 19:17:17,535 log 10884 16852 Forbidden: /buy/GetGroupBuys/
WARNING 2023-05-14 19:17:17,554 log 10884 16852 Bad Request: /buy/UserGroupBuys/
ERROR 2023-05-14 19:17:17,566 log 10884 16852 Internal Server Error: /buy/UserGroupBuys/
WARNING 2023-05-14 19:17:17,599 log 10884 16852 Bad Request: /buy/UserGroupBuys/
WARNING 2023-05-14 19:17:17,604 log 10884 16852 Unauthorized: /buy/UserGroupBuys/
WARNING 2023-05-14 19:17:17,670 log 10884 16852 Forbidden: /buy/UserGroupBuys/
ERROR 2023-05-14 19:17:42,257 log 9504 12608 Internal Server Error: /buy/GetGroupBuys/
Traceback (most recent call last):
  File "C:\Users\PASARGAD\AppData\Local\Programs\Python\Python311\Lib\site-packages\django\utils\datastructures.py", line 84, in __getitem__
    list_ = super().__getitem__(key)
            ^^^^^^^^^^^^^^^^^^^^^^^^
KeyError: 'groupID'

During handling of the above exception, another exception occurred:

Traceback (most recent call last):
  File "C:\Users\PASARGAD\AppData\Local\Programs\Python\Python311\Lib\site-packages\django\core\handlers\exception.py", line 55, in inner
    response = get_response(request)
               ^^^^^^^^^^^^^^^^^^^^^
  File "C:\Users\PASARGAD\AppData\Local\Programs\Python\Python311\Lib\site-packages\django\core\handlers\base.py", line 197, in _get_response
    response = wrapped_callback(request, *callback_args, **callback_kwargs)
               ^^^^^^^^^^^^^^^^^^^^^^^^^^^^^^^^^^^^^^^^^^^^^^^^^^^^^^^^^^^^
  File "C:\Users\PASARGAD\AppData\Local\Programs\Python\Python311\Lib\site-packages\django\views\decorators\csrf.py", line 54, in wrapped_view
    return view_func(*args, **kwargs)
           ^^^^^^^^^^^^^^^^^^^^^^^^^^
  File "C:\Users\PASARGAD\AppData\Local\Programs\Python\Python311\Lib\site-packages\django\views\generic\base.py", line 103, in view
    return self.dispatch(request, *args, **kwargs)
           ^^^^^^^^^^^^^^^^^^^^^^^^^^^^^^^^^^^^^^^
  File "C:\Users\PASARGAD\AppData\Local\Programs\Python\Python311\Lib\site-packages\rest_framework\views.py", line 509, in dispatch
    response = self.handle_exception(exc)
               ^^^^^^^^^^^^^^^^^^^^^^^^^^
  File "C:\Users\PASARGAD\AppData\Local\Programs\Python\Python311\Lib\site-packages\rest_framework\views.py", line 469, in handle_exception
    self.raise_uncaught_exception(exc)
  File "C:\Users\PASARGAD\AppData\Local\Programs\Python\Python311\Lib\site-packages\rest_framework\views.py", line 480, in raise_uncaught_exception
    raise exc
  File "C:\Users\PASARGAD\AppData\Local\Programs\Python\Python311\Lib\site-packages\rest_framework\views.py", line 506, in dispatch
    response = handler(request, *args, **kwargs)
               ^^^^^^^^^^^^^^^^^^^^^^^^^^^^^^^^^
  File "E:\Exe-T8\design\Enigma_BackEnd\Enigma\buy\views.py", line 36, in post
    perch = buy.objects.filter(groupID=request.data['groupID'])
                                       ~~~~~~~~~~~~^^^^^^^^^^^
  File "C:\Users\PASARGAD\AppData\Local\Programs\Python\Python311\Lib\site-packages\django\utils\datastructures.py", line 86, in __getitem__
    raise MultiValueDictKeyError(key)
django.utils.datastructures.MultiValueDictKeyError: 'groupID'
WARNING 2023-05-14 19:17:42,289 log 9504 12608 Unauthorized: /buy/GetGroupBuys/
WARNING 2023-05-14 19:17:42,307 log 9504 12608 Bad Request: /buy/UserGroupBuys/
ERROR 2023-05-14 19:17:42,317 log 9504 12608 Internal Server Error: /buy/UserGroupBuys/
WARNING 2023-05-14 19:17:42,349 log 9504 12608 Bad Request: /buy/UserGroupBuys/
WARNING 2023-05-14 19:17:42,354 log 9504 12608 Unauthorized: /buy/UserGroupBuys/
WARNING 2023-05-14 19:17:42,419 log 9504 12608 Forbidden: /buy/UserGroupBuys/
ERROR 2023-05-14 19:18:01,267 log 7444 10368 Internal Server Error: /buy/GetGroupBuys/
Traceback (most recent call last):
  File "C:\Users\PASARGAD\AppData\Local\Programs\Python\Python311\Lib\site-packages\django\utils\datastructures.py", line 84, in __getitem__
    list_ = super().__getitem__(key)
            ^^^^^^^^^^^^^^^^^^^^^^^^
KeyError: 'groupID'

During handling of the above exception, another exception occurred:

Traceback (most recent call last):
  File "C:\Users\PASARGAD\AppData\Local\Programs\Python\Python311\Lib\site-packages\django\core\handlers\exception.py", line 55, in inner
    response = get_response(request)
               ^^^^^^^^^^^^^^^^^^^^^
  File "C:\Users\PASARGAD\AppData\Local\Programs\Python\Python311\Lib\site-packages\django\core\handlers\base.py", line 197, in _get_response
    response = wrapped_callback(request, *callback_args, **callback_kwargs)
               ^^^^^^^^^^^^^^^^^^^^^^^^^^^^^^^^^^^^^^^^^^^^^^^^^^^^^^^^^^^^
  File "C:\Users\PASARGAD\AppData\Local\Programs\Python\Python311\Lib\site-packages\django\views\decorators\csrf.py", line 54, in wrapped_view
    return view_func(*args, **kwargs)
           ^^^^^^^^^^^^^^^^^^^^^^^^^^
  File "C:\Users\PASARGAD\AppData\Local\Programs\Python\Python311\Lib\site-packages\django\views\generic\base.py", line 103, in view
    return self.dispatch(request, *args, **kwargs)
           ^^^^^^^^^^^^^^^^^^^^^^^^^^^^^^^^^^^^^^^
  File "C:\Users\PASARGAD\AppData\Local\Programs\Python\Python311\Lib\site-packages\rest_framework\views.py", line 509, in dispatch
    response = self.handle_exception(exc)
               ^^^^^^^^^^^^^^^^^^^^^^^^^^
  File "C:\Users\PASARGAD\AppData\Local\Programs\Python\Python311\Lib\site-packages\rest_framework\views.py", line 469, in handle_exception
    self.raise_uncaught_exception(exc)
  File "C:\Users\PASARGAD\AppData\Local\Programs\Python\Python311\Lib\site-packages\rest_framework\views.py", line 480, in raise_uncaught_exception
    raise exc
  File "C:\Users\PASARGAD\AppData\Local\Programs\Python\Python311\Lib\site-packages\rest_framework\views.py", line 506, in dispatch
    response = handler(request, *args, **kwargs)
               ^^^^^^^^^^^^^^^^^^^^^^^^^^^^^^^^^
  File "E:\Exe-T8\design\Enigma_BackEnd\Enigma\buy\views.py", line 36, in post
    perch = buy.objects.filter(groupID=request.data['groupID'])
                                       ~~~~~~~~~~~~^^^^^^^^^^^
  File "C:\Users\PASARGAD\AppData\Local\Programs\Python\Python311\Lib\site-packages\django\utils\datastructures.py", line 86, in __getitem__
    raise MultiValueDictKeyError(key)
django.utils.datastructures.MultiValueDictKeyError: 'groupID'
WARNING 2023-05-14 19:18:01,292 log 7444 10368 Unauthorized: /buy/GetGroupBuys/
WARNING 2023-05-14 19:18:01,307 log 7444 10368 Bad Request: /buy/UserGroupBuys/
ERROR 2023-05-14 19:18:01,318 log 7444 10368 Internal Server Error: /buy/UserGroupBuys/
WARNING 2023-05-14 19:18:01,352 log 7444 10368 Bad Request: /buy/UserGroupBuys/
WARNING 2023-05-14 19:18:01,358 log 7444 10368 Unauthorized: /buy/UserGroupBuys/
WARNING 2023-05-14 19:18:01,422 log 7444 10368 Forbidden: /buy/UserGroupBuys/
ERROR 2023-05-14 19:18:21,174 log 16276 1340 Internal Server Error: /buy/GetGroupBuys/
Traceback (most recent call last):
  File "C:\Users\PASARGAD\AppData\Local\Programs\Python\Python311\Lib\site-packages\django\utils\datastructures.py", line 84, in __getitem__
    list_ = super().__getitem__(key)
            ^^^^^^^^^^^^^^^^^^^^^^^^
KeyError: 'groupID'

During handling of the above exception, another exception occurred:

Traceback (most recent call last):
  File "C:\Users\PASARGAD\AppData\Local\Programs\Python\Python311\Lib\site-packages\django\core\handlers\exception.py", line 55, in inner
    response = get_response(request)
               ^^^^^^^^^^^^^^^^^^^^^
  File "C:\Users\PASARGAD\AppData\Local\Programs\Python\Python311\Lib\site-packages\django\core\handlers\base.py", line 197, in _get_response
    response = wrapped_callback(request, *callback_args, **callback_kwargs)
               ^^^^^^^^^^^^^^^^^^^^^^^^^^^^^^^^^^^^^^^^^^^^^^^^^^^^^^^^^^^^
  File "C:\Users\PASARGAD\AppData\Local\Programs\Python\Python311\Lib\site-packages\django\views\decorators\csrf.py", line 54, in wrapped_view
    return view_func(*args, **kwargs)
           ^^^^^^^^^^^^^^^^^^^^^^^^^^
  File "C:\Users\PASARGAD\AppData\Local\Programs\Python\Python311\Lib\site-packages\django\views\generic\base.py", line 103, in view
    return self.dispatch(request, *args, **kwargs)
           ^^^^^^^^^^^^^^^^^^^^^^^^^^^^^^^^^^^^^^^
  File "C:\Users\PASARGAD\AppData\Local\Programs\Python\Python311\Lib\site-packages\rest_framework\views.py", line 509, in dispatch
    response = self.handle_exception(exc)
               ^^^^^^^^^^^^^^^^^^^^^^^^^^
  File "C:\Users\PASARGAD\AppData\Local\Programs\Python\Python311\Lib\site-packages\rest_framework\views.py", line 469, in handle_exception
    self.raise_uncaught_exception(exc)
  File "C:\Users\PASARGAD\AppData\Local\Programs\Python\Python311\Lib\site-packages\rest_framework\views.py", line 480, in raise_uncaught_exception
    raise exc
  File "C:\Users\PASARGAD\AppData\Local\Programs\Python\Python311\Lib\site-packages\rest_framework\views.py", line 506, in dispatch
    response = handler(request, *args, **kwargs)
               ^^^^^^^^^^^^^^^^^^^^^^^^^^^^^^^^^
  File "E:\Exe-T8\design\Enigma_BackEnd\Enigma\buy\views.py", line 36, in post
    perch = buy.objects.filter(groupID=request.data['groupID'])
                                       ~~~~~~~~~~~~^^^^^^^^^^^
  File "C:\Users\PASARGAD\AppData\Local\Programs\Python\Python311\Lib\site-packages\django\utils\datastructures.py", line 86, in __getitem__
    raise MultiValueDictKeyError(key)
django.utils.datastructures.MultiValueDictKeyError: 'groupID'
WARNING 2023-05-14 19:18:21,201 log 16276 1340 Unauthorized: /buy/GetGroupBuys/
WARNING 2023-05-14 19:18:21,217 log 16276 1340 Bad Request: /buy/UserGroupBuys/
ERROR 2023-05-14 19:18:21,225 log 16276 1340 Internal Server Error: /buy/UserGroupBuys/
WARNING 2023-05-14 19:18:21,260 log 16276 1340 Bad Request: /buy/UserGroupBuys/
WARNING 2023-05-14 19:18:21,266 log 16276 1340 Unauthorized: /buy/UserGroupBuys/
WARNING 2023-05-14 19:18:21,330 log 16276 1340 Forbidden: /buy/UserGroupBuys/
ERROR 2023-05-14 19:19:03,258 log 16256 1844 Internal Server Error: /buy/GetGroupBuys/
Traceback (most recent call last):
  File "C:\Users\PASARGAD\AppData\Local\Programs\Python\Python311\Lib\site-packages\django\utils\datastructures.py", line 84, in __getitem__
    list_ = super().__getitem__(key)
            ^^^^^^^^^^^^^^^^^^^^^^^^
KeyError: 'groupID'

During handling of the above exception, another exception occurred:

Traceback (most recent call last):
  File "C:\Users\PASARGAD\AppData\Local\Programs\Python\Python311\Lib\site-packages\django\core\handlers\exception.py", line 55, in inner
    response = get_response(request)
               ^^^^^^^^^^^^^^^^^^^^^
  File "C:\Users\PASARGAD\AppData\Local\Programs\Python\Python311\Lib\site-packages\django\core\handlers\base.py", line 197, in _get_response
    response = wrapped_callback(request, *callback_args, **callback_kwargs)
               ^^^^^^^^^^^^^^^^^^^^^^^^^^^^^^^^^^^^^^^^^^^^^^^^^^^^^^^^^^^^
  File "C:\Users\PASARGAD\AppData\Local\Programs\Python\Python311\Lib\site-packages\django\views\decorators\csrf.py", line 54, in wrapped_view
    return view_func(*args, **kwargs)
           ^^^^^^^^^^^^^^^^^^^^^^^^^^
  File "C:\Users\PASARGAD\AppData\Local\Programs\Python\Python311\Lib\site-packages\django\views\generic\base.py", line 103, in view
    return self.dispatch(request, *args, **kwargs)
           ^^^^^^^^^^^^^^^^^^^^^^^^^^^^^^^^^^^^^^^
  File "C:\Users\PASARGAD\AppData\Local\Programs\Python\Python311\Lib\site-packages\rest_framework\views.py", line 509, in dispatch
    response = self.handle_exception(exc)
               ^^^^^^^^^^^^^^^^^^^^^^^^^^
  File "C:\Users\PASARGAD\AppData\Local\Programs\Python\Python311\Lib\site-packages\rest_framework\views.py", line 469, in handle_exception
    self.raise_uncaught_exception(exc)
  File "C:\Users\PASARGAD\AppData\Local\Programs\Python\Python311\Lib\site-packages\rest_framework\views.py", line 480, in raise_uncaught_exception
    raise exc
  File "C:\Users\PASARGAD\AppData\Local\Programs\Python\Python311\Lib\site-packages\rest_framework\views.py", line 506, in dispatch
    response = handler(request, *args, **kwargs)
               ^^^^^^^^^^^^^^^^^^^^^^^^^^^^^^^^^
  File "E:\Exe-T8\design\Enigma_BackEnd\Enigma\buy\views.py", line 36, in post
    perch = buy.objects.filter(groupID=request.data['groupID'])
                                       ~~~~~~~~~~~~^^^^^^^^^^^
  File "C:\Users\PASARGAD\AppData\Local\Programs\Python\Python311\Lib\site-packages\django\utils\datastructures.py", line 86, in __getitem__
    raise MultiValueDictKeyError(key)
django.utils.datastructures.MultiValueDictKeyError: 'groupID'
WARNING 2023-05-14 19:19:03,284 log 16256 1844 Unauthorized: /buy/GetGroupBuys/
WARNING 2023-05-14 19:19:03,307 log 16256 1844 Bad Request: /buy/UserGroupBuys/
ERROR 2023-05-14 19:19:03,316 log 16256 1844 Internal Server Error: /buy/UserGroupBuys/
WARNING 2023-05-14 19:19:03,354 log 16256 1844 Bad Request: /buy/UserGroupBuys/
WARNING 2023-05-14 19:19:03,359 log 16256 1844 Unauthorized: /buy/UserGroupBuys/
WARNING 2023-05-14 19:19:03,427 log 16256 1844 Forbidden: /buy/UserGroupBuys/
WARNING 2023-05-14 19:19:33,841 log 17268 2736 Forbidden: /buy/GetGroupBuys/
WARNING 2023-05-14 19:19:33,846 log 17268 2736 Forbidden: /buy/GetGroupBuys/
WARNING 2023-05-14 19:19:33,865 log 17268 2736 Forbidden: /buy/GetGroupBuys/
WARNING 2023-05-14 19:19:33,884 log 17268 2736 Bad Request: /buy/UserGroupBuys/
ERROR 2023-05-14 19:19:33,897 log 17268 2736 Internal Server Error: /buy/UserGroupBuys/
WARNING 2023-05-14 19:19:33,930 log 17268 2736 Bad Request: /buy/UserGroupBuys/
WARNING 2023-05-14 19:19:33,934 log 17268 2736 Unauthorized: /buy/UserGroupBuys/
WARNING 2023-05-14 19:19:34,005 log 17268 2736 Forbidden: /buy/UserGroupBuys/
WARNING 2023-05-14 19:20:00,867 log 2592 10204 Forbidden: /buy/GetGroupBuys/
WARNING 2023-05-14 19:20:00,870 log 2592 10204 Forbidden: /buy/GetGroupBuys/
WARNING 2023-05-14 19:20:00,890 log 2592 10204 Forbidden: /buy/GetGroupBuys/
WARNING 2023-05-14 19:20:00,909 log 2592 10204 Bad Request: /buy/UserGroupBuys/
ERROR 2023-05-14 19:20:00,920 log 2592 10204 Internal Server Error: /buy/UserGroupBuys/
WARNING 2023-05-14 19:20:00,952 log 2592 10204 Bad Request: /buy/UserGroupBuys/
WARNING 2023-05-14 19:20:00,957 log 2592 10204 Unauthorized: /buy/UserGroupBuys/
WARNING 2023-05-14 19:20:01,023 log 2592 10204 Forbidden: /buy/UserGroupBuys/
INFO 2023-05-14 19:21:07,038 autoreload 6440 6072 Watching for file changes with StatReloader
INFO 2023-05-14 19:21:21,126 basehttp 6440 17132 "POST /auth/token/?access_token=151d1f4eddc4f0c37baa37133170c17ff9d287fb HTTP/1.1" 200 52
INFO 2023-05-14 19:21:46,693 basehttp 6440 17132 "POST /buy/UserGroupBuys/ HTTP/1.1" 200 1849
INFO 2023-05-14 19:22:20,031 basehttp 6440 17132 "POST /buy/GetGroupBuys/ HTTP/1.1" 200 2684
WARNING 2023-05-14 19:22:43,936 log 6440 17132 Forbidden: /buy/GetGroupBuys/
WARNING 2023-05-14 19:22:43,937 basehttp 6440 17132 "POST /buy/GetGroupBuys/ HTTP/1.1" 403 63
INFO 2023-05-14 19:22:51,625 basehttp 6440 17132 "POST /buy/GetGroupBuys/ HTTP/1.1" 200 2684
WARNING 2023-05-14 19:22:56,594 log 6440 17132 Forbidden: /buy/GetGroupBuys/
WARNING 2023-05-14 19:22:56,594 basehttp 6440 17132 "POST /buy/GetGroupBuys/ HTTP/1.1" 403 63
WARNING 2023-05-14 19:23:20,525 log 13556 17372 Forbidden: /buy/GetGroupBuys/
WARNING 2023-05-14 19:23:20,529 log 13556 17372 Forbidden: /buy/GetGroupBuys/
WARNING 2023-05-14 19:23:20,562 log 13556 17372 Forbidden: /buy/GetGroupBuys/
WARNING 2023-05-14 19:23:20,585 log 13556 17372 Bad Request: /buy/UserGroupBuys/
ERROR 2023-05-14 19:23:20,594 log 13556 17372 Internal Server Error: /buy/UserGroupBuys/
WARNING 2023-05-14 19:23:20,631 log 13556 17372 Bad Request: /buy/UserGroupBuys/
WARNING 2023-05-14 19:23:20,638 log 13556 17372 Unauthorized: /buy/UserGroupBuys/
WARNING 2023-05-14 19:23:20,703 log 13556 17372 Forbidden: /buy/UserGroupBuys/
WARNING 2023-05-14 19:26:39,646 log 14192 7200 Forbidden: /buy/GetGroupBuys/
WARNING 2023-05-14 19:26:39,649 log 14192 7200 Forbidden: /buy/GetGroupBuys/
WARNING 2023-05-14 19:26:39,674 log 14192 7200 Forbidden: /buy/GetGroupBuys/
WARNING 2023-05-14 19:26:39,695 log 14192 7200 Bad Request: /buy/UserGroupBuys/
ERROR 2023-05-14 19:26:39,706 log 14192 7200 Internal Server Error: /buy/UserGroupBuys/
WARNING 2023-05-14 19:26:39,739 log 14192 7200 Bad Request: /buy/UserGroupBuys/
WARNING 2023-05-14 19:26:39,748 log 14192 7200 Unauthorized: /buy/UserGroupBuys/
WARNING 2023-05-14 19:26:39,814 log 14192 7200 Forbidden: /buy/UserGroupBuys/
WARNING 2023-05-14 19:27:34,207 log 7844 10884 Forbidden: /buy/GetGroupBuys/
WARNING 2023-05-14 19:27:34,211 log 7844 10884 Forbidden: /buy/GetGroupBuys/
WARNING 2023-05-14 19:27:34,258 log 7844 10884 Forbidden: /buy/GetGroupBuys/
WARNING 2023-05-14 19:27:34,278 log 7844 10884 Bad Request: /buy/UserGroupBuys/
ERROR 2023-05-14 19:27:34,289 log 7844 10884 Internal Server Error: /buy/UserGroupBuys/
WARNING 2023-05-14 19:27:34,322 log 7844 10884 Bad Request: /buy/UserGroupBuys/
WARNING 2023-05-14 19:27:34,327 log 7844 10884 Unauthorized: /buy/UserGroupBuys/
WARNING 2023-05-14 19:27:34,399 log 7844 10884 Forbidden: /buy/UserGroupBuys/
WARNING 2023-05-14 19:27:57,535 log 13264 17204 Forbidden: /buy/GetGroupBuys/
WARNING 2023-05-14 19:27:57,540 log 13264 17204 Forbidden: /buy/GetGroupBuys/
WARNING 2023-05-14 19:27:57,584 log 13264 17204 Forbidden: /buy/GetGroupBuys/
WARNING 2023-05-14 19:27:57,605 log 13264 17204 Bad Request: /buy/UserGroupBuys/
ERROR 2023-05-14 19:27:57,617 log 13264 17204 Internal Server Error: /buy/UserGroupBuys/
WARNING 2023-05-14 19:27:57,655 log 13264 17204 Bad Request: /buy/UserGroupBuys/
WARNING 2023-05-14 19:27:57,662 log 13264 17204 Unauthorized: /buy/UserGroupBuys/
WARNING 2023-05-14 19:27:57,735 log 13264 17204 Forbidden: /buy/UserGroupBuys/
WARNING 2023-05-14 19:29:26,431 log 16396 17220 Forbidden: /buy/GetGroupBuys/
WARNING 2023-05-14 19:29:26,435 log 16396 17220 Forbidden: /buy/GetGroupBuys/
WARNING 2023-05-14 19:29:26,494 log 16396 17220 Forbidden: /buy/GetGroupBuys/
WARNING 2023-05-14 19:29:26,515 log 16396 17220 Bad Request: /buy/UserGroupBuys/
ERROR 2023-05-14 19:29:26,525 log 16396 17220 Internal Server Error: /buy/UserGroupBuys/
WARNING 2023-05-14 19:29:26,561 log 16396 17220 Bad Request: /buy/UserGroupBuys/
WARNING 2023-05-14 19:29:26,567 log 16396 17220 Unauthorized: /buy/UserGroupBuys/
WARNING 2023-05-14 19:29:26,630 log 16396 17220 Forbidden: /buy/UserGroupBuys/
WARNING 2023-05-14 19:33:07,821 log 15972 3004 Forbidden: /buy/GetGroupBuys/
WARNING 2023-05-14 19:33:07,861 log 15972 3004 Forbidden: /buy/GetGroupBuys/
WARNING 2023-05-14 19:33:07,866 log 15972 3004 Forbidden: /buy/GetGroupBuys/
WARNING 2023-05-14 19:33:07,919 log 15972 3004 Forbidden: /buy/GetGroupBuys/
WARNING 2023-05-14 19:33:07,938 log 15972 3004 Bad Request: /buy/UserGroupBuys/
ERROR 2023-05-14 19:33:07,949 log 15972 3004 Internal Server Error: /buy/UserGroupBuys/
WARNING 2023-05-14 19:33:07,984 log 15972 3004 Bad Request: /buy/UserGroupBuys/
WARNING 2023-05-14 19:33:07,988 log 15972 3004 Unauthorized: /buy/UserGroupBuys/
WARNING 2023-05-14 19:33:08,058 log 15972 3004 Forbidden: /buy/UserGroupBuys/
WARNING 2023-05-14 19:33:24,773 log 5420 15652 Forbidden: /buy/GetGroupBuys/
WARNING 2023-05-14 19:33:24,945 log 5420 15652 Forbidden: /buy/GetGroupBuys/
WARNING 2023-05-14 19:33:24,998 log 5420 15652 Forbidden: /buy/GetGroupBuys/
WARNING 2023-05-14 19:33:25,016 log 5420 15652 Bad Request: /buy/UserGroupBuys/
ERROR 2023-05-14 19:33:25,024 log 5420 15652 Internal Server Error: /buy/UserGroupBuys/
WARNING 2023-05-14 19:33:25,059 log 5420 15652 Bad Request: /buy/UserGroupBuys/
WARNING 2023-05-14 19:33:25,067 log 5420 15652 Unauthorized: /buy/UserGroupBuys/
WARNING 2023-05-14 19:33:25,127 log 5420 15652 Forbidden: /buy/UserGroupBuys/
WARNING 2023-05-14 19:33:54,864 log 14736 1588 Forbidden: /buy/GetGroupBuys/
WARNING 2023-05-14 19:33:55,035 log 14736 1588 Forbidden: /buy/GetGroupBuys/
WARNING 2023-05-14 19:33:55,089 log 14736 1588 Forbidden: /buy/GetGroupBuys/
WARNING 2023-05-14 19:33:55,107 log 14736 1588 Bad Request: /buy/UserGroupBuys/
ERROR 2023-05-14 19:33:55,119 log 14736 1588 Internal Server Error: /buy/UserGroupBuys/
WARNING 2023-05-14 19:33:55,151 log 14736 1588 Bad Request: /buy/UserGroupBuys/
WARNING 2023-05-14 19:33:55,155 log 14736 1588 Unauthorized: /buy/UserGroupBuys/
WARNING 2023-05-14 19:33:55,220 log 14736 1588 Forbidden: /buy/UserGroupBuys/
WARNING 2023-05-14 19:35:59,233 log 2056 1116 Forbidden: /buy/GetGroupBuys/
WARNING 2023-05-14 19:35:59,416 log 2056 1116 Forbidden: /buy/GetGroupBuys/
WARNING 2023-05-14 19:35:59,483 log 2056 1116 Forbidden: /buy/GetGroupBuys/
WARNING 2023-05-14 19:35:59,501 log 2056 1116 Bad Request: /buy/UserGroupBuys/
ERROR 2023-05-14 19:35:59,513 log 2056 1116 Internal Server Error: /buy/UserGroupBuys/
WARNING 2023-05-14 19:35:59,548 log 2056 1116 Bad Request: /buy/UserGroupBuys/
WARNING 2023-05-14 19:35:59,553 log 2056 1116 Unauthorized: /buy/UserGroupBuys/
WARNING 2023-05-14 19:35:59,618 log 2056 1116 Forbidden: /buy/UserGroupBuys/
WARNING 2023-05-14 19:36:21,238 log 12796 7212 Forbidden: /buy/GetGroupBuys/
WARNING 2023-05-14 19:36:21,410 log 12796 7212 Forbidden: /buy/GetGroupBuys/
WARNING 2023-05-14 19:36:21,462 log 12796 7212 Forbidden: /buy/GetGroupBuys/
WARNING 2023-05-14 19:36:21,482 log 12796 7212 Bad Request: /buy/UserGroupBuys/
ERROR 2023-05-14 19:36:21,492 log 12796 7212 Internal Server Error: /buy/UserGroupBuys/
WARNING 2023-05-14 19:36:21,524 log 12796 7212 Bad Request: /buy/UserGroupBuys/
WARNING 2023-05-14 19:36:21,528 log 12796 7212 Unauthorized: /buy/UserGroupBuys/
WARNING 2023-05-14 19:36:21,594 log 12796 7212 Forbidden: /buy/UserGroupBuys/
WARNING 2023-05-14 19:36:49,504 log 4180 10388 Forbidden: /buy/GetGroupBuys/
WARNING 2023-05-14 19:36:49,679 log 4180 10388 Forbidden: /buy/GetGroupBuys/
WARNING 2023-05-14 19:36:49,694 log 4180 10388 Forbidden: /buy/GetGroupBuys/
WARNING 2023-05-14 19:36:49,735 log 4180 10388 Forbidden: /buy/GetGroupBuys/
WARNING 2023-05-14 19:36:49,754 log 4180 10388 Bad Request: /buy/UserGroupBuys/
ERROR 2023-05-14 19:36:49,765 log 4180 10388 Internal Server Error: /buy/UserGroupBuys/
WARNING 2023-05-14 19:36:49,796 log 4180 10388 Bad Request: /buy/UserGroupBuys/
WARNING 2023-05-14 19:36:49,802 log 4180 10388 Unauthorized: /buy/UserGroupBuys/
WARNING 2023-05-14 19:36:49,866 log 4180 10388 Forbidden: /buy/UserGroupBuys/
